Workbook

Sheet Start Here
B2: Etsy Seller Profit & Fee Tracker
B3: See what you really keep from every Etsy sale after fees, postage and materials. Works in Excel and Google Sheets.
B5: QUICK START (10 minutes)
B6: 1. 'Products' tab: list what you sell and what one unit costs you to make (materials + packaging). Delete the example row first.
B7: 2. 'Orders' tab: one row per order. Pick the product from the dropdown, enter the quantity, what the buyer paid for the items and for shipping,
B8: the postage label you paid, and whether the sale came from an Etsy Offsite Ad. Etsy fees, product cost and profit work themselves out.
B9: 3. 'Shop Expenses' tab: everything not tied to one order: Etsy Ads, listing fees, packaging bought in bulk, software, photography.
B10: 4. 'Dashboard' shows the year at a glance (change the year in cell C3). 'Monthly P&L' shows each month.
B11: 5. 'Price Calculator' tells you what to charge for a new product to hit the profit you want, after every Etsy fee.
B12: 6. 'Fee Settings' holds Etsy's fee rates. They are set to Etsy's standard US rates; update them there if Etsy changes its fees.
B13: 7. Red cells mean a row needs fixing (bad date, unknown product, text in an amount). That row stays out of the totals until fixed.
B14: The count shows at the top of each tab and on the Dashboard.
... B34: Questions or a formula not behaving? Email nora@qnsai.com. Made by Nora Studio.

Sheet Dashboard
B1: Etsy Shop Dashboard
B3: Year: | C3: 2026 | D3: ="Updates automatically from Orders and Shop Expenses"&IF(Orders!M2+'Shop Expenses'!G2>0," | "&(Orders!M2+'Shop Expenses'!G2)&" row(s) need fixing - see red cells","") -> Updates automatically from Orders and Shop Expenses | V3: Chart data (do not edit)
V4: Month | W4: Gross sales | X4: Net profit | Y4: Etsy fees
B5: GROSS SALES | G5: NET PROFIT | L5: PROFIT MARGIN | V5: Jan | W5: =Calc!E3+Calc!F3 -> 82.9 | X5: =Calc!R3 -> 23.7556 | Y5: =Calc!N3 -> 16.7044
B6: =Calc!E15+Calc!F15 -> 82.9 | G6: =Calc!R15 -> 23.7556 | L6: =Calc!S15 -> 0.2865573 | V6: Feb | W6: =Calc!E4+Calc!F4 -> 0 | X6: =Calc!R4 -> 0 | Y6: =Calc!N4 -> 0
V7: Mar | W7: =Calc!E5+Calc!F5 -> 0 | X7: =Calc!R5 -> 0 | Y7: =Calc!N5 -> 0
V8: Apr | W8: =Calc!E6+Calc!F6 -> 0 | X8: =Calc!R6 -> 0 | Y8: =Calc!N6 -> 0
B9: ETSY FEES | G9: FEES AS % OF SALES | L9: ORDERS | V9: May | W9: =Calc!E7+Calc!F7 -> 0 | X9: =Calc!R7 -> 0 | Y9: =Calc!N7 -> 0
B10: =Calc!N15 -> 16.7044 | G10: =IF(Calc!E15+Calc!F15>0,Calc!N15/(Calc!E15+Calc!F15),0) -> 0.2015006 | L10: =Calc!C15 -> 2 | V10: Jun | W10: =Calc!E8+Calc!F8 -> 0 | X10: =Calc!R8 -> 0 | Y10: =Calc!N8 -> 0
V11: Jul | W11: =Calc!E9+Calc!F9 -> 0 | X11: =Calc!R9 -> 0 | Y11: =Calc!N9 -> 0
V12: Aug | W12: =Calc!E10+Calc!F10 -> 0 | X12: =Calc!R10 -> 0 | Y12: =Calc!N10 -> 0
V13: Sep | W13: =Calc!E11+Calc!F11 -> 0 | X13: =Calc!R11 -> 0 | Y13: =Calc!N11 -> 0
V14: Oct | W14: =Calc!E12+Calc!F12 -> 0 | X14: =Calc!R12 -> 0 | Y14: =Calc!N12 -> 0
V15: Nov | W15: =Calc!E13+Calc!F13 -> 0 | X15: =Calc!R13 -> 0 | Y15: =Calc!N13 -> 0
V16: Dec | W16: =Calc!E14+Calc!F14 -> 0 | X16: =Calc!R14 -> 0 | Y16: =Calc!N14 -> 0
V19: Where sales go | W19: Amount
V20: Transaction fees | W20: =Calc!J15 -> 5.3885
V21: Processing fees | W21: =Calc!K15 -> 3.1559
V22: Offsite Ads | W22: =Calc!L15 -> 7.56
V23: Listing renewals | W23: =Calc!M15 -> 0.6
V24: Postage | W24: =Calc!H15 -> 8.24
V25: Product costs | W25: =Calc!O15 -> 19.2
V26: Shop expenses | W26: =Calc!P15 -> 15
V27: Your profit | W27: =Calc!R15 -> 23.7556
V30: Product | W30: Profit on items | X30: Sort key
V31: =IF(Products!B5="","",Products!B5) -> EXAMPLE: Custom name necklace | W31: =IF(Products!B5="",0,N(Products!G5)) -> 43.592 | X31: =IF(V31="",-1000000000000,W31)+50/1000000 -> 43.59205
V32: =IF(Products!B6="","",Products!B6) | W32: =IF(Products!B6="",0,N(Products!G6)) -> 0 | X32: =IF(V32="",-1000000000000,W32)+49/1000000 -> -1000000000000
V33: =IF(Products!B7="","",Products!B7) | W33: =IF(Products!B7="",0,N(Products!G7)) -> 0 | X33: =IF(V33="",-1000000000000,W33)+48/1000000 -> -1000000000000
V34: =IF(Products!B8="","",Products!B8) | W34: =IF(Products!B8="",0,N(Products!G8)) -> 0 | X34: =IF(V34="",-1000000000000,W34)+47/1000000 -> -1000000000000
V35: =IF(Products!B9="","",Products!B9) | W35: =IF(Products!B9="",0,N(Products!G9)) -> 0 | X35: =IF(V35="",-1000000000000,W35)+46/1000000 -> -1000000000000
V36: =IF(Products!B10="","",Products!B10) | W36: =IF(Products!B10="",0,N(Products!G10)) -> 0 | X36: =IF(V36="",-1000000000000,W36)+45/1000000 -> -1000000000000
V37: =IF(Products!B11="","",Products!B11) | W37: =IF(Products!B11="",0,N(Products!G11)) -> 0 | X37: =IF(V37="",-1000000000000,W37)+44/1000000 -> -1000000000000
V38: =IF(Products!B12="","",Products!B12) | W38: =IF(Products!B12="",0,N(Products!G12)) -> 0 | X38: =IF(V38="",-1000000000000,W38)+43/1000000 -> -1000000000000
V39: =IF(Products!B13="","",Products!B13) | W39: =IF(Products!B13="",0,N(Products!G13)) -> 0 | X39: =IF(V39="",-1000000000000,W39)+42/1000000 -> -1000000000000
V40: =IF(Products!B14="","",Products!B14) | W40: =IF(Products!B14="",0,N(Products!G14)) -> 0 | X40: =IF(V40="",-1000000000000,W40)+41/1000000 -> -1000000000000
V41: =IF(Products!B15="","",Products!B15) | W41: =IF(Products!B15="",0,N(Products!G15)) -> 0 | X41: =IF(V41="",-1000000000000,W41)+40/1000000 -> -1000000000000
V42: =IF(Products!B16="","",Products!B16) | W42: =IF(Products!B16="",0,N(Products!G16)) -> 0 | X42: =IF(V42="",-1000000000000,W42)+39/1000000 -> -1000000000000
V43: =IF(Products!B17="","",Products!B17) | W43: =IF(Products!B17="",0,N(Products!G17)) -> 0 | X43: =IF(V43="",-1000000000000,W43)+38/1000000 -> -1000000000000
V44: =IF(Products!B18="","",Products!B18) | W44: =IF(Products!B18="",0,N(Products!G18)) -> 0 | X44: =IF(V44="",-1000000000000,W44)+37/1000000 -> -1000000000000
V45: =IF(Products!B19="","",Products!B19) | W45: =IF(Products!B19="",0,N(Products!G19)) -> 0 | X45: =IF(V45="",-1000000000000,W45)+36/1000000 -> -1000000000000
...

Sheet Orders
A1: Orders
A2: One row per order (or per product in a multi-product order). Amounts are what the buyer paid, before Etsy's fees. | L2: Rows to fix: | M2: =SUMPRODUCT((((Orders!$A$5:$A$2004<>"")+(Orders!$C$5:$C$2004<>"")+(Orders!$D$5:$D$2004<>"")+(Orders!$E$5:$E$2004<>"")+(Orders!$F$5:$F$2004<>"")+(Orders!$H$5:$H$2004<>"")+(Orders!$J$5:$J$2004<>""))>0)*((ISNUMBER(Orders!$A$5:$A$2004)*ISNUMBER(MATCH(Orders!$C$5:$C$2004,Lists!$A$2:$A$26,0))*ISNUMBER(Orders!$D$5:$D$2004)*(Orders!$D$5:$D$2004>0)*ISNUMBER(Orders!$E$5:$E$2004)*(ISNUMBER(Orders!$F$5:$F$2004)+(Orders!$F$5:$F$2004=""))*(ISNUMBER(Orders!$G$5:$G$2004)+(Orders!$G$5:$G$2004=""))*(ISNUMBER(Orders!$H$5:$H$2004)+(Orders!$H$5:$H$2004=""))*(ISNUMBER(Orders!$J$5:$J$2004)+(Orders!$J$5:$J$2004=""))*((Orders!$I$5:$I$2004="Yes")+(Orders!$I$5:$I$2004="No")+(Orders!$I$5:$I$2004="")))=0)) -> 0
A3: Red cell = something to fix (bad date, unknown product, text in an amount). That row stays out of the totals until fixed.
A4: Date | B4: Order # | C4: Product | D4: Qty | E4: Item total paid | F4: Shipping charged | G4: Sales tax (Etsy collected) | H4: Postage you paid | I4: Offsite Ads sale? | J4: Refunded to buyer | K4: Etsy fees (est.) | L4: Product cost | M4: Profit
A5: 46028 | B5: 3301 | C5: EXAMPLE: Custom name necklace | D5: 1 | E5: 28 | F5: 4.5 | G5: 2.1 | H5: 4.12 | I5: No | K5: =IF(C5="","",IFERROR(N('Fee Settings'!$C$5)*(E5+N(F5)-N(J5))+N('Fee Settings'!$C$6)*(E5+N(F5)+N(G5))+N('Fee Settings'!$C$7)+N('Fee Settings'!$C$10)*D5+IF(I5="Yes",MIN(N('Fee Settings'!$C$8)*(E5+N(F5)),N('Fee Settings'!$C$9)),0),"")) -> 3.6005 | L5: =IF(C5="","",IFERROR(D5*N(INDEX(Products!$C$5:$C$29,MATCH(C5,Lists!$A$2:$A$26,0))),"")) -> 6.4 | M5: =IF(C5="","",IFERROR(E5+N(F5)-N(J5)-K5-L5-N(H5),"")) -> 18.3795
A6: 46031 | B6: 3302 | C6: EXAMPLE: Custom name necklace | D6: 2 | E6: 50.4 | F6: 0 | G6: 3.53 | H6: 4.12 | I6: Yes | K6: =IF(C6="","",IFERROR(N('Fee Settings'!$C$5)*(E6+N(F6)-N(J6))+N('Fee Settings'!$C$6)*(E6+N(F6)+N(G6))+N('Fee Settings'!$C$7)+N('Fee Settings'!$C$10)*D6+IF(I6="Yes",MIN(N('Fee Settings'!$C$8)*(E6+N(F6)),N('Fee Settings'!$C$9)),0),"")) -> 13.1039 | L6: =IF(C6="","",IFERROR(D6*N(INDEX(Products!$C$5:$C$29,MATCH(C6,Lists!$A$2:$A$26,0))),"")) -> 12.8 | M6: =IF(C6="","",IFERROR(E6+N(F6)-N(J6)-K6-L6-N(H6),"")) -> 20.3761
K7: =IF(C7="","",IFERROR(N('Fee Settings'!$C$5)*(E7+N(F7)-N(J7))+N('Fee Settings'!$C$6)*(E7+N(F7)+N(G7))+N('Fee Settings'!$C$7)+N('Fee Settings'!$C$10)*D7+IF(I7="Yes",MIN(N('Fee Settings'!$C$8)*(E7+N(F7)),N('Fee Settings'!$C$9)),0),"")) | L7: =IF(C7="","",IFERROR(D7*N(INDEX(Products!$C$5:$C$29,MATCH(C7,Lists!$A$2:$A$26,0))),"")) | M7: =IF(C7="","",IFERROR(E7+N(F7)-N(J7)-K7-L7-N(H7),""))
K8: =IF(C8="","",IFERROR(N('Fee Settings'!$C$5)*(E8+N(F8)-N(J8))+N('Fee Settings'!$C$6)*(E8+N(F8)+N(G8))+N('Fee Settings'!$C$7)+N('Fee Settings'!$C$10)*D8+IF(I8="Yes",MIN(N('Fee Settings'!$C$8)*(E8+N(F8)),N('Fee Settings'!$C$9)),0),"")) | L8: =IF(C8="","",IFERROR(D8*N(INDEX(Products!$C$5:$C$29,MATCH(C8,Lists!$A$2:$A$26,0))),"")) | M8: =IF(C8="","",IFERROR(E8+N(F8)-N(J8)-K8-L8-N(H8),""))
K9: =IF(C9="","",IFERROR(N('Fee Settings'!$C$5)*(E9+N(F9)-N(J9))+N('Fee Settings'!$C$6)*(E9+N(F9)+N(G9))+N('Fee Settings'!$C$7)+N('Fee Settings'!$C$10)*D9+IF(I9="Yes",MIN(N('Fee Settings'!$C$8)*(E9+N(F9)),N('Fee Settings'!$C$9)),0),"")) | L9: =IF(C9="","",IFERROR(D9*N(INDEX(Products!$C$5:$C$29,MATCH(C9,Lists!$A$2:$A$26,0))),"")) | M9: =IF(C9="","",IFERROR(E9+N(F9)-N(J9)-K9-L9-N(H9),""))
K10: =IF(C10="","",IFERROR(N('Fee Settings'!$C$5)*(E10+N(F10)-N(J10))+N('Fee Settings'!$C$6)*(E10+N(F10)+N(G10))+N('Fee Settings'!$C$7)+N('Fee Settings'!$C$10)*D10+IF(I10="Yes",MIN(N('Fee Settings'!$C$8)*(E10+N(F10)),N('Fee Settings'!$C$9)),0),"")) | L10: =IF(C10="","",IFERROR(D10*N(INDEX(Products!$C$5:$C$29,MATCH(C10,Lists!$A$2:$A$26,0))),"")) | M10: =IF(C10="","",IFERROR(E10+N(F10)-N(J10)-K10-L10-N(H10),""))
K11: =IF(C11="","",IFERROR(N('Fee Settings'!$C$5)*(E11+N(F11)-N(J11))+N('Fee Settings'!$C$6)*(E11+N(F11)+N(G11))+N('Fee Settings'!$C$7)+N('Fee Settings'!$C$10)*D11+IF(I11="Yes",MIN(N('Fee Settings'!$C$8)*(E11+N(F11)),N('Fee Settings'!$C$9)),0),"")) | L11: =IF(C11="","",IFERROR(D11*N(INDEX(Products!$C$5:$C$29,MATCH(C11,Lists!$A$2:$A$26,0))),"")) | M11: =IF(C11="","",IFERROR(E11+N(F11)-N(J11)-K11-L11-N(H11),""))
K12: =IF(C12="","",IFERROR(N('Fee Settings'!$C$5)*(E12+N(F12)-N(J12))+N('Fee Settings'!$C$6)*(E12+N(F12)+N(G12))+N('Fee Settings'!$C$7)+N('Fee Settings'!$C$10)*D12+IF(I12="Yes",MIN(N('Fee Settings'!$C$8)*(E12+N(F12)),N('Fee Settings'!$C$9)),0),"")) | L12: =IF(C12="","",IFERROR(D12*N(INDEX(Products!$C$5:$C$29,MATCH(C12,Lists!$A$2:$A$26,0))),"")) | M12: =IF(C12="","",IFERROR(E12+N(F12)-N(J12)-K12-L12-N(H12),""))
K13: =IF(C13="","",IFERROR(N('Fee Settings'!$C$5)*(E13+N(F13)-N(J13))+N('Fee Settings'!$C$6)*(E13+N(F13)+N(G13))+N('Fee Settings'!$C$7)+N('Fee Settings'!$C$10)*D13+IF(I13="Yes",MIN(N('Fee Settings'!$C$8)*(E13+N(F13)),N('Fee Settings'!$C$9)),0),"")) | L13: =IF(C13="","",IFERROR(D13*N(INDEX(Products!$C$5:$C$29,MATCH(C13,Lists!$A$2:$A$26,0))),"")) | M13: =IF(C13="","",IFERROR(E13+N(F13)-N(J13)-K13-L13-N(H13),""))
K14: =IF(C14="","",IFERROR(N('Fee Settings'!$C$5)*(E14+N(F14)-N(J14))+N('Fee Settings'!$C$6)*(E14+N(F14)+N(G14))+N('Fee Settings'!$C$7)+N('Fee Settings'!$C$10)*D14+IF(I14="Yes",MIN(N('Fee Settings'!$C$8)*(E14+N(F14)),N('Fee Settings'!$C$9)),0),"")) | L14: =IF(C14="","",IFERROR(D14*N(INDEX(Products!$C$5:$C$29,MATCH(C14,Lists!$A$2:$A$26,0))),"")) | M14: =IF(C14="","",IFERROR(E14+N(F14)-N(J14)-K14-L14-N(H14),""))
K15: =IF(C15="","",IFERROR(N('Fee Settings'!$C$5)*(E15+N(F15)-N(J15))+N('Fee Settings'!$C$6)*(E15+N(F15)+N(G15))+N('Fee Settings'!$C$7)+N('Fee Settings'!$C$10)*D15+IF(I15="Yes",MIN(N('Fee Settings'!$C$8)*(E15+N(F15)),N('Fee Settings'!$C$9)),0),"")) | L15: =IF(C15="","",IFERROR(D15*N(INDEX(Products!$C$5:$C$29,MATCH(C15,Lists!$A$2:$A$26,0))),"")) | M15: =IF(C15="","",IFERROR(E15+N(F15)-N(J15)-K15-L15-N(H15),""))
K16: =IF(C16="","",IFERROR(N('Fee Settings'!$C$5)*(E16+N(F16)-N(J16))+N('Fee Settings'!$C$6)*(E16+N(F16)+N(G16))+N('Fee Settings'!$C$7)+N('Fee Settings'!$C$10)*D16+IF(I16="Yes",MIN(N('Fee Settings'!$C$8)*(E16+N(F16)),N('Fee Settings'!$C$9)),0),"")) | L16: =IF(C16="","",IFERROR(D16*N(INDEX(Products!$C$5:$C$29,MATCH(C16,Lists!$A$2:$A$26,0))),"")) | M16: =IF(C16="","",IFERROR(E16+N(F16)-N(J16)-K16-L16-N(H16),""))
K17: =IF(C17="","",IFERROR(N('Fee Settings'!$C$5)*(E17+N(F17)-N(J17))+N('Fee Settings'!$C$6)*(E17+N(F17)+N(G17))+N('Fee Settings'!$C$7)+N('Fee Settings'!$C$10)*D17+IF(I17="Yes",MIN(N('Fee Settings'!$C$8)*(E17+N(F17)),N('Fee Settings'!$C$9)),0),"")) | L17: =IF(C17="","",IFERROR(D17*N(INDEX(Products!$C$5:$C$29,MATCH(C17,Lists!$A$2:$A$26,0))),"")) | M17: =IF(C17="","",IFERROR(E17+N(F17)-N(J17)-K17-L17-N(H17),""))
K18: =IF(C18="","",IFERROR(N('Fee Settings'!$C$5)*(E18+N(F18)-N(J18))+N('Fee Settings'!$C$6)*(E18+N(F18)+N(G18))+N('Fee Settings'!$C$7)+N('Fee Settings'!$C$10)*D18+IF(I18="Yes",MIN(N('Fee Settings'!$C$8)*(E18+N(F18)),N('Fee Settings'!$C$9)),0),"")) | L18: =IF(C18="","",IFERROR(D18*N(INDEX(Products!$C$5:$C$29,MATCH(C18,Lists!$A$2:$A$26,0))),"")) | M18: =IF(C18="","",IFERROR(E18+N(F18)-N(J18)-K18-L18-N(H18),""))
... K2004: =IF(C2004="","",IFERROR(N('Fee Settings'!$C$5)*(E2004+N(F2004)-N(J2004))+N('Fee Settings'!$C$6)*(E2004+N(F2004)+N(G2004))+N('Fee Settings'!$C$7)+N('Fee Settings'!$C$10)*D2004+IF(I2004="Yes",MIN(N('Fee Settings'!$C$8)*(E2004+N(F2004)),N('Fee Settings'!$C$9)),0),"")) | L2004: =IF(C2004="","",IFERROR(D2004*N(INDEX(Products!$C$5:$C$29,MATCH(C2004,Lists!$A$2:$A$26,0))),"")) | M2004: =IF(C2004="","",IFERROR(E2004+N(F2004)-N(J2004)-K2004-L2004-N(H2004),""))

Sheet Products
A1: Products
A2: Up to 25 products. Yellow = you type. Year figures follow the year on the Dashboard.
A4: # | B4: Product name | C4: Your cost per unit (materials + packaging) | D4: Usual price | E4: Units sold | F4: Item sales | G4: Profit on items* | H4: Profit per unit
A5: 1 | B5: EXAMPLE: Custom name necklace | C5: 6.4 | D5: 28 | E5: =IF(B5="","",Calc!S20) -> 3 | F5: =IF(B5="","",Calc!P20) -> 78.4 | G5: =IF(B5="","",Calc!P20-Calc!Q20-N('Fee Settings'!$C$5)*(Calc!P20-Calc!Q20)-N('Fee Settings'!$C$6)*Calc!P20-Calc!R20-N('Fee Settings'!$C$10)*Calc!S20-N(C5)*Calc!S20) -> 43.592 | H5: =IF(OR(B5="",N(E5)=0),"",G5/E5) -> 14.530667
A6: 2 | E6: =IF(B6="","",Calc!S21) | F6: =IF(B6="","",Calc!P21) | G6: =IF(B6="","",Calc!P21-Calc!Q21-N('Fee Settings'!$C$5)*(Calc!P21-Calc!Q21)-N('Fee Settings'!$C$6)*Calc!P21-Calc!R21-N('Fee Settings'!$C$10)*Calc!S21-N(C6)*Calc!S21) | H6: =IF(OR(B6="",N(E6)=0),"",G6/E6)
A7: 3 | E7: =IF(B7="","",Calc!S22) | F7: =IF(B7="","",Calc!P22) | G7: =IF(B7="","",Calc!P22-Calc!Q22-N('Fee Settings'!$C$5)*(Calc!P22-Calc!Q22)-N('Fee Settings'!$C$6)*Calc!P22-Calc!R22-N('Fee Settings'!$C$10)*Calc!S22-N(C7)*Calc!S22) | H7: =IF(OR(B7="",N(E7)=0),"",G7/E7)
A8: 4 | E8: =IF(B8="","",Calc!S23) | F8: =IF(B8="","",Calc!P23) | G8: =IF(B8="","",Calc!P23-Calc!Q23-N('Fee Settings'!$C$5)*(Calc!P23-Calc!Q23)-N('Fee Settings'!$C$6)*Calc!P23-Calc!R23-N('Fee Settings'!$C$10)*Calc!S23-N(C8)*Calc!S23) | H8: =IF(OR(B8="",N(E8)=0),"",G8/E8)
A9: 5 | E9: =IF(B9="","",Calc!S24) | F9: =IF(B9="","",Calc!P24) | G9: =IF(B9="","",Calc!P24-Calc!Q24-N('Fee Settings'!$C$5)*(Calc!P24-Calc!Q24)-N('Fee Settings'!$C$6)*Calc!P24-Calc!R24-N('Fee Settings'!$C$10)*Calc!S24-N(C9)*Calc!S24) | H9: =IF(OR(B9="",N(E9)=0),"",G9/E9)
A10: 6 | E10: =IF(B10="","",Calc!S25) | F10: =IF(B10="","",Calc!P25) | G10: =IF(B10="","",Calc!P25-Calc!Q25-N('Fee Settings'!$C$5)*(Calc!P25-Calc!Q25)-N('Fee Settings'!$C$6)*Calc!P25-Calc!R25-N('Fee Settings'!$C$10)*Calc!S25-N(C10)*Calc!S25) | H10: =IF(OR(B10="",N(E10)=0),"",G10/E10)
A11: 7 | E11: =IF(B11="","",Calc!S26) | F11: =IF(B11="","",Calc!P26) | G11: =IF(B11="","",Calc!P26-Calc!Q26-N('Fee Settings'!$C$5)*(Calc!P26-Calc!Q26)-N('Fee Settings'!$C$6)*Calc!P26-Calc!R26-N('Fee Settings'!$C$10)*Calc!S26-N(C11)*Calc!S26) | H11: =IF(OR(B11="",N(E11)=0),"",G11/E11)
A12: 8 | E12: =IF(B12="","",Calc!S27) | F12: =IF(B12="","",Calc!P27) | G12: =IF(B12="","",Calc!P27-Calc!Q27-N('Fee Settings'!$C$5)*(Calc!P27-Calc!Q27)-N('Fee Settings'!$C$6)*Calc!P27-Calc!R27-N('Fee Settings'!$C$10)*Calc!S27-N(C12)*Calc!S27) | H12: =IF(OR(B12="",N(E12)=0),"",G12/E12)
A13: 9 | E13: =IF(B13="","",Calc!S28) | F13: =IF(B13="","",Calc!P28) | G13: =IF(B13="","",Calc!P28-Calc!Q28-N('Fee Settings'!$C$5)*(Calc!P28-Calc!Q28)-N('Fee Settings'!$C$6)*Calc!P28-Calc!R28-N('Fee Settings'!$C$10)*Calc!S28-N(C13)*Calc!S28) | H13: =IF(OR(B13="",N(E13)=0),"",G13/E13)
A14: 10 | E14: =IF(B14="","",Calc!S29) | F14: =IF(B14="","",Calc!P29) | G14: =IF(B14="","",Calc!P29-Calc!Q29-N('Fee Settings'!$C$5)*(Calc!P29-Calc!Q29)-N('Fee Settings'!$C$6)*Calc!P29-Calc!R29-N('Fee Settings'!$C$10)*Calc!S29-N(C14)*Calc!S29) | H14: =IF(OR(B14="",N(E14)=0),"",G14/E14)
A15: 11 | E15: =IF(B15="","",Calc!S30) | F15: =IF(B15="","",Calc!P30) | G15: =IF(B15="","",Calc!P30-Calc!Q30-N('Fee Settings'!$C$5)*(Calc!P30-Calc!Q30)-N('Fee Settings'!$C$6)*Calc!P30-Calc!R30-N('Fee Settings'!$C$10)*Calc!S30-N(C15)*Calc!S30) | H15: =IF(OR(B15="",N(E15)=0),"",G15/E15)
A16: 12 | E16: =IF(B16="","",Calc!S31) | F16: =IF(B16="","",Calc!P31) | G16: =IF(B16="","",Calc!P31-Calc!Q31-N('Fee Settings'!$C$5)*(Calc!P31-Calc!Q31)-N('Fee Settings'!$C$6)*Calc!P31-Calc!R31-N('Fee Settings'!$C$10)*Calc!S31-N(C16)*Calc!S31) | H16: =IF(OR(B16="",N(E16)=0),"",G16/E16)
A17: 13 | E17: =IF(B17="","",Calc!S32) | F17: =IF(B17="","",Calc!P32) | G17: =IF(B17="","",Calc!P32-Calc!Q32-N('Fee Settings'!$C$5)*(Calc!P32-Calc!Q32)-N('Fee Settings'!$C$6)*Calc!P32-Calc!R32-N('Fee Settings'!$C$10)*Calc!S32-N(C17)*Calc!S32) | H17: =IF(OR(B17="",N(E17)=0),"",G17/E17)
... A29: 25 | E29: =IF(B29="","",Calc!S44) | F29: =IF(B29="","",Calc!P44) | G29: =IF(B29="","",Calc!P44-Calc!Q44-N('Fee Settings'!$C$5)*(Calc!P44-Calc!Q44)-N('Fee Settings'!$C$6)*Calc!P44-Calc!R44-N('Fee Settings'!$C$10)*Calc!S44-N(C29)*Calc!S44) | H29: =IF(OR(B29="",N(E29)=0),"",G29/E29)
A31: *Profit on items = item sales minus refunds, the percentage Etsy fees on the items, renewals and your unit cost. Shipping, postage, fixed per-order fees and shop expenses are counted in the shop totals, not here.

Sheet Shop Expenses
A1: Shop Expenses
A2: Costs not tied to one order. Don't repeat materials here if they're already in a product's unit cost. | F2: Rows to fix: | G2: =SUMPRODUCT((('Shop Expenses'!$A$5:$A$504<>"")+('Shop Expenses'!$B$5:$B$504<>"")+('Shop Expenses'!$D$5:$D$504<>"")>0)*((ISNUMBER('Shop Expenses'!$A$5:$A$504)*ISNUMBER(MATCH('Shop Expenses'!$B$5:$B$504,Lists!$D$2:$D$13,0))*ISNUMBER('Shop Expenses'!$D$5:$D$504))=0)) -> 0
A3: Red cell = something to fix. That row stays out of the totals until fixed.
A4: Date | B4: Category | C4: Description / payee | D4: Amount
A5: 46025 | B5: Etsy Ads | C5: EXAMPLE: January Etsy Ads | D5: 15

Sheet Monthly P&L
A1: Monthly P&L
B3: Year: | C3: =Dashboard!C3 -> 2026 | D3: (change it on the Dashboard)
B5: Month | C5: Orders | D5: Gross sales | E5: Refunds | F5: Etsy fees | G5: Postage | H5: Product cost | I5: Shop expenses | J5: Net profit | K5: Margin
B6: Jan | C6: =Calc!C3 -> 2 | D6: =Calc!E3+Calc!F3 -> 82.9 | E6: =Calc!I3 -> 0 | F6: =Calc!N3 -> 16.7044 | G6: =Calc!H3 -> 8.24 | H6: =Calc!O3 -> 19.2 | I6: =Calc!P3 -> 15 | J6: =Calc!R3 -> 23.7556 | K6: =Calc!S3 -> 0.2865573
B7: Feb | C7: =Calc!C4 -> 0 | D7: =Calc!E4+Calc!F4 -> 0 | E7: =Calc!I4 -> 0 | F7: =Calc!N4 -> 0 | G7: =Calc!H4 -> 0 | H7: =Calc!O4 -> 0 | I7: =Calc!P4 -> 0 | J7: =Calc!R4 -> 0 | K7: =Calc!S4 -> 0
B8: Mar | C8: =Calc!C5 -> 0 | D8: =Calc!E5+Calc!F5 -> 0 | E8: =Calc!I5 -> 0 | F8: =Calc!N5 -> 0 | G8: =Calc!H5 -> 0 | H8: =Calc!O5 -> 0 | I8: =Calc!P5 -> 0 | J8: =Calc!R5 -> 0 | K8: =Calc!S5 -> 0
B9: Apr | C9: =Calc!C6 -> 0 | D9: =Calc!E6+Calc!F6 -> 0 | E9: =Calc!I6 -> 0 | F9: =Calc!N6 -> 0 | G9: =Calc!H6 -> 0 | H9: =Calc!O6 -> 0 | I9: =Calc!P6 -> 0 | J9: =Calc!R6 -> 0 | K9: =Calc!S6 -> 0
B10: May | C10: =Calc!C7 -> 0 | D10: =Calc!E7+Calc!F7 -> 0 | E10: =Calc!I7 -> 0 | F10: =Calc!N7 -> 0 | G10: =Calc!H7 -> 0 | H10: =Calc!O7 -> 0 | I10: =Calc!P7 -> 0 | J10: =Calc!R7 -> 0 | K10: =Calc!S7 -> 0
B11: Jun | C11: =Calc!C8 -> 0 | D11: =Calc!E8+Calc!F8 -> 0 | E11: =Calc!I8 -> 0 | F11: =Calc!N8 -> 0 | G11: =Calc!H8 -> 0 | H11: =Calc!O8 -> 0 | I11: =Calc!P8 -> 0 | J11: =Calc!R8 -> 0 | K11: =Calc!S8 -> 0
B12: Jul | C12: =Calc!C9 -> 0 | D12: =Calc!E9+Calc!F9 -> 0 | E12: =Calc!I9 -> 0 | F12: =Calc!N9 -> 0 | G12: =Calc!H9 -> 0 | H12: =Calc!O9 -> 0 | I12: =Calc!P9 -> 0 | J12: =Calc!R9 -> 0 | K12: =Calc!S9 -> 0
B13: Aug | C13: =Calc!C10 -> 0 | D13: =Calc!E10+Calc!F10 -> 0 | E13: =Calc!I10 -> 0 | F13: =Calc!N10 -> 0 | G13: =Calc!H10 -> 0 | H13: =Calc!O10 -> 0 | I13: =Calc!P10 -> 0 | J13: =Calc!R10 -> 0 | K13: =Calc!S10 -> 0
B14: Sep | C14: =Calc!C11 -> 0 | D14: =Calc!E11+Calc!F11 -> 0 | E14: =Calc!I11 -> 0 | F14: =Calc!N11 -> 0 | G14: =Calc!H11 -> 0 | H14: =Calc!O11 -> 0 | I14: =Calc!P11 -> 0 | J14: =Calc!R11 -> 0 | K14: =Calc!S11 -> 0
B15: Oct | C15: =Calc!C12 -> 0 | D15: =Calc!E12+Calc!F12 -> 0 | E15: =Calc!I12 -> 0 | F15: =Calc!N12 -> 0 | G15: =Calc!H12 -> 0 | H15: =Calc!O12 -> 0 | I15: =Calc!P12 -> 0 | J15: =Calc!R12 -> 0 | K15: =Calc!S12 -> 0
B16: Nov | C16: =Calc!C13 -> 0 | D16: =Calc!E13+Calc!F13 -> 0 | E16: =Calc!I13 -> 0 | F16: =Calc!N13 -> 0 | G16: =Calc!H13 -> 0 | H16: =Calc!O13 -> 0 | I16: =Calc!P13 -> 0 | J16: =Calc!R13 -> 0 | K16: =Calc!S13 -> 0
B17: Dec | C17: =Calc!C14 -> 0 | D17: =Calc!E14+Calc!F14 -> 0 | E17: =Calc!I14 -> 0 | F17: =Calc!N14 -> 0 | G17: =Calc!H14 -> 0 | H17: =Calc!O14 -> 0 | I17: =Calc!P14 -> 0 | J17: =Calc!R14 -> 0 | K17: =Calc!S14 -> 0
B18: Total | C18: =Calc!C15 -> 2 | D18: =Calc!E15+Calc!F15 -> 82.9 | E18: =Calc!I15 -> 0 | F18: =Calc!N15 -> 16.7044 | G18: =Calc!H15 -> 8.24 | H18: =Calc!O15 -> 19.2 | I18: =Calc!P15 -> 15 | J18: =Calc!R15 -> 23.7556 | K18: =Calc!S15 -> 0.2865573
B20: Gross sales = item totals + shipping charged. Sales tax is excluded (Etsy collects and pays it).

Sheet Price Calculator
A1: Price Calculator
A2: What should this product cost on Etsy? Fill the yellow cells.
B4: Inputs | E4: Recommended price
B5: Materials per item | C5: 6 | E5: Total cost per item (materials, packaging, time, postage) | F5: =(N(C5)+N(C6)+N(C7)*N(C8)+N(C9)) -> 21.7
B6: Packaging per item | C6: 1.2 | E6: Etsy % fees on item + shipping | F6: =(N('Fee Settings'!$C$5)+N('Fee Settings'!$C$6)+IF($C$12="Yes",N('Fee Settings'!$C$8),0)) -> 0.095
B7: Your time per item (hours) | C7: 0.5 | E7: Price to charge (exact) | F7: =IFERROR(MAX(0,((N(C5)+N(C6)+N(C7)*N(C8)+N(C9))+N(C11)+N('Fee Settings'!$C$7)+N('Fee Settings'!$C$10)-N(C10)*(1-(N('Fee Settings'!$C$5)+N('Fee Settings'!$C$6)+IF($C$12="Yes",N('Fee Settings'!$C$8),0))))/(1-(N('Fee Settings'!$C$5)+N('Fee Settings'!$C$6)+IF($C$12="Yes",N('Fee Settings'!$C$8),0)))),0) -> 28.814917
B8: Your hourly rate | C8: 20 | E8: Price to charge (rounded to .99) | F8: =IF(F7<=0,0,CEILING(F7+0.01,1)-0.01) -> 28.99
B9: Postage you pay | C9: 4.5 | E9: Etsy fees at that price | F9: =IF(F8=0,0,N('Fee Settings'!$C$5)*(F8+N(C10))+N('Fee Settings'!$C$6)*(F8+N(C10))+N('Fee Settings'!$C$7)+N('Fee Settings'!$C$10)+IF($C$12="Yes",MIN(N('Fee Settings'!$C$8)*(F8+N(C10)),N('Fee Settings'!$C$9)),0)) -> 3.63155
B10: Shipping you charge the buyer | C10: 4.5 | E10: Profit per sale at that price | F10: =IF(F8=0,0,F8+N(C10)-F9-F5) -> 8.15845
B11: Profit you want per sale (after paying yourself) | C11: 8
B12: Assume an Offsite Ads sale? (Yes/No) | C12: No
E13: Check a price you have in mind
E14: Your price | F14: 25
B15: Your time is a cost: the recommended price pays your hourly rate first, then the profit you asked for. | E15: Etsy fees | F15: =IF(N(F14)=0,0,N('Fee Settings'!$C$5)*(N(F14)+N(C10))+N('Fee Settings'!$C$6)*(N(F14)+N(C10))+N('Fee Settings'!$C$7)+N('Fee Settings'!$C$10)+IF($C$12="Yes",MIN(N('Fee Settings'!$C$8)*(N(F14)+N(C10)),N('Fee Settings'!$C$9)),0)) -> 3.2525
B16: Sales tax is left out: Etsy collects it, and the small processing fee on it is ignored here. | E16: Profit per sale (after paying yourself) | F16: =IF(N(F14)=0,0,N(F14)+N(C10)-F15-F5) -> 4.5475
E17: Profit margin | F17: =IF(N(F14)+N(C10)=0,0,F16/(N(F14)+N(C10))) -> 0.15415254

Sheet Fee Settings
A1: Fee Settings
A2: Etsy's standard US seller fees. Change a yellow cell only if Etsy changes its rates or you sell from another country.
B4: Fee | C4: Rate | D4: Notes
B5: Transaction fee (% of item + shipping) | C5: 0.065 | D5: Etsy transaction fee.
B6: Payment processing (% of order total) | C6: 0.03 | D6: US Etsy Payments rate; charged on item + shipping + sales tax.
B7: Payment processing (fixed, per order) | C7: 0.25 | D7: Charged once per order.
B8: Offsite Ads fee (% of item + shipping) | C8: 0.15 | D8: 15%; 12% if your shop made $10,000+ in the past 12 months.
B9: Offsite Ads cap (per order) | C9: 100 | D9: Etsy never charges more than this per order.
B10: Listing renewal (per item sold) | C10: 0.2 | D10: An auto-renewed or multi-quantity listing costs this for each item sold.
B12: Rates last checked against etsy.com/legal/fees: October 2026.

Sheet Lists
A1: Valid products (for totals) | B1: Product dropdown | D1: Expense categories | F1: Yes/No
A2: =IF(Products!B5="","[empty slot 1]",Products!B5) -> EXAMPLE: Custom name necklace | B2: =IF(Products!B5="","",Products!B5) -> EXAMPLE: Custom name necklace | D2: Etsy Ads | F2: Yes
A3: =IF(Products!B6="","[empty slot 2]",Products!B6) -> [empty slot 2] | B3: =IF(Products!B6="","",Products!B6) | D3: Listing fees (not tied to a sale) | F3: No
A4: =IF(Products!B7="","[empty slot 3]",Products!B7) -> [empty slot 3] | B4: =IF(Products!B7="","",Products!B7) | D4: Etsy Plus / subscriptions
A5: =IF(Products!B8="","[empty slot 4]",Products!B8) -> [empty slot 4] | B5: =IF(Products!B8="","",Products!B8) | D5: Shipping supplies
A6: =IF(Products!B9="","[empty slot 5]",Products!B9) -> [empty slot 5] | B6: =IF(Products!B9="","",Products!B9) | D6: Packaging
A7: =IF(Products!B10="","[empty slot 6]",Products!B10) -> [empty slot 6] | B7: =IF(Products!B10="","",Products!B10) | D7: Materials bought in bulk
A8: =IF(Products!B11="","[empty slot 7]",Products!B11) -> [empty slot 7] | B8: =IF(Products!B11="","",Products!B11) | D8: Equipment and tools
A9: =IF(Products!B12="","[empty slot 8]",Products!B12) -> [empty slot 8] | B9: =IF(Products!B12="","",Products!B12) | D9: Software and apps
A10: =IF(Products!B13="","[empty slot 9]",Products!B13) -> [empty slot 9] | B10: =IF(Products!B13="","",Products!B13) | D10: Photography
A11: =IF(Products!B14="","[empty slot 10]",Products!B14) -> [empty slot 10] | B11: =IF(Products!B14="","",Products!B14) | D11: Marketing (non-Etsy)
A12: =IF(Products!B15="","[empty slot 11]",Products!B15) -> [empty slot 11] | B12: =IF(Products!B15="","",Products!B15) | D12: Bank and other fees
A13: =IF(Products!B16="","[empty slot 12]",Products!B16) -> [empty slot 12] | B13: =IF(Products!B16="","",Products!B16) | D13: Other
A14: =IF(Products!B17="","[empty slot 13]",Products!B17) -> [empty slot 13] | B14: =IF(Products!B17="","",Products!B17)
A15: =IF(Products!B18="","[empty slot 14]",Products!B18) -> [empty slot 14] | B15: =IF(Products!B18="","",Products!B18)
A16: =IF(Products!B19="","[empty slot 15]",Products!B19) -> [empty slot 15] | B16: =IF(Products!B19="","",Products!B19)
A17: =IF(Products!B20="","[empty slot 16]",Products!B20) -> [empty slot 16] | B17: =IF(Products!B20="","",Products!B20)
A18: =IF(Products!B21="","[empty slot 17]",Products!B21) -> [empty slot 17] | B18: =IF(Products!B21="","",Products!B21)
A19: =IF(Products!B22="","[empty slot 18]",Products!B22) -> [empty slot 18] | B19: =IF(Products!B22="","",Products!B22)
A20: =IF(Products!B23="","[empty slot 19]",Products!B23) -> [empty slot 19] | B20: =IF(Products!B23="","",Products!B23)
A21: =IF(Products!B24="","[empty slot 20]",Products!B24) -> [empty slot 20] | B21: =IF(Products!B24="","",Products!B24)
A22: =IF(Products!B25="","[empty slot 21]",Products!B25) -> [empty slot 21] | B22: =IF(Products!B25="","",Products!B25)
A23: =IF(Products!B26="","[empty slot 22]",Products!B26) -> [empty slot 22] | B23: =IF(Products!B26="","",Products!B26)
A24: =IF(Products!B27="","[empty slot 23]",Products!B27) -> [empty slot 23] | B24: =IF(Products!B27="","",Products!B27)
A25: =IF(Products!B28="","[empty slot 24]",Products!B28) -> [empty slot 24] | B25: =IF(Products!B28="","",Products!B28)
A26: =IF(Products!B29="","[empty slot 25]",Products!B29) -> [empty slot 25] | B26: =IF(Products!B29="","",Products!B29)

Sheet Calc
B2: Month | C2: Orders | D2: Qty | E2: Item sales | F2: Shipping | G2: Sales tax | H2: Postage | I2: Refunds | J2: Transaction fee | K2: Processing fee | L2: Offsite Ads fee | M2: Renewal fee | N2: Etsy fees total | O2: Product cost | P2: Shop expenses | Q2: Net sales | R2: Net profit | S2: Margin
B3: Jan | C3: =SUMPRODUCT((ISNUMBER(Orders!$A$5:$A$2004)*ISNUMBER(MATCH(Orders!$C$5:$C$2004,Lists!$A$2:$A$26,0))*ISNUMBER(Orders!$D$5:$D$2004)*(Orders!$D$5:$D$2004>0)*ISNUMBER(Orders!$E$5:$E$2004)*(ISNUMBER(Orders!$F$5:$F$2004)+(Orders!$F$5:$F$2004=""))*(ISNUMBER(Orders!$G$5:$G$2004)+(Orders!$G$5:$G$2004=""))*(ISNUMBER(Orders!$H$5:$H$2004)+(Orders!$H$5:$H$2004=""))*(ISNUMBER(Orders!$J$5:$J$2004)+(Orders!$J$5:$J$2004=""))*((Orders!$I$5:$I$2004="Yes")+(Orders!$I$5:$I$2004="No")+(Orders!$I$5:$I$2004="")))*(Orders!$A$5:$A$2004>=DATE(Dashboard!$C$3,1,1))*(Orders!$A$5:$A$2004<DATE(Dashboard!$C$3,2,1))) -> 2 | D3: =SUMPRODUCT((ISNUMBER(Orders!$A$5:$A$2004)*ISNUMBER(MATCH(Orders!$C$5:$C$2004,Lists!$A$2:$A$26,0))*ISNUMBER(Orders!$D$5:$D$2004)*(Orders!$D$5:$D$2004>0)*ISNUMBER(Orders!$E$5:$E$2004)*(ISNUMBER(Orders!$F$5:$F$2004)+(Orders!$F$5:$F$2004=""))*(ISNUMBER(Orders!$G$5:$G$2004)+(Orders!$G$5:$G$2004=""))*(ISNUMBER(Orders!$H$5:$H$2004)+(Orders!$H$5:$H$2004=""))*(ISNUMBER(Orders!$J$5:$J$2004)+(Orders!$J$5:$J$2004=""))*((Orders!$I$5:$I$2004="Yes")+(Orders!$I$5:$I$2004="No")+(Orders!$I$5:$I$2004="")))*(Orders!$A$5:$A$2004>=DATE(Dashboard!$C$3,1,1))*(Orders!$A$5:$A$2004<DATE(Dashboard!$C$3,2,1)),Orders!$D$5:$D$2004) -> 3 | E3: =SUMPRODUCT((ISNUMBER(Orders!$A$5:$A$2004)*ISNUMBER(MATCH(Orders!$C$5:$C$2004,Lists!$A$2:$A$26,0))*ISNUMBER(Orders!$D$5:$D$2004)*(Orders!$D$5:$D$2004>0)*ISNUMBER(Orders!$E$5:$E$2004)*(ISNUMBER(Orders!$F$5:$F$2004)+(Orders!$F$5:$F$2004=""))*(ISNUMBER(Orders!$G$5:$G$2004)+(Orders!$G$5:$G$2004=""))*(ISNUMBER(Orders!$H$5:$H$2004)+(Orders!$H$5:$H$2004=""))*(ISNUMBER(Orders!$J$5:$J$2004)+(Orders!$J$5:$J$2004=""))*((Orders!$I$5:$I$2004="Yes")+(Orders!$I$5:$I$2004="No")+(Orders!$I$5:$I$2004="")))*(Orders!$A$5:$A$2004>=DATE(Dashboard!$C$3,1,1))*(Orders!$A$5:$A$2004<DATE(Dashboard!$C$3,2,1)),Orders!$E$5:$E$2004) -> 78.4 | F3: =SUMPRODUCT((ISNUMBER(Orders!$A$5:$A$2004)*ISNUMBER(MATCH(Orders!$C$5:$C$2004,Lists!$A$2:$A$26,0))*ISNUMBER(Orders!$D$5:$D$2004)*(Orders!$D$5:$D$2004>0)*ISNUMBER(Orders!$E$5:$E$2004)*(ISNUMBER(Orders!$F$5:$F$2004)+(Orders!$F$5:$F$2004=""))*(ISNUMBER(Orders!$G$5:$G$2004)+(Orders!$G$5:$G$2004=""))*(ISNUMBER(Orders!$H$5:$H$2004)+(Orders!$H$5:$H$2004=""))*(ISNUMBER(Orders!$J$5:$J$2004)+(Orders!$J$5:$J$2004=""))*((Orders!$I$5:$I$2004="Yes")+(Orders!$I$5:$I$2004="No")+(Orders!$I$5:$I$2004="")))*(Orders!$A$5:$A$2004>=DATE(Dashboard!$C$3,1,1))*(Orders!$A$5:$A$2004<DATE(Dashboard!$C$3,2,1)),Orders!$F$5:$F$2004) -> 4.5 | G3: =SUMPRODUCT((ISNUMBER(Orders!$A$5:$A$2004)*ISNUMBER(MATCH(Orders!$C$5:$C$2004,Lists!$A$2:$A$26,0))*ISNUMBER(Orders!$D$5:$D$2004)*(Orders!$D$5:$D$2004>0)*ISNUMBER(Orders!$E$5:$E$2004)*(ISNUMBER(Orders!$F$5:$F$2004)+(Orders!$F$5:$F$2004=""))*(ISNUMBER(Orders!$G$5:$G$2004)+(Orders!$G$5:$G$2004=""))*(ISNUMBER(Orders!$H$5:$H$2004)+(Orders!$H$5:$H$2004=""))*(ISNUMBER(Orders!$J$5:$J$2004)+(Orders!$J$5:$J$2004=""))*((Orders!$I$5:$I$2004="Yes")+(Orders!$I$5:$I$2004="No")+(Orders!$I$5:$I$2004="")))*(Orders!$A$5:$A$2004>=DATE(Dashboard!$C$3,1,1))*(Orders!$A$5:$A$2004<DATE(Dashboard!$C$3,2,1)),Orders!$G$5:$G$2004) -> 5.63 | H3: =SUMPRODUCT((ISNUMBER(Orders!$A$5:$A$2004)*ISNUMBER(MATCH(Orders!$C$5:$C$2004,Lists!$A$2:$A$26,0))*ISNUMBER(Orders!$D$5:$D$2004)*(Orders!$D$5:$D$2004>0)*ISNUMBER(Orders!$E$5:$E$2004)*(ISNUMBER(Orders!$F$5:$F$2004)+(Orders!$F$5:$F$2004=""))*(ISNUMBER(Orders!$G$5:$G$2004)+(Orders!$G$5:$G$2004=""))*(ISNUMBER(Orders!$H$5:$H$2004)+(Orders!$H$5:$H$2004=""))*(ISNUMBER(Orders!$J$5:$J$2004)+(Orders!$J$5:$J$2004=""))*((Orders!$I$5:$I$2004="Yes")+(Orders!$I$5:$I$2004="No")+(Orders!$I$5:$I$2004="")))*(Orders!$A$5:$A$2004>=DATE(Dashboard!$C$3,1,1))*(Orders!$A$5:$A$2004<DATE(Dashboard!$C$3,2,1)),Orders!$H$5:$H$2004) -> 8.24 | I3: =SUMPRODUCT((ISNUMBER(Orders!$A$5:$A$2004)*ISNUMBER(MATCH(Orders!$C$5:$C$2004,Lists!$A$2:$A$26,0))*ISNUMBER(Orders!$D$5:$D$2004)*(Orders!$D$5:$D$2004>0)*ISNUMBER(Orders!$E$5:$E$2004)*(ISNUMBER(Orders!$F$5:$F$2004)+(Orders!$F$5:$F$2004=""))*(ISNUMBER(Orders!$G$5:$G$2004)+(Orders!$G$5:$G$2004=""))*(ISNUMBER(Orders!$H$5:$H$2004)+(Orders!$H$5:$H$2004=""))*(ISNUMBER(Orders!$J$5:$J$2004)+(Orders!$J$5:$J$2004=""))*((Orders!$I$5:$I$2004="Yes")+(Orders!$I$5:$I$2004="No")+(Orders!$I$5:$I$2004="")))*(Orders!$A$5:$A$2004>=DATE(Dashboard!$C$3,1,1))*(Orders!$A$5:$A$2004<DATE(Dashboard!$C$3,2,1)),Orders!$J$5:$J$2004) -> 0 | J3: =N('Fee Settings'!$C$5)*(E3+F3-I3) -> 5.3885 | K3: =N('Fee Settings'!$C$6)*(E3+F3+G3)+N('Fee Settings'!$C$7)*C3 -> 3.1559 | L3: {=SUM(IF(((ISNUMBER(Orders!$A$5:$A$2004)*ISNUMBER(MATCH(Orders!$C$5:$C$2004,Lists!$A$2:$A$26,0))*ISNUMBER(Orders!$D$5:$D$2004)*(Orders!$D$5:$D$2004>0)*ISNUMBER(Orders!$E$5:$E$2004)*(ISNUMBER(Orders!$F$5:$F$2004)+(Orders!$F$5:$F$2004=""))*(ISNUMBER(Orders!$G$5:$G$2004)+(Orders!$G$5:$G$2004=""))*(ISNUMBER(Orders!$H$5:$H$2004)+(Orders!$H$5:$H$2004=""))*(ISNUMBER(Orders!$J$5:$J$2004)+(Orders!$J$5:$J$2004=""))*((Orders!$I$5:$I$2004="Yes")+(Orders!$I$5:$I$2004="No")+(Orders!$I$5:$I$2004="")))*(Orders!$A$5:$A$2004>=DATE(Dashboard!$C$3,1,1))*(Orders!$A$5:$A$2004<DATE(Dashboard!$C$3,2,1)))*(Orders!$I$5:$I$2004="Yes")=1,IF(N('Fee Settings'!$C$8)*(Orders!$E$5:$E$2004+Orders!$F$5:$F$2004)>N('Fee Settings'!$C$9),N('Fee Settings'!$C$9),N('Fee Settings'!$C$8)*(Orders!$E$5:$E$2004+Orders!$F$5:$F$2004)),0))} -> 7.56 | M3: =N('Fee Settings'!$C$10)*D3 -> 0.6 | N3: =J3+K3+L3+M3 -> 16.7044 | O3: =SUMPRODUCT(Products!$C$5:$C$29,C20:C44) -> 19.2 | P3: =SUMPRODUCT((ISNUMBER('Shop Expenses'!$A$5:$A$504)*ISNUMBER(MATCH('Shop Expenses'!$B$5:$B$504,Lists!$D$2:$D$13,0))*ISNUMBER('Shop Expenses'!$D$5:$D$504))*('Shop Expenses'!$A$5:$A$504>=DATE(Dashboard!$C$3,1,1))*('Shop Expenses'!$A$5:$A$504<DATE(Dashboard!$C$3,2,1)),'Shop Expenses'!$D$5:$D$504) -> 15 | Q3: =E3+F3-I3 -> 82.9 | R3: =Q3-N3-H3-O3-P3 -> 23.7556 | S3: =IF(Q3>0,R3/Q3,0) -> 0.2865573
B4: Feb | C4: =SUMPRODUCT((ISNUMBER(Orders!$A$5:$A$2004)*ISNUMBER(MATCH(Orders!$C$5:$C$2004,Lists!$A$2:$A$26,0))*ISNUMBER(Orders!$D$5:$D$2004)*(Orders!$D$5:$D$2004>0)*ISNUMBER(Orders!$E$5:$E$2004)*(ISNUMBER(Orders!$F$5:$F$2004)+(Orders!$F$5:$F$2004=""))*(ISNUMBER(Orders!$G$5:$G$2004)+(Orders!$G$5:$G$2004=""))*(ISNUMBER(Orders!$H$5:$H$2004)+(Orders!$H$5:$H$2004=""))*(ISNUMBER(Orders!$J$5:$J$2004)+(Orders!$J$5:$J$2004=""))*((Orders!$I$5:$I$2004="Yes")+(Orders!$I$5:$I$2004="No")+(Orders!$I$5:$I$2004="")))*(Orders!$A$5:$A$2004>=DATE(Dashboard!$C$3,2,1))*(Orders!$A$5:$A$2004<DATE(Dashboard!$C$3,3,1))) -> 0 | D4: =SUMPRODUCT((ISNUMBER(Orders!$A$5:$A$2004)*ISNUMBER(MATCH(Orders!$C$5:$C$2004,Lists!$A$2:$A$26,0))*ISNUMBER(Orders!$D$5:$D$2004)*(Orders!$D$5:$D$2004>0)*ISNUMBER(Orders!$E$5:$E$2004)*(ISNUMBER(Orders!$F$5:$F$2004)+(Orders!$F$5:$F$2004=""))*(ISNUMBER(Orders!$G$5:$G$2004)+(Orders!$G$5:$G$2004=""))*(ISNUMBER(Orders!$H$5:$H$2004)+(Orders!$H$5:$H$2004=""))*(ISNUMBER(Orders!$J$5:$J$2004)+(Orders!$J$5:$J$2004=""))*((Orders!$I$5:$I$2004="Yes")+(Orders!$I$5:$I$2004="No")+(Orders!$I$5:$I$2004="")))*(Orders!$A$5:$A$2004>=DATE(Dashboard!$C$3,2,1))*(Orders!$A$5:$A$2004<DATE(Dashboard!$C$3,3,1)),Orders!$D$5:$D$2004) -> 0 | E4: =SUMPRODUCT((ISNUMBER(Orders!$A$5:$A$2004)*ISNUMBER(MATCH(Orders!$C$5:$C$2004,Lists!$A$2:$A$26,0))*ISNUMBER(Orders!$D$5:$D$2004)*(Orders!$D$5:$D$2004>0)*ISNUMBER(Orders!$E$5:$E$2004)*(ISNUMBER(Orders!$F$5:$F$2004)+(Orders!$F$5:$F$2004=""))*(ISNUMBER(Orders!$G$5:$G$2004)+(Orders!$G$5:$G$2004=""))*(ISNUMBER(Orders!$H$5:$H$2004)+(Orders!$H$5:$H$2004=""))*(ISNUMBER(Orders!$J$5:$J$2004)+(Orders!$J$5:$J$2004=""))*((Orders!$I$5:$I$2004="Yes")+(Orders!$I$5:$I$2004="No")+(Orders!$I$5:$I$2004="")))*(Orders!$A$5:$A$2004>=DATE(Dashboard!$C$3,2,1))*(Orders!$A$5:$A$2004<DATE(Dashboard!$C$3,3,1)),Orders!$E$5:$E$2004) -> 0 | F4: =SUMPRODUCT((ISNUMBER(Orders!$A$5:$A$2004)*ISNUMBER(MATCH(Orders!$C$5:$C$2004,Lists!$A$2:$A$26,0))*ISNUMBER(Orders!$D$5:$D$2004)*(Orders!$D$5:$D$2004>0)*ISNUMBER(Orders!$E$5:$E$2004)*(ISNUMBER(Orders!$F$5:$F$2004)+(Orders!$F$5:$F$2004=""))*(ISNUMBER(Orders!$G$5:$G$2004)+(Orders!$G$5:$G$2004=""))*(ISNUMBER(Orders!$H$5:$H$2004)+(Orders!$H$5:$H$2004=""))*(ISNUMBER(Orders!$J$5:$J$2004)+(Orders!$J$5:$J$2004=""))*((Orders!$I$5:$I$2004="Yes")+(Orders!$I$5:$I$2004="No")+(Orders!$I$5:$I$2004="")))*(Orders!$A$5:$A$2004>=DATE(Dashboard!$C$3,2,1))*(Orders!$A$5:$A$2004<DATE(Dashboard!$C$3,3,1)),Orders!$F$5:$F$2004) -> 0 | G4: =SUMPRODUCT((ISNUMBER(Orders!$A$5:$A$2004)*ISNUMBER(MATCH(Orders!$C$5:$C$2004,Lists!$A$2:$A$26,0))*ISNUMBER(Orders!$D$5:$D$2004)*(Orders!$D$5:$D$2004>0)*ISNUMBER(Orders!$E$5:$E$2004)*(ISNUMBER(Orders!$F$5:$F$2004)+(Orders!$F$5:$F$2004=""))*(ISNUMBER(Orders!$G$5:$G$2004)+(Orders!$G$5:$G$2004=""))*(ISNUMBER(Orders!$H$5:$H$2004)+(Orders!$H$5:$H$2004=""))*(ISNUMBER(Orders!$J$5:$J$2004)+(Orders!$J$5:$J$2004=""))*((Orders!$I$5:$I$2004="Yes")+(Orders!$I$5:$I$2004="No")+(Orders!$I$5:$I$2004="")))*(Orders!$A$5:$A$2004>=DATE(Dashboard!$C$3,2,1))*(Orders!$A$5:$A$2004<DATE(Dashboard!$C$3,3,1)),Orders!$G$5:$G$2004) -> 0 | H4: =SUMPRODUCT((ISNUMBER(Orders!$A$5:$A$2004)*ISNUMBER(MATCH(Orders!$C$5:$C$2004,Lists!$A$2:$A$26,0))*ISNUMBER(Orders!$D$5:$D$2004)*(Orders!$D$5:$D$2004>0)*ISNUMBER(Orders!$E$5:$E$2004)*(ISNUMBER(Orders!$F$5:$F$2004)+(Orders!$F$5:$F$2004=""))*(ISNUMBER(Orders!$G$5:$G$2004)+(Orders!$G$5:$G$2004=""))*(ISNUMBER(Orders!$H$5:$H$2004)+(Orders!$H$5:$H$2004=""))*(ISNUMBER(Orders!$J$5:$J$2004)+(Orders!$J$5:$J$2004=""))*((Orders!$I$5:$I$2004="Yes")+(Orders!$I$5:$I$2004="No")+(Orders!$I$5:$I$2004="")))*(Orders!$A$5:$A$2004>=DATE(Dashboard!$C$3,2,1))*(Orders!$A$5:$A$2004<DATE(Dashboard!$C$3,3,1)),Orders!$H$5:$H$2004) -> 0 | I4: =SUMPRODUCT((ISNUMBER(Orders!$A$5:$A$2004)*ISNUMBER(MATCH(Orders!$C$5:$C$2004,Lists!$A$2:$A$26,0))*ISNUMBER(Orders!$D$5:$D$2004)*(Orders!$D$5:$D$2004>0)*ISNUMBER(Orders!$E$5:$E$2004)*(ISNUMBER(Orders!$F$5:$F$2004)+(Orders!$F$5:$F$2004=""))*(ISNUMBER(Orders!$G$5:$G$2004)+(Orders!$G$5:$G$2004=""))*(ISNUMBER(Orders!$H$5:$H$2004)+(Orders!$H$5:$H$2004=""))*(ISNUMBER(Orders!$J$5:$J$2004)+(Orders!$J$5:$J$2004=""))*((Orders!$I$5:$I$2004="Yes")+(Orders!$I$5:$I$2004="No")+(Orders!$I$5:$I$2004="")))*(Orders!$A$5:$A$2004>=DATE(Dashboard!$C$3,2,1))*(Orders!$A$5:$A$2004<DATE(Dashboard!$C$3,3,1)),Orders!$J$5:$J$2004) -> 0 | J4: =N('Fee Settings'!$C$5)*(E4+F4-I4) -> 0 | K4: =N('Fee Settings'!$C$6)*(E4+F4+G4)+N('Fee Settings'!$C$7)*C4 -> 0 | L4: {=SUM(IF(((ISNUMBER(Orders!$A$5:$A$2004)*ISNUMBER(MATCH(Orders!$C$5:$C$2004,Lists!$A$2:$A$26,0))*ISNUMBER(Orders!$D$5:$D$2004)*(Orders!$D$5:$D$2004>0)*ISNUMBER(Orders!$E$5:$E$2004)*(ISNUMBER(Orders!$F$5:$F$2004)+(Orders!$F$5:$F$2004=""))*(ISNUMBER(Orders!$G$5:$G$2004)+(Orders!$G$5:$G$2004=""))*(ISNUMBER(Orders!$H$5:$H$2004)+(Orders!$H$5:$H$2004=""))*(ISNUMBER(Orders!$J$5:$J$2004)+(Orders!$J$5:$J$2004=""))*((Orders!$I$5:$I$2004="Yes")+(Orders!$I$5:$I$2004="No")+(Orders!$I$5:$I$2004="")))*(Orders!$A$5:$A$2004>=DATE(Dashboard!$C$3,2,1))*(Orders!$A$5:$A$2004<DATE(Dashboard!$C$3,3,1)))*(Orders!$I$5:$I$2004="Yes")=1,IF(N('Fee Settings'!$C$8)*(Orders!$E$5:$E$2004+Orders!$F$5:$F$2004)>N('Fee Settings'!$C$9),N('Fee Settings'!$C$9),N('Fee Settings'!$C$8)*(Orders!$E$5:$E$2004+Orders!$F$5:$F$2004)),0))} -> 0 | M4: =N('Fee Settings'!$C$10)*D4 -> 0 | N4: =J4+K4+L4+M4 -> 0 | O4: =SUMPRODUCT(Products!$C$5:$C$29,D20:D44) -> 0 | P4: =SUMPRODUCT((ISNUMBER('Shop Expenses'!$A$5:$A$504)*ISNUMBER(MATCH('Shop Expenses'!$B$5:$B$504,Lists!$D$2:$D$13,0))*ISNUMBER('Shop Expenses'!$D$5:$D$504))*('Shop Expenses'!$A$5:$A$504>=DATE(Dashboard!$C$3,2,1))*('Shop Expenses'!$A$5:$A$504<DATE(Dashboard!$C$3,3,1)),'Shop Expenses'!$D$5:$D$504) -> 0 | Q4: =E4+F4-I4 -> 0 | R4: =Q4-N4-H4-O4-P4 -> 0 | S4: =IF(Q4>0,R4/Q4,0) -> 0
B5: Mar | C5: =SUMPRODUCT((ISNUMBER(Orders!$A$5:$A$2004)*ISNUMBER(MATCH(Orders!$C$5:$C$2004,Lists!$A$2:$A$26,0))*ISNUMBER(Orders!$D$5:$D$2004)*(Orders!$D$5:$D$2004>0)*ISNUMBER(Orders!$E$5:$E$2004)*(ISNUMBER(Orders!$F$5:$F$2004)+(Orders!$F$5:$F$2004=""))*(ISNUMBER(Orders!$G$5:$G$2004)+(Orders!$G$5:$G$2004=""))*(ISNUMBER(Orders!$H$5:$H$2004)+(Orders!$H$5:$H$2004=""))*(ISNUMBER(Orders!$J$5:$J$2004)+(Orders!$J$5:$J$2004=""))*((Orders!$I$5:$I$2004="Yes")+(Orders!$I$5:$I$2004="No")+(Orders!$I$5:$I$2004="")))*(Orders!$A$5:$A$2004>=DATE(Dashboard!$C$3,3,1))*(Orders!$A$5:$A$2004<DATE(Dashboard!$C$3,4,1))) -> 0 | D5: =SUMPRODUCT((ISNUMBER(Orders!$A$5:$A$2004)*ISNUMBER(MATCH(Orders!$C$5:$C$2004,Lists!$A$2:$A$26,0))*ISNUMBER(Orders!$D$5:$D$2004)*(Orders!$D$5:$D$2004>0)*ISNUMBER(Orders!$E$5:$E$2004)*(ISNUMBER(Orders!$F$5:$F$2004)+(Orders!$F$5:$F$2004=""))*(ISNUMBER(Orders!$G$5:$G$2004)+(Orders!$G$5:$G$2004=""))*(ISNUMBER(Orders!$H$5:$H$2004)+(Orders!$H$5:$H$2004=""))*(ISNUMBER(Orders!$J$5:$J$2004)+(Orders!$J$5:$J$2004=""))*((Orders!$I$5:$I$2004="Yes")+(Orders!$I$5:$I$2004="No")+(Orders!$I$5:$I$2004="")))*(Orders!$A$5:$A$2004>=DATE(Dashboard!$C$3,3,1))*(Orders!$A$5:$A$2004<DATE(Dashboard!$C$3,4,1)),Orders!$D$5:$D$2004) -> 0 | E5: =SUMPRODUCT((ISNUMBER(Orders!$A$5:$A$2004)*ISNUMBER(MATCH(Orders!$C$5:$C$2004,Lists!$A$2:$A$26,0))*ISNUMBER(Orders!$D$5:$D$2004)*(Orders!$D$5:$D$2004>0)*ISNUMBER(Orders!$E$5:$E$2004)*(ISNUMBER(Orders!$F$5:$F$2004)+(Orders!$F$5:$F$2004=""))*(ISNUMBER(Orders!$G$5:$G$2004)+(Orders!$G$5:$G$2004=""))*(ISNUMBER(Orders!$H$5:$H$2004)+(Orders!$H$5:$H$2004=""))*(ISNUMBER(Orders!$J$5:$J$2004)+(Orders!$J$5:$J$2004=""))*((Orders!$I$5:$I$2004="Yes")+(Orders!$I$5:$I$2004="No")+(Orders!$I$5:$I$2004="")))*(Orders!$A$5:$A$2004>=DATE(Dashboard!$C$3,3,1))*(Orders!$A$5:$A$2004<DATE(Dashboard!$C$3,4,1)),Orders!$E$5:$E$2004) -> 0 | F5: =SUMPRODUCT((ISNUMBER(Orders!$A$5:$A$2004)*ISNUMBER(MATCH(Orders!$C$5:$C$2004,Lists!$A$2:$A$26,0))*ISNUMBER(Orders!$D$5:$D$2004)*(Orders!$D$5:$D$2004>0)*ISNUMBER(Orders!$E$5:$E$2004)*(ISNUMBER(Orders!$F$5:$F$2004)+(Orders!$F$5:$F$2004=""))*(ISNUMBER(Orders!$G$5:$G$2004)+(Orders!$G$5:$G$2004=""))*(ISNUMBER(Orders!$H$5:$H$2004)+(Orders!$H$5:$H$2004=""))*(ISNUMBER(Orders!$J$5:$J$2004)+(Orders!$J$5:$J$2004=""))*((Orders!$I$5:$I$2004="Yes")+(Orders!$I$5:$I$2004="No")+(Orders!$I$5:$I$2004="")))*(Orders!$A$5:$A$2004>=DATE(Dashboard!$C$3,3,1))*(Orders!$A$5:$A$2004<DATE(Dashboard!$C$3,4,1)),Orders!$F$5:$F$2004) -> 0 | G5: =SUMPRODUCT((ISNUMBER(Orders!$A$5:$A$2004)*ISNUMBER(MATCH(Orders!$C$5:$C$2004,Lists!$A$2:$A$26,0))*ISNUMBER(Orders!$D$5:$D$2004)*(Orders!$D$5:$D$2004>0)*ISNUMBER(Orders!$E$5:$E$2004)*(ISNUMBER(Orders!$F$5:$F$2004)+(Orders!$F$5:$F$2004=""))*(ISNUMBER(Orders!$G$5:$G$2004)+(Orders!$G$5:$G$2004=""))*(ISNUMBER(Orders!$H$5:$H$2004)+(Orders!$H$5:$H$2004=""))*(ISNUMBER(Orders!$J$5:$J$2004)+(Orders!$J$5:$J$2004=""))*((Orders!$I$5:$I$2004="Yes")+(Orders!$I$5:$I$2004="No")+(Orders!$I$5:$I$2004="")))*(Orders!$A$5:$A$2004>=DATE(Dashboard!$C$3,3,1))*(Orders!$A$5:$A$2004<DATE(Dashboard!$C$3,4,1)),Orders!$G$5:$G$2004) -> 0 | H5: =SUMPRODUCT((ISNUMBER(Orders!$A$5:$A$2004)*ISNUMBER(MATCH(Orders!$C$5:$C$2004,Lists!$A$2:$A$26,0))*ISNUMBER(Orders!$D$5:$D$2004)*(Orders!$D$5:$D$2004>0)*ISNUMBER(Orders!$E$5:$E$2004)*(ISNUMBER(Orders!$F$5:$F$2004)+(Orders!$F$5:$F$2004=""))*(ISNUMBER(Orders!$G$5:$G$2004)+(Orders!$G$5:$G$2004=""))*(ISNUMBER(Orders!$H$5:$H$2004)+(Orders!$H$5:$H$2004=""))*(ISNUMBER(Orders!$J$5:$J$2004)+(Orders!$J$5:$J$2004=""))*((Orders!$I$5:$I$2004="Yes")+(Orders!$I$5:$I$2004="No")+(Orders!$I$5:$I$2004="")))*(Orders!$A$5:$A$2004>=DATE(Dashboard!$C$3,3,1))*(Orders!$A$5:$A$2004<DATE(Dashboard!$C$3,4,1)),Orders!$H$5:$H$2004) -> 0 | I5: =SUMPRODUCT((ISNUMBER(Orders!$A$5:$A$2004)*ISNUMBER(MATCH(Orders!$C$5:$C$2004,Lists!$A$2:$A$26,0))*ISNUMBER(Orders!$D$5:$D$2004)*(Orders!$D$5:$D$2004>0)*ISNUMBER(Orders!$E$5:$E$2004)*(ISNUMBER(Orders!$F$5:$F$2004)+(Orders!$F$5:$F$2004=""))*(ISNUMBER(Orders!$G$5:$G$2004)+(Orders!$G$5:$G$2004=""))*(ISNUMBER(Orders!$H$5:$H$2004)+(Orders!$H$5:$H$2004=""))*(ISNUMBER(Orders!$J$5:$J$2004)+(Orders!$J$5:$J$2004=""))*((Orders!$I$5:$I$2004="Yes")+(Orders!$I$5:$I$2004="No")+(Orders!$I$5:$I$2004="")))*(Orders!$A$5:$A$2004>=DATE(Dashboard!$C$3,3,1))*(Orders!$A$5:$A$2004<DATE(Dashboard!$C$3,4,1)),Orders!$J$5:$J$2004) -> 0 | J5: =N('Fee Settings'!$C$5)*(E5+F5-I5) -> 0 | K5: =N('Fee Settings'!$C$6)*(E5+F5+G5)+N('Fee Settings'!$C$7)*C5 -> 0 | L5: {=SUM(IF(((ISNUMBER(Orders!$A$5:$A$2004)*ISNUMBER(MATCH(Orders!$C$5:$C$2004,Lists!$A$2:$A$26,0))*ISNUMBER(Orders!$D$5:$D$2004)*(Orders!$D$5:$D$2004>0)*ISNUMBER(Orders!$E$5:$E$2004)*(ISNUMBER(Orders!$F$5:$F$2004)+(Orders!$F$5:$F$2004=""))*(ISNUMBER(Orders!$G$5:$G$2004)+(Orders!$G$5:$G$2004=""))*(ISNUMBER(Orders!$H$5:$H$2004)+(Orders!$H$5:$H$2004=""))*(ISNUMBER(Orders!$J$5:$J$2004)+(Orders!$J$5:$J$2004=""))*((Orders!$I$5:$I$2004="Yes")+(Orders!$I$5:$I$2004="No")+(Orders!$I$5:$I$2004="")))*(Orders!$A$5:$A$2004>=DATE(Dashboard!$C$3,3,1))*(Orders!$A$5:$A$2004<DATE(Dashboard!$C$3,4,1)))*(Orders!$I$5:$I$2004="Yes")=1,IF(N('Fee Settings'!$C$8)*(Orders!$E$5:$E$2004+Orders!$F$5:$F$2004)>N('Fee Settings'!$C$9),N('Fee Settings'!$C$9),N('Fee Settings'!$C$8)*(Orders!$E$5:$E$2004+Orders!$F$5:$F$2004)),0))} -> 0 | M5: =N('Fee Settings'!$C$10)*D5 -> 0 | N5: =J5+K5+L5+M5 -> 0 | O5: =SUMPRODUCT(Products!$C$5:$C$29,E20:E44) -> 0 | P5: =SUMPRODUCT((ISNUMBER('Shop Expenses'!$A$5:$A$504)*ISNUMBER(MATCH('Shop Expenses'!$B$5:$B$504,Lists!$D$2:$D$13,0))*ISNUMBER('Shop Expenses'!$D$5:$D$504))*('Shop Expenses'!$A$5:$A$504>=DATE(Dashboard!$C$3,3,1))*('Shop Expenses'!$A$5:$A$504<DATE(Dashboard!$C$3,4,1)),'Shop Expenses'!$D$5:$D$504) -> 0 | Q5: =E5+F5-I5 -> 0 | R5: =Q5-N5-H5-O5-P5 -> 0 | S5: =IF(Q5>0,R5/Q5,0) -> 0
B6: Apr | C6: =SUMPRODUCT((ISNUMBER(Orders!$A$5:$A$2004)*ISNUMBER(MATCH(Orders!$C$5:$C$2004,Lists!$A$2:$A$26,0))*ISNUMBER(Orders!$D$5:$D$2004)*(Orders!$D$5:$D$2004>0)*ISNUMBER(Orders!$E$5:$E$2004)*(ISNUMBER(Orders!$F$5:$F$2004)+(Orders!$F$5:$F$2004=""))*(ISNUMBER(Orders!$G$5:$G$2004)+(Orders!$G$5:$G$2004=""))*(ISNUMBER(Orders!$H$5:$H$2004)+(Orders!$H$5:$H$2004=""))*(ISNUMBER(Orders!$J$5:$J$2004)+(Orders!$J$5:$J$2004=""))*((Orders!$I$5:$I$2004="Yes")+(Orders!$I$5:$I$2004="No")+(Orders!$I$5:$I$2004="")))*(Orders!$A$5:$A$2004>=DATE(Dashboard!$C$3,4,1))*(Orders!$A$5:$A$2004<DATE(Dashboard!$C$3,5,1))) -> 0 | D6: =SUMPRODUCT((ISNUMBER(Orders!$A$5:$A$2004)*ISNUMBER(MATCH(Orders!$C$5:$C$2004,Lists!$A$2:$A$26,0))*ISNUMBER(Orders!$D$5:$D$2004)*(Orders!$D$5:$D$2004>0)*ISNUMBER(Orders!$E$5:$E$2004)*(ISNUMBER(Orders!$F$5:$F$2004)+(Orders!$F$5:$F$2004=""))*(ISNUMBER(Orders!$G$5:$G$2004)+(Orders!$G$5:$G$2004=""))*(ISNUMBER(Orders!$H$5:$H$2004)+(Orders!$H$5:$H$2004=""))*(ISNUMBER(Orders!$J$5:$J$2004)+(Orders!$J$5:$J$2004=""))*((Orders!$I$5:$I$2004="Yes")+(Orders!$I$5:$I$2004="No")+(Orders!$I$5:$I$2004="")))*(Orders!$A$5:$A$2004>=DATE(Dashboard!$C$3,4,1))*(Orders!$A$5:$A$2004<DATE(Dashboard!$C$3,5,1)),Orders!$D$5:$D$2004) -> 0 | E6: =SUMPRODUCT((ISNUMBER(Orders!$A$5:$A$2004)*ISNUMBER(MATCH(Orders!$C$5:$C$2004,Lists!$A$2:$A$26,0))*ISNUMBER(Orders!$D$5:$D$2004)*(Orders!$D$5:$D$2004>0)*ISNUMBER(Orders!$E$5:$E$2004)*(ISNUMBER(Orders!$F$5:$F$2004)+(Orders!$F$5:$F$2004=""))*(ISNUMBER(Orders!$G$5:$G$2004)+(Orders!$G$5:$G$2004=""))*(ISNUMBER(Orders!$H$5:$H$2004)+(Orders!$H$5:$H$2004=""))*(ISNUMBER(Orders!$J$5:$J$2004)+(Orders!$J$5:$J$2004=""))*((Orders!$I$5:$I$2004="Yes")+(Orders!$I$5:$I$2004="No")+(Orders!$I$5:$I$2004="")))*(Orders!$A$5:$A$2004>=DATE(Dashboard!$C$3,4,1))*(Orders!$A$5:$A$2004<DATE(Dashboard!$C$3,5,1)),Orders!$E$5:$E$2004) -> 0 | F6: =SUMPRODUCT((ISNUMBER(Orders!$A$5:$A$2004)*ISNUMBER(MATCH(Orders!$C$5:$C$2004,Lists!$A$2:$A$26,0))*ISNUMBER(Orders!$D$5:$D$2004)*(Orders!$D$5:$D$2004>0)*ISNUMBER(Orders!$E$5:$E$2004)*(ISNUMBER(Orders!$F$5:$F$2004)+(Orders!$F$5:$F$2004=""))*(ISNUMBER(Orders!$G$5:$G$2004)+(Orders!$G$5:$G$2004=""))*(ISNUMBER(Orders!$H$5:$H$2004)+(Orders!$H$5:$H$2004=""))*(ISNUMBER(Orders!$J$5:$J$2004)+(Orders!$J$5:$J$2004=""))*((Orders!$I$5:$I$2004="Yes")+(Orders!$I$5:$I$2004="No")+(Orders!$I$5:$I$2004="")))*(Orders!$A$5:$A$2004>=DATE(Dashboard!$C$3,4,1))*(Orders!$A$5:$A$2004<DATE(Dashboard!$C$3,5,1)),Orders!$F$5:$F$2004) -> 0 | G6: =SUMPRODUCT((ISNUMBER(Orders!$A$5:$A$2004)*ISNUMBER(MATCH(Orders!$C$5:$C$2004,Lists!$A$2:$A$26,0))*ISNUMBER(Orders!$D$5:$D$2004)*(Orders!$D$5:$D$2004>0)*ISNUMBER(Orders!$E$5:$E$2004)*(ISNUMBER(Orders!$F$5:$F$2004)+(Orders!$F$5:$F$2004=""))*(ISNUMBER(Orders!$G$5:$G$2004)+(Orders!$G$5:$G$2004=""))*(ISNUMBER(Orders!$H$5:$H$2004)+(Orders!$H$5:$H$2004=""))*(ISNUMBER(Orders!$J$5:$J$2004)+(Orders!$J$5:$J$2004=""))*((Orders!$I$5:$I$2004="Yes")+(Orders!$I$5:$I$2004="No")+(Orders!$I$5:$I$2004="")))*(Orders!$A$5:$A$2004>=DATE(Dashboard!$C$3,4,1))*(Orders!$A$5:$A$2004<DATE(Dashboard!$C$3,5,1)),Orders!$G$5:$G$2004) -> 0 | H6: =SUMPRODUCT((ISNUMBER(Orders!$A$5:$A$2004)*ISNUMBER(MATCH(Orders!$C$5:$C$2004,Lists!$A$2:$A$26,0))*ISNUMBER(Orders!$D$5:$D$2004)*(Orders!$D$5:$D$2004>0)*ISNUMBER(Orders!$E$5:$E$2004)*(ISNUMBER(Orders!$F$5:$F$2004)+(Orders!$F$5:$F$2004=""))*(ISNUMBER(Orders!$G$5:$G$2004)+(Orders!$G$5:$G$2004=""))*(ISNUMBER(Orders!$H$5:$H$2004)+(Orders!$H$5:$H$2004=""))*(ISNUMBER(Orders!$J$5:$J$2004)+(Orders!$J$5:$J$2004=""))*((Orders!$I$5:$I$2004="Yes")+(Orders!$I$5:$I$2004="No")+(Orders!$I$5:$I$2004="")))*(Orders!$A$5:$A$2004>=DATE(Dashboard!$C$3,4,1))*(Orders!$A$5:$A$2004<DATE(Dashboard!$C$3,5,1)),Orders!$H$5:$H$2004) -> 0 | I6: =SUMPRODUCT((ISNUMBER(Orders!$A$5:$A$2004)*ISNUMBER(MATCH(Orders!$C$5:$C$2004,Lists!$A$2:$A$26,0))*ISNUMBER(Orders!$D$5:$D$2004)*(Orders!$D$5:$D$2004>0)*ISNUMBER(Orders!$E$5:$E$2004)*(ISNUMBER(Orders!$F$5:$F$2004)+(Orders!$F$5:$F$2004=""))*(ISNUMBER(Orders!$G$5:$G$2004)+(Orders!$G$5:$G$2004=""))*(ISNUMBER(Orders!$H$5:$H$2004)+(Orders!$H$5:$H$2004=""))*(ISNUMBER(Orders!$J$5:$J$2004)+(Orders!$J$5:$J$2004=""))*((Orders!$I$5:$I$2004="Yes")+(Orders!$I$5:$I$2004="No")+(Orders!$I$5:$I$2004="")))*(Orders!$A$5:$A$2004>=DATE(Dashboard!$C$3,4,1))*(Orders!$A$5:$A$2004<DATE(Dashboard!$C$3,5,1)),Orders!$J$5:$J$2004) -> 0 | J6: =N('Fee Settings'!$C$5)*(E6+F6-I6) -> 0 | K6: =N('Fee Settings'!$C$6)*(E6+F6+G6)+N('Fee Settings'!$C$7)*C6 -> 0 | L6: {=SUM(IF(((ISNUMBER(Orders!$A$5:$A$2004)*ISNUMBER(MATCH(Orders!$C$5:$C$2004,Lists!$A$2:$A$26,0))*ISNUMBER(Orders!$D$5:$D$2004)*(Orders!$D$5:$D$2004>0)*ISNUMBER(Orders!$E$5:$E$2004)*(ISNUMBER(Orders!$F$5:$F$2004)+(Orders!$F$5:$F$2004=""))*(ISNUMBER(Orders!$G$5:$G$2004)+(Orders!$G$5:$G$2004=""))*(ISNUMBER(Orders!$H$5:$H$2004)+(Orders!$H$5:$H$2004=""))*(ISNUMBER(Orders!$J$5:$J$2004)+(Orders!$J$5:$J$2004=""))*((Orders!$I$5:$I$2004="Yes")+(Orders!$I$5:$I$2004="No")+(Orders!$I$5:$I$2004="")))*(Orders!$A$5:$A$2004>=DATE(Dashboard!$C$3,4,1))*(Orders!$A$5:$A$2004<DATE(Dashboard!$C$3,5,1)))*(Orders!$I$5:$I$2004="Yes")=1,IF(N('Fee Settings'!$C$8)*(Orders!$E$5:$E$2004+Orders!$F$5:$F$2004)>N('Fee Settings'!$C$9),N('Fee Settings'!$C$9),N('Fee Settings'!$C$8)*(Orders!$E$5:$E$2004+Orders!$F$5:$F$2004)),0))} -> 0 | M6: =N('Fee Settings'!$C$10)*D6 -> 0 | N6: =J6+K6+L6+M6 -> 0 | O6: =SUMPRODUCT(Products!$C$5:$C$29,F20:F44) -> 0 | P6: =SUMPRODUCT((ISNUMBER('Shop Expenses'!$A$5:$A$504)*ISNUMBER(MATCH('Shop Expenses'!$B$5:$B$504,Lists!$D$2:$D$13,0))*ISNUMBER('Shop Expenses'!$D$5:$D$504))*('Shop Expenses'!$A$5:$A$504>=DATE(Dashboard!$C$3,4,1))*('Shop Expenses'!$A$5:$A$504<DATE(Dashboard!$C$3,5,1)),'Shop Expenses'!$D$5:$D$504) -> 0 | Q6: =E6+F6-I6 -> 0 | R6: =Q6-N6-H6-O6-P6 -> 0 | S6: =IF(Q6>0,R6/Q6,0) -> 0
B7: May | C7: =SUMPRODUCT((ISNUMBER(Orders!$A$5:$A$2004)*ISNUMBER(MATCH(Orders!$C$5:$C$2004,Lists!$A$2:$A$26,0))*ISNUMBER(Orders!$D$5:$D$2004)*(Orders!$D$5:$D$2004>0)*ISNUMBER(Orders!$E$5:$E$2004)*(ISNUMBER(Orders!$F$5:$F$2004)+(Orders!$F$5:$F$2004=""))*(ISNUMBER(Orders!$G$5:$G$2004)+(Orders!$G$5:$G$2004=""))*(ISNUMBER(Orders!$H$5:$H$2004)+(Orders!$H$5:$H$2004=""))*(ISNUMBER(Orders!$J$5:$J$2004)+(Orders!$J$5:$J$2004=""))*((Orders!$I$5:$I$2004="Yes")+(Orders!$I$5:$I$2004="No")+(Orders!$I$5:$I$2004="")))*(Orders!$A$5:$A$2004>=DATE(Dashboard!$C$3,5,1))*(Orders!$A$5:$A$2004<DATE(Dashboard!$C$3,6,1))) -> 0 | D7: =SUMPRODUCT((ISNUMBER(Orders!$A$5:$A$2004)*ISNUMBER(MATCH(Orders!$C$5:$C$2004,Lists!$A$2:$A$26,0))*ISNUMBER(Orders!$D$5:$D$2004)*(Orders!$D$5:$D$2004>0)*ISNUMBER(Orders!$E$5:$E$2004)*(ISNUMBER(Orders!$F$5:$F$2004)+(Orders!$F$5:$F$2004=""))*(ISNUMBER(Orders!$G$5:$G$2004)+(Orders!$G$5:$G$2004=""))*(ISNUMBER(Orders!$H$5:$H$2004)+(Orders!$H$5:$H$2004=""))*(ISNUMBER(Orders!$J$5:$J$2004)+(Orders!$J$5:$J$2004=""))*((Orders!$I$5:$I$2004="Yes")+(Orders!$I$5:$I$2004="No")+(Orders!$I$5:$I$2004="")))*(Orders!$A$5:$A$2004>=DATE(Dashboard!$C$3,5,1))*(Orders!$A$5:$A$2004<DATE(Dashboard!$C$3,6,1)),Orders!$D$5:$D$2004) -> 0 | E7: =SUMPRODUCT((ISNUMBER(Orders!$A$5:$A$2004)*ISNUMBER(MATCH(Orders!$C$5:$C$2004,Lists!$A$2:$A$26,0))*ISNUMBER(Orders!$D$5:$D$2004)*(Orders!$D$5:$D$2004>0)*ISNUMBER(Orders!$E$5:$E$2004)*(ISNUMBER(Orders!$F$5:$F$2004)+(Orders!$F$5:$F$2004=""))*(ISNUMBER(Orders!$G$5:$G$2004)+(Orders!$G$5:$G$2004=""))*(ISNUMBER(Orders!$H$5:$H$2004)+(Orders!$H$5:$H$2004=""))*(ISNUMBER(Orders!$J$5:$J$2004)+(Orders!$J$5:$J$2004=""))*((Orders!$I$5:$I$2004="Yes")+(Orders!$I$5:$I$2004="No")+(Orders!$I$5:$I$2004="")))*(Orders!$A$5:$A$2004>=DATE(Dashboard!$C$3,5,1))*(Orders!$A$5:$A$2004<DATE(Dashboard!$C$3,6,1)),Orders!$E$5:$E$2004) -> 0 | F7: =SUMPRODUCT((ISNUMBER(Orders!$A$5:$A$2004)*ISNUMBER(MATCH(Orders!$C$5:$C$2004,Lists!$A$2:$A$26,0))*ISNUMBER(Orders!$D$5:$D$2004)*(Orders!$D$5:$D$2004>0)*ISNUMBER(Orders!$E$5:$E$2004)*(ISNUMBER(Orders!$F$5:$F$2004)+(Orders!$F$5:$F$2004=""))*(ISNUMBER(Orders!$G$5:$G$2004)+(Orders!$G$5:$G$2004=""))*(ISNUMBER(Orders!$H$5:$H$2004)+(Orders!$H$5:$H$2004=""))*(ISNUMBER(Orders!$J$5:$J$2004)+(Orders!$J$5:$J$2004=""))*((Orders!$I$5:$I$2004="Yes")+(Orders!$I$5:$I$2004="No")+(Orders!$I$5:$I$2004="")))*(Orders!$A$5:$A$2004>=DATE(Dashboard!$C$3,5,1))*(Orders!$A$5:$A$2004<DATE(Dashboard!$C$3,6,1)),Orders!$F$5:$F$2004) -> 0 | G7: =SUMPRODUCT((ISNUMBER(Orders!$A$5:$A$2004)*ISNUMBER(MATCH(Orders!$C$5:$C$2004,Lists!$A$2:$A$26,0))*ISNUMBER(Orders!$D$5:$D$2004)*(Orders!$D$5:$D$2004>0)*ISNUMBER(Orders!$E$5:$E$2004)*(ISNUMBER(Orders!$F$5:$F$2004)+(Orders!$F$5:$F$2004=""))*(ISNUMBER(Orders!$G$5:$G$2004)+(Orders!$G$5:$G$2004=""))*(ISNUMBER(Orders!$H$5:$H$2004)+(Orders!$H$5:$H$2004=""))*(ISNUMBER(Orders!$J$5:$J$2004)+(Orders!$J$5:$J$2004=""))*((Orders!$I$5:$I$2004="Yes")+(Orders!$I$5:$I$2004="No")+(Orders!$I$5:$I$2004="")))*(Orders!$A$5:$A$2004>=DATE(Dashboard!$C$3,5,1))*(Orders!$A$5:$A$2004<DATE(Dashboard!$C$3,6,1)),Orders!$G$5:$G$2004) -> 0 | H7: =SUMPRODUCT((ISNUMBER(Orders!$A$5:$A$2004)*ISNUMBER(MATCH(Orders!$C$5:$C$2004,Lists!$A$2:$A$26,0))*ISNUMBER(Orders!$D$5:$D$2004)*(Orders!$D$5:$D$2004>0)*ISNUMBER(Orders!$E$5:$E$2004)*(ISNUMBER(Orders!$F$5:$F$2004)+(Orders!$F$5:$F$2004=""))*(ISNUMBER(Orders!$G$5:$G$2004)+(Orders!$G$5:$G$2004=""))*(ISNUMBER(Orders!$H$5:$H$2004)+(Orders!$H$5:$H$2004=""))*(ISNUMBER(Orders!$J$5:$J$2004)+(Orders!$J$5:$J$2004=""))*((Orders!$I$5:$I$2004="Yes")+(Orders!$I$5:$I$2004="No")+(Orders!$I$5:$I$2004="")))*(Orders!$A$5:$A$2004>=DATE(Dashboard!$C$3,5,1))*(Orders!$A$5:$A$2004<DATE(Dashboard!$C$3,6,1)),Orders!$H$5:$H$2004) -> 0 | I7: =SUMPRODUCT((ISNUMBER(Orders!$A$5:$A$2004)*ISNUMBER(MATCH(Orders!$C$5:$C$2004,Lists!$A$2:$A$26,0))*ISNUMBER(Orders!$D$5:$D$2004)*(Orders!$D$5:$D$2004>0)*ISNUMBER(Orders!$E$5:$E$2004)*(ISNUMBER(Orders!$F$5:$F$2004)+(Orders!$F$5:$F$2004=""))*(ISNUMBER(Orders!$G$5:$G$2004)+(Orders!$G$5:$G$2004=""))*(ISNUMBER(Orders!$H$5:$H$2004)+(Orders!$H$5:$H$2004=""))*(ISNUMBER(Orders!$J$5:$J$2004)+(Orders!$J$5:$J$2004=""))*((Orders!$I$5:$I$2004="Yes")+(Orders!$I$5:$I$2004="No")+(Orders!$I$5:$I$2004="")))*(Orders!$A$5:$A$2004>=DATE(Dashboard!$C$3,5,1))*(Orders!$A$5:$A$2004<DATE(Dashboard!$C$3,6,1)),Orders!$J$5:$J$2004) -> 0 | J7: =N('Fee Settings'!$C$5)*(E7+F7-I7) -> 0 | K7: =N('Fee Settings'!$C$6)*(E7+F7+G7)+N('Fee Settings'!$C$7)*C7 -> 0 | L7: {=SUM(IF(((ISNUMBER(Orders!$A$5:$A$2004)*ISNUMBER(MATCH(Orders!$C$5:$C$2004,Lists!$A$2:$A$26,0))*ISNUMBER(Orders!$D$5:$D$2004)*(Orders!$D$5:$D$2004>0)*ISNUMBER(Orders!$E$5:$E$2004)*(ISNUMBER(Orders!$F$5:$F$2004)+(Orders!$F$5:$F$2004=""))*(ISNUMBER(Orders!$G$5:$G$2004)+(Orders!$G$5:$G$2004=""))*(ISNUMBER(Orders!$H$5:$H$2004)+(Orders!$H$5:$H$2004=""))*(ISNUMBER(Orders!$J$5:$J$2004)+(Orders!$J$5:$J$2004=""))*((Orders!$I$5:$I$2004="Yes")+(Orders!$I$5:$I$2004="No")+(Orders!$I$5:$I$2004="")))*(Orders!$A$5:$A$2004>=DATE(Dashboard!$C$3,5,1))*(Orders!$A$5:$A$2004<DATE(Dashboard!$C$3,6,1)))*(Orders!$I$5:$I$2004="Yes")=1,IF(N('Fee Settings'!$C$8)*(Orders!$E$5:$E$2004+Orders!$F$5:$F$2004)>N('Fee Settings'!$C$9),N('Fee Settings'!$C$9),N('Fee Settings'!$C$8)*(Orders!$E$5:$E$2004+Orders!$F$5:$F$2004)),0))} -> 0 | M7: =N('Fee Settings'!$C$10)*D7 -> 0 | N7: =J7+K7+L7+M7 -> 0 | O7: =SUMPRODUCT(Products!$C$5:$C$29,G20:G44) -> 0 | P7: =SUMPRODUCT((ISNUMBER('Shop Expenses'!$A$5:$A$504)*ISNUMBER(MATCH('Shop Expenses'!$B$5:$B$504,Lists!$D$2:$D$13,0))*ISNUMBER('Shop Expenses'!$D$5:$D$504))*('Shop Expenses'!$A$5:$A$504>=DATE(Dashboard!$C$3,5,1))*('Shop Expenses'!$A$5:$A$504<DATE(Dashboard!$C$3,6,1)),'Shop Expenses'!$D$5:$D$504) -> 0 | Q7: =E7+F7-I7 -> 0 | R7: =Q7-N7-H7-O7-P7 -> 0 | S7: =IF(Q7>0,R7/Q7,0) -> 0
