Workbook

Sheet Start Here
B2: Debt Payoff Planner
B3: Snowball vs avalanche, your debt-free date, interest saved and a month-by-month payoff plan. Works in Excel and Google Sheets.
B5: QUICK START (5 minutes)
B6: 1. 'Debts': list each debt with its current balance, interest rate (APR, e.g. 22.99) and minimum monthly payment. Up to 15 debts.
B7: Delete the EXAMPLE rows first. Type is optional. 'My order' is optional: number the debts 1, 2, 3... to choose your own order.
B8: 2. 'Dashboard': type the EXTRA you can pay each month on top of all the minimums, pick a strategy, and (optional) the month you start.
B9: 3. Read your debt-free date, total interest and how much you save compared with paying only the minimums.
B10: The comparison table shows Snowball, Avalanche and your own order side by side, so you can pick the plan that suits you.
B11: 4. 'Payoff Schedule': what to pay each month, interest, and every debt's balance until you are debt-free.
B12: 5. Every few months, update the balances on 'Debts' to your real statements and set the start month to the current month.
B13: 6. Red cells mean a row needs fixing (text in a number, a missing balance, rate or minimum). That debt stays out of the plan until fixed.
B15: HOW THE PLAN WORKS
... B28: Questions or a formula not behaving? Email nora@qnsai.com. Made by Nora Studio. Not financial advice.

Sheet Dashboard
B1: Debt Payoff Dashboard
B3: Extra per month: | C3: 200 | D3: ="on top of your minimums ("&TEXT(Calc!$C$6,"$#,##0.00")&") = "&TEXT(Calc!$C$7,"$#,##0.00")&" a month" -> on top of your minimums ($550.00) = $750.00 a month | V3: Chart data (do not edit)
B4: Strategy: | C4: Snowball (smallest balance first) | H4: =IF(Calc!$O$3>0,Calc!$O$3&" debt row(s) need fixing - see red cells on Debts",IF(Calc!$C$46>0,Calc!$C$46&" debt(s) have a minimum below the interest - see Debts","Updates automatically from the Debts tab")) -> Updates automatically from the Debts tab | V4: Year | W4: Your plan | X4: Minimums only | Z4: Debt | AA4: Months to pay off | AB4: Balance
B5: Start month: | G5: =IF(ISNUMBER(C5),"","(blank = this month: "&TEXT(Calc!$C$5,"mmm yyyy")&")") -> (blank = this month: Oct 2026) | V5: 0 | W5: =CHOOSE(Calc!$C$3,'Snowball Engine'!AW6,'Avalanche Engine'!AW6,'My Order Engine'!AW6) -> 18100 | X5: ='Minimums Engine'!AW6 -> 18100 | Z5: =Calc!B10 -> EXAMPLE: Visa card | AA5: =IF(Calc!C10=1,IF(Debts!I7="30+ years",360,Debts!I7),0) -> 19 | AB5: =Calc!D10 -> 4850
W6: =CHOOSE(Calc!$C$3,'Snowball Engine'!AW9,'Avalanche Engine'!AW9,'My Order Engine'!AW9) -> 16445.56 | X6: ='Minimums Engine'!AW9 -> 17045.56 | Z6: =Calc!B11 -> EXAMPLE: Store card | AA6: =IF(Calc!C11=1,IF(Debts!I8="30+ years",360,Debts!I8),0) -> 7 | AB6: =Calc!D11 -> 1200
B7: TOTAL DEBT | G7: DEBT-FREE BY | L7: MONTHS TO GO | W7: =CHOOSE(Calc!$C$3,'Snowball Engine'!AW12,'Avalanche Engine'!AW12,'My Order Engine'!AW12) -> 14740.45 | X7: ='Minimums Engine'!AW12 -> 15966.13 | Z7: =Calc!B12 -> EXAMPLE: Car loan | AA7: =IF(Calc!C12=1,IF(Debts!I9="30+ years",360,Debts!I9),0) -> 28 | AB7: =Calc!D12 -> 11400
B8: =Calc!C9 -> 18100 | G8: =Calc!C39 -> Jan 2029 | L8: =IF(Calc!C36=999,"360+",Calc!C36) -> 28 | W8: =CHOOSE(Calc!$C$3,'Snowball Engine'!AW15,'Avalanche Engine'!AW15,'My Order Engine'!AW15) -> 12952.93 | X8: ='Minimums Engine'!AW15 -> 14860.71 | Z8: =Calc!B13 -> EXAMPLE: Medical bill | AA8: =IF(Calc!C13=1,IF(Debts!I10="30+ years",360,Debts!I10),0) -> 3 | AB8: =Calc!D13 -> 650
V9: 1 | W9: =CHOOSE(Calc!$C$3,'Snowball Engine'!AW18,'Avalanche Engine'!AW18,'My Order Engine'!AW18) -> 11084.82 | X9: ='Minimums Engine'!AW18 -> 13728.25 | Z9: =Calc!B14 | AA9: =IF(Calc!C14=1,IF(Debts!I11="30+ years",360,Debts!I11),0) -> 0 | AB9: =Calc!D14 -> 0
W10: =CHOOSE(Calc!$C$3,'Snowball Engine'!AW21,'Avalanche Engine'!AW21,'My Order Engine'!AW21) -> 9132.53 | X10: ='Minimums Engine'!AW21 -> 12667.65 | Z10: =Calc!B15 | AA10: =IF(Calc!C15=1,IF(Debts!I12="30+ years",360,Debts!I12),0) -> 0 | AB10: =Calc!D15 -> 0
B11: TOTAL INTEREST (YOUR PLAN) | G11: INTEREST SAVED VS MINIMUMS | L11: TIME SAVED VS MINIMUMS | W11: =CHOOSE(Calc!$C$3,'Snowball Engine'!AW24,'Avalanche Engine'!AW24,'My Order Engine'!AW24) -> 7091.32 | X11: ='Minimums Engine'!AW24 -> 11627.75 | Z11: =Calc!B16 | AA11: =IF(Calc!C16=1,IF(Debts!I13="30+ years",360,Debts!I13),0) -> 0 | AB11: =Calc!D16 -> 0
B12: =Calc!C37 -> 2737.64 | G12: =Calc!C40 -> 3328.44 | L12: =Calc!C42 -> 2 yr 6 mo sooner | W12: =CHOOSE(Calc!$C$3,'Snowball Engine'!AW27,'Avalanche Engine'!AW27,'My Order Engine'!AW27) -> 4965.74 | X12: ='Minimums Engine'!AW27 -> 10557.29 | Z12: =Calc!B17 | AA12: =IF(Calc!C17=1,IF(Debts!I14="30+ years",360,Debts!I14),0) -> 0 | AB12: =Calc!D17 -> 0
V13: 2 | W13: =CHOOSE(Calc!$C$3,'Snowball Engine'!AW30,'Avalanche Engine'!AW30,'My Order Engine'!AW30) -> 2795.34 | X13: ='Minimums Engine'!AW30 -> 9454.98 | Z13: =Calc!B18 | AA13: =IF(Calc!C18=1,IF(Debts!I15="30+ years",360,Debts!I15),0) -> 0 | AB13: =Calc!D18 -> 0
W14: =CHOOSE(Calc!$C$3,'Snowball Engine'!AW33,'Avalanche Engine'!AW33,'My Order Engine'!AW33) -> 583.99 | X14: ='Minimums Engine'!AW33 -> 8319.46 | Z14: =Calc!B19 | AA14: =IF(Calc!C19=1,IF(Debts!I16="30+ years",360,Debts!I16),0) -> 0 | AB14: =Calc!D19 -> 0
B15: MONTHLY PAYMENT | G15: FIRST DEBT GONE | L15: HIGHEST INTEREST RATE | W15: =CHOOSE(Calc!$C$3,'Snowball Engine'!AW36,'Avalanche Engine'!AW36,'My Order Engine'!AW36) -> 0 | X15: ='Minimums Engine'!AW36 -> 7149.25 | Z15: =Calc!B20 | AA15: =IF(Calc!C20=1,IF(Debts!I17="30+ years",360,Debts!I17),0) -> 0 | AB15: =Calc!D20 -> 0
B16: =Calc!C7 -> 750 | G16: =Calc!C43 -> EXAMPLE: Medical bill (Dec 2026) | L16: =Calc!C44 -> EXAMPLE: Store card (28.99%) | W16: =CHOOSE(Calc!$C$3,'Snowball Engine'!AW39,'Avalanche Engine'!AW39,'My Order Engine'!AW39) -> 0 | X16: ='Minimums Engine'!AW39 -> 5942.83 | Z16: =Calc!B21 | AA16: =IF(Calc!C21=1,IF(Debts!I18="30+ years",360,Debts!I18),0) -> 0 | AB16: =Calc!D21 -> 0
V17: 3 | W17: =CHOOSE(Calc!$C$3,'Snowball Engine'!AW42,'Avalanche Engine'!AW42,'My Order Engine'!AW42) -> 0 | X17: ='Minimums Engine'!AW42 -> 4698.59 | Z17: =Calc!B22 | AA17: =IF(Calc!C22=1,IF(Debts!I19="30+ years",360,Debts!I19),0) -> 0 | AB17: =Calc!D22 -> 0
W18: =CHOOSE(Calc!$C$3,'Snowball Engine'!AW45,'Avalanche Engine'!AW45,'My Order Engine'!AW45) -> 0 | X18: ='Minimums Engine'!AW45 -> 3414.82 | Z18: =Calc!B23 | AA18: =IF(Calc!C23=1,IF(Debts!I20="30+ years",360,Debts!I20),0) -> 0 | AB18: =Calc!D23 -> 0
W19: =CHOOSE(Calc!$C$3,'Snowball Engine'!AW48,'Avalanche Engine'!AW48,'My Order Engine'!AW48) -> 0 | X19: ='Minimums Engine'!AW48 -> 2355.12 | Z19: =Calc!B24 | AA19: =IF(Calc!C24=1,IF(Debts!I21="30+ years",360,Debts!I21),0) -> 0 | AB19: =Calc!D24 -> 0
B20: Compare strategies | W20: =CHOOSE(Calc!$C$3,'Snowball Engine'!AW51,'Avalanche Engine'!AW51,'My Order Engine'!AW51) -> 0 | X20: ='Minimums Engine'!AW51 -> 1942.62
B21: Plan | E21: Debt-free by | G21: Months | H21: Total interest | J21: Interest saved | V21: 4 | W21: =CHOOSE(Calc!$C$3,'Snowball Engine'!AW54,'Avalanche Engine'!AW54,'My Order Engine'!AW54) -> 0 | X21: ='Minimums Engine'!AW54 -> 1502.84
B22: =Calc!B30 -> Minimums only | E22: =Calc!F30 -> Jul 2031 | G22: =IF(Calc!C30=999,"360+",Calc!C30) -> 58 | H22: =Calc!D30 -> 6066.08 | J22: =IF(Calc!$C$8=0,0,Calc!$D$30-Calc!D30) -> 0 | L22: ="Your plan: "&Dashboard!$C$4 -> Your plan: Snowball (smallest balance first) | W22: =CHOOSE(Calc!$C$3,'Snowball Engine'!AW57,'Avalanche Engine'!AW57,'My Order Engine'!AW57) -> 0 | X22: ='Minimums Engine'!AW57 -> 1033.99 | Z22: Plan | AA22: Total interest
B23: =Calc!B31 -> Snowball | E23: =Calc!F31 -> Jan 2029 | G23: =IF(Calc!C31=999,"360+",Calc!C31) -> 28 | H23: =Calc!D31 -> 2737.64 | J23: =IF(Calc!$C$8=0,0,Calc!$D$30-Calc!D31) -> 3328.44 | W23: =CHOOSE(Calc!$C$3,'Snowball Engine'!AW60,'Avalanche Engine'!AW60,'My Order Engine'!AW60) -> 0 | X23: ='Minimums Engine'!AW60 -> 534.11 | Z23: =Calc!B30 -> Minimums only | AA23: =Calc!D30 -> 6066.08
B24: =Calc!B32 -> Avalanche | E24: =Calc!F32 -> Jan 2029 | G24: =IF(Calc!C32=999,"360+",Calc!C32) -> 28 | H24: =Calc!D32 -> 2630.62 | J24: =IF(Calc!$C$8=0,0,Calc!$D$30-Calc!D32) -> 3435.46 | W24: =CHOOSE(Calc!$C$3,'Snowball Engine'!AW63,'Avalanche Engine'!AW63,'My Order Engine'!AW63) -> 0 | X24: ='Minimums Engine'!AW63 -> 122.32 | Z24: =Calc!B31 -> Snowball | AA24: =Calc!D31 -> 2737.64
B25: =Calc!B33 -> My order | E25: =Calc!F33 -> Jan 2029 | G25: =IF(Calc!C33=999,"360+",Calc!C33) -> 28 | H25: =Calc!D33 -> 2696.56 | J25: =IF(Calc!$C$8=0,0,Calc!$D$30-Calc!D33) -> 3369.52 | V25: 5 | W25: =CHOOSE(Calc!$C$3,'Snowball Engine'!AW66,'Avalanche Engine'!AW66,'My Order Engine'!AW66) -> 0 | X25: ='Minimums Engine'!AW66 -> 0 | Z25: =Calc!B32 -> Avalanche | AA25: =Calc!D32 -> 2630.62
B26: Minimums only = paying just the minimums, no extra and no snowball. Interest is capped at 30 years for plans that never finish. | W26: =CHOOSE(Calc!$C$3,'Snowball Engine'!AW69,'Avalanche Engine'!AW69,'My Order Engine'!AW69) -> 0 | X26: ='Minimums Engine'!AW69 -> 0 | Z26: =Calc!B33 -> My order | AA26: =Calc!D33 -> 2696.56
W27: =CHOOSE(Calc!$C$3,'Snowball Engine'!AW72,'Avalanche Engine'!AW72,'My Order Engine'!AW72) -> 0 | X27: ='Minimums Engine'!AW72 -> 0
W28: =CHOOSE(Calc!$C$3,'Snowball Engine'!AW75,'Avalanche Engine'!AW75,'My Order Engine'!AW75) -> 0 | X28: ='Minimums Engine'!AW75 -> 0 | Z28: Your plan pays | AA28: Amount
V29: 6 | W29: =CHOOSE(Calc!$C$3,'Snowball Engine'!AW78,'Avalanche Engine'!AW78,'My Order Engine'!AW78) -> 0 | X29: ='Minimums Engine'!AW78 -> 0 | Z29: Debt (principal) | AA29: =Calc!C9 -> 18100
W30: =CHOOSE(Calc!$C$3,'Snowball Engine'!AW81,'Avalanche Engine'!AW81,'My Order Engine'!AW81) -> 0 | X30: ='Minimums Engine'!AW81 -> 0 | Z30: Interest | AA30: =MAX(0,Calc!C37) -> 2737.64
W31: =CHOOSE(Calc!$C$3,'Snowball Engine'!AW84,'Avalanche Engine'!AW84,'My Order Engine'!AW84) -> 0 | X31: ='Minimums Engine'!AW84 -> 0
W32: =CHOOSE(Calc!$C$3,'Snowball Engine'!AW87,'Avalanche Engine'!AW87,'My Order Engine'!AW87) -> 0 | X32: ='Minimums Engine'!AW87 -> 0
V33: 7 | W33: =CHOOSE(Calc!$C$3,'Snowball Engine'!AW90,'Avalanche Engine'!AW90,'My Order Engine'!AW90) -> 0 | X33: ='Minimums Engine'!AW90 -> 0
W34: =CHOOSE(Calc!$C$3,'Snowball Engine'!AW93,'Avalanche Engine'!AW93,'My Order Engine'!AW93) -> 0 | X34: ='Minimums Engine'!AW93 -> 0
W35: =CHOOSE(Calc!$C$3,'Snowball Engine'!AW96,'Avalanche Engine'!AW96,'My Order Engine'!AW96) -> 0 | X35: ='Minimums Engine'!AW96 -> 0
W36: =CHOOSE(Calc!$C$3,'Snowball Engine'!AW99,'Avalanche Engine'!AW99,'My Order Engine'!AW99) -> 0 | X36: ='Minimums Engine'!AW99 -> 0
V37: 8 | W37: =CHOOSE(Calc!$C$3,'Snowball Engine'!AW102,'Avalanche Engine'!AW102,'My Order Engine'!AW102) -> 0 | X37: ='Minimums Engine'!AW102 -> 0
W38: =CHOOSE(Calc!$C$3,'Snowball Engine'!AW105,'Avalanche Engine'!AW105,'My Order Engine'!AW105) -> 0 | X38: ='Minimums Engine'!AW105 -> 0
W39: =CHOOSE(Calc!$C$3,'Snowball Engine'!AW108,'Avalanche Engine'!AW108,'My Order Engine'!AW108) -> 0 | X39: ='Minimums Engine'!AW108 -> 0
W40: =CHOOSE(Calc!$C$3,'Snowball Engine'!AW111,'Avalanche Engine'!AW111,'My Order Engine'!AW111) -> 0 | X40: ='Minimums Engine'!AW111 -> 0
V41: 9 | W41: =CHOOSE(Calc!$C$3,'Snowball Engine'!AW114,'Avalanche Engine'!AW114,'My Order Engine'!AW114) -> 0 | X41: ='Minimums Engine'!AW114 -> 0
...

Sheet Debts
A1: Debts
A2: Everything you owe: balance, interest rate (APR %) and minimum payment. The plan columns fill in automatically. | J2: Rows to fix: | K2: =Calc!$O$3 -> 0
A3: Red cell = something to fix (that debt stays out of the plan). Orange = the minimum doesn't cover the interest.
A6: Debt | B6: Type (optional) | C6: Balance now | D6: APR % (e.g. 22.99) | E6: Minimum payment / month | F6: My order (optional) | G6: Interest this month | H6: Pay-off order (your plan) | I6: Months to pay off | J6: Paid off by | K6: Interest you'll pay | L6: Note
A7: EXAMPLE: Visa card | B7: Credit card | C7: 4850 | D7: 24.99 | E7: 145 | G7: =IF(Calc!$C$10=1,ROUND(C7*D7/1200,2),"") -> 101 | H7: =IF(Calc!$C$10=1,Calc!$L$10,"") -> 3 | I7: =IF(Calc!$C$10=1,IF(CHOOSE(Calc!$C$3,INDEX('Snowball Engine'!$AH$369:$AV$369,Calc!$I$10),INDEX('Avalanche Engine'!$AH$369:$AV$369,Calc!$J$10),INDEX('My Order Engine'!$AH$369:$AV$369,Calc!$K$10))=999,"30+ years",CHOOSE(Calc!$C$3,INDEX('Snowball Engine'!$AH$369:$AV$369,Calc!$I$10),INDEX('Avalanche Engine'!$AH$369:$AV$369,Calc!$J$10),INDEX('My Order Engine'!$AH$369:$AV$369,Calc!$K$10))),"") -> 19 | J7: =IF(OR(I7="",I7="30+ years"),"",EDATE(Calc!$C$5,I7-1)) -> 46844 | K7: =IF(Calc!$C$10=1,CHOOSE(Calc!$C$3,INDEX('Snowball Engine'!$AH$370:$AV$370,Calc!$I$10),INDEX('Avalanche Engine'!$AH$370:$AV$370,Calc!$J$10),INDEX('My Order Engine'!$AH$370:$AV$370,Calc!$K$10)),"") -> 1306.24 | L7: =IF(Calc!$C$10=1,IF(G7>=E7,"Minimum doesn't cover the interest: balance grows on minimums",IF(N(D7)=0,"0% interest","")),IF(OR(A7<>"",B7<>"",C7<>"",D7<>"",E7<>"",F7<>""),"Fix the red cells",""))
A8: EXAMPLE: Store card | B8: Store card | C8: 1200 | D8: 28.99 | E8: 40 | G8: =IF(Calc!$C$11=1,ROUND(C8*D8/1200,2),"") -> 28.99 | H8: =IF(Calc!$C$11=1,Calc!$L$11,"") -> 2 | I8: =IF(Calc!$C$11=1,IF(CHOOSE(Calc!$C$3,INDEX('Snowball Engine'!$AH$369:$AV$369,Calc!$I$11),INDEX('Avalanche Engine'!$AH$369:$AV$369,Calc!$J$11),INDEX('My Order Engine'!$AH$369:$AV$369,Calc!$K$11))=999,"30+ years",CHOOSE(Calc!$C$3,INDEX('Snowball Engine'!$AH$369:$AV$369,Calc!$I$11),INDEX('Avalanche Engine'!$AH$369:$AV$369,Calc!$J$11),INDEX('My Order Engine'!$AH$369:$AV$369,Calc!$K$11))),"") -> 7 | J8: =IF(OR(I8="",I8="30+ years"),"",EDATE(Calc!$C$5,I8-1)) -> 46478 | K8: =IF(Calc!$C$11=1,CHOOSE(Calc!$C$3,INDEX('Snowball Engine'!$AH$370:$AV$370,Calc!$I$11),INDEX('Avalanche Engine'!$AH$370:$AV$370,Calc!$J$11),INDEX('My Order Engine'!$AH$370:$AV$370,Calc!$K$11)),"") -> 150.27 | L8: =IF(Calc!$C$11=1,IF(G8>=E8,"Minimum doesn't cover the interest: balance grows on minimums",IF(N(D8)=0,"0% interest","")),IF(OR(A8<>"",B8<>"",C8<>"",D8<>"",E8<>"",F8<>""),"Fix the red cells",""))
A9: EXAMPLE: Car loan | B9: Car loan | C9: 11400 | D9: 7.5 | E9: 315 | G9: =IF(Calc!$C$12=1,ROUND(C9*D9/1200,2),"") -> 71.25 | H9: =IF(Calc!$C$12=1,Calc!$L$12,"") -> 4 | I9: =IF(Calc!$C$12=1,IF(CHOOSE(Calc!$C$3,INDEX('Snowball Engine'!$AH$369:$AV$369,Calc!$I$12),INDEX('Avalanche Engine'!$AH$369:$AV$369,Calc!$J$12),INDEX('My Order Engine'!$AH$369:$AV$369,Calc!$K$12))=999,"30+ years",CHOOSE(Calc!$C$3,INDEX('Snowball Engine'!$AH$369:$AV$369,Calc!$I$12),INDEX('Avalanche Engine'!$AH$369:$AV$369,Calc!$J$12),INDEX('My Order Engine'!$AH$369:$AV$369,Calc!$K$12))),"") -> 28 | J9: =IF(OR(I9="",I9="30+ years"),"",EDATE(Calc!$C$5,I9-1)) -> 47119 | K9: =IF(Calc!$C$12=1,CHOOSE(Calc!$C$3,INDEX('Snowball Engine'!$AH$370:$AV$370,Calc!$I$12),INDEX('Avalanche Engine'!$AH$370:$AV$370,Calc!$J$12),INDEX('My Order Engine'!$AH$370:$AV$370,Calc!$K$12)),"") -> 1281.13 | L9: =IF(Calc!$C$12=1,IF(G9>=E9,"Minimum doesn't cover the interest: balance grows on minimums",IF(N(D9)=0,"0% interest","")),IF(OR(A9<>"",B9<>"",C9<>"",D9<>"",E9<>"",F9<>""),"Fix the red cells",""))
A10: EXAMPLE: Medical bill | B10: Medical | C10: 650 | D10: 0 | E10: 50 | G10: =IF(Calc!$C$13=1,ROUND(C10*D10/1200,2),"") -> 0 | H10: =IF(Calc!$C$13=1,Calc!$L$13,"") -> 1 | I10: =IF(Calc!$C$13=1,IF(CHOOSE(Calc!$C$3,INDEX('Snowball Engine'!$AH$369:$AV$369,Calc!$I$13),INDEX('Avalanche Engine'!$AH$369:$AV$369,Calc!$J$13),INDEX('My Order Engine'!$AH$369:$AV$369,Calc!$K$13))=999,"30+ years",CHOOSE(Calc!$C$3,INDEX('Snowball Engine'!$AH$369:$AV$369,Calc!$I$13),INDEX('Avalanche Engine'!$AH$369:$AV$369,Calc!$J$13),INDEX('My Order Engine'!$AH$369:$AV$369,Calc!$K$13))),"") -> 3 | J10: =IF(OR(I10="",I10="30+ years"),"",EDATE(Calc!$C$5,I10-1)) -> 46357 | K10: =IF(Calc!$C$13=1,CHOOSE(Calc!$C$3,INDEX('Snowball Engine'!$AH$370:$AV$370,Calc!$I$13),INDEX('Avalanche Engine'!$AH$370:$AV$370,Calc!$J$13),INDEX('My Order Engine'!$AH$370:$AV$370,Calc!$K$13)),"") -> 0 | L10: =IF(Calc!$C$13=1,IF(G10>=E10,"Minimum doesn't cover the interest: balance grows on minimums",IF(N(D10)=0,"0% interest","")),IF(OR(A10<>"",B10<>"",C10<>"",D10<>"",E10<>"",F10<>""),"Fix the red cells","")) -> 0% interest
G11: =IF(Calc!$C$14=1,ROUND(C11*D11/1200,2),"") | H11: =IF(Calc!$C$14=1,Calc!$L$14,"") | I11: =IF(Calc!$C$14=1,IF(CHOOSE(Calc!$C$3,INDEX('Snowball Engine'!$AH$369:$AV$369,Calc!$I$14),INDEX('Avalanche Engine'!$AH$369:$AV$369,Calc!$J$14),INDEX('My Order Engine'!$AH$369:$AV$369,Calc!$K$14))=999,"30+ years",CHOOSE(Calc!$C$3,INDEX('Snowball Engine'!$AH$369:$AV$369,Calc!$I$14),INDEX('Avalanche Engine'!$AH$369:$AV$369,Calc!$J$14),INDEX('My Order Engine'!$AH$369:$AV$369,Calc!$K$14))),"") | J11: =IF(OR(I11="",I11="30+ years"),"",EDATE(Calc!$C$5,I11-1)) | K11: =IF(Calc!$C$14=1,CHOOSE(Calc!$C$3,INDEX('Snowball Engine'!$AH$370:$AV$370,Calc!$I$14),INDEX('Avalanche Engine'!$AH$370:$AV$370,Calc!$J$14),INDEX('My Order Engine'!$AH$370:$AV$370,Calc!$K$14)),"") | L11: =IF(Calc!$C$14=1,IF(G11>=E11,"Minimum doesn't cover the interest: balance grows on minimums",IF(N(D11)=0,"0% interest","")),IF(OR(A11<>"",B11<>"",C11<>"",D11<>"",E11<>"",F11<>""),"Fix the red cells",""))
G12: =IF(Calc!$C$15=1,ROUND(C12*D12/1200,2),"") | H12: =IF(Calc!$C$15=1,Calc!$L$15,"") | I12: =IF(Calc!$C$15=1,IF(CHOOSE(Calc!$C$3,INDEX('Snowball Engine'!$AH$369:$AV$369,Calc!$I$15),INDEX('Avalanche Engine'!$AH$369:$AV$369,Calc!$J$15),INDEX('My Order Engine'!$AH$369:$AV$369,Calc!$K$15))=999,"30+ years",CHOOSE(Calc!$C$3,INDEX('Snowball Engine'!$AH$369:$AV$369,Calc!$I$15),INDEX('Avalanche Engine'!$AH$369:$AV$369,Calc!$J$15),INDEX('My Order Engine'!$AH$369:$AV$369,Calc!$K$15))),"") | J12: =IF(OR(I12="",I12="30+ years"),"",EDATE(Calc!$C$5,I12-1)) | K12: =IF(Calc!$C$15=1,CHOOSE(Calc!$C$3,INDEX('Snowball Engine'!$AH$370:$AV$370,Calc!$I$15),INDEX('Avalanche Engine'!$AH$370:$AV$370,Calc!$J$15),INDEX('My Order Engine'!$AH$370:$AV$370,Calc!$K$15)),"") | L12: =IF(Calc!$C$15=1,IF(G12>=E12,"Minimum doesn't cover the interest: balance grows on minimums",IF(N(D12)=0,"0% interest","")),IF(OR(A12<>"",B12<>"",C12<>"",D12<>"",E12<>"",F12<>""),"Fix the red cells",""))
G13: =IF(Calc!$C$16=1,ROUND(C13*D13/1200,2),"") | H13: =IF(Calc!$C$16=1,Calc!$L$16,"") | I13: =IF(Calc!$C$16=1,IF(CHOOSE(Calc!$C$3,INDEX('Snowball Engine'!$AH$369:$AV$369,Calc!$I$16),INDEX('Avalanche Engine'!$AH$369:$AV$369,Calc!$J$16),INDEX('My Order Engine'!$AH$369:$AV$369,Calc!$K$16))=999,"30+ years",CHOOSE(Calc!$C$3,INDEX('Snowball Engine'!$AH$369:$AV$369,Calc!$I$16),INDEX('Avalanche Engine'!$AH$369:$AV$369,Calc!$J$16),INDEX('My Order Engine'!$AH$369:$AV$369,Calc!$K$16))),"") | J13: =IF(OR(I13="",I13="30+ years"),"",EDATE(Calc!$C$5,I13-1)) | K13: =IF(Calc!$C$16=1,CHOOSE(Calc!$C$3,INDEX('Snowball Engine'!$AH$370:$AV$370,Calc!$I$16),INDEX('Avalanche Engine'!$AH$370:$AV$370,Calc!$J$16),INDEX('My Order Engine'!$AH$370:$AV$370,Calc!$K$16)),"") | L13: =IF(Calc!$C$16=1,IF(G13>=E13,"Minimum doesn't cover the interest: balance grows on minimums",IF(N(D13)=0,"0% interest","")),IF(OR(A13<>"",B13<>"",C13<>"",D13<>"",E13<>"",F13<>""),"Fix the red cells",""))
G14: =IF(Calc!$C$17=1,ROUND(C14*D14/1200,2),"") | H14: =IF(Calc!$C$17=1,Calc!$L$17,"") | I14: =IF(Calc!$C$17=1,IF(CHOOSE(Calc!$C$3,INDEX('Snowball Engine'!$AH$369:$AV$369,Calc!$I$17),INDEX('Avalanche Engine'!$AH$369:$AV$369,Calc!$J$17),INDEX('My Order Engine'!$AH$369:$AV$369,Calc!$K$17))=999,"30+ years",CHOOSE(Calc!$C$3,INDEX('Snowball Engine'!$AH$369:$AV$369,Calc!$I$17),INDEX('Avalanche Engine'!$AH$369:$AV$369,Calc!$J$17),INDEX('My Order Engine'!$AH$369:$AV$369,Calc!$K$17))),"") | J14: =IF(OR(I14="",I14="30+ years"),"",EDATE(Calc!$C$5,I14-1)) | K14: =IF(Calc!$C$17=1,CHOOSE(Calc!$C$3,INDEX('Snowball Engine'!$AH$370:$AV$370,Calc!$I$17),INDEX('Avalanche Engine'!$AH$370:$AV$370,Calc!$J$17),INDEX('My Order Engine'!$AH$370:$AV$370,Calc!$K$17)),"") | L14: =IF(Calc!$C$17=1,IF(G14>=E14,"Minimum doesn't cover the interest: balance grows on minimums",IF(N(D14)=0,"0% interest","")),IF(OR(A14<>"",B14<>"",C14<>"",D14<>"",E14<>"",F14<>""),"Fix the red cells",""))
G15: =IF(Calc!$C$18=1,ROUND(C15*D15/1200,2),"") | H15: =IF(Calc!$C$18=1,Calc!$L$18,"") | I15: =IF(Calc!$C$18=1,IF(CHOOSE(Calc!$C$3,INDEX('Snowball Engine'!$AH$369:$AV$369,Calc!$I$18),INDEX('Avalanche Engine'!$AH$369:$AV$369,Calc!$J$18),INDEX('My Order Engine'!$AH$369:$AV$369,Calc!$K$18))=999,"30+ years",CHOOSE(Calc!$C$3,INDEX('Snowball Engine'!$AH$369:$AV$369,Calc!$I$18),INDEX('Avalanche Engine'!$AH$369:$AV$369,Calc!$J$18),INDEX('My Order Engine'!$AH$369:$AV$369,Calc!$K$18))),"") | J15: =IF(OR(I15="",I15="30+ years"),"",EDATE(Calc!$C$5,I15-1)) | K15: =IF(Calc!$C$18=1,CHOOSE(Calc!$C$3,INDEX('Snowball Engine'!$AH$370:$AV$370,Calc!$I$18),INDEX('Avalanche Engine'!$AH$370:$AV$370,Calc!$J$18),INDEX('My Order Engine'!$AH$370:$AV$370,Calc!$K$18)),"") | L15: =IF(Calc!$C$18=1,IF(G15>=E15,"Minimum doesn't cover the interest: balance grows on minimums",IF(N(D15)=0,"0% interest","")),IF(OR(A15<>"",B15<>"",C15<>"",D15<>"",E15<>"",F15<>""),"Fix the red cells",""))
G16: =IF(Calc!$C$19=1,ROUND(C16*D16/1200,2),"") | H16: =IF(Calc!$C$19=1,Calc!$L$19,"") | I16: =IF(Calc!$C$19=1,IF(CHOOSE(Calc!$C$3,INDEX('Snowball Engine'!$AH$369:$AV$369,Calc!$I$19),INDEX('Avalanche Engine'!$AH$369:$AV$369,Calc!$J$19),INDEX('My Order Engine'!$AH$369:$AV$369,Calc!$K$19))=999,"30+ years",CHOOSE(Calc!$C$3,INDEX('Snowball Engine'!$AH$369:$AV$369,Calc!$I$19),INDEX('Avalanche Engine'!$AH$369:$AV$369,Calc!$J$19),INDEX('My Order Engine'!$AH$369:$AV$369,Calc!$K$19))),"") | J16: =IF(OR(I16="",I16="30+ years"),"",EDATE(Calc!$C$5,I16-1)) | K16: =IF(Calc!$C$19=1,CHOOSE(Calc!$C$3,INDEX('Snowball Engine'!$AH$370:$AV$370,Calc!$I$19),INDEX('Avalanche Engine'!$AH$370:$AV$370,Calc!$J$19),INDEX('My Order Engine'!$AH$370:$AV$370,Calc!$K$19)),"") | L16: =IF(Calc!$C$19=1,IF(G16>=E16,"Minimum doesn't cover the interest: balance grows on minimums",IF(N(D16)=0,"0% interest","")),IF(OR(A16<>"",B16<>"",C16<>"",D16<>"",E16<>"",F16<>""),"Fix the red cells",""))
G17: =IF(Calc!$C$20=1,ROUND(C17*D17/1200,2),"") | H17: =IF(Calc!$C$20=1,Calc!$L$20,"") | I17: =IF(Calc!$C$20=1,IF(CHOOSE(Calc!$C$3,INDEX('Snowball Engine'!$AH$369:$AV$369,Calc!$I$20),INDEX('Avalanche Engine'!$AH$369:$AV$369,Calc!$J$20),INDEX('My Order Engine'!$AH$369:$AV$369,Calc!$K$20))=999,"30+ years",CHOOSE(Calc!$C$3,INDEX('Snowball Engine'!$AH$369:$AV$369,Calc!$I$20),INDEX('Avalanche Engine'!$AH$369:$AV$369,Calc!$J$20),INDEX('My Order Engine'!$AH$369:$AV$369,Calc!$K$20))),"") | J17: =IF(OR(I17="",I17="30+ years"),"",EDATE(Calc!$C$5,I17-1)) | K17: =IF(Calc!$C$20=1,CHOOSE(Calc!$C$3,INDEX('Snowball Engine'!$AH$370:$AV$370,Calc!$I$20),INDEX('Avalanche Engine'!$AH$370:$AV$370,Calc!$J$20),INDEX('My Order Engine'!$AH$370:$AV$370,Calc!$K$20)),"") | L17: =IF(Calc!$C$20=1,IF(G17>=E17,"Minimum doesn't cover the interest: balance grows on minimums",IF(N(D17)=0,"0% interest","")),IF(OR(A17<>"",B17<>"",C17<>"",D17<>"",E17<>"",F17<>""),"Fix the red cells",""))
G18: =IF(Calc!$C$21=1,ROUND(C18*D18/1200,2),"") | H18: =IF(Calc!$C$21=1,Calc!$L$21,"") | I18: =IF(Calc!$C$21=1,IF(CHOOSE(Calc!$C$3,INDEX('Snowball Engine'!$AH$369:$AV$369,Calc!$I$21),INDEX('Avalanche Engine'!$AH$369:$AV$369,Calc!$J$21),INDEX('My Order Engine'!$AH$369:$AV$369,Calc!$K$21))=999,"30+ years",CHOOSE(Calc!$C$3,INDEX('Snowball Engine'!$AH$369:$AV$369,Calc!$I$21),INDEX('Avalanche Engine'!$AH$369:$AV$369,Calc!$J$21),INDEX('My Order Engine'!$AH$369:$AV$369,Calc!$K$21))),"") | J18: =IF(OR(I18="",I18="30+ years"),"",EDATE(Calc!$C$5,I18-1)) | K18: =IF(Calc!$C$21=1,CHOOSE(Calc!$C$3,INDEX('Snowball Engine'!$AH$370:$AV$370,Calc!$I$21),INDEX('Avalanche Engine'!$AH$370:$AV$370,Calc!$J$21),INDEX('My Order Engine'!$AH$370:$AV$370,Calc!$K$21)),"") | L18: =IF(Calc!$C$21=1,IF(G18>=E18,"Minimum doesn't cover the interest: balance grows on minimums",IF(N(D18)=0,"0% interest","")),IF(OR(A18<>"",B18<>"",C18<>"",D18<>"",E18<>"",F18<>""),"Fix the red cells",""))
G19: =IF(Calc!$C$22=1,ROUND(C19*D19/1200,2),"") | H19: =IF(Calc!$C$22=1,Calc!$L$22,"") | I19: =IF(Calc!$C$22=1,IF(CHOOSE(Calc!$C$3,INDEX('Snowball Engine'!$AH$369:$AV$369,Calc!$I$22),INDEX('Avalanche Engine'!$AH$369:$AV$369,Calc!$J$22),INDEX('My Order Engine'!$AH$369:$AV$369,Calc!$K$22))=999,"30+ years",CHOOSE(Calc!$C$3,INDEX('Snowball Engine'!$AH$369:$AV$369,Calc!$I$22),INDEX('Avalanche Engine'!$AH$369:$AV$369,Calc!$J$22),INDEX('My Order Engine'!$AH$369:$AV$369,Calc!$K$22))),"") | J19: =IF(OR(I19="",I19="30+ years"),"",EDATE(Calc!$C$5,I19-1)) | K19: =IF(Calc!$C$22=1,CHOOSE(Calc!$C$3,INDEX('Snowball Engine'!$AH$370:$AV$370,Calc!$I$22),INDEX('Avalanche Engine'!$AH$370:$AV$370,Calc!$J$22),INDEX('My Order Engine'!$AH$370:$AV$370,Calc!$K$22)),"") | L19: =IF(Calc!$C$22=1,IF(G19>=E19,"Minimum doesn't cover the interest: balance grows on minimums",IF(N(D19)=0,"0% interest","")),IF(OR(A19<>"",B19<>"",C19<>"",D19<>"",E19<>"",F19<>""),"Fix the red cells",""))
G20: =IF(Calc!$C$23=1,ROUND(C20*D20/1200,2),"") | H20: =IF(Calc!$C$23=1,Calc!$L$23,"") | I20: =IF(Calc!$C$23=1,IF(CHOOSE(Calc!$C$3,INDEX('Snowball Engine'!$AH$369:$AV$369,Calc!$I$23),INDEX('Avalanche Engine'!$AH$369:$AV$369,Calc!$J$23),INDEX('My Order Engine'!$AH$369:$AV$369,Calc!$K$23))=999,"30+ years",CHOOSE(Calc!$C$3,INDEX('Snowball Engine'!$AH$369:$AV$369,Calc!$I$23),INDEX('Avalanche Engine'!$AH$369:$AV$369,Calc!$J$23),INDEX('My Order Engine'!$AH$369:$AV$369,Calc!$K$23))),"") | J20: =IF(OR(I20="",I20="30+ years"),"",EDATE(Calc!$C$5,I20-1)) | K20: =IF(Calc!$C$23=1,CHOOSE(Calc!$C$3,INDEX('Snowball Engine'!$AH$370:$AV$370,Calc!$I$23),INDEX('Avalanche Engine'!$AH$370:$AV$370,Calc!$J$23),INDEX('My Order Engine'!$AH$370:$AV$370,Calc!$K$23)),"") | L20: =IF(Calc!$C$23=1,IF(G20>=E20,"Minimum doesn't cover the interest: balance grows on minimums",IF(N(D20)=0,"0% interest","")),IF(OR(A20<>"",B20<>"",C20<>"",D20<>"",E20<>"",F20<>""),"Fix the red cells",""))
G21: =IF(Calc!$C$24=1,ROUND(C21*D21/1200,2),"") | H21: =IF(Calc!$C$24=1,Calc!$L$24,"") | I21: =IF(Calc!$C$24=1,IF(CHOOSE(Calc!$C$3,INDEX('Snowball Engine'!$AH$369:$AV$369,Calc!$I$24),INDEX('Avalanche Engine'!$AH$369:$AV$369,Calc!$J$24),INDEX('My Order Engine'!$AH$369:$AV$369,Calc!$K$24))=999,"30+ years",CHOOSE(Calc!$C$3,INDEX('Snowball Engine'!$AH$369:$AV$369,Calc!$I$24),INDEX('Avalanche Engine'!$AH$369:$AV$369,Calc!$J$24),INDEX('My Order Engine'!$AH$369:$AV$369,Calc!$K$24))),"") | J21: =IF(OR(I21="",I21="30+ years"),"",EDATE(Calc!$C$5,I21-1)) | K21: =IF(Calc!$C$24=1,CHOOSE(Calc!$C$3,INDEX('Snowball Engine'!$AH$370:$AV$370,Calc!$I$24),INDEX('Avalanche Engine'!$AH$370:$AV$370,Calc!$J$24),INDEX('My Order Engine'!$AH$370:$AV$370,Calc!$K$24)),"") | L21: =IF(Calc!$C$24=1,IF(G21>=E21,"Minimum doesn't cover the interest: balance grows on minimums",IF(N(D21)=0,"0% interest","")),IF(OR(A21<>"",B21<>"",C21<>"",D21<>"",E21<>"",F21<>""),"Fix the red cells",""))
A22: Total | C22: =Calc!$C$9 -> 18100 | E22: =Calc!$C$6 -> 550 | G22: =SUM(G7:G21) -> 201.24 | K22: =SUM(K7:K21) -> 2737.64
A24: Totals count valid rows only. 'Paid off by' assumes you start on the month picked on the Dashboard and pay the plan every month.
A25: APR: type the yearly rate as a number, e.g. 22.99 for 22.99%. Use 0 for an interest-free debt.

Sheet Payoff Schedule
A1: Payoff Schedule
A2: ="Your plan: "&Dashboard!$C$4&". Pay "&TEXT(Calc!$C$7,"$#,##0.00")&" every month. Debt-free: "&Calc!$C$39&". Nothing to type here." -> Your plan: Snowball (smallest balance first). Pay $750.00 every month. Debt-free: Jan 2029. Nothing to type here.
A4: Month | B4: Date | C4: Payment | D4: Interest | E4: Principal | F4: Total left | G4: =IF(Calc!$C$10=1,Debts!A7,"") -> EXAMPLE: Visa card | H4: =IF(Calc!$C$11=1,Debts!A8,"") -> EXAMPLE: Store card | I4: =IF(Calc!$C$12=1,Debts!A9,"") -> EXAMPLE: Car loan | J4: =IF(Calc!$C$13=1,Debts!A10,"") -> EXAMPLE: Medical bill | K4: =IF(Calc!$C$14=1,Debts!A11,"") | L4: =IF(Calc!$C$15=1,Debts!A12,"") | M4: =IF(Calc!$C$16=1,Debts!A13,"") | N4: =IF(Calc!$C$17=1,Debts!A14,"") | O4: =IF(Calc!$C$18=1,Debts!A15,"") | P4: =IF(Calc!$C$19=1,Debts!A16,"") | Q4: =IF(Calc!$C$20=1,Debts!A17,"") | R4: =IF(Calc!$C$21=1,Debts!A18,"") | S4: =IF(Calc!$C$22=1,Debts!A19,"") | T4: =IF(Calc!$C$23=1,Debts!A20,"") | U4: =IF(Calc!$C$24=1,Debts!A21,"")
A5: 1 | B5: =IF($A5<=IF(Calc!$C$36=999,360,Calc!$C$36),EDATE(Calc!$C$5,A5-1),"") -> 46296 | C5: =IF($A5<=IF(Calc!$C$36=999,360,Calc!$C$36),CHOOSE(Calc!$C$3,'Snowball Engine'!AY7,'Avalanche Engine'!AY7,'My Order Engine'!AY7),"") -> 750 | D5: =IF($A5<=IF(Calc!$C$36=999,360,Calc!$C$36),CHOOSE(Calc!$C$3,'Snowball Engine'!AX7,'Avalanche Engine'!AX7,'My Order Engine'!AX7),"") -> 201.24 | E5: =IF($A5<=IF(Calc!$C$36=999,360,Calc!$C$36),C5-D5,"") -> 548.76 | F5: =IF($A5<=IF(Calc!$C$36=999,360,Calc!$C$36),CHOOSE(Calc!$C$3,'Snowball Engine'!AW7,'Avalanche Engine'!AW7,'My Order Engine'!AW7),"") -> 17551.24 | G5: =IF(AND($A5<=IF(Calc!$C$36=999,360,Calc!$C$36),Calc!$C$10=1),CHOOSE(Calc!$C$3,INDEX('Snowball Engine'!$AH7:$AV7,Calc!$I$10),INDEX('Avalanche Engine'!$AH7:$AV7,Calc!$J$10),INDEX('My Order Engine'!$AH7:$AV7,Calc!$K$10)),"") -> 4806 | H5: =IF(AND($A5<=IF(Calc!$C$36=999,360,Calc!$C$36),Calc!$C$11=1),CHOOSE(Calc!$C$3,INDEX('Snowball Engine'!$AH7:$AV7,Calc!$I$11),INDEX('Avalanche Engine'!$AH7:$AV7,Calc!$J$11),INDEX('My Order Engine'!$AH7:$AV7,Calc!$K$11)),"") -> 1188.99 | I5: =IF(AND($A5<=IF(Calc!$C$36=999,360,Calc!$C$36),Calc!$C$12=1),CHOOSE(Calc!$C$3,INDEX('Snowball Engine'!$AH7:$AV7,Calc!$I$12),INDEX('Avalanche Engine'!$AH7:$AV7,Calc!$J$12),INDEX('My Order Engine'!$AH7:$AV7,Calc!$K$12)),"") -> 11156.25 | J5: =IF(AND($A5<=IF(Calc!$C$36=999,360,Calc!$C$36),Calc!$C$13=1),CHOOSE(Calc!$C$3,INDEX('Snowball Engine'!$AH7:$AV7,Calc!$I$13),INDEX('Avalanche Engine'!$AH7:$AV7,Calc!$J$13),INDEX('My Order Engine'!$AH7:$AV7,Calc!$K$13)),"") -> 400 | K5: =IF(AND($A5<=IF(Calc!$C$36=999,360,Calc!$C$36),Calc!$C$14=1),CHOOSE(Calc!$C$3,INDEX('Snowball Engine'!$AH7:$AV7,Calc!$I$14),INDEX('Avalanche Engine'!$AH7:$AV7,Calc!$J$14),INDEX('My Order Engine'!$AH7:$AV7,Calc!$K$14)),"") | L5: =IF(AND($A5<=IF(Calc!$C$36=999,360,Calc!$C$36),Calc!$C$15=1),CHOOSE(Calc!$C$3,INDEX('Snowball Engine'!$AH7:$AV7,Calc!$I$15),INDEX('Avalanche Engine'!$AH7:$AV7,Calc!$J$15),INDEX('My Order Engine'!$AH7:$AV7,Calc!$K$15)),"") | M5: =IF(AND($A5<=IF(Calc!$C$36=999,360,Calc!$C$36),Calc!$C$16=1),CHOOSE(Calc!$C$3,INDEX('Snowball Engine'!$AH7:$AV7,Calc!$I$16),INDEX('Avalanche Engine'!$AH7:$AV7,Calc!$J$16),INDEX('My Order Engine'!$AH7:$AV7,Calc!$K$16)),"") | N5: =IF(AND($A5<=IF(Calc!$C$36=999,360,Calc!$C$36),Calc!$C$17=1),CHOOSE(Calc!$C$3,INDEX('Snowball Engine'!$AH7:$AV7,Calc!$I$17),INDEX('Avalanche Engine'!$AH7:$AV7,Calc!$J$17),INDEX('My Order Engine'!$AH7:$AV7,Calc!$K$17)),"") | O5: =IF(AND($A5<=IF(Calc!$C$36=999,360,Calc!$C$36),Calc!$C$18=1),CHOOSE(Calc!$C$3,INDEX('Snowball Engine'!$AH7:$AV7,Calc!$I$18),INDEX('Avalanche Engine'!$AH7:$AV7,Calc!$J$18),INDEX('My Order Engine'!$AH7:$AV7,Calc!$K$18)),"") | P5: =IF(AND($A5<=IF(Calc!$C$36=999,360,Calc!$C$36),Calc!$C$19=1),CHOOSE(Calc!$C$3,INDEX('Snowball Engine'!$AH7:$AV7,Calc!$I$19),INDEX('Avalanche Engine'!$AH7:$AV7,Calc!$J$19),INDEX('My Order Engine'!$AH7:$AV7,Calc!$K$19)),"") | Q5: =IF(AND($A5<=IF(Calc!$C$36=999,360,Calc!$C$36),Calc!$C$20=1),CHOOSE(Calc!$C$3,INDEX('Snowball Engine'!$AH7:$AV7,Calc!$I$20),INDEX('Avalanche Engine'!$AH7:$AV7,Calc!$J$20),INDEX('My Order Engine'!$AH7:$AV7,Calc!$K$20)),"") | R5: =IF(AND($A5<=IF(Calc!$C$36=999,360,Calc!$C$36),Calc!$C$21=1),CHOOSE(Calc!$C$3,INDEX('Snowball Engine'!$AH7:$AV7,Calc!$I$21),INDEX('Avalanche Engine'!$AH7:$AV7,Calc!$J$21),INDEX('My Order Engine'!$AH7:$AV7,Calc!$K$21)),"") | S5: =IF(AND($A5<=IF(Calc!$C$36=999,360,Calc!$C$36),Calc!$C$22=1),CHOOSE(Calc!$C$3,INDEX('Snowball Engine'!$AH7:$AV7,Calc!$I$22),INDEX('Avalanche Engine'!$AH7:$AV7,Calc!$J$22),INDEX('My Order Engine'!$AH7:$AV7,Calc!$K$22)),"") | T5: =IF(AND($A5<=IF(Calc!$C$36=999,360,Calc!$C$36),Calc!$C$23=1),CHOOSE(Calc!$C$3,INDEX('Snowball Engine'!$AH7:$AV7,Calc!$I$23),INDEX('Avalanche Engine'!$AH7:$AV7,Calc!$J$23),INDEX('My Order Engine'!$AH7:$AV7,Calc!$K$23)),"") | U5: =IF(AND($A5<=IF(Calc!$C$36=999,360,Calc!$C$36),Calc!$C$24=1),CHOOSE(Calc!$C$3,INDEX('Snowball Engine'!$AH7:$AV7,Calc!$I$24),INDEX('Avalanche Engine'!$AH7:$AV7,Calc!$J$24),INDEX('My Order Engine'!$AH7:$AV7,Calc!$K$24)),"")
A6: 2 | B6: =IF($A6<=IF(Calc!$C$36=999,360,Calc!$C$36),EDATE(Calc!$C$5,A6-1),"") -> 46327 | C6: =IF($A6<=IF(Calc!$C$36=999,360,Calc!$C$36),CHOOSE(Calc!$C$3,'Snowball Engine'!AY8,'Avalanche Engine'!AY8,'My Order Engine'!AY8),"") -> 750 | D6: =IF($A6<=IF(Calc!$C$36=999,360,Calc!$C$36),CHOOSE(Calc!$C$3,'Snowball Engine'!AX8,'Avalanche Engine'!AX8,'My Order Engine'!AX8),"") -> 198.53 | E6: =IF($A6<=IF(Calc!$C$36=999,360,Calc!$C$36),C6-D6,"") -> 551.47 | F6: =IF($A6<=IF(Calc!$C$36=999,360,Calc!$C$36),CHOOSE(Calc!$C$3,'Snowball Engine'!AW8,'Avalanche Engine'!AW8,'My Order Engine'!AW8),"") -> 16999.77 | G6: =IF(AND($A6<=IF(Calc!$C$36=999,360,Calc!$C$36),Calc!$C$10=1),CHOOSE(Calc!$C$3,INDEX('Snowball Engine'!$AH8:$AV8,Calc!$I$10),INDEX('Avalanche Engine'!$AH8:$AV8,Calc!$J$10),INDEX('My Order Engine'!$AH8:$AV8,Calc!$K$10)),"") -> 4761.08 | H6: =IF(AND($A6<=IF(Calc!$C$36=999,360,Calc!$C$36),Calc!$C$11=1),CHOOSE(Calc!$C$3,INDEX('Snowball Engine'!$AH8:$AV8,Calc!$I$11),INDEX('Avalanche Engine'!$AH8:$AV8,Calc!$J$11),INDEX('My Order Engine'!$AH8:$AV8,Calc!$K$11)),"") -> 1177.71 | I6: =IF(AND($A6<=IF(Calc!$C$36=999,360,Calc!$C$36),Calc!$C$12=1),CHOOSE(Calc!$C$3,INDEX('Snowball Engine'!$AH8:$AV8,Calc!$I$12),INDEX('Avalanche Engine'!$AH8:$AV8,Calc!$J$12),INDEX('My Order Engine'!$AH8:$AV8,Calc!$K$12)),"") -> 10910.98 | J6: =IF(AND($A6<=IF(Calc!$C$36=999,360,Calc!$C$36),Calc!$C$13=1),CHOOSE(Calc!$C$3,INDEX('Snowball Engine'!$AH8:$AV8,Calc!$I$13),INDEX('Avalanche Engine'!$AH8:$AV8,Calc!$J$13),INDEX('My Order Engine'!$AH8:$AV8,Calc!$K$13)),"") -> 150 | K6: =IF(AND($A6<=IF(Calc!$C$36=999,360,Calc!$C$36),Calc!$C$14=1),CHOOSE(Calc!$C$3,INDEX('Snowball Engine'!$AH8:$AV8,Calc!$I$14),INDEX('Avalanche Engine'!$AH8:$AV8,Calc!$J$14),INDEX('My Order Engine'!$AH8:$AV8,Calc!$K$14)),"") | L6: =IF(AND($A6<=IF(Calc!$C$36=999,360,Calc!$C$36),Calc!$C$15=1),CHOOSE(Calc!$C$3,INDEX('Snowball Engine'!$AH8:$AV8,Calc!$I$15),INDEX('Avalanche Engine'!$AH8:$AV8,Calc!$J$15),INDEX('My Order Engine'!$AH8:$AV8,Calc!$K$15)),"") | M6: =IF(AND($A6<=IF(Calc!$C$36=999,360,Calc!$C$36),Calc!$C$16=1),CHOOSE(Calc!$C$3,INDEX('Snowball Engine'!$AH8:$AV8,Calc!$I$16),INDEX('Avalanche Engine'!$AH8:$AV8,Calc!$J$16),INDEX('My Order Engine'!$AH8:$AV8,Calc!$K$16)),"") | N6: =IF(AND($A6<=IF(Calc!$C$36=999,360,Calc!$C$36),Calc!$C$17=1),CHOOSE(Calc!$C$3,INDEX('Snowball Engine'!$AH8:$AV8,Calc!$I$17),INDEX('Avalanche Engine'!$AH8:$AV8,Calc!$J$17),INDEX('My Order Engine'!$AH8:$AV8,Calc!$K$17)),"") | O6: =IF(AND($A6<=IF(Calc!$C$36=999,360,Calc!$C$36),Calc!$C$18=1),CHOOSE(Calc!$C$3,INDEX('Snowball Engine'!$AH8:$AV8,Calc!$I$18),INDEX('Avalanche Engine'!$AH8:$AV8,Calc!$J$18),INDEX('My Order Engine'!$AH8:$AV8,Calc!$K$18)),"") | P6: =IF(AND($A6<=IF(Calc!$C$36=999,360,Calc!$C$36),Calc!$C$19=1),CHOOSE(Calc!$C$3,INDEX('Snowball Engine'!$AH8:$AV8,Calc!$I$19),INDEX('Avalanche Engine'!$AH8:$AV8,Calc!$J$19),INDEX('My Order Engine'!$AH8:$AV8,Calc!$K$19)),"") | Q6: =IF(AND($A6<=IF(Calc!$C$36=999,360,Calc!$C$36),Calc!$C$20=1),CHOOSE(Calc!$C$3,INDEX('Snowball Engine'!$AH8:$AV8,Calc!$I$20),INDEX('Avalanche Engine'!$AH8:$AV8,Calc!$J$20),INDEX('My Order Engine'!$AH8:$AV8,Calc!$K$20)),"") | R6: =IF(AND($A6<=IF(Calc!$C$36=999,360,Calc!$C$36),Calc!$C$21=1),CHOOSE(Calc!$C$3,INDEX('Snowball Engine'!$AH8:$AV8,Calc!$I$21),INDEX('Avalanche Engine'!$AH8:$AV8,Calc!$J$21),INDEX('My Order Engine'!$AH8:$AV8,Calc!$K$21)),"") | S6: =IF(AND($A6<=IF(Calc!$C$36=999,360,Calc!$C$36),Calc!$C$22=1),CHOOSE(Calc!$C$3,INDEX('Snowball Engine'!$AH8:$AV8,Calc!$I$22),INDEX('Avalanche Engine'!$AH8:$AV8,Calc!$J$22),INDEX('My Order Engine'!$AH8:$AV8,Calc!$K$22)),"") | T6: =IF(AND($A6<=IF(Calc!$C$36=999,360,Calc!$C$36),Calc!$C$23=1),CHOOSE(Calc!$C$3,INDEX('Snowball Engine'!$AH8:$AV8,Calc!$I$23),INDEX('Avalanche Engine'!$AH8:$AV8,Calc!$J$23),INDEX('My Order Engine'!$AH8:$AV8,Calc!$K$23)),"") | U6: =IF(AND($A6<=IF(Calc!$C$36=999,360,Calc!$C$36),Calc!$C$24=1),CHOOSE(Calc!$C$3,INDEX('Snowball Engine'!$AH8:$AV8,Calc!$I$24),INDEX('Avalanche Engine'!$AH8:$AV8,Calc!$J$24),INDEX('My Order Engine'!$AH8:$AV8,Calc!$K$24)),"")
A7: 3 | B7: =IF($A7<=IF(Calc!$C$36=999,360,Calc!$C$36),EDATE(Calc!$C$5,A7-1),"") -> 46357 | C7: =IF($A7<=IF(Calc!$C$36=999,360,Calc!$C$36),CHOOSE(Calc!$C$3,'Snowball Engine'!AY9,'Avalanche Engine'!AY9,'My Order Engine'!AY9),"") -> 750 | D7: =IF($A7<=IF(Calc!$C$36=999,360,Calc!$C$36),CHOOSE(Calc!$C$3,'Snowball Engine'!AX9,'Avalanche Engine'!AX9,'My Order Engine'!AX9),"") -> 195.79 | E7: =IF($A7<=IF(Calc!$C$36=999,360,Calc!$C$36),C7-D7,"") -> 554.21 | F7: =IF($A7<=IF(Calc!$C$36=999,360,Calc!$C$36),CHOOSE(Calc!$C$3,'Snowball Engine'!AW9,'Avalanche Engine'!AW9,'My Order Engine'!AW9),"") -> 16445.56 | G7: =IF(AND($A7<=IF(Calc!$C$36=999,360,Calc!$C$36),Calc!$C$10=1),CHOOSE(Calc!$C$3,INDEX('Snowball Engine'!$AH9:$AV9,Calc!$I$10),INDEX('Avalanche Engine'!$AH9:$AV9,Calc!$J$10),INDEX('My Order Engine'!$AH9:$AV9,Calc!$K$10)),"") -> 4715.23 | H7: =IF(AND($A7<=IF(Calc!$C$36=999,360,Calc!$C$36),Calc!$C$11=1),CHOOSE(Calc!$C$3,INDEX('Snowball Engine'!$AH9:$AV9,Calc!$I$11),INDEX('Avalanche Engine'!$AH9:$AV9,Calc!$J$11),INDEX('My Order Engine'!$AH9:$AV9,Calc!$K$11)),"") -> 1066.16 | I7: =IF(AND($A7<=IF(Calc!$C$36=999,360,Calc!$C$36),Calc!$C$12=1),CHOOSE(Calc!$C$3,INDEX('Snowball Engine'!$AH9:$AV9,Calc!$I$12),INDEX('Avalanche Engine'!$AH9:$AV9,Calc!$J$12),INDEX('My Order Engine'!$AH9:$AV9,Calc!$K$12)),"") -> 10664.17 | J7: =IF(AND($A7<=IF(Calc!$C$36=999,360,Calc!$C$36),Calc!$C$13=1),CHOOSE(Calc!$C$3,INDEX('Snowball Engine'!$AH9:$AV9,Calc!$I$13),INDEX('Avalanche Engine'!$AH9:$AV9,Calc!$J$13),INDEX('My Order Engine'!$AH9:$AV9,Calc!$K$13)),"") -> 0 | K7: =IF(AND($A7<=IF(Calc!$C$36=999,360,Calc!$C$36),Calc!$C$14=1),CHOOSE(Calc!$C$3,INDEX('Snowball Engine'!$AH9:$AV9,Calc!$I$14),INDEX('Avalanche Engine'!$AH9:$AV9,Calc!$J$14),INDEX('My Order Engine'!$AH9:$AV9,Calc!$K$14)),"") | L7: =IF(AND($A7<=IF(Calc!$C$36=999,360,Calc!$C$36),Calc!$C$15=1),CHOOSE(Calc!$C$3,INDEX('Snowball Engine'!$AH9:$AV9,Calc!$I$15),INDEX('Avalanche Engine'!$AH9:$AV9,Calc!$J$15),INDEX('My Order Engine'!$AH9:$AV9,Calc!$K$15)),"") | M7: =IF(AND($A7<=IF(Calc!$C$36=999,360,Calc!$C$36),Calc!$C$16=1),CHOOSE(Calc!$C$3,INDEX('Snowball Engine'!$AH9:$AV9,Calc!$I$16),INDEX('Avalanche Engine'!$AH9:$AV9,Calc!$J$16),INDEX('My Order Engine'!$AH9:$AV9,Calc!$K$16)),"") | N7: =IF(AND($A7<=IF(Calc!$C$36=999,360,Calc!$C$36),Calc!$C$17=1),CHOOSE(Calc!$C$3,INDEX('Snowball Engine'!$AH9:$AV9,Calc!$I$17),INDEX('Avalanche Engine'!$AH9:$AV9,Calc!$J$17),INDEX('My Order Engine'!$AH9:$AV9,Calc!$K$17)),"") | O7: =IF(AND($A7<=IF(Calc!$C$36=999,360,Calc!$C$36),Calc!$C$18=1),CHOOSE(Calc!$C$3,INDEX('Snowball Engine'!$AH9:$AV9,Calc!$I$18),INDEX('Avalanche Engine'!$AH9:$AV9,Calc!$J$18),INDEX('My Order Engine'!$AH9:$AV9,Calc!$K$18)),"") | P7: =IF(AND($A7<=IF(Calc!$C$36=999,360,Calc!$C$36),Calc!$C$19=1),CHOOSE(Calc!$C$3,INDEX('Snowball Engine'!$AH9:$AV9,Calc!$I$19),INDEX('Avalanche Engine'!$AH9:$AV9,Calc!$J$19),INDEX('My Order Engine'!$AH9:$AV9,Calc!$K$19)),"") | Q7: =IF(AND($A7<=IF(Calc!$C$36=999,360,Calc!$C$36),Calc!$C$20=1),CHOOSE(Calc!$C$3,INDEX('Snowball Engine'!$AH9:$AV9,Calc!$I$20),INDEX('Avalanche Engine'!$AH9:$AV9,Calc!$J$20),INDEX('My Order Engine'!$AH9:$AV9,Calc!$K$20)),"") | R7: =IF(AND($A7<=IF(Calc!$C$36=999,360,Calc!$C$36),Calc!$C$21=1),CHOOSE(Calc!$C$3,INDEX('Snowball Engine'!$AH9:$AV9,Calc!$I$21),INDEX('Avalanche Engine'!$AH9:$AV9,Calc!$J$21),INDEX('My Order Engine'!$AH9:$AV9,Calc!$K$21)),"") | S7: =IF(AND($A7<=IF(Calc!$C$36=999,360,Calc!$C$36),Calc!$C$22=1),CHOOSE(Calc!$C$3,INDEX('Snowball Engine'!$AH9:$AV9,Calc!$I$22),INDEX('Avalanche Engine'!$AH9:$AV9,Calc!$J$22),INDEX('My Order Engine'!$AH9:$AV9,Calc!$K$22)),"") | T7: =IF(AND($A7<=IF(Calc!$C$36=999,360,Calc!$C$36),Calc!$C$23=1),CHOOSE(Calc!$C$3,INDEX('Snowball Engine'!$AH9:$AV9,Calc!$I$23),INDEX('Avalanche Engine'!$AH9:$AV9,Calc!$J$23),INDEX('My Order Engine'!$AH9:$AV9,Calc!$K$23)),"") | U7: =IF(AND($A7<=IF(Calc!$C$36=999,360,Calc!$C$36),Calc!$C$24=1),CHOOSE(Calc!$C$3,INDEX('Snowball Engine'!$AH9:$AV9,Calc!$I$24),INDEX('Avalanche Engine'!$AH9:$AV9,Calc!$J$24),INDEX('My Order Engine'!$AH9:$AV9,Calc!$K$24)),"")
A8: 4 | B8: =IF($A8<=IF(Calc!$C$36=999,360,Calc!$C$36),EDATE(Calc!$C$5,A8-1),"") -> 46388 | C8: =IF($A8<=IF(Calc!$C$36=999,360,Calc!$C$36),CHOOSE(Calc!$C$3,'Snowball Engine'!AY10,'Avalanche Engine'!AY10,'My Order Engine'!AY10),"") -> 750 | D8: =IF($A8<=IF(Calc!$C$36=999,360,Calc!$C$36),CHOOSE(Calc!$C$3,'Snowball Engine'!AX10,'Avalanche Engine'!AX10,'My Order Engine'!AX10),"") -> 190.6 | E8: =IF($A8<=IF(Calc!$C$36=999,360,Calc!$C$36),C8-D8,"") -> 559.4 | F8: =IF($A8<=IF(Calc!$C$36=999,360,Calc!$C$36),CHOOSE(Calc!$C$3,'Snowball Engine'!AW10,'Avalanche Engine'!AW10,'My Order Engine'!AW10),"") -> 15886.16 | G8: =IF(AND($A8<=IF(Calc!$C$36=999,360,Calc!$C$36),Calc!$C$10=1),CHOOSE(Calc!$C$3,INDEX('Snowball Engine'!$AH10:$AV10,Calc!$I$10),INDEX('Avalanche Engine'!$AH10:$AV10,Calc!$J$10),INDEX('My Order Engine'!$AH10:$AV10,Calc!$K$10)),"") -> 4668.42 | H8: =IF(AND($A8<=IF(Calc!$C$36=999,360,Calc!$C$36),Calc!$C$11=1),CHOOSE(Calc!$C$3,INDEX('Snowball Engine'!$AH10:$AV10,Calc!$I$11),INDEX('Avalanche Engine'!$AH10:$AV10,Calc!$J$11),INDEX('My Order Engine'!$AH10:$AV10,Calc!$K$11)),"") -> 801.92 | I8: =IF(AND($A8<=IF(Calc!$C$36=999,360,Calc!$C$36),Calc!$C$12=1),CHOOSE(Calc!$C$3,INDEX('Snowball Engine'!$AH10:$AV10,Calc!$I$12),INDEX('Avalanche Engine'!$AH10:$AV10,Calc!$J$12),INDEX('My Order Engine'!$AH10:$AV10,Calc!$K$12)),"") -> 10415.82 | J8: =IF(AND($A8<=IF(Calc!$C$36=999,360,Calc!$C$36),Calc!$C$13=1),CHOOSE(Calc!$C$3,INDEX('Snowball Engine'!$AH10:$AV10,Calc!$I$13),INDEX('Avalanche Engine'!$AH10:$AV10,Calc!$J$13),INDEX('My Order Engine'!$AH10:$AV10,Calc!$K$13)),"") -> 0 | K8: =IF(AND($A8<=IF(Calc!$C$36=999,360,Calc!$C$36),Calc!$C$14=1),CHOOSE(Calc!$C$3,INDEX('Snowball Engine'!$AH10:$AV10,Calc!$I$14),INDEX('Avalanche Engine'!$AH10:$AV10,Calc!$J$14),INDEX('My Order Engine'!$AH10:$AV10,Calc!$K$14)),"") | L8: =IF(AND($A8<=IF(Calc!$C$36=999,360,Calc!$C$36),Calc!$C$15=1),CHOOSE(Calc!$C$3,INDEX('Snowball Engine'!$AH10:$AV10,Calc!$I$15),INDEX('Avalanche Engine'!$AH10:$AV10,Calc!$J$15),INDEX('My Order Engine'!$AH10:$AV10,Calc!$K$15)),"") | M8: =IF(AND($A8<=IF(Calc!$C$36=999,360,Calc!$C$36),Calc!$C$16=1),CHOOSE(Calc!$C$3,INDEX('Snowball Engine'!$AH10:$AV10,Calc!$I$16),INDEX('Avalanche Engine'!$AH10:$AV10,Calc!$J$16),INDEX('My Order Engine'!$AH10:$AV10,Calc!$K$16)),"") | N8: =IF(AND($A8<=IF(Calc!$C$36=999,360,Calc!$C$36),Calc!$C$17=1),CHOOSE(Calc!$C$3,INDEX('Snowball Engine'!$AH10:$AV10,Calc!$I$17),INDEX('Avalanche Engine'!$AH10:$AV10,Calc!$J$17),INDEX('My Order Engine'!$AH10:$AV10,Calc!$K$17)),"") | O8: =IF(AND($A8<=IF(Calc!$C$36=999,360,Calc!$C$36),Calc!$C$18=1),CHOOSE(Calc!$C$3,INDEX('Snowball Engine'!$AH10:$AV10,Calc!$I$18),INDEX('Avalanche Engine'!$AH10:$AV10,Calc!$J$18),INDEX('My Order Engine'!$AH10:$AV10,Calc!$K$18)),"") | P8: =IF(AND($A8<=IF(Calc!$C$36=999,360,Calc!$C$36),Calc!$C$19=1),CHOOSE(Calc!$C$3,INDEX('Snowball Engine'!$AH10:$AV10,Calc!$I$19),INDEX('Avalanche Engine'!$AH10:$AV10,Calc!$J$19),INDEX('My Order Engine'!$AH10:$AV10,Calc!$K$19)),"") | Q8: =IF(AND($A8<=IF(Calc!$C$36=999,360,Calc!$C$36),Calc!$C$20=1),CHOOSE(Calc!$C$3,INDEX('Snowball Engine'!$AH10:$AV10,Calc!$I$20),INDEX('Avalanche Engine'!$AH10:$AV10,Calc!$J$20),INDEX('My Order Engine'!$AH10:$AV10,Calc!$K$20)),"") | R8: =IF(AND($A8<=IF(Calc!$C$36=999,360,Calc!$C$36),Calc!$C$21=1),CHOOSE(Calc!$C$3,INDEX('Snowball Engine'!$AH10:$AV10,Calc!$I$21),INDEX('Avalanche Engine'!$AH10:$AV10,Calc!$J$21),INDEX('My Order Engine'!$AH10:$AV10,Calc!$K$21)),"") | S8: =IF(AND($A8<=IF(Calc!$C$36=999,360,Calc!$C$36),Calc!$C$22=1),CHOOSE(Calc!$C$3,INDEX('Snowball Engine'!$AH10:$AV10,Calc!$I$22),INDEX('Avalanche Engine'!$AH10:$AV10,Calc!$J$22),INDEX('My Order Engine'!$AH10:$AV10,Calc!$K$22)),"") | T8: =IF(AND($A8<=IF(Calc!$C$36=999,360,Calc!$C$36),Calc!$C$23=1),CHOOSE(Calc!$C$3,INDEX('Snowball Engine'!$AH10:$AV10,Calc!$I$23),INDEX('Avalanche Engine'!$AH10:$AV10,Calc!$J$23),INDEX('My Order Engine'!$AH10:$AV10,Calc!$K$23)),"") | U8: =IF(AND($A8<=IF(Calc!$C$36=999,360,Calc!$C$36),Calc!$C$24=1),CHOOSE(Calc!$C$3,INDEX('Snowball Engine'!$AH10:$AV10,Calc!$I$24),INDEX('Avalanche Engine'!$AH10:$AV10,Calc!$J$24),INDEX('My Order Engine'!$AH10:$AV10,Calc!$K$24)),"")
A9: 5 | B9: =IF($A9<=IF(Calc!$C$36=999,360,Calc!$C$36),EDATE(Calc!$C$5,A9-1),"") -> 46419 | C9: =IF($A9<=IF(Calc!$C$36=999,360,Calc!$C$36),CHOOSE(Calc!$C$3,'Snowball Engine'!AY11,'Avalanche Engine'!AY11,'My Order Engine'!AY11),"") -> 750 | D9: =IF($A9<=IF(Calc!$C$36=999,360,Calc!$C$36),CHOOSE(Calc!$C$3,'Snowball Engine'!AX11,'Avalanche Engine'!AX11,'My Order Engine'!AX11),"") -> 181.69 | E9: =IF($A9<=IF(Calc!$C$36=999,360,Calc!$C$36),C9-D9,"") -> 568.31 | F9: =IF($A9<=IF(Calc!$C$36=999,360,Calc!$C$36),CHOOSE(Calc!$C$3,'Snowball Engine'!AW11,'Avalanche Engine'!AW11,'My Order Engine'!AW11),"") -> 15317.85 | G9: =IF(AND($A9<=IF(Calc!$C$36=999,360,Calc!$C$36),Calc!$C$10=1),CHOOSE(Calc!$C$3,INDEX('Snowball Engine'!$AH11:$AV11,Calc!$I$10),INDEX('Avalanche Engine'!$AH11:$AV11,Calc!$J$10),INDEX('My Order Engine'!$AH11:$AV11,Calc!$K$10)),"") -> 4620.64 | H9: =IF(AND($A9<=IF(Calc!$C$36=999,360,Calc!$C$36),Calc!$C$11=1),CHOOSE(Calc!$C$3,INDEX('Snowball Engine'!$AH11:$AV11,Calc!$I$11),INDEX('Avalanche Engine'!$AH11:$AV11,Calc!$J$11),INDEX('My Order Engine'!$AH11:$AV11,Calc!$K$11)),"") -> 531.29 | I9: =IF(AND($A9<=IF(Calc!$C$36=999,360,Calc!$C$36),Calc!$C$12=1),CHOOSE(Calc!$C$3,INDEX('Snowball Engine'!$AH11:$AV11,Calc!$I$12),INDEX('Avalanche Engine'!$AH11:$AV11,Calc!$J$12),INDEX('My Order Engine'!$AH11:$AV11,Calc!$K$12)),"") -> 10165.92 | J9: =IF(AND($A9<=IF(Calc!$C$36=999,360,Calc!$C$36),Calc!$C$13=1),CHOOSE(Calc!$C$3,INDEX('Snowball Engine'!$AH11:$AV11,Calc!$I$13),INDEX('Avalanche Engine'!$AH11:$AV11,Calc!$J$13),INDEX('My Order Engine'!$AH11:$AV11,Calc!$K$13)),"") -> 0 | K9: =IF(AND($A9<=IF(Calc!$C$36=999,360,Calc!$C$36),Calc!$C$14=1),CHOOSE(Calc!$C$3,INDEX('Snowball Engine'!$AH11:$AV11,Calc!$I$14),INDEX('Avalanche Engine'!$AH11:$AV11,Calc!$J$14),INDEX('My Order Engine'!$AH11:$AV11,Calc!$K$14)),"") | L9: =IF(AND($A9<=IF(Calc!$C$36=999,360,Calc!$C$36),Calc!$C$15=1),CHOOSE(Calc!$C$3,INDEX('Snowball Engine'!$AH11:$AV11,Calc!$I$15),INDEX('Avalanche Engine'!$AH11:$AV11,Calc!$J$15),INDEX('My Order Engine'!$AH11:$AV11,Calc!$K$15)),"") | M9: =IF(AND($A9<=IF(Calc!$C$36=999,360,Calc!$C$36),Calc!$C$16=1),CHOOSE(Calc!$C$3,INDEX('Snowball Engine'!$AH11:$AV11,Calc!$I$16),INDEX('Avalanche Engine'!$AH11:$AV11,Calc!$J$16),INDEX('My Order Engine'!$AH11:$AV11,Calc!$K$16)),"") | N9: =IF(AND($A9<=IF(Calc!$C$36=999,360,Calc!$C$36),Calc!$C$17=1),CHOOSE(Calc!$C$3,INDEX('Snowball Engine'!$AH11:$AV11,Calc!$I$17),INDEX('Avalanche Engine'!$AH11:$AV11,Calc!$J$17),INDEX('My Order Engine'!$AH11:$AV11,Calc!$K$17)),"") | O9: =IF(AND($A9<=IF(Calc!$C$36=999,360,Calc!$C$36),Calc!$C$18=1),CHOOSE(Calc!$C$3,INDEX('Snowball Engine'!$AH11:$AV11,Calc!$I$18),INDEX('Avalanche Engine'!$AH11:$AV11,Calc!$J$18),INDEX('My Order Engine'!$AH11:$AV11,Calc!$K$18)),"") | P9: =IF(AND($A9<=IF(Calc!$C$36=999,360,Calc!$C$36),Calc!$C$19=1),CHOOSE(Calc!$C$3,INDEX('Snowball Engine'!$AH11:$AV11,Calc!$I$19),INDEX('Avalanche Engine'!$AH11:$AV11,Calc!$J$19),INDEX('My Order Engine'!$AH11:$AV11,Calc!$K$19)),"") | Q9: =IF(AND($A9<=IF(Calc!$C$36=999,360,Calc!$C$36),Calc!$C$20=1),CHOOSE(Calc!$C$3,INDEX('Snowball Engine'!$AH11:$AV11,Calc!$I$20),INDEX('Avalanche Engine'!$AH11:$AV11,Calc!$J$20),INDEX('My Order Engine'!$AH11:$AV11,Calc!$K$20)),"") | R9: =IF(AND($A9<=IF(Calc!$C$36=999,360,Calc!$C$36),Calc!$C$21=1),CHOOSE(Calc!$C$3,INDEX('Snowball Engine'!$AH11:$AV11,Calc!$I$21),INDEX('Avalanche Engine'!$AH11:$AV11,Calc!$J$21),INDEX('My Order Engine'!$AH11:$AV11,Calc!$K$21)),"") | S9: =IF(AND($A9<=IF(Calc!$C$36=999,360,Calc!$C$36),Calc!$C$22=1),CHOOSE(Calc!$C$3,INDEX('Snowball Engine'!$AH11:$AV11,Calc!$I$22),INDEX('Avalanche Engine'!$AH11:$AV11,Calc!$J$22),INDEX('My Order Engine'!$AH11:$AV11,Calc!$K$22)),"") | T9: =IF(AND($A9<=IF(Calc!$C$36=999,360,Calc!$C$36),Calc!$C$23=1),CHOOSE(Calc!$C$3,INDEX('Snowball Engine'!$AH11:$AV11,Calc!$I$23),INDEX('Avalanche Engine'!$AH11:$AV11,Calc!$J$23),INDEX('My Order Engine'!$AH11:$AV11,Calc!$K$23)),"") | U9: =IF(AND($A9<=IF(Calc!$C$36=999,360,Calc!$C$36),Calc!$C$24=1),CHOOSE(Calc!$C$3,INDEX('Snowball Engine'!$AH11:$AV11,Calc!$I$24),INDEX('Avalanche Engine'!$AH11:$AV11,Calc!$J$24),INDEX('My Order Engine'!$AH11:$AV11,Calc!$K$24)),"")
A10: 6 | B10: =IF($A10<=IF(Calc!$C$36=999,360,Calc!$C$36),EDATE(Calc!$C$5,A10-1),"") -> 46447 | C10: =IF($A10<=IF(Calc!$C$36=999,360,Calc!$C$36),CHOOSE(Calc!$C$3,'Snowball Engine'!AY12,'Avalanche Engine'!AY12,'My Order Engine'!AY12),"") -> 750 | D10: =IF($A10<=IF(Calc!$C$36=999,360,Calc!$C$36),CHOOSE(Calc!$C$3,'Snowball Engine'!AX12,'Avalanche Engine'!AX12,'My Order Engine'!AX12),"") -> 172.6 | E10: =IF($A10<=IF(Calc!$C$36=999,360,Calc!$C$36),C10-D10,"") -> 577.4 | F10: =IF($A10<=IF(Calc!$C$36=999,360,Calc!$C$36),CHOOSE(Calc!$C$3,'Snowball Engine'!AW12,'Avalanche Engine'!AW12,'My Order Engine'!AW12),"") -> 14740.45 | G10: =IF(AND($A10<=IF(Calc!$C$36=999,360,Calc!$C$36),Calc!$C$10=1),CHOOSE(Calc!$C$3,INDEX('Snowball Engine'!$AH12:$AV12,Calc!$I$10),INDEX('Avalanche Engine'!$AH12:$AV12,Calc!$J$10),INDEX('My Order Engine'!$AH12:$AV12,Calc!$K$10)),"") -> 4571.86 | H10: =IF(AND($A10<=IF(Calc!$C$36=999,360,Calc!$C$36),Calc!$C$11=1),CHOOSE(Calc!$C$3,INDEX('Snowball Engine'!$AH12:$AV12,Calc!$I$11),INDEX('Avalanche Engine'!$AH12:$AV12,Calc!$J$11),INDEX('My Order Engine'!$AH12:$AV12,Calc!$K$11)),"") -> 254.13 | I10: =IF(AND($A10<=IF(Calc!$C$36=999,360,Calc!$C$36),Calc!$C$12=1),CHOOSE(Calc!$C$3,INDEX('Snowball Engine'!$AH12:$AV12,Calc!$I$12),INDEX('Avalanche Engine'!$AH12:$AV12,Calc!$J$12),INDEX('My Order Engine'!$AH12:$AV12,Calc!$K$12)),"") -> 9914.46 | J10: =IF(AND($A10<=IF(Calc!$C$36=999,360,Calc!$C$36),Calc!$C$13=1),CHOOSE(Calc!$C$3,INDEX('Snowball Engine'!$AH12:$AV12,Calc!$I$13),INDEX('Avalanche Engine'!$AH12:$AV12,Calc!$J$13),INDEX('My Order Engine'!$AH12:$AV12,Calc!$K$13)),"") -> 0 | K10: =IF(AND($A10<=IF(Calc!$C$36=999,360,Calc!$C$36),Calc!$C$14=1),CHOOSE(Calc!$C$3,INDEX('Snowball Engine'!$AH12:$AV12,Calc!$I$14),INDEX('Avalanche Engine'!$AH12:$AV12,Calc!$J$14),INDEX('My Order Engine'!$AH12:$AV12,Calc!$K$14)),"") | L10: =IF(AND($A10<=IF(Calc!$C$36=999,360,Calc!$C$36),Calc!$C$15=1),CHOOSE(Calc!$C$3,INDEX('Snowball Engine'!$AH12:$AV12,Calc!$I$15),INDEX('Avalanche Engine'!$AH12:$AV12,Calc!$J$15),INDEX('My Order Engine'!$AH12:$AV12,Calc!$K$15)),"") | M10: =IF(AND($A10<=IF(Calc!$C$36=999,360,Calc!$C$36),Calc!$C$16=1),CHOOSE(Calc!$C$3,INDEX('Snowball Engine'!$AH12:$AV12,Calc!$I$16),INDEX('Avalanche Engine'!$AH12:$AV12,Calc!$J$16),INDEX('My Order Engine'!$AH12:$AV12,Calc!$K$16)),"") | N10: =IF(AND($A10<=IF(Calc!$C$36=999,360,Calc!$C$36),Calc!$C$17=1),CHOOSE(Calc!$C$3,INDEX('Snowball Engine'!$AH12:$AV12,Calc!$I$17),INDEX('Avalanche Engine'!$AH12:$AV12,Calc!$J$17),INDEX('My Order Engine'!$AH12:$AV12,Calc!$K$17)),"") | O10: =IF(AND($A10<=IF(Calc!$C$36=999,360,Calc!$C$36),Calc!$C$18=1),CHOOSE(Calc!$C$3,INDEX('Snowball Engine'!$AH12:$AV12,Calc!$I$18),INDEX('Avalanche Engine'!$AH12:$AV12,Calc!$J$18),INDEX('My Order Engine'!$AH12:$AV12,Calc!$K$18)),"") | P10: =IF(AND($A10<=IF(Calc!$C$36=999,360,Calc!$C$36),Calc!$C$19=1),CHOOSE(Calc!$C$3,INDEX('Snowball Engine'!$AH12:$AV12,Calc!$I$19),INDEX('Avalanche Engine'!$AH12:$AV12,Calc!$J$19),INDEX('My Order Engine'!$AH12:$AV12,Calc!$K$19)),"") | Q10: =IF(AND($A10<=IF(Calc!$C$36=999,360,Calc!$C$36),Calc!$C$20=1),CHOOSE(Calc!$C$3,INDEX('Snowball Engine'!$AH12:$AV12,Calc!$I$20),INDEX('Avalanche Engine'!$AH12:$AV12,Calc!$J$20),INDEX('My Order Engine'!$AH12:$AV12,Calc!$K$20)),"") | R10: =IF(AND($A10<=IF(Calc!$C$36=999,360,Calc!$C$36),Calc!$C$21=1),CHOOSE(Calc!$C$3,INDEX('Snowball Engine'!$AH12:$AV12,Calc!$I$21),INDEX('Avalanche Engine'!$AH12:$AV12,Calc!$J$21),INDEX('My Order Engine'!$AH12:$AV12,Calc!$K$21)),"") | S10: =IF(AND($A10<=IF(Calc!$C$36=999,360,Calc!$C$36),Calc!$C$22=1),CHOOSE(Calc!$C$3,INDEX('Snowball Engine'!$AH12:$AV12,Calc!$I$22),INDEX('Avalanche Engine'!$AH12:$AV12,Calc!$J$22),INDEX('My Order Engine'!$AH12:$AV12,Calc!$K$22)),"") | T10: =IF(AND($A10<=IF(Calc!$C$36=999,360,Calc!$C$36),Calc!$C$23=1),CHOOSE(Calc!$C$3,INDEX('Snowball Engine'!$AH12:$AV12,Calc!$I$23),INDEX('Avalanche Engine'!$AH12:$AV12,Calc!$J$23),INDEX('My Order Engine'!$AH12:$AV12,Calc!$K$23)),"") | U10: =IF(AND($A10<=IF(Calc!$C$36=999,360,Calc!$C$36),Calc!$C$24=1),CHOOSE(Calc!$C$3,INDEX('Snowball Engine'!$AH12:$AV12,Calc!$I$24),INDEX('Avalanche Engine'!$AH12:$AV12,Calc!$J$24),INDEX('My Order Engine'!$AH12:$AV12,Calc!$K$24)),"")
A11: 7 | B11: =IF($A11<=IF(Calc!$C$36=999,360,Calc!$C$36),EDATE(Calc!$C$5,A11-1),"") -> 46478 | C11: =IF($A11<=IF(Calc!$C$36=999,360,Calc!$C$36),CHOOSE(Calc!$C$3,'Snowball Engine'!AY13,'Avalanche Engine'!AY13,'My Order Engine'!AY13),"") -> 750 | D11: =IF($A11<=IF(Calc!$C$36=999,360,Calc!$C$36),CHOOSE(Calc!$C$3,'Snowball Engine'!AX13,'Avalanche Engine'!AX13,'My Order Engine'!AX13),"") -> 163.32 | E11: =IF($A11<=IF(Calc!$C$36=999,360,Calc!$C$36),C11-D11,"") -> 586.68 | F11: =IF($A11<=IF(Calc!$C$36=999,360,Calc!$C$36),CHOOSE(Calc!$C$3,'Snowball Engine'!AW13,'Avalanche Engine'!AW13,'My Order Engine'!AW13),"") -> 14153.77 | G11: =IF(AND($A11<=IF(Calc!$C$36=999,360,Calc!$C$36),Calc!$C$10=1),CHOOSE(Calc!$C$3,INDEX('Snowball Engine'!$AH13:$AV13,Calc!$I$10),INDEX('Avalanche Engine'!$AH13:$AV13,Calc!$J$10),INDEX('My Order Engine'!$AH13:$AV13,Calc!$K$10)),"") -> 4492.34 | H11: =IF(AND($A11<=IF(Calc!$C$36=999,360,Calc!$C$36),Calc!$C$11=1),CHOOSE(Calc!$C$3,INDEX('Snowball Engine'!$AH13:$AV13,Calc!$I$11),INDEX('Avalanche Engine'!$AH13:$AV13,Calc!$J$11),INDEX('My Order Engine'!$AH13:$AV13,Calc!$K$11)),"") -> 0 | I11: =IF(AND($A11<=IF(Calc!$C$36=999,360,Calc!$C$36),Calc!$C$12=1),CHOOSE(Calc!$C$3,INDEX('Snowball Engine'!$AH13:$AV13,Calc!$I$12),INDEX('Avalanche Engine'!$AH13:$AV13,Calc!$J$12),INDEX('My Order Engine'!$AH13:$AV13,Calc!$K$12)),"") -> 9661.43 | J11: =IF(AND($A11<=IF(Calc!$C$36=999,360,Calc!$C$36),Calc!$C$13=1),CHOOSE(Calc!$C$3,INDEX('Snowball Engine'!$AH13:$AV13,Calc!$I$13),INDEX('Avalanche Engine'!$AH13:$AV13,Calc!$J$13),INDEX('My Order Engine'!$AH13:$AV13,Calc!$K$13)),"") -> 0 | K11: =IF(AND($A11<=IF(Calc!$C$36=999,360,Calc!$C$36),Calc!$C$14=1),CHOOSE(Calc!$C$3,INDEX('Snowball Engine'!$AH13:$AV13,Calc!$I$14),INDEX('Avalanche Engine'!$AH13:$AV13,Calc!$J$14),INDEX('My Order Engine'!$AH13:$AV13,Calc!$K$14)),"") | L11: =IF(AND($A11<=IF(Calc!$C$36=999,360,Calc!$C$36),Calc!$C$15=1),CHOOSE(Calc!$C$3,INDEX('Snowball Engine'!$AH13:$AV13,Calc!$I$15),INDEX('Avalanche Engine'!$AH13:$AV13,Calc!$J$15),INDEX('My Order Engine'!$AH13:$AV13,Calc!$K$15)),"") | M11: =IF(AND($A11<=IF(Calc!$C$36=999,360,Calc!$C$36),Calc!$C$16=1),CHOOSE(Calc!$C$3,INDEX('Snowball Engine'!$AH13:$AV13,Calc!$I$16),INDEX('Avalanche Engine'!$AH13:$AV13,Calc!$J$16),INDEX('My Order Engine'!$AH13:$AV13,Calc!$K$16)),"") | N11: =IF(AND($A11<=IF(Calc!$C$36=999,360,Calc!$C$36),Calc!$C$17=1),CHOOSE(Calc!$C$3,INDEX('Snowball Engine'!$AH13:$AV13,Calc!$I$17),INDEX('Avalanche Engine'!$AH13:$AV13,Calc!$J$17),INDEX('My Order Engine'!$AH13:$AV13,Calc!$K$17)),"") | O11: =IF(AND($A11<=IF(Calc!$C$36=999,360,Calc!$C$36),Calc!$C$18=1),CHOOSE(Calc!$C$3,INDEX('Snowball Engine'!$AH13:$AV13,Calc!$I$18),INDEX('Avalanche Engine'!$AH13:$AV13,Calc!$J$18),INDEX('My Order Engine'!$AH13:$AV13,Calc!$K$18)),"") | P11: =IF(AND($A11<=IF(Calc!$C$36=999,360,Calc!$C$36),Calc!$C$19=1),CHOOSE(Calc!$C$3,INDEX('Snowball Engine'!$AH13:$AV13,Calc!$I$19),INDEX('Avalanche Engine'!$AH13:$AV13,Calc!$J$19),INDEX('My Order Engine'!$AH13:$AV13,Calc!$K$19)),"") | Q11: =IF(AND($A11<=IF(Calc!$C$36=999,360,Calc!$C$36),Calc!$C$20=1),CHOOSE(Calc!$C$3,INDEX('Snowball Engine'!$AH13:$AV13,Calc!$I$20),INDEX('Avalanche Engine'!$AH13:$AV13,Calc!$J$20),INDEX('My Order Engine'!$AH13:$AV13,Calc!$K$20)),"") | R11: =IF(AND($A11<=IF(Calc!$C$36=999,360,Calc!$C$36),Calc!$C$21=1),CHOOSE(Calc!$C$3,INDEX('Snowball Engine'!$AH13:$AV13,Calc!$I$21),INDEX('Avalanche Engine'!$AH13:$AV13,Calc!$J$21),INDEX('My Order Engine'!$AH13:$AV13,Calc!$K$21)),"") | S11: =IF(AND($A11<=IF(Calc!$C$36=999,360,Calc!$C$36),Calc!$C$22=1),CHOOSE(Calc!$C$3,INDEX('Snowball Engine'!$AH13:$AV13,Calc!$I$22),INDEX('Avalanche Engine'!$AH13:$AV13,Calc!$J$22),INDEX('My Order Engine'!$AH13:$AV13,Calc!$K$22)),"") | T11: =IF(AND($A11<=IF(Calc!$C$36=999,360,Calc!$C$36),Calc!$C$23=1),CHOOSE(Calc!$C$3,INDEX('Snowball Engine'!$AH13:$AV13,Calc!$I$23),INDEX('Avalanche Engine'!$AH13:$AV13,Calc!$J$23),INDEX('My Order Engine'!$AH13:$AV13,Calc!$K$23)),"") | U11: =IF(AND($A11<=IF(Calc!$C$36=999,360,Calc!$C$36),Calc!$C$24=1),CHOOSE(Calc!$C$3,INDEX('Snowball Engine'!$AH13:$AV13,Calc!$I$24),INDEX('Avalanche Engine'!$AH13:$AV13,Calc!$J$24),INDEX('My Order Engine'!$AH13:$AV13,Calc!$K$24)),"")
