Workbook

Sheet Start Here
B2: Wedding Budget Planner & Tracker
B3: Budget, payments, vendors, guest list and a 12-month checklist in one workbook. Works in Excel and Google Sheets.
B5: QUICK START (10 minutes)
B6: 1. 'Dashboard': type your wedding date and total budget in the two yellow cells at the top. Everything else counts from them.
B7: 2. 'Budget': each category gets a share of your total (typical % shown for guidance). Change 'Your %' to suit you,
B8: or type a fixed dollar amount (e.g. a quote you already have) and it replaces the % for that category.
B9: 3. 'Vendors': one row per vendor: contact details, status, contract total and deposit. Paid so far, balance and next due date fill in.
B10: 4. 'Payments': log every deposit, payment and invoice. Status 'Paid' = money gone; 'Owed' = still to pay (add the due date).
B11: Owed payments past their due date turn orange. Refund or credit? Enter a negative amount.
B12: 5. 'Guest List': one row per invited guest; RSVP, meal, plus-one and table. Headcounts and a catering estimate update live.
B13: Your side names, meal options and catering cost per guest are the yellow cells on the right of that tab.
B14: 6. 'Checklist': 50 planning tasks with due dates counted back from your wedding date. Mark 'Yes' when done; add your own tasks.
... B32: Questions or a formula not behaving? Email nora@qnsai.com. Made by Nora Studio. Congratulations!

Sheet Dashboard
B1: Wedding Dashboard
B3: Wedding date: | D3: Total budget: | E3: 30000 | G3: =IF(AND(C3<>"",NOT(ISNUMBER(C3))),"Wedding date is not a date. ",IF(C3="","Type your wedding date in C3. ",""))&IF(AND(E3<>"",NOT(ISNUMBER(E3))),"Total budget is not a number. ","")&IF((Payments!H2+Budget!J2+Vendors!K2+'Guest List'!I2+Checklist!F2)>0,(Payments!H2+Budget!J2+Vendors!K2+'Guest List'!I2+Checklist!F2)&" row(s) need fixing - see red cells","Updates automatically from every tab") -> Type your wedding date in C3. Updates automatically from every tab | V3: Chart data (do not edit)
V4: Category | W4: Budget | X4: Committed
B5: TOTAL BUDGET | G5: COMMITTED (PAID + OWED) | L5: REMAINING | V5: =Calc!B3 -> Venue | W5: =Calc!C3 -> 6000 | X5: =Calc!D3 -> 12000
B6: =N(Dashboard!$E$3) -> 30000 | G6: =Calc!C25 -> 12000 | L6: =N(Dashboard!$E$3)-Calc!C25 -> 18000 | V6: =Calc!B4 -> Catering & bar | W6: =Calc!C4 -> 7500 | X6: =Calc!D4 -> 0
V7: =Calc!B5 -> Photography | W7: =Calc!C5 -> 3000 | X7: =Calc!D5 -> 0
V8: =Calc!B6 -> Videography | W8: =Calc!C6 -> 1200 | X8: =Calc!D6 -> 0
B9: % OF BUDGET USED | G9: PAID SO FAR | L9: STILL OWED | V9: =Calc!B7 -> Attire | W9: =Calc!C7 -> 1800 | X9: =Calc!D7 -> 0
B10: =IF(N(Dashboard!$E$3)>0,Calc!C25/N(Dashboard!$E$3),0) -> 0.4 | G10: =Calc!C26 -> 3000 | L10: =Calc!C27 -> 9000 | V10: =Calc!B8 -> Hair & makeup | W10: =Calc!C8 -> 600 | X10: =Calc!D8 -> 0
V11: =Calc!B9 -> Flowers & decor | W11: =Calc!C9 -> 2400 | X11: =Calc!D9 -> 0
V12: =Calc!B10 -> Music & entertainment | W12: =Calc!C10 -> 1500 | X12: =Calc!D10 -> 0
B13: DAYS TO THE WEDDING | G13: OVERDUE PAYMENTS | L13: NEXT PAYMENT DUE | V13: =Calc!B11 -> Wedding planner | W13: =Calc!C11 -> 900 | X13: =Calc!D11 -> 0
B14: =IF(ISNUMBER(C3),C3-TODAY(),"Set your date") -> Set your date | G14: =Calc!C28 -> 0 | L14: =IF(Calc!C30=0,"None",Calc!C30) -> 46508 | V14: =Calc!B12 -> Rings | W14: =Calc!C12 -> 900 | X14: =Calc!D12 -> 0
V15: =Calc!B13 -> Cake & desserts | W15: =Calc!C13 -> 600 | X15: =Calc!D13 -> 0
V16: =Calc!B14 -> Stationery | W16: =Calc!C14 -> 600 | X16: =Calc!D14 -> 0
B17: GUESTS ATTENDING | G17: CATERING ESTIMATE | L17: CHECKLIST DONE | V17: =Calc!B15 -> Rentals | W17: =Calc!C15 -> 600 | X17: =Calc!D15 -> 0
B18: ='Guest List'!L20 -> 2 | G18: ='Guest List'!L24 -> 285 | L18: =Calc!C118 -> 0 | V18: =Calc!B16 -> Transportation | W18: =Calc!C16 -> 600 | X18: =Calc!D16 -> 0
V19: =Calc!B17 -> Favors & gifts | W19: =Calc!C17 -> 300 | X19: =Calc!D17 -> 0
V20: =Calc!B18 -> Officiant & license | W20: =Calc!C18 -> 300 | X20: =Calc!D18 -> 0
B21: ="RSVPs still out: "&'Guest List'!L21&" | Overdue payments: "&Calc!C29&" | Overdue tasks: "&Calc!C117&" | Tasks done: "&Calc!C116&" of "&Calc!C115 -> RSVPs still out: 1 | Overdue payments: 0 | Overdue tasks: 0 | Tasks done: 0 of 50 | V21: =Calc!B19 -> Contingency / other | W21: =Calc!C19 -> 1200 | X21: =Calc!D19 -> 0
B22: Committed = paid + still owed. Catering estimate = (attending + not replied) x cost per guest (Guest List tab). | V22: =Calc!B20 | W22: =Calc!C20 -> 0 | X22: =Calc!D20 -> 0
V23: =Calc!B21 | W23: =Calc!C21 -> 0 | X23: =Calc!D21 -> 0
V24: =Calc!B22 | W24: =Calc!C22 -> 0 | X24: =Calc!D22 -> 0
V27: Month | W27: Paid | X27: Owed (by due date)
V28: =Calc!C34 -> Earlier | W28: =Calc!D34 -> 0 | X28: =Calc!E34 -> 0
V29: =Calc!C35 -> Jun 25 | W29: =Calc!D35 -> 0 | X29: =Calc!E35 -> 0
V30: =Calc!C36 -> Jul 25 | W30: =Calc!D36 -> 0 | X30: =Calc!E36 -> 0
V31: =Calc!C37 -> Aug 25 | W31: =Calc!D37 -> 0 | X31: =Calc!E37 -> 0
V32: =Calc!C38 -> Sep 25 | W32: =Calc!D38 -> 0 | X32: =Calc!E38 -> 0
V33: =Calc!C39 -> Oct 25 | W33: =Calc!D39 -> 0 | X33: =Calc!E39 -> 0
V34: =Calc!C40 -> Nov 25 | W34: =Calc!D40 -> 0 | X34: =Calc!E40 -> 0
V35: =Calc!C41 -> Dec 25 | W35: =Calc!D41 -> 0 | X35: =Calc!E41 -> 0
V36: =Calc!C42 -> Jan 26 | W36: =Calc!D42 -> 0 | X36: =Calc!E42 -> 0
V37: =Calc!C43 -> Feb 26 | W37: =Calc!D43 -> 0 | X37: =Calc!E43 -> 0
V38: =Calc!C44 -> Mar 26 | W38: =Calc!D44 -> 0 | X38: =Calc!E44 -> 0
V39: =Calc!C45 -> Apr 26 | W39: =Calc!D45 -> 0 | X39: =Calc!E45 -> 0
... V48: =Calc!C54 -> No due date | W48: =Calc!D54 -> 0 | X48: =Calc!E54 -> 0
V51: Status | W51: Amount
V52: Paid | W52: =MAX(0,Calc!C26) -> 3000
V53: Still owed | W53: =MAX(0,Calc!C27) -> 9000
...

Sheet Budget
A1: Budget
A2: Your total budget split by category. Edit 'Your %' or type a fixed amount; spending comes from the Payments tab. | I2: Rows to fix: | J2: =SUMPRODUCT((((Budget!$A$7:$A$26<>"")+(Budget!$C$7:$C$26<>"")+(Budget!$D$7:$D$26<>""))>0)*(((Budget!$A$7:$A$26<>"")*(((Budget!$C$7:$C$26="")+ISNUMBER(Budget!$C$7:$C$26))>0)*(((Budget!$D$7:$D$26="")+ISNUMBER(Budget!$D$7:$D$26))>0)*(Budget!$C$7:$C$26>=0)*(Budget!$D$7:$D$26>=0))=0)) -> 0
A3: Red cell = something to fix. Orange = category over budget.
A4: Total budget | B4: =Dashboard!E3 -> 30000 | C4: Allocated | D4: =E27 -> 30000 | E4: Unallocated | F4: =N(Dashboard!$E$3)-E27 -> 0 | G4: (change the total on the Dashboard)
A6: Category | B6: Typical % | C6: Your % | D6: Fixed amount (optional) | E6: Budget | F6: Committed (paid + owed) | G6: Paid | H6: Still owed | I6: Remaining | J6: % used
A7: Venue | B7: 0.2 | C7: 0.2 | E7: =IF(A7="","",IF(OR(AND(C7<>"",NOT(ISNUMBER(C7))),AND(D7<>"",NOT(ISNUMBER(D7))),N(C7)<0,N(D7)<0),0,IF(ISNUMBER(D7),D7,N(Dashboard!$E$3)*N(C7)))) -> 6000 | F7: =IF(A7="","",Calc!D3) -> 12000 | G7: =IF(A7="","",Calc!E3) -> 3000 | H7: =IF(A7="","",Calc!F3) -> 9000 | I7: =IF(A7="","",E7-F7) -> -6000 | J7: =IF(OR(A7="",N(E7)=0),"",F7/E7) -> 2
A8: Catering & bar | B8: 0.25 | C8: 0.25 | E8: =IF(A8="","",IF(OR(AND(C8<>"",NOT(ISNUMBER(C8))),AND(D8<>"",NOT(ISNUMBER(D8))),N(C8)<0,N(D8)<0),0,IF(ISNUMBER(D8),D8,N(Dashboard!$E$3)*N(C8)))) -> 7500 | F8: =IF(A8="","",Calc!D4) -> 0 | G8: =IF(A8="","",Calc!E4) -> 0 | H8: =IF(A8="","",Calc!F4) -> 0 | I8: =IF(A8="","",E8-F8) -> 7500 | J8: =IF(OR(A8="",N(E8)=0),"",F8/E8) -> 0
A9: Photography | B9: 0.1 | C9: 0.1 | E9: =IF(A9="","",IF(OR(AND(C9<>"",NOT(ISNUMBER(C9))),AND(D9<>"",NOT(ISNUMBER(D9))),N(C9)<0,N(D9)<0),0,IF(ISNUMBER(D9),D9,N(Dashboard!$E$3)*N(C9)))) -> 3000 | F9: =IF(A9="","",Calc!D5) -> 0 | G9: =IF(A9="","",Calc!E5) -> 0 | H9: =IF(A9="","",Calc!F5) -> 0 | I9: =IF(A9="","",E9-F9) -> 3000 | J9: =IF(OR(A9="",N(E9)=0),"",F9/E9) -> 0
A10: Videography | B10: 0.04 | C10: 0.04 | E10: =IF(A10="","",IF(OR(AND(C10<>"",NOT(ISNUMBER(C10))),AND(D10<>"",NOT(ISNUMBER(D10))),N(C10)<0,N(D10)<0),0,IF(ISNUMBER(D10),D10,N(Dashboard!$E$3)*N(C10)))) -> 1200 | F10: =IF(A10="","",Calc!D6) -> 0 | G10: =IF(A10="","",Calc!E6) -> 0 | H10: =IF(A10="","",Calc!F6) -> 0 | I10: =IF(A10="","",E10-F10) -> 1200 | J10: =IF(OR(A10="",N(E10)=0),"",F10/E10) -> 0
A11: Attire | B11: 0.06 | C11: 0.06 | E11: =IF(A11="","",IF(OR(AND(C11<>"",NOT(ISNUMBER(C11))),AND(D11<>"",NOT(ISNUMBER(D11))),N(C11)<0,N(D11)<0),0,IF(ISNUMBER(D11),D11,N(Dashboard!$E$3)*N(C11)))) -> 1800 | F11: =IF(A11="","",Calc!D7) -> 0 | G11: =IF(A11="","",Calc!E7) -> 0 | H11: =IF(A11="","",Calc!F7) -> 0 | I11: =IF(A11="","",E11-F11) -> 1800 | J11: =IF(OR(A11="",N(E11)=0),"",F11/E11) -> 0
A12: Hair & makeup | B12: 0.02 | C12: 0.02 | E12: =IF(A12="","",IF(OR(AND(C12<>"",NOT(ISNUMBER(C12))),AND(D12<>"",NOT(ISNUMBER(D12))),N(C12)<0,N(D12)<0),0,IF(ISNUMBER(D12),D12,N(Dashboard!$E$3)*N(C12)))) -> 600 | F12: =IF(A12="","",Calc!D8) -> 0 | G12: =IF(A12="","",Calc!E8) -> 0 | H12: =IF(A12="","",Calc!F8) -> 0 | I12: =IF(A12="","",E12-F12) -> 600 | J12: =IF(OR(A12="",N(E12)=0),"",F12/E12) -> 0
A13: Flowers & decor | B13: 0.08 | C13: 0.08 | E13: =IF(A13="","",IF(OR(AND(C13<>"",NOT(ISNUMBER(C13))),AND(D13<>"",NOT(ISNUMBER(D13))),N(C13)<0,N(D13)<0),0,IF(ISNUMBER(D13),D13,N(Dashboard!$E$3)*N(C13)))) -> 2400 | F13: =IF(A13="","",Calc!D9) -> 0 | G13: =IF(A13="","",Calc!E9) -> 0 | H13: =IF(A13="","",Calc!F9) -> 0 | I13: =IF(A13="","",E13-F13) -> 2400 | J13: =IF(OR(A13="",N(E13)=0),"",F13/E13) -> 0
A14: Music & entertainment | B14: 0.05 | C14: 0.05 | E14: =IF(A14="","",IF(OR(AND(C14<>"",NOT(ISNUMBER(C14))),AND(D14<>"",NOT(ISNUMBER(D14))),N(C14)<0,N(D14)<0),0,IF(ISNUMBER(D14),D14,N(Dashboard!$E$3)*N(C14)))) -> 1500 | F14: =IF(A14="","",Calc!D10) -> 0 | G14: =IF(A14="","",Calc!E10) -> 0 | H14: =IF(A14="","",Calc!F10) -> 0 | I14: =IF(A14="","",E14-F14) -> 1500 | J14: =IF(OR(A14="",N(E14)=0),"",F14/E14) -> 0
A15: Wedding planner | B15: 0.03 | C15: 0.03 | E15: =IF(A15="","",IF(OR(AND(C15<>"",NOT(ISNUMBER(C15))),AND(D15<>"",NOT(ISNUMBER(D15))),N(C15)<0,N(D15)<0),0,IF(ISNUMBER(D15),D15,N(Dashboard!$E$3)*N(C15)))) -> 900 | F15: =IF(A15="","",Calc!D11) -> 0 | G15: =IF(A15="","",Calc!E11) -> 0 | H15: =IF(A15="","",Calc!F11) -> 0 | I15: =IF(A15="","",E15-F15) -> 900 | J15: =IF(OR(A15="",N(E15)=0),"",F15/E15) -> 0
A16: Rings | B16: 0.03 | C16: 0.03 | E16: =IF(A16="","",IF(OR(AND(C16<>"",NOT(ISNUMBER(C16))),AND(D16<>"",NOT(ISNUMBER(D16))),N(C16)<0,N(D16)<0),0,IF(ISNUMBER(D16),D16,N(Dashboard!$E$3)*N(C16)))) -> 900 | F16: =IF(A16="","",Calc!D12) -> 0 | G16: =IF(A16="","",Calc!E12) -> 0 | H16: =IF(A16="","",Calc!F12) -> 0 | I16: =IF(A16="","",E16-F16) -> 900 | J16: =IF(OR(A16="",N(E16)=0),"",F16/E16) -> 0
A17: Cake & desserts | B17: 0.02 | C17: 0.02 | E17: =IF(A17="","",IF(OR(AND(C17<>"",NOT(ISNUMBER(C17))),AND(D17<>"",NOT(ISNUMBER(D17))),N(C17)<0,N(D17)<0),0,IF(ISNUMBER(D17),D17,N(Dashboard!$E$3)*N(C17)))) -> 600 | F17: =IF(A17="","",Calc!D13) -> 0 | G17: =IF(A17="","",Calc!E13) -> 0 | H17: =IF(A17="","",Calc!F13) -> 0 | I17: =IF(A17="","",E17-F17) -> 600 | J17: =IF(OR(A17="",N(E17)=0),"",F17/E17) -> 0
A18: Stationery | B18: 0.02 | C18: 0.02 | E18: =IF(A18="","",IF(OR(AND(C18<>"",NOT(ISNUMBER(C18))),AND(D18<>"",NOT(ISNUMBER(D18))),N(C18)<0,N(D18)<0),0,IF(ISNUMBER(D18),D18,N(Dashboard!$E$3)*N(C18)))) -> 600 | F18: =IF(A18="","",Calc!D14) -> 0 | G18: =IF(A18="","",Calc!E14) -> 0 | H18: =IF(A18="","",Calc!F14) -> 0 | I18: =IF(A18="","",E18-F18) -> 600 | J18: =IF(OR(A18="",N(E18)=0),"",F18/E18) -> 0
... A23: Contingency / other | B23: 0.04 | C23: 0.04 | E23: =IF(A23="","",IF(OR(AND(C23<>"",NOT(ISNUMBER(C23))),AND(D23<>"",NOT(ISNUMBER(D23))),N(C23)<0,N(D23)<0),0,IF(ISNUMBER(D23),D23,N(Dashboard!$E$3)*N(C23)))) -> 1200 | F23: =IF(A23="","",Calc!D19) -> 0 | G23: =IF(A23="","",Calc!E19) -> 0 | H23: =IF(A23="","",Calc!F19) -> 0 | I23: =IF(A23="","",E23-F23) -> 1200 | J23: =IF(OR(A23="",N(E23)=0),"",F23/E23) -> 0
E24: =IF(A24="","",IF(OR(AND(C24<>"",NOT(ISNUMBER(C24))),AND(D24<>"",NOT(ISNUMBER(D24))),N(C24)<0,N(D24)<0),0,IF(ISNUMBER(D24),D24,N(Dashboard!$E$3)*N(C24)))) | F24: =IF(A24="","",Calc!D20) | G24: =IF(A24="","",Calc!E20) | H24: =IF(A24="","",Calc!F20) | I24: =IF(A24="","",E24-F24) | J24: =IF(OR(A24="",N(E24)=0),"",F24/E24)
E25: =IF(A25="","",IF(OR(AND(C25<>"",NOT(ISNUMBER(C25))),AND(D25<>"",NOT(ISNUMBER(D25))),N(C25)<0,N(D25)<0),0,IF(ISNUMBER(D25),D25,N(Dashboard!$E$3)*N(C25)))) | F25: =IF(A25="","",Calc!D21) | G25: =IF(A25="","",Calc!E21) | H25: =IF(A25="","",Calc!F21) | I25: =IF(A25="","",E25-F25) | J25: =IF(OR(A25="",N(E25)=0),"",F25/E25)
E26: =IF(A26="","",IF(OR(AND(C26<>"",NOT(ISNUMBER(C26))),AND(D26<>"",NOT(ISNUMBER(D26))),N(C26)<0,N(D26)<0),0,IF(ISNUMBER(D26),D26,N(Dashboard!$E$3)*N(C26)))) | F26: =IF(A26="","",Calc!D22) | G26: =IF(A26="","",Calc!E22) | H26: =IF(A26="","",Calc!F22) | I26: =IF(A26="","",E26-F26) | J26: =IF(OR(A26="",N(E26)=0),"",F26/E26)
A27: Total | C27: =SUM(C7:C26) -> 1 | E27: =SUM(E7:E26) -> 30000 | F27: =SUM(F7:F26) -> 12000 | G27: =SUM(G7:G26) -> 3000 | H27: =SUM(H7:H26) -> 9000 | I27: =SUM(I7:I26) -> 18000 | J27: =IF(E27=0,"",F27/E27) -> 0.4
A29: ="Catering estimate from your Guest List: "&TEXT('Guest List'!L23,"0")&" guests x "&TEXT('Guest List'!L16,"$#,##0")&" = "&TEXT('Guest List'!L24,"$#,##0")&" | your Catering & bar budget: "&TEXT(SUMIF(A7:A26,"Catering & bar",E7:E26),"$#,##0") -> Catering estimate from your Guest List: 3 guests x $95 = $285 | your Catering & bar budget: $7,500
A30: Typical % = rough US averages for guidance only. Your % column should add up to 100% (see Total); spare rows are for your own categories.
A31: Renaming a category? Rename it here first; payments under the old name turn red until you pick the new name.

Sheet Payments
A1: Payments
A2: Every deposit, payment and invoice. Paid = money gone. Owed = still to pay (add the due date). | G2: Rows to fix: | H2: =SUMPRODUCT((((Payments!$A$5:$A$504<>"")+(Payments!$B$5:$B$504<>"")+(Payments!$C$5:$C$504<>"")+(Payments!$E$5:$E$504<>"")+(Payments!$F$5:$F$504<>"")+(Payments!$G$5:$G$504<>""))>0)*((ISNUMBER(Payments!$A$5:$A$504)*ISNUMBER(MATCH(Payments!$B$5:$B$504,Lists!$A$2:$A$21,0))*(((Payments!$C$5:$C$504="")+ISNUMBER(MATCH(Payments!$C$5:$C$504,Lists!$C$2:$C$41,0)))>0)*ISNUMBER(Payments!$E$5:$E$504)*(((Payments!$F$5:$F$504="Paid")+(Payments!$F$5:$F$504="Owed"))>0)*(((Payments!$G$5:$G$504="")+ISNUMBER(Payments!$G$5:$G$504))>0))=0)) -> 0
A3: Red cell = something to fix (row stays out of the totals). Orange row = owed and past its due date.
A4: Date | B4: Category | C4: Vendor (optional) | D4: Description | E4: Amount | F4: Paid / Owed | G4: Due date (if owed) | H4: Alert
A5: 46266 | B5: Venue | C5: EXAMPLE Venue | D5: EXAMPLE: venue deposit | E5: 3000 | F5: Paid | H5: =IF(AND(F5="Owed",ISNUMBER(G5)),IF(G5<TODAY(),"OVERDUE",IF(G5-TODAY()<=30,"Due in "&(G5-TODAY())&" days","")),"")
A6: 46266 | B6: Venue | C6: EXAMPLE Venue | D6: EXAMPLE: venue balance | E6: 9000 | F6: Owed | G6: 46508 | H6: =IF(AND(F6="Owed",ISNUMBER(G6)),IF(G6<TODAY(),"OVERDUE",IF(G6-TODAY()<=30,"Due in "&(G6-TODAY())&" days","")),"")
H7: =IF(AND(F7="Owed",ISNUMBER(G7)),IF(G7<TODAY(),"OVERDUE",IF(G7-TODAY()<=30,"Due in "&(G7-TODAY())&" days","")),"")
H8: =IF(AND(F8="Owed",ISNUMBER(G8)),IF(G8<TODAY(),"OVERDUE",IF(G8-TODAY()<=30,"Due in "&(G8-TODAY())&" days","")),"")
H9: =IF(AND(F9="Owed",ISNUMBER(G9)),IF(G9<TODAY(),"OVERDUE",IF(G9-TODAY()<=30,"Due in "&(G9-TODAY())&" days","")),"")
H10: =IF(AND(F10="Owed",ISNUMBER(G10)),IF(G10<TODAY(),"OVERDUE",IF(G10-TODAY()<=30,"Due in "&(G10-TODAY())&" days","")),"")
H11: =IF(AND(F11="Owed",ISNUMBER(G11)),IF(G11<TODAY(),"OVERDUE",IF(G11-TODAY()<=30,"Due in "&(G11-TODAY())&" days","")),"")
H12: =IF(AND(F12="Owed",ISNUMBER(G12)),IF(G12<TODAY(),"OVERDUE",IF(G12-TODAY()<=30,"Due in "&(G12-TODAY())&" days","")),"")
H13: =IF(AND(F13="Owed",ISNUMBER(G13)),IF(G13<TODAY(),"OVERDUE",IF(G13-TODAY()<=30,"Due in "&(G13-TODAY())&" days","")),"")
H14: =IF(AND(F14="Owed",ISNUMBER(G14)),IF(G14<TODAY(),"OVERDUE",IF(G14-TODAY()<=30,"Due in "&(G14-TODAY())&" days","")),"")
H15: =IF(AND(F15="Owed",ISNUMBER(G15)),IF(G15<TODAY(),"OVERDUE",IF(G15-TODAY()<=30,"Due in "&(G15-TODAY())&" days","")),"")
H16: =IF(AND(F16="Owed",ISNUMBER(G16)),IF(G16<TODAY(),"OVERDUE",IF(G16-TODAY()<=30,"Due in "&(G16-TODAY())&" days","")),"")
H17: =IF(AND(F17="Owed",ISNUMBER(G17)),IF(G17<TODAY(),"OVERDUE",IF(G17-TODAY()<=30,"Due in "&(G17-TODAY())&" days","")),"")
H18: =IF(AND(F18="Owed",ISNUMBER(G18)),IF(G18<TODAY(),"OVERDUE",IF(G18-TODAY()<=30,"Due in "&(G18-TODAY())&" days","")),"")
... H504: =IF(AND(F504="Owed",ISNUMBER(G504)),IF(G504<TODAY(),"OVERDUE",IF(G504-TODAY()<=30,"Due in "&(G504-TODAY())&" days","")),"")

Sheet Vendors
A1: Vendors
A2: Who you're working with. Paid so far, balance and next due date come from the Payments tab. | J2: Rows to fix: | K2: =SUMPRODUCT((((Vendors!$A$5:$A$44<>"")+(Vendors!$B$5:$B$44<>"")+(Vendors!$C$5:$C$44<>"")+(Vendors!$D$5:$D$44<>"")+(Vendors!$E$5:$E$44<>"")+(Vendors!$F$5:$F$44<>"")+(Vendors!$G$5:$G$44<>"")+(Vendors!$H$5:$H$44<>""))>0)*(((Vendors!$A$5:$A$44<>"")*(((Vendors!$B$5:$B$44="")+ISNUMBER(MATCH(Vendors!$B$5:$B$44,Lists!$A$2:$A$21,0)))>0)*(((Vendors!$F$5:$F$44="")+ISNUMBER(MATCH(Vendors!$F$5:$F$44,Lists!$F$2:$F$5,0)))>0)*(((Vendors!$G$5:$G$44="")+ISNUMBER(Vendors!$G$5:$G$44))>0)*(((Vendors!$H$5:$H$44="")+ISNUMBER(Vendors!$H$5:$H$44))>0)*(Vendors!$G$5:$G$44>=0)*(Vendors!$H$5:$H$44>=0))=0)) -> 0
A3: Red cell = something to fix. Orange = a payment to this vendor is overdue.
A4: Vendor | B4: Category | C4: Contact person | D4: Phone | E4: Email | F4: Status | G4: Contract total | H4: Deposit | I4: Paid so far | J4: Balance due | K4: Next payment due | L4: Notes
A5: EXAMPLE Venue | B5: Venue | C5: Jane Smith | D5: 555-0100 | E5: events@example.com | F5: Booked | G5: 12000 | H5: 3000 | I5: =IF(A5="","",Calc!D60) -> 3000 | J5: =IF(A5="","",IF(ISNUMBER(G5),G5-I5,Calc!E60)) -> 9000 | K5: =IF(OR(A5="",Calc!F60=0),"",Calc!F60) -> 46508
I6: =IF(A6="","",Calc!D61) | J6: =IF(A6="","",IF(ISNUMBER(G6),G6-I6,Calc!E61)) | K6: =IF(OR(A6="",Calc!F61=0),"",Calc!F61)
I7: =IF(A7="","",Calc!D62) | J7: =IF(A7="","",IF(ISNUMBER(G7),G7-I7,Calc!E62)) | K7: =IF(OR(A7="",Calc!F62=0),"",Calc!F62)
I8: =IF(A8="","",Calc!D63) | J8: =IF(A8="","",IF(ISNUMBER(G8),G8-I8,Calc!E63)) | K8: =IF(OR(A8="",Calc!F63=0),"",Calc!F63)
I9: =IF(A9="","",Calc!D64) | J9: =IF(A9="","",IF(ISNUMBER(G9),G9-I9,Calc!E64)) | K9: =IF(OR(A9="",Calc!F64=0),"",Calc!F64)
I10: =IF(A10="","",Calc!D65) | J10: =IF(A10="","",IF(ISNUMBER(G10),G10-I10,Calc!E65)) | K10: =IF(OR(A10="",Calc!F65=0),"",Calc!F65)
I11: =IF(A11="","",Calc!D66) | J11: =IF(A11="","",IF(ISNUMBER(G11),G11-I11,Calc!E66)) | K11: =IF(OR(A11="",Calc!F66=0),"",Calc!F66)
I12: =IF(A12="","",Calc!D67) | J12: =IF(A12="","",IF(ISNUMBER(G12),G12-I12,Calc!E67)) | K12: =IF(OR(A12="",Calc!F67=0),"",Calc!F67)
I13: =IF(A13="","",Calc!D68) | J13: =IF(A13="","",IF(ISNUMBER(G13),G13-I13,Calc!E68)) | K13: =IF(OR(A13="",Calc!F68=0),"",Calc!F68)
I14: =IF(A14="","",Calc!D69) | J14: =IF(A14="","",IF(ISNUMBER(G14),G14-I14,Calc!E69)) | K14: =IF(OR(A14="",Calc!F69=0),"",Calc!F69)
I15: =IF(A15="","",Calc!D70) | J15: =IF(A15="","",IF(ISNUMBER(G15),G15-I15,Calc!E70)) | K15: =IF(OR(A15="",Calc!F70=0),"",Calc!F70)
I16: =IF(A16="","",Calc!D71) | J16: =IF(A16="","",IF(ISNUMBER(G16),G16-I16,Calc!E71)) | K16: =IF(OR(A16="",Calc!F71=0),"",Calc!F71)
I17: =IF(A17="","",Calc!D72) | J17: =IF(A17="","",IF(ISNUMBER(G17),G17-I17,Calc!E72)) | K17: =IF(OR(A17="",Calc!F72=0),"",Calc!F72)
... I44: =IF(A44="","",Calc!D99) | J44: =IF(A44="","",IF(ISNUMBER(G44),G44-I44,Calc!E99)) | K44: =IF(OR(A44="",Calc!F99=0),"",Calc!F99)

Sheet Guest List
A1: Guest List
A2: One row per invited guest. Plus-ones count automatically. Your options are in the yellow cells on the right. | G2: Rows to fix: | I2: =SUMPRODUCT(((($A$5:$A$504<>"")+($B$5:$B$504<>"")+($C$5:$C$504<>"")+($D$5:$D$504<>"")+($E$5:$E$504<>"")+($F$5:$F$504<>"")+($G$5:$G$504<>"")+($H$5:$H$504<>""))>0)*((($A$5:$A$504<>"")*((($B$5:$B$504="")+ISNUMBER(MATCH($B$5:$B$504,$L$5:$L$7,0)))>0)*((($D$5:$D$504="")+($D$5:$D$504="Yes")+($D$5:$D$504="No")+($D$5:$D$504="Pending"))>0)*((($E$5:$E$504="")+ISNUMBER(MATCH($E$5:$E$504,$L$9:$L$14,0)))>0)*((($F$5:$F$504="")+($F$5:$F$504="Yes")+($F$5:$F$504="No"))>0)*((($G$5:$G$504="")+ISNUMBER(MATCH($G$5:$G$504,$L$9:$L$14,0)))>0))=0)) -> 0
A3: Red cell = something to fix. That guest stays out of the headcounts until fixed.
A4: Guest name | B4: Side | C4: Group | D4: RSVP | E4: Meal choice | F4: Plus-one? | G4: Plus-one meal | H4: Table | I4: Address / notes | K4: Your options
A5: EXAMPLE: Aunt Mary | B5: Bride | C5: Family | D5: Yes | E5: Chicken | F5: Yes | G5: Fish | H5: 1 | K5: Side 1 | L5: Bride
A6: EXAMPLE: Tom Lee | B6: Groom | C6: College | D6: Pending | F6: No | K6: Side 2 | L6: Groom
K7: Side 3 | L7: Both
K9: Meal option 1 | L9: Chicken
K10: Meal option 2 | L10: Beef
K11: Meal option 3 | L11: Fish
K12: Meal option 4 | L12: Vegetarian
K13: Meal option 5 | L13: Kids meal
K14: Meal option 6
K16: Catering cost per guest | L16: 95
K18: Headcount | L18: People
K19: Invited (guests + plus-ones) | L19: =SUMPRODUCT((($A$5:$A$504<>"")*((($B$5:$B$504="")+ISNUMBER(MATCH($B$5:$B$504,$L$5:$L$7,0)))>0)*((($D$5:$D$504="")+($D$5:$D$504="Yes")+($D$5:$D$504="No")+($D$5:$D$504="Pending"))>0)*((($E$5:$E$504="")+ISNUMBER(MATCH($E$5:$E$504,$L$9:$L$14,0)))>0)*((($F$5:$F$504="")+($F$5:$F$504="Yes")+($F$5:$F$504="No"))>0)*((($G$5:$G$504="")+ISNUMBER(MATCH($G$5:$G$504,$L$9:$L$14,0)))>0))*(1+($F$5:$F$504="Yes"))) -> 3
K20: Attending (RSVP Yes) | L20: =SUMPRODUCT((($A$5:$A$504<>"")*((($B$5:$B$504="")+ISNUMBER(MATCH($B$5:$B$504,$L$5:$L$7,0)))>0)*((($D$5:$D$504="")+($D$5:$D$504="Yes")+($D$5:$D$504="No")+($D$5:$D$504="Pending"))>0)*((($E$5:$E$504="")+ISNUMBER(MATCH($E$5:$E$504,$L$9:$L$14,0)))>0)*((($F$5:$F$504="")+($F$5:$F$504="Yes")+($F$5:$F$504="No"))>0)*((($G$5:$G$504="")+ISNUMBER(MATCH($G$5:$G$504,$L$9:$L$14,0)))>0))*($D$5:$D$504="Yes")*(1+($F$5:$F$504="Yes"))) -> 2
K21: Not replied yet | L21: =SUMPRODUCT((($A$5:$A$504<>"")*((($B$5:$B$504="")+ISNUMBER(MATCH($B$5:$B$504,$L$5:$L$7,0)))>0)*((($D$5:$D$504="")+($D$5:$D$504="Yes")+($D$5:$D$504="No")+($D$5:$D$504="Pending"))>0)*((($E$5:$E$504="")+ISNUMBER(MATCH($E$5:$E$504,$L$9:$L$14,0)))>0)*((($F$5:$F$504="")+($F$5:$F$504="Yes")+($F$5:$F$504="No"))>0)*((($G$5:$G$504="")+ISNUMBER(MATCH($G$5:$G$504,$L$9:$L$14,0)))>0))*((($D$5:$D$504="")+($D$5:$D$504="Pending"))>0)*(1+($F$5:$F$504="Yes"))) -> 1
K22: Declined | L22: =SUMPRODUCT((($A$5:$A$504<>"")*((($B$5:$B$504="")+ISNUMBER(MATCH($B$5:$B$504,$L$5:$L$7,0)))>0)*((($D$5:$D$504="")+($D$5:$D$504="Yes")+($D$5:$D$504="No")+($D$5:$D$504="Pending"))>0)*((($E$5:$E$504="")+ISNUMBER(MATCH($E$5:$E$504,$L$9:$L$14,0)))>0)*((($F$5:$F$504="")+($F$5:$F$504="Yes")+($F$5:$F$504="No"))>0)*((($G$5:$G$504="")+ISNUMBER(MATCH($G$5:$G$504,$L$9:$L$14,0)))>0))*($D$5:$D$504="No")*(1+($F$5:$F$504="Yes"))) -> 0
K23: Expected headcount (attending + not replied) | L23: =L20+L21 -> 3
K24: Catering estimate | L24: =L23*N(L16) -> 285
K26: Attending by side | L26: People
K27: =IF(L5="","",L5) -> Bride | L27: =IF(L5="",0,SUMPRODUCT((($A$5:$A$504<>"")*((($B$5:$B$504="")+ISNUMBER(MATCH($B$5:$B$504,$L$5:$L$7,0)))>0)*((($D$5:$D$504="")+($D$5:$D$504="Yes")+($D$5:$D$504="No")+($D$5:$D$504="Pending"))>0)*((($E$5:$E$504="")+ISNUMBER(MATCH($E$5:$E$504,$L$9:$L$14,0)))>0)*((($F$5:$F$504="")+($F$5:$F$504="Yes")+($F$5:$F$504="No"))>0)*((($G$5:$G$504="")+ISNUMBER(MATCH($G$5:$G$504,$L$9:$L$14,0)))>0))*($D$5:$D$504="Yes")*($B$5:$B$504=L5)*(1+($F$5:$F$504="Yes")))) -> 2
K28: =IF(L6="","",L6) -> Groom | L28: =IF(L6="",0,SUMPRODUCT((($A$5:$A$504<>"")*((($B$5:$B$504="")+ISNUMBER(MATCH($B$5:$B$504,$L$5:$L$7,0)))>0)*((($D$5:$D$504="")+($D$5:$D$504="Yes")+($D$5:$D$504="No")+($D$5:$D$504="Pending"))>0)*((($E$5:$E$504="")+ISNUMBER(MATCH($E$5:$E$504,$L$9:$L$14,0)))>0)*((($F$5:$F$504="")+($F$5:$F$504="Yes")+($F$5:$F$504="No"))>0)*((($G$5:$G$504="")+ISNUMBER(MATCH($G$5:$G$504,$L$9:$L$14,0)))>0))*($D$5:$D$504="Yes")*($B$5:$B$504=L6)*(1+($F$5:$F$504="Yes")))) -> 0
K29: =IF(L7="","",L7) -> Both | L29: =IF(L7="",0,SUMPRODUCT((($A$5:$A$504<>"")*((($B$5:$B$504="")+ISNUMBER(MATCH($B$5:$B$504,$L$5:$L$7,0)))>0)*((($D$5:$D$504="")+($D$5:$D$504="Yes")+($D$5:$D$504="No")+($D$5:$D$504="Pending"))>0)*((($E$5:$E$504="")+ISNUMBER(MATCH($E$5:$E$504,$L$9:$L$14,0)))>0)*((($F$5:$F$504="")+($F$5:$F$504="Yes")+($F$5:$F$504="No"))>0)*((($G$5:$G$504="")+ISNUMBER(MATCH($G$5:$G$504,$L$9:$L$14,0)))>0))*($D$5:$D$504="Yes")*($B$5:$B$504=L7)*(1+($F$5:$F$504="Yes")))) -> 0
K30: No side chosen | L30: =L20-SUM(L27:L29) -> 0
K32: Meals (attending guests) | L32: Meals
K33: =IF(L9="","",L9) -> Chicken | L33: =IF(L9="",0,SUMPRODUCT((($A$5:$A$504<>"")*((($B$5:$B$504="")+ISNUMBER(MATCH($B$5:$B$504,$L$5:$L$7,0)))>0)*((($D$5:$D$504="")+($D$5:$D$504="Yes")+($D$5:$D$504="No")+($D$5:$D$504="Pending"))>0)*((($E$5:$E$504="")+ISNUMBER(MATCH($E$5:$E$504,$L$9:$L$14,0)))>0)*((($F$5:$F$504="")+($F$5:$F$504="Yes")+($F$5:$F$504="No"))>0)*((($G$5:$G$504="")+ISNUMBER(MATCH($G$5:$G$504,$L$9:$L$14,0)))>0))*($D$5:$D$504="Yes")*($E$5:$E$504=L9))+SUMPRODUCT((($A$5:$A$504<>"")*((($B$5:$B$504="")+ISNUMBER(MATCH($B$5:$B$504,$L$5:$L$7,0)))>0)*((($D$5:$D$504="")+($D$5:$D$504="Yes")+($D$5:$D$504="No")+($D$5:$D$504="Pending"))>0)*((($E$5:$E$504="")+ISNUMBER(MATCH($E$5:$E$504,$L$9:$L$14,0)))>0)*((($F$5:$F$504="")+($F$5:$F$504="Yes")+($F$5:$F$504="No"))>0)*((($G$5:$G$504="")+ISNUMBER(MATCH($G$5:$G$504,$L$9:$L$14,0)))>0))*($D$5:$D$504="Yes")*($F$5:$F$504="Yes")*($G$5:$G$504=L9))) -> 1
K34: =IF(L10="","",L10) -> Beef | L34: =IF(L10="",0,SUMPRODUCT((($A$5:$A$504<>"")*((($B$5:$B$504="")+ISNUMBER(MATCH($B$5:$B$504,$L$5:$L$7,0)))>0)*((($D$5:$D$504="")+($D$5:$D$504="Yes")+($D$5:$D$504="No")+($D$5:$D$504="Pending"))>0)*((($E$5:$E$504="")+ISNUMBER(MATCH($E$5:$E$504,$L$9:$L$14,0)))>0)*((($F$5:$F$504="")+($F$5:$F$504="Yes")+($F$5:$F$504="No"))>0)*((($G$5:$G$504="")+ISNUMBER(MATCH($G$5:$G$504,$L$9:$L$14,0)))>0))*($D$5:$D$504="Yes")*($E$5:$E$504=L10))+SUMPRODUCT((($A$5:$A$504<>"")*((($B$5:$B$504="")+ISNUMBER(MATCH($B$5:$B$504,$L$5:$L$7,0)))>0)*((($D$5:$D$504="")+($D$5:$D$504="Yes")+($D$5:$D$504="No")+($D$5:$D$504="Pending"))>0)*((($E$5:$E$504="")+ISNUMBER(MATCH($E$5:$E$504,$L$9:$L$14,0)))>0)*((($F$5:$F$504="")+($F$5:$F$504="Yes")+($F$5:$F$504="No"))>0)*((($G$5:$G$504="")+ISNUMBER(MATCH($G$5:$G$504,$L$9:$L$14,0)))>0))*($D$5:$D$504="Yes")*($F$5:$F$504="Yes")*($G$5:$G$504=L10))) -> 0
K35: =IF(L11="","",L11) -> Fish | L35: =IF(L11="",0,SUMPRODUCT((($A$5:$A$504<>"")*((($B$5:$B$504="")+ISNUMBER(MATCH($B$5:$B$504,$L$5:$L$7,0)))>0)*((($D$5:$D$504="")+($D$5:$D$504="Yes")+($D$5:$D$504="No")+($D$5:$D$504="Pending"))>0)*((($E$5:$E$504="")+ISNUMBER(MATCH($E$5:$E$504,$L$9:$L$14,0)))>0)*((($F$5:$F$504="")+($F$5:$F$504="Yes")+($F$5:$F$504="No"))>0)*((($G$5:$G$504="")+ISNUMBER(MATCH($G$5:$G$504,$L$9:$L$14,0)))>0))*($D$5:$D$504="Yes")*($E$5:$E$504=L11))+SUMPRODUCT((($A$5:$A$504<>"")*((($B$5:$B$504="")+ISNUMBER(MATCH($B$5:$B$504,$L$5:$L$7,0)))>0)*((($D$5:$D$504="")+($D$5:$D$504="Yes")+($D$5:$D$504="No")+($D$5:$D$504="Pending"))>0)*((($E$5:$E$504="")+ISNUMBER(MATCH($E$5:$E$504,$L$9:$L$14,0)))>0)*((($F$5:$F$504="")+($F$5:$F$504="Yes")+($F$5:$F$504="No"))>0)*((($G$5:$G$504="")+ISNUMBER(MATCH($G$5:$G$504,$L$9:$L$14,0)))>0))*($D$5:$D$504="Yes")*($F$5:$F$504="Yes")*($G$5:$G$504=L11))) -> 1
K36: =IF(L12="","",L12) -> Vegetarian | L36: =IF(L12="",0,SUMPRODUCT((($A$5:$A$504<>"")*((($B$5:$B$504="")+ISNUMBER(MATCH($B$5:$B$504,$L$5:$L$7,0)))>0)*((($D$5:$D$504="")+($D$5:$D$504="Yes")+($D$5:$D$504="No")+($D$5:$D$504="Pending"))>0)*((($E$5:$E$504="")+ISNUMBER(MATCH($E$5:$E$504,$L$9:$L$14,0)))>0)*((($F$5:$F$504="")+($F$5:$F$504="Yes")+($F$5:$F$504="No"))>0)*((($G$5:$G$504="")+ISNUMBER(MATCH($G$5:$G$504,$L$9:$L$14,0)))>0))*($D$5:$D$504="Yes")*($E$5:$E$504=L12))+SUMPRODUCT((($A$5:$A$504<>"")*((($B$5:$B$504="")+ISNUMBER(MATCH($B$5:$B$504,$L$5:$L$7,0)))>0)*((($D$5:$D$504="")+($D$5:$D$504="Yes")+($D$5:$D$504="No")+($D$5:$D$504="Pending"))>0)*((($E$5:$E$504="")+ISNUMBER(MATCH($E$5:$E$504,$L$9:$L$14,0)))>0)*((($F$5:$F$504="")+($F$5:$F$504="Yes")+($F$5:$F$504="No"))>0)*((($G$5:$G$504="")+ISNUMBER(MATCH($G$5:$G$504,$L$9:$L$14,0)))>0))*($D$5:$D$504="Yes")*($F$5:$F$504="Yes")*($G$5:$G$504=L12))) -> 0
K37: =IF(L13="","",L13) -> Kids meal | L37: =IF(L13="",0,SUMPRODUCT((($A$5:$A$504<>"")*((($B$5:$B$504="")+ISNUMBER(MATCH($B$5:$B$504,$L$5:$L$7,0)))>0)*((($D$5:$D$504="")+($D$5:$D$504="Yes")+($D$5:$D$504="No")+($D$5:$D$504="Pending"))>0)*((($E$5:$E$504="")+ISNUMBER(MATCH($E$5:$E$504,$L$9:$L$14,0)))>0)*((($F$5:$F$504="")+($F$5:$F$504="Yes")+($F$5:$F$504="No"))>0)*((($G$5:$G$504="")+ISNUMBER(MATCH($G$5:$G$504,$L$9:$L$14,0)))>0))*($D$5:$D$504="Yes")*($E$5:$E$504=L13))+SUMPRODUCT((($A$5:$A$504<>"")*((($B$5:$B$504="")+ISNUMBER(MATCH($B$5:$B$504,$L$5:$L$7,0)))>0)*((($D$5:$D$504="")+($D$5:$D$504="Yes")+($D$5:$D$504="No")+($D$5:$D$504="Pending"))>0)*((($E$5:$E$504="")+ISNUMBER(MATCH($E$5:$E$504,$L$9:$L$14,0)))>0)*((($F$5:$F$504="")+($F$5:$F$504="Yes")+($F$5:$F$504="No"))>0)*((($G$5:$G$504="")+ISNUMBER(MATCH($G$5:$G$504,$L$9:$L$14,0)))>0))*($D$5:$D$504="Yes")*($F$5:$F$504="Yes")*($G$5:$G$504=L13))) -> 0
K38: =IF(L14="","",L14) | L38: =IF(L14="",0,SUMPRODUCT((($A$5:$A$504<>"")*((($B$5:$B$504="")+ISNUMBER(MATCH($B$5:$B$504,$L$5:$L$7,0)))>0)*((($D$5:$D$504="")+($D$5:$D$504="Yes")+($D$5:$D$504="No")+($D$5:$D$504="Pending"))>0)*((($E$5:$E$504="")+ISNUMBER(MATCH($E$5:$E$504,$L$9:$L$14,0)))>0)*((($F$5:$F$504="")+($F$5:$F$504="Yes")+($F$5:$F$504="No"))>0)*((($G$5:$G$504="")+ISNUMBER(MATCH($G$5:$G$504,$L$9:$L$14,0)))>0))*($D$5:$D$504="Yes")*($E$5:$E$504=L14))+SUMPRODUCT((($A$5:$A$504<>"")*((($B$5:$B$504="")+ISNUMBER(MATCH($B$5:$B$504,$L$5:$L$7,0)))>0)*((($D$5:$D$504="")+($D$5:$D$504="Yes")+($D$5:$D$504="No")+($D$5:$D$504="Pending"))>0)*((($E$5:$E$504="")+ISNUMBER(MATCH($E$5:$E$504,$L$9:$L$14,0)))>0)*((($F$5:$F$504="")+($F$5:$F$504="Yes")+($F$5:$F$504="No"))>0)*((($G$5:$G$504="")+ISNUMBER(MATCH($G$5:$G$504,$L$9:$L$14,0)))>0))*($D$5:$D$504="Yes")*($F$5:$F$504="Yes")*($G$5:$G$504=L14))) -> 0
K39: No meal chosen yet | L39: =L20-SUM(L33:L38) -> 0
K41: Two brides or two grooms? Just rename the sides above.
K42: Renaming a meal or side turns rows using the old name red.

Sheet Checklist
A1: Checklist
A2: =IF(ISNUMBER(Dashboard!$C$3),"Due dates count back from your wedding date: "&TEXT(Dashboard!$C$3,"mmmm d, yyyy"),"Type your wedding date on the Dashboard and the due dates fill in.") -> Type your wedding date on the Dashboard and the due dates fill in. | D2: Rows to fix: | F2: =SUMPRODUCT((((Checklist!$A$5:$A$124<>"")+(Checklist!$B$5:$B$124<>"")+(Checklist!$C$5:$C$124<>"")+(Checklist!$E$5:$E$124<>""))>0)*(((Checklist!$A$5:$A$124<>"")*(((Checklist!$B$5:$B$124="")+ISNUMBER(Checklist!$B$5:$B$124))>0)*(((Checklist!$C$5:$C$124="")+ISNUMBER(Checklist!$C$5:$C$124))>0)*(((Checklist!$E$5:$E$124="")+(Checklist!$E$5:$E$124="Yes"))>0))=0)) -> 0
A3: Red cell = something to fix. Orange = overdue. Want a different date for a task? Type it in 'Your own due date'.
A4: Task | B4: Months before | C4: Your own due date (optional) | D4: Due date | E4: Done? | F4: Status | G4: Notes
A5: Agree on your total budget and fill in the Budget tab | B5: 12 | D5: =IF(A5="","",IF(ISNUMBER(C5),C5,IF(AND(ISNUMBER(B5),ISNUMBER(Dashboard!$C$3)),DATE(YEAR(Dashboard!$C$3),MONTH(Dashboard!$C$3)-INT(B5),DAY(Dashboard!$C$3)-ROUND(MOD(B5,1)*28,0)),""))) | F5: =IF(A5="","",IF(E5="Yes","Done",IF(D5="","No date",IF(D5<TODAY(),"OVERDUE",IF(D5-TODAY()<=30,"Due soon","Upcoming"))))) -> No date
A6: Pick a date (or season) and a rough guest count | B6: 12 | D6: =IF(A6="","",IF(ISNUMBER(C6),C6,IF(AND(ISNUMBER(B6),ISNUMBER(Dashboard!$C$3)),DATE(YEAR(Dashboard!$C$3),MONTH(Dashboard!$C$3)-INT(B6),DAY(Dashboard!$C$3)-ROUND(MOD(B6,1)*28,0)),""))) | F6: =IF(A6="","",IF(E6="Yes","Done",IF(D6="","No date",IF(D6<TODAY(),"OVERDUE",IF(D6-TODAY()<=30,"Due soon","Upcoming"))))) -> No date
A7: Start the guest list | B7: 12 | D7: =IF(A7="","",IF(ISNUMBER(C7),C7,IF(AND(ISNUMBER(B7),ISNUMBER(Dashboard!$C$3)),DATE(YEAR(Dashboard!$C$3),MONTH(Dashboard!$C$3)-INT(B7),DAY(Dashboard!$C$3)-ROUND(MOD(B7,1)*28,0)),""))) | F7: =IF(A7="","",IF(E7="Yes","Done",IF(D7="","No date",IF(D7<TODAY(),"OVERDUE",IF(D7-TODAY()<=30,"Due soon","Upcoming"))))) -> No date
A8: Research and book the venue | B8: 12 | D8: =IF(A8="","",IF(ISNUMBER(C8),C8,IF(AND(ISNUMBER(B8),ISNUMBER(Dashboard!$C$3)),DATE(YEAR(Dashboard!$C$3),MONTH(Dashboard!$C$3)-INT(B8),DAY(Dashboard!$C$3)-ROUND(MOD(B8,1)*28,0)),""))) | F8: =IF(A8="","",IF(E8="Yes","Done",IF(D8="","No date",IF(D8<TODAY(),"OVERDUE",IF(D8-TODAY()<=30,"Due soon","Upcoming"))))) -> No date
A9: Decide whether to hire a wedding planner | B9: 12 | D9: =IF(A9="","",IF(ISNUMBER(C9),C9,IF(AND(ISNUMBER(B9),ISNUMBER(Dashboard!$C$3)),DATE(YEAR(Dashboard!$C$3),MONTH(Dashboard!$C$3)-INT(B9),DAY(Dashboard!$C$3)-ROUND(MOD(B9,1)*28,0)),""))) | F9: =IF(A9="","",IF(E9="Yes","Done",IF(D9="","No date",IF(D9<TODAY(),"OVERDUE",IF(D9-TODAY()<=30,"Due soon","Upcoming"))))) -> No date
A10: Choose your wedding party | B10: 12 | D10: =IF(A10="","",IF(ISNUMBER(C10),C10,IF(AND(ISNUMBER(B10),ISNUMBER(Dashboard!$C$3)),DATE(YEAR(Dashboard!$C$3),MONTH(Dashboard!$C$3)-INT(B10),DAY(Dashboard!$C$3)-ROUND(MOD(B10,1)*28,0)),""))) | F10: =IF(A10="","",IF(E10="Yes","Done",IF(D10="","No date",IF(D10<TODAY(),"OVERDUE",IF(D10-TODAY()<=30,"Due soon","Upcoming"))))) -> No date
A11: Book the photographer | B11: 10 | D11: =IF(A11="","",IF(ISNUMBER(C11),C11,IF(AND(ISNUMBER(B11),ISNUMBER(Dashboard!$C$3)),DATE(YEAR(Dashboard!$C$3),MONTH(Dashboard!$C$3)-INT(B11),DAY(Dashboard!$C$3)-ROUND(MOD(B11,1)*28,0)),""))) | F11: =IF(A11="","",IF(E11="Yes","Done",IF(D11="","No date",IF(D11<TODAY(),"OVERDUE",IF(D11-TODAY()<=30,"Due soon","Upcoming"))))) -> No date
A12: Book the videographer | B12: 10 | D12: =IF(A12="","",IF(ISNUMBER(C12),C12,IF(AND(ISNUMBER(B12),ISNUMBER(Dashboard!$C$3)),DATE(YEAR(Dashboard!$C$3),MONTH(Dashboard!$C$3)-INT(B12),DAY(Dashboard!$C$3)-ROUND(MOD(B12,1)*28,0)),""))) | F12: =IF(A12="","",IF(E12="Yes","Done",IF(D12="","No date",IF(D12<TODAY(),"OVERDUE",IF(D12-TODAY()<=30,"Due soon","Upcoming"))))) -> No date
A13: Book the caterer (if not included with the venue) | B13: 10 | D13: =IF(A13="","",IF(ISNUMBER(C13),C13,IF(AND(ISNUMBER(B13),ISNUMBER(Dashboard!$C$3)),DATE(YEAR(Dashboard!$C$3),MONTH(Dashboard!$C$3)-INT(B13),DAY(Dashboard!$C$3)-ROUND(MOD(B13,1)*28,0)),""))) | F13: =IF(A13="","",IF(E13="Yes","Done",IF(D13="","No date",IF(D13<TODAY(),"OVERDUE",IF(D13-TODAY()<=30,"Due soon","Upcoming"))))) -> No date
A14: Book the band or DJ | B14: 10 | D14: =IF(A14="","",IF(ISNUMBER(C14),C14,IF(AND(ISNUMBER(B14),ISNUMBER(Dashboard!$C$3)),DATE(YEAR(Dashboard!$C$3),MONTH(Dashboard!$C$3)-INT(B14),DAY(Dashboard!$C$3)-ROUND(MOD(B14,1)*28,0)),""))) | F14: =IF(A14="","",IF(E14="Yes","Done",IF(D14="","No date",IF(D14<TODAY(),"OVERDUE",IF(D14-TODAY()<=30,"Due soon","Upcoming"))))) -> No date
A15: Set up a wedding website | B15: 10 | D15: =IF(A15="","",IF(ISNUMBER(C15),C15,IF(AND(ISNUMBER(B15),ISNUMBER(Dashboard!$C$3)),DATE(YEAR(Dashboard!$C$3),MONTH(Dashboard!$C$3)-INT(B15),DAY(Dashboard!$C$3)-ROUND(MOD(B15,1)*28,0)),""))) | F15: =IF(A15="","",IF(E15="Yes","Done",IF(D15="","No date",IF(D15<TODAY(),"OVERDUE",IF(D15-TODAY()<=30,"Due soon","Upcoming"))))) -> No date
A16: Shop for wedding attire | B16: 9 | D16: =IF(A16="","",IF(ISNUMBER(C16),C16,IF(AND(ISNUMBER(B16),ISNUMBER(Dashboard!$C$3)),DATE(YEAR(Dashboard!$C$3),MONTH(Dashboard!$C$3)-INT(B16),DAY(Dashboard!$C$3)-ROUND(MOD(B16,1)*28,0)),""))) | F16: =IF(A16="","",IF(E16="Yes","Done",IF(D16="","No date",IF(D16<TODAY(),"OVERDUE",IF(D16-TODAY()<=30,"Due soon","Upcoming"))))) -> No date
... A54: Close out the budget: settle any last balances | B54: -1 | D54: =IF(A54="","",IF(ISNUMBER(C54),C54,IF(AND(ISNUMBER(B54),ISNUMBER(Dashboard!$C$3)),DATE(YEAR(Dashboard!$C$3),MONTH(Dashboard!$C$3)-INT(B54),DAY(Dashboard!$C$3)-ROUND(MOD(B54,1)*28,0)),""))) | F54: =IF(A54="","",IF(E54="Yes","Done",IF(D54="","No date",IF(D54<TODAY(),"OVERDUE",IF(D54-TODAY()<=30,"Due soon","Upcoming"))))) -> No date
D55: =IF(A55="","",IF(ISNUMBER(C55),C55,IF(AND(ISNUMBER(B55),ISNUMBER(Dashboard!$C$3)),DATE(YEAR(Dashboard!$C$3),MONTH(Dashboard!$C$3)-INT(B55),DAY(Dashboard!$C$3)-ROUND(MOD(B55,1)*28,0)),""))) | F55: =IF(A55="","",IF(E55="Yes","Done",IF(D55="","No date",IF(D55<TODAY(),"OVERDUE",IF(D55-TODAY()<=30,"Due soon","Upcoming")))))
D56: =IF(A56="","",IF(ISNUMBER(C56),C56,IF(AND(ISNUMBER(B56),ISNUMBER(Dashboard!$C$3)),DATE(YEAR(Dashboard!$C$3),MONTH(Dashboard!$C$3)-INT(B56),DAY(Dashboard!$C$3)-ROUND(MOD(B56,1)*28,0)),""))) | F56: =IF(A56="","",IF(E56="Yes","Done",IF(D56="","No date",IF(D56<TODAY(),"OVERDUE",IF(D56-TODAY()<=30,"Due soon","Upcoming")))))
D57: =IF(A57="","",IF(ISNUMBER(C57),C57,IF(AND(ISNUMBER(B57),ISNUMBER(Dashboard!$C$3)),DATE(YEAR(Dashboard!$C$3),MONTH(Dashboard!$C$3)-INT(B57),DAY(Dashboard!$C$3)-ROUND(MOD(B57,1)*28,0)),""))) | F57: =IF(A57="","",IF(E57="Yes","Done",IF(D57="","No date",IF(D57<TODAY(),"OVERDUE",IF(D57-TODAY()<=30,"Due soon","Upcoming")))))
D58: =IF(A58="","",IF(ISNUMBER(C58),C58,IF(AND(ISNUMBER(B58),ISNUMBER(Dashboard!$C$3)),DATE(YEAR(Dashboard!$C$3),MONTH(Dashboard!$C$3)-INT(B58),DAY(Dashboard!$C$3)-ROUND(MOD(B58,1)*28,0)),""))) | F58: =IF(A58="","",IF(E58="Yes","Done",IF(D58="","No date",IF(D58<TODAY(),"OVERDUE",IF(D58-TODAY()<=30,"Due soon","Upcoming")))))
D59: =IF(A59="","",IF(ISNUMBER(C59),C59,IF(AND(ISNUMBER(B59),ISNUMBER(Dashboard!$C$3)),DATE(YEAR(Dashboard!$C$3),MONTH(Dashboard!$C$3)-INT(B59),DAY(Dashboard!$C$3)-ROUND(MOD(B59,1)*28,0)),""))) | F59: =IF(A59="","",IF(E59="Yes","Done",IF(D59="","No date",IF(D59<TODAY(),"OVERDUE",IF(D59-TODAY()<=30,"Due soon","Upcoming")))))
D60: =IF(A60="","",IF(ISNUMBER(C60),C60,IF(AND(ISNUMBER(B60),ISNUMBER(Dashboard!$C$3)),DATE(YEAR(Dashboard!$C$3),MONTH(Dashboard!$C$3)-INT(B60),DAY(Dashboard!$C$3)-ROUND(MOD(B60,1)*28,0)),""))) | F60: =IF(A60="","",IF(E60="Yes","Done",IF(D60="","No date",IF(D60<TODAY(),"OVERDUE",IF(D60-TODAY()<=30,"Due soon","Upcoming")))))
D61: =IF(A61="","",IF(ISNUMBER(C61),C61,IF(AND(ISNUMBER(B61),ISNUMBER(Dashboard!$C$3)),DATE(YEAR(Dashboard!$C$3),MONTH(Dashboard!$C$3)-INT(B61),DAY(Dashboard!$C$3)-ROUND(MOD(B61,1)*28,0)),""))) | F61: =IF(A61="","",IF(E61="Yes","Done",IF(D61="","No date",IF(D61<TODAY(),"OVERDUE",IF(D61-TODAY()<=30,"Due soon","Upcoming")))))
D62: =IF(A62="","",IF(ISNUMBER(C62),C62,IF(AND(ISNUMBER(B62),ISNUMBER(Dashboard!$C$3)),DATE(YEAR(Dashboard!$C$3),MONTH(Dashboard!$C$3)-INT(B62),DAY(Dashboard!$C$3)-ROUND(MOD(B62,1)*28,0)),""))) | F62: =IF(A62="","",IF(E62="Yes","Done",IF(D62="","No date",IF(D62<TODAY(),"OVERDUE",IF(D62-TODAY()<=30,"Due soon","Upcoming")))))
D63: =IF(A63="","",IF(ISNUMBER(C63),C63,IF(AND(ISNUMBER(B63),ISNUMBER(Dashboard!$C$3)),DATE(YEAR(Dashboard!$C$3),MONTH(Dashboard!$C$3)-INT(B63),DAY(Dashboard!$C$3)-ROUND(MOD(B63,1)*28,0)),""))) | F63: =IF(A63="","",IF(E63="Yes","Done",IF(D63="","No date",IF(D63<TODAY(),"OVERDUE",IF(D63-TODAY()<=30,"Due soon","Upcoming")))))
D64: =IF(A64="","",IF(ISNUMBER(C64),C64,IF(AND(ISNUMBER(B64),ISNUMBER(Dashboard!$C$3)),DATE(YEAR(Dashboard!$C$3),MONTH(Dashboard!$C$3)-INT(B64),DAY(Dashboard!$C$3)-ROUND(MOD(B64,1)*28,0)),""))) | F64: =IF(A64="","",IF(E64="Yes","Done",IF(D64="","No date",IF(D64<TODAY(),"OVERDUE",IF(D64-TODAY()<=30,"Due soon","Upcoming")))))
D65: =IF(A65="","",IF(ISNUMBER(C65),C65,IF(AND(ISNUMBER(B65),ISNUMBER(Dashboard!$C$3)),DATE(YEAR(Dashboard!$C$3),MONTH(Dashboard!$C$3)-INT(B65),DAY(Dashboard!$C$3)-ROUND(MOD(B65,1)*28,0)),""))) | F65: =IF(A65="","",IF(E65="Yes","Done",IF(D65="","No date",IF(D65<TODAY(),"OVERDUE",IF(D65-TODAY()<=30,"Due soon","Upcoming")))))
D66: =IF(A66="","",IF(ISNUMBER(C66),C66,IF(AND(ISNUMBER(B66),ISNUMBER(Dashboard!$C$3)),DATE(YEAR(Dashboard!$C$3),MONTH(Dashboard!$C$3)-INT(B66),DAY(Dashboard!$C$3)-ROUND(MOD(B66,1)*28,0)),""))) | F66: =IF(A66="","",IF(E66="Yes","Done",IF(D66="","No date",IF(D66<TODAY(),"OVERDUE",IF(D66-TODAY()<=30,"Due soon","Upcoming")))))
... D124: =IF(A124="","",IF(ISNUMBER(C124),C124,IF(AND(ISNUMBER(B124),ISNUMBER(Dashboard!$C$3)),DATE(YEAR(Dashboard!$C$3),MONTH(Dashboard!$C$3)-INT(B124),DAY(Dashboard!$C$3)-ROUND(MOD(B124,1)*28,0)),""))) | F124: =IF(A124="","",IF(E124="Yes","Done",IF(D124="","No date",IF(D124<TODAY(),"OVERDUE",IF(D124-TODAY()<=30,"Due soon","Upcoming")))))

Sheet Lists
A1: Valid categories | B1: Category dropdown | C1: Valid vendors | D1: Vendor dropdown | E1: Payment status | F1: Vendor status | G1: Yes/No | H1: RSVP | I1: Done
A2: =IF(Budget!A7="","[empty slot 1]",Budget!A7) -> Venue | B2: =IF(Budget!A7="","",Budget!A7) -> Venue | C2: =IF(Vendors!A5="","[empty vendor 1]",Vendors!A5) -> EXAMPLE Venue | D2: =IF(Vendors!A5="","",Vendors!A5) -> EXAMPLE Venue | E2: Paid | F2: Considering | G2: Yes | H2: Yes | I2: Yes
A3: =IF(Budget!A8="","[empty slot 2]",Budget!A8) -> Catering & bar | B3: =IF(Budget!A8="","",Budget!A8) -> Catering & bar | C3: =IF(Vendors!A6="","[empty vendor 2]",Vendors!A6) -> [empty vendor 2] | D3: =IF(Vendors!A6="","",Vendors!A6) | E3: Owed | F3: Booked | G3: No | H3: No
A4: =IF(Budget!A9="","[empty slot 3]",Budget!A9) -> Photography | B4: =IF(Budget!A9="","",Budget!A9) -> Photography | C4: =IF(Vendors!A7="","[empty vendor 3]",Vendors!A7) -> [empty vendor 3] | D4: =IF(Vendors!A7="","",Vendors!A7) | F4: Paid in full | H4: Pending
A5: =IF(Budget!A10="","[empty slot 4]",Budget!A10) -> Videography | B5: =IF(Budget!A10="","",Budget!A10) -> Videography | C5: =IF(Vendors!A8="","[empty vendor 4]",Vendors!A8) -> [empty vendor 4] | D5: =IF(Vendors!A8="","",Vendors!A8) | F5: Cancelled
A6: =IF(Budget!A11="","[empty slot 5]",Budget!A11) -> Attire | B6: =IF(Budget!A11="","",Budget!A11) -> Attire | C6: =IF(Vendors!A9="","[empty vendor 5]",Vendors!A9) -> [empty vendor 5] | D6: =IF(Vendors!A9="","",Vendors!A9)
A7: =IF(Budget!A12="","[empty slot 6]",Budget!A12) -> Hair & makeup | B7: =IF(Budget!A12="","",Budget!A12) -> Hair & makeup | C7: =IF(Vendors!A10="","[empty vendor 6]",Vendors!A10) -> [empty vendor 6] | D7: =IF(Vendors!A10="","",Vendors!A10)
A8: =IF(Budget!A13="","[empty slot 7]",Budget!A13) -> Flowers & decor | B8: =IF(Budget!A13="","",Budget!A13) -> Flowers & decor | C8: =IF(Vendors!A11="","[empty vendor 7]",Vendors!A11) -> [empty vendor 7] | D8: =IF(Vendors!A11="","",Vendors!A11)
A9: =IF(Budget!A14="","[empty slot 8]",Budget!A14) -> Music & entertainment | B9: =IF(Budget!A14="","",Budget!A14) -> Music & entertainment | C9: =IF(Vendors!A12="","[empty vendor 8]",Vendors!A12) -> [empty vendor 8] | D9: =IF(Vendors!A12="","",Vendors!A12)
A10: =IF(Budget!A15="","[empty slot 9]",Budget!A15) -> Wedding planner | B10: =IF(Budget!A15="","",Budget!A15) -> Wedding planner | C10: =IF(Vendors!A13="","[empty vendor 9]",Vendors!A13) -> [empty vendor 9] | D10: =IF(Vendors!A13="","",Vendors!A13)
A11: =IF(Budget!A16="","[empty slot 10]",Budget!A16) -> Rings | B11: =IF(Budget!A16="","",Budget!A16) -> Rings | C11: =IF(Vendors!A14="","[empty vendor 10]",Vendors!A14) -> [empty vendor 10] | D11: =IF(Vendors!A14="","",Vendors!A14)
A12: =IF(Budget!A17="","[empty slot 11]",Budget!A17) -> Cake & desserts | B12: =IF(Budget!A17="","",Budget!A17) -> Cake & desserts | C12: =IF(Vendors!A15="","[empty vendor 11]",Vendors!A15) -> [empty vendor 11] | D12: =IF(Vendors!A15="","",Vendors!A15)
A13: =IF(Budget!A18="","[empty slot 12]",Budget!A18) -> Stationery | B13: =IF(Budget!A18="","",Budget!A18) -> Stationery | C13: =IF(Vendors!A16="","[empty vendor 12]",Vendors!A16) -> [empty vendor 12] | D13: =IF(Vendors!A16="","",Vendors!A16)
A14: =IF(Budget!A19="","[empty slot 13]",Budget!A19) -> Rentals | B14: =IF(Budget!A19="","",Budget!A19) -> Rentals | C14: =IF(Vendors!A17="","[empty vendor 13]",Vendors!A17) -> [empty vendor 13] | D14: =IF(Vendors!A17="","",Vendors!A17)
A15: =IF(Budget!A20="","[empty slot 14]",Budget!A20) -> Transportation | B15: =IF(Budget!A20="","",Budget!A20) -> Transportation | C15: =IF(Vendors!A18="","[empty vendor 14]",Vendors!A18) -> [empty vendor 14] | D15: =IF(Vendors!A18="","",Vendors!A18)
A16: =IF(Budget!A21="","[empty slot 15]",Budget!A21) -> Favors & gifts | B16: =IF(Budget!A21="","",Budget!A21) -> Favors & gifts | C16: =IF(Vendors!A19="","[empty vendor 15]",Vendors!A19) -> [empty vendor 15] | D16: =IF(Vendors!A19="","",Vendors!A19)
A17: =IF(Budget!A22="","[empty slot 16]",Budget!A22) -> Officiant & license | B17: =IF(Budget!A22="","",Budget!A22) -> Officiant & license | C17: =IF(Vendors!A20="","[empty vendor 16]",Vendors!A20) -> [empty vendor 16] | D17: =IF(Vendors!A20="","",Vendors!A20)
A18: =IF(Budget!A23="","[empty slot 17]",Budget!A23) -> Contingency / other | B18: =IF(Budget!A23="","",Budget!A23) -> Contingency / other | C18: =IF(Vendors!A21="","[empty vendor 17]",Vendors!A21) -> [empty vendor 17] | D18: =IF(Vendors!A21="","",Vendors!A21)
A19: =IF(Budget!A24="","[empty slot 18]",Budget!A24) -> [empty slot 18] | B19: =IF(Budget!A24="","",Budget!A24) | C19: =IF(Vendors!A22="","[empty vendor 18]",Vendors!A22) -> [empty vendor 18] | D19: =IF(Vendors!A22="","",Vendors!A22)
A20: =IF(Budget!A25="","[empty slot 19]",Budget!A25) -> [empty slot 19] | B20: =IF(Budget!A25="","",Budget!A25) | C20: =IF(Vendors!A23="","[empty vendor 19]",Vendors!A23) -> [empty vendor 19] | D20: =IF(Vendors!A23="","",Vendors!A23)
A21: =IF(Budget!A26="","[empty slot 20]",Budget!A26) -> [empty slot 20] | B21: =IF(Budget!A26="","",Budget!A26) | C21: =IF(Vendors!A24="","[empty vendor 20]",Vendors!A24) -> [empty vendor 20] | D21: =IF(Vendors!A24="","",Vendors!A24)
C22: =IF(Vendors!A25="","[empty vendor 21]",Vendors!A25) -> [empty vendor 21] | D22: =IF(Vendors!A25="","",Vendors!A25)
C23: =IF(Vendors!A26="","[empty vendor 22]",Vendors!A26) -> [empty vendor 22] | D23: =IF(Vendors!A26="","",Vendors!A26)
C24: =IF(Vendors!A27="","[empty vendor 23]",Vendors!A27) -> [empty vendor 23] | D24: =IF(Vendors!A27="","",Vendors!A27)
C25: =IF(Vendors!A28="","[empty vendor 24]",Vendors!A28) -> [empty vendor 24] | D25: =IF(Vendors!A28="","",Vendors!A28)
C26: =IF(Vendors!A29="","[empty vendor 25]",Vendors!A29) -> [empty vendor 25] | D26: =IF(Vendors!A29="","",Vendors!A29)
C27: =IF(Vendors!A30="","[empty vendor 26]",Vendors!A30) -> [empty vendor 26] | D27: =IF(Vendors!A30="","",Vendors!A30)
C28: =IF(Vendors!A31="","[empty vendor 27]",Vendors!A31) -> [empty vendor 27] | D28: =IF(Vendors!A31="","",Vendors!A31)
C29: =IF(Vendors!A32="","[empty vendor 28]",Vendors!A32) -> [empty vendor 28] | D29: =IF(Vendors!A32="","",Vendors!A32)
C30: =IF(Vendors!A33="","[empty vendor 29]",Vendors!A33) -> [empty vendor 29] | D30: =IF(Vendors!A33="","",Vendors!A33)
C31: =IF(Vendors!A34="","[empty vendor 30]",Vendors!A34) -> [empty vendor 30] | D31: =IF(Vendors!A34="","",Vendors!A34)
C32: =IF(Vendors!A35="","[empty vendor 31]",Vendors!A35) -> [empty vendor 31] | D32: =IF(Vendors!A35="","",Vendors!A35)
C33: =IF(Vendors!A36="","[empty vendor 32]",Vendors!A36) -> [empty vendor 32] | D33: =IF(Vendors!A36="","",Vendors!A36)
C34: =IF(Vendors!A37="","[empty vendor 33]",Vendors!A37) -> [empty vendor 33] | D34: =IF(Vendors!A37="","",Vendors!A37)
C35: =IF(Vendors!A38="","[empty vendor 34]",Vendors!A38) -> [empty vendor 34] | D35: =IF(Vendors!A38="","",Vendors!A38)
C36: =IF(Vendors!A39="","[empty vendor 35]",Vendors!A39) -> [empty vendor 35] | D36: =IF(Vendors!A39="","",Vendors!A39)
C37: =IF(Vendors!A40="","[empty vendor 36]",Vendors!A40) -> [empty vendor 36] | D37: =IF(Vendors!A40="","",Vendors!A40)
C38: =IF(Vendors!A41="","[empty vendor 37]",Vendors!A41) -> [empty vendor 37] | D38: =IF(Vendors!A41="","",Vendors!A41)
C39: =IF(Vendors!A42="","[empty vendor 38]",Vendors!A42) -> [empty vendor 38] | D39: =IF(Vendors!A42="","",Vendors!A42)
C40: =IF(Vendors!A43="","[empty vendor 39]",Vendors!A43) -> [empty vendor 39] | D40: =IF(Vendors!A43="","",Vendors!A43)
...

Sheet Calc
B2: Category | C2: Budget | D2: Committed | E2: Paid | F2: Owed
B3: =IF(Budget!A7="","",Budget!A7) -> Venue | C3: =N(Budget!E7) -> 6000 | D3: =SUMPRODUCT((ISNUMBER(Payments!$A$5:$A$504)*ISNUMBER(MATCH(Payments!$B$5:$B$504,Lists!$A$2:$A$21,0))*(((Payments!$C$5:$C$504="")+ISNUMBER(MATCH(Payments!$C$5:$C$504,Lists!$C$2:$C$41,0)))>0)*ISNUMBER(Payments!$E$5:$E$504)*(((Payments!$F$5:$F$504="Paid")+(Payments!$F$5:$F$504="Owed"))>0)*(((Payments!$G$5:$G$504="")+ISNUMBER(Payments!$G$5:$G$504))>0))*(Payments!$B$5:$B$504=Lists!$A$2),Payments!$E$5:$E$504) -> 12000 | E3: =SUMPRODUCT((ISNUMBER(Payments!$A$5:$A$504)*ISNUMBER(MATCH(Payments!$B$5:$B$504,Lists!$A$2:$A$21,0))*(((Payments!$C$5:$C$504="")+ISNUMBER(MATCH(Payments!$C$5:$C$504,Lists!$C$2:$C$41,0)))>0)*ISNUMBER(Payments!$E$5:$E$504)*(((Payments!$F$5:$F$504="Paid")+(Payments!$F$5:$F$504="Owed"))>0)*(((Payments!$G$5:$G$504="")+ISNUMBER(Payments!$G$5:$G$504))>0))*(Payments!$B$5:$B$504=Lists!$A$2)*(Payments!$F$5:$F$504="Paid"),Payments!$E$5:$E$504) -> 3000 | F3: =SUMPRODUCT((ISNUMBER(Payments!$A$5:$A$504)*ISNUMBER(MATCH(Payments!$B$5:$B$504,Lists!$A$2:$A$21,0))*(((Payments!$C$5:$C$504="")+ISNUMBER(MATCH(Payments!$C$5:$C$504,Lists!$C$2:$C$41,0)))>0)*ISNUMBER(Payments!$E$5:$E$504)*(((Payments!$F$5:$F$504="Paid")+(Payments!$F$5:$F$504="Owed"))>0)*(((Payments!$G$5:$G$504="")+ISNUMBER(Payments!$G$5:$G$504))>0))*(Payments!$B$5:$B$504=Lists!$A$2)*(Payments!$F$5:$F$504="Owed"),Payments!$E$5:$E$504) -> 9000
B4: =IF(Budget!A8="","",Budget!A8) -> Catering & bar | C4: =N(Budget!E8) -> 7500 | D4: =SUMPRODUCT((ISNUMBER(Payments!$A$5:$A$504)*ISNUMBER(MATCH(Payments!$B$5:$B$504,Lists!$A$2:$A$21,0))*(((Payments!$C$5:$C$504="")+ISNUMBER(MATCH(Payments!$C$5:$C$504,Lists!$C$2:$C$41,0)))>0)*ISNUMBER(Payments!$E$5:$E$504)*(((Payments!$F$5:$F$504="Paid")+(Payments!$F$5:$F$504="Owed"))>0)*(((Payments!$G$5:$G$504="")+ISNUMBER(Payments!$G$5:$G$504))>0))*(Payments!$B$5:$B$504=Lists!$A$3),Payments!$E$5:$E$504) -> 0 | E4: =SUMPRODUCT((ISNUMBER(Payments!$A$5:$A$504)*ISNUMBER(MATCH(Payments!$B$5:$B$504,Lists!$A$2:$A$21,0))*(((Payments!$C$5:$C$504="")+ISNUMBER(MATCH(Payments!$C$5:$C$504,Lists!$C$2:$C$41,0)))>0)*ISNUMBER(Payments!$E$5:$E$504)*(((Payments!$F$5:$F$504="Paid")+(Payments!$F$5:$F$504="Owed"))>0)*(((Payments!$G$5:$G$504="")+ISNUMBER(Payments!$G$5:$G$504))>0))*(Payments!$B$5:$B$504=Lists!$A$3)*(Payments!$F$5:$F$504="Paid"),Payments!$E$5:$E$504) -> 0 | F4: =SUMPRODUCT((ISNUMBER(Payments!$A$5:$A$504)*ISNUMBER(MATCH(Payments!$B$5:$B$504,Lists!$A$2:$A$21,0))*(((Payments!$C$5:$C$504="")+ISNUMBER(MATCH(Payments!$C$5:$C$504,Lists!$C$2:$C$41,0)))>0)*ISNUMBER(Payments!$E$5:$E$504)*(((Payments!$F$5:$F$504="Paid")+(Payments!$F$5:$F$504="Owed"))>0)*(((Payments!$G$5:$G$504="")+ISNUMBER(Payments!$G$5:$G$504))>0))*(Payments!$B$5:$B$504=Lists!$A$3)*(Payments!$F$5:$F$504="Owed"),Payments!$E$5:$E$504) -> 0
B5: =IF(Budget!A9="","",Budget!A9) -> Photography | C5: =N(Budget!E9) -> 3000 | D5: =SUMPRODUCT((ISNUMBER(Payments!$A$5:$A$504)*ISNUMBER(MATCH(Payments!$B$5:$B$504,Lists!$A$2:$A$21,0))*(((Payments!$C$5:$C$504="")+ISNUMBER(MATCH(Payments!$C$5:$C$504,Lists!$C$2:$C$41,0)))>0)*ISNUMBER(Payments!$E$5:$E$504)*(((Payments!$F$5:$F$504="Paid")+(Payments!$F$5:$F$504="Owed"))>0)*(((Payments!$G$5:$G$504="")+ISNUMBER(Payments!$G$5:$G$504))>0))*(Payments!$B$5:$B$504=Lists!$A$4),Payments!$E$5:$E$504) -> 0 | E5: =SUMPRODUCT((ISNUMBER(Payments!$A$5:$A$504)*ISNUMBER(MATCH(Payments!$B$5:$B$504,Lists!$A$2:$A$21,0))*(((Payments!$C$5:$C$504="")+ISNUMBER(MATCH(Payments!$C$5:$C$504,Lists!$C$2:$C$41,0)))>0)*ISNUMBER(Payments!$E$5:$E$504)*(((Payments!$F$5:$F$504="Paid")+(Payments!$F$5:$F$504="Owed"))>0)*(((Payments!$G$5:$G$504="")+ISNUMBER(Payments!$G$5:$G$504))>0))*(Payments!$B$5:$B$504=Lists!$A$4)*(Payments!$F$5:$F$504="Paid"),Payments!$E$5:$E$504) -> 0 | F5: =SUMPRODUCT((ISNUMBER(Payments!$A$5:$A$504)*ISNUMBER(MATCH(Payments!$B$5:$B$504,Lists!$A$2:$A$21,0))*(((Payments!$C$5:$C$504="")+ISNUMBER(MATCH(Payments!$C$5:$C$504,Lists!$C$2:$C$41,0)))>0)*ISNUMBER(Payments!$E$5:$E$504)*(((Payments!$F$5:$F$504="Paid")+(Payments!$F$5:$F$504="Owed"))>0)*(((Payments!$G$5:$G$504="")+ISNUMBER(Payments!$G$5:$G$504))>0))*(Payments!$B$5:$B$504=Lists!$A$4)*(Payments!$F$5:$F$504="Owed"),Payments!$E$5:$E$504) -> 0
B6: =IF(Budget!A10="","",Budget!A10) -> Videography | C6: =N(Budget!E10) -> 1200 | D6: =SUMPRODUCT((ISNUMBER(Payments!$A$5:$A$504)*ISNUMBER(MATCH(Payments!$B$5:$B$504,Lists!$A$2:$A$21,0))*(((Payments!$C$5:$C$504="")+ISNUMBER(MATCH(Payments!$C$5:$C$504,Lists!$C$2:$C$41,0)))>0)*ISNUMBER(Payments!$E$5:$E$504)*(((Payments!$F$5:$F$504="Paid")+(Payments!$F$5:$F$504="Owed"))>0)*(((Payments!$G$5:$G$504="")+ISNUMBER(Payments!$G$5:$G$504))>0))*(Payments!$B$5:$B$504=Lists!$A$5),Payments!$E$5:$E$504) -> 0 | E6: =SUMPRODUCT((ISNUMBER(Payments!$A$5:$A$504)*ISNUMBER(MATCH(Payments!$B$5:$B$504,Lists!$A$2:$A$21,0))*(((Payments!$C$5:$C$504="")+ISNUMBER(MATCH(Payments!$C$5:$C$504,Lists!$C$2:$C$41,0)))>0)*ISNUMBER(Payments!$E$5:$E$504)*(((Payments!$F$5:$F$504="Paid")+(Payments!$F$5:$F$504="Owed"))>0)*(((Payments!$G$5:$G$504="")+ISNUMBER(Payments!$G$5:$G$504))>0))*(Payments!$B$5:$B$504=Lists!$A$5)*(Payments!$F$5:$F$504="Paid"),Payments!$E$5:$E$504) -> 0 | F6: =SUMPRODUCT((ISNUMBER(Payments!$A$5:$A$504)*ISNUMBER(MATCH(Payments!$B$5:$B$504,Lists!$A$2:$A$21,0))*(((Payments!$C$5:$C$504="")+ISNUMBER(MATCH(Payments!$C$5:$C$504,Lists!$C$2:$C$41,0)))>0)*ISNUMBER(Payments!$E$5:$E$504)*(((Payments!$F$5:$F$504="Paid")+(Payments!$F$5:$F$504="Owed"))>0)*(((Payments!$G$5:$G$504="")+ISNUMBER(Payments!$G$5:$G$504))>0))*(Payments!$B$5:$B$504=Lists!$A$5)*(Payments!$F$5:$F$504="Owed"),Payments!$E$5:$E$504) -> 0
B7: =IF(Budget!A11="","",Budget!A11) -> Attire | C7: =N(Budget!E11) -> 1800 | D7: =SUMPRODUCT((ISNUMBER(Payments!$A$5:$A$504)*ISNUMBER(MATCH(Payments!$B$5:$B$504,Lists!$A$2:$A$21,0))*(((Payments!$C$5:$C$504="")+ISNUMBER(MATCH(Payments!$C$5:$C$504,Lists!$C$2:$C$41,0)))>0)*ISNUMBER(Payments!$E$5:$E$504)*(((Payments!$F$5:$F$504="Paid")+(Payments!$F$5:$F$504="Owed"))>0)*(((Payments!$G$5:$G$504="")+ISNUMBER(Payments!$G$5:$G$504))>0))*(Payments!$B$5:$B$504=Lists!$A$6),Payments!$E$5:$E$504) -> 0 | E7: =SUMPRODUCT((ISNUMBER(Payments!$A$5:$A$504)*ISNUMBER(MATCH(Payments!$B$5:$B$504,Lists!$A$2:$A$21,0))*(((Payments!$C$5:$C$504="")+ISNUMBER(MATCH(Payments!$C$5:$C$504,Lists!$C$2:$C$41,0)))>0)*ISNUMBER(Payments!$E$5:$E$504)*(((Payments!$F$5:$F$504="Paid")+(Payments!$F$5:$F$504="Owed"))>0)*(((Payments!$G$5:$G$504="")+ISNUMBER(Payments!$G$5:$G$504))>0))*(Payments!$B$5:$B$504=Lists!$A$6)*(Payments!$F$5:$F$504="Paid"),Payments!$E$5:$E$504) -> 0 | F7: =SUMPRODUCT((ISNUMBER(Payments!$A$5:$A$504)*ISNUMBER(MATCH(Payments!$B$5:$B$504,Lists!$A$2:$A$21,0))*(((Payments!$C$5:$C$504="")+ISNUMBER(MATCH(Payments!$C$5:$C$504,Lists!$C$2:$C$41,0)))>0)*ISNUMBER(Payments!$E$5:$E$504)*(((Payments!$F$5:$F$504="Paid")+(Payments!$F$5:$F$504="Owed"))>0)*(((Payments!$G$5:$G$504="")+ISNUMBER(Payments!$G$5:$G$504))>0))*(Payments!$B$5:$B$504=Lists!$A$6)*(Payments!$F$5:$F$504="Owed"),Payments!$E$5:$E$504) -> 0
B8: =IF(Budget!A12="","",Budget!A12) -> Hair & makeup | C8: =N(Budget!E12) -> 600 | D8: =SUMPRODUCT((ISNUMBER(Payments!$A$5:$A$504)*ISNUMBER(MATCH(Payments!$B$5:$B$504,Lists!$A$2:$A$21,0))*(((Payments!$C$5:$C$504="")+ISNUMBER(MATCH(Payments!$C$5:$C$504,Lists!$C$2:$C$41,0)))>0)*ISNUMBER(Payments!$E$5:$E$504)*(((Payments!$F$5:$F$504="Paid")+(Payments!$F$5:$F$504="Owed"))>0)*(((Payments!$G$5:$G$504="")+ISNUMBER(Payments!$G$5:$G$504))>0))*(Payments!$B$5:$B$504=Lists!$A$7),Payments!$E$5:$E$504) -> 0 | E8: =SUMPRODUCT((ISNUMBER(Payments!$A$5:$A$504)*ISNUMBER(MATCH(Payments!$B$5:$B$504,Lists!$A$2:$A$21,0))*(((Payments!$C$5:$C$504="")+ISNUMBER(MATCH(Payments!$C$5:$C$504,Lists!$C$2:$C$41,0)))>0)*ISNUMBER(Payments!$E$5:$E$504)*(((Payments!$F$5:$F$504="Paid")+(Payments!$F$5:$F$504="Owed"))>0)*(((Payments!$G$5:$G$504="")+ISNUMBER(Payments!$G$5:$G$504))>0))*(Payments!$B$5:$B$504=Lists!$A$7)*(Payments!$F$5:$F$504="Paid"),Payments!$E$5:$E$504) -> 0 | F8: =SUMPRODUCT((ISNUMBER(Payments!$A$5:$A$504)*ISNUMBER(MATCH(Payments!$B$5:$B$504,Lists!$A$2:$A$21,0))*(((Payments!$C$5:$C$504="")+ISNUMBER(MATCH(Payments!$C$5:$C$504,Lists!$C$2:$C$41,0)))>0)*ISNUMBER(Payments!$E$5:$E$504)*(((Payments!$F$5:$F$504="Paid")+(Payments!$F$5:$F$504="Owed"))>0)*(((Payments!$G$5:$G$504="")+ISNUMBER(Payments!$G$5:$G$504))>0))*(Payments!$B$5:$B$504=Lists!$A$7)*(Payments!$F$5:$F$504="Owed"),Payments!$E$5:$E$504) -> 0
B9: =IF(Budget!A13="","",Budget!A13) -> Flowers & decor | C9: =N(Budget!E13) -> 2400 | D9: =SUMPRODUCT((ISNUMBER(Payments!$A$5:$A$504)*ISNUMBER(MATCH(Payments!$B$5:$B$504,Lists!$A$2:$A$21,0))*(((Payments!$C$5:$C$504="")+ISNUMBER(MATCH(Payments!$C$5:$C$504,Lists!$C$2:$C$41,0)))>0)*ISNUMBER(Payments!$E$5:$E$504)*(((Payments!$F$5:$F$504="Paid")+(Payments!$F$5:$F$504="Owed"))>0)*(((Payments!$G$5:$G$504="")+ISNUMBER(Payments!$G$5:$G$504))>0))*(Payments!$B$5:$B$504=Lists!$A$8),Payments!$E$5:$E$504) -> 0 | E9: =SUMPRODUCT((ISNUMBER(Payments!$A$5:$A$504)*ISNUMBER(MATCH(Payments!$B$5:$B$504,Lists!$A$2:$A$21,0))*(((Payments!$C$5:$C$504="")+ISNUMBER(MATCH(Payments!$C$5:$C$504,Lists!$C$2:$C$41,0)))>0)*ISNUMBER(Payments!$E$5:$E$504)*(((Payments!$F$5:$F$504="Paid")+(Payments!$F$5:$F$504="Owed"))>0)*(((Payments!$G$5:$G$504="")+ISNUMBER(Payments!$G$5:$G$504))>0))*(Payments!$B$5:$B$504=Lists!$A$8)*(Payments!$F$5:$F$504="Paid"),Payments!$E$5:$E$504) -> 0 | F9: =SUMPRODUCT((ISNUMBER(Payments!$A$5:$A$504)*ISNUMBER(MATCH(Payments!$B$5:$B$504,Lists!$A$2:$A$21,0))*(((Payments!$C$5:$C$504="")+ISNUMBER(MATCH(Payments!$C$5:$C$504,Lists!$C$2:$C$41,0)))>0)*ISNUMBER(Payments!$E$5:$E$504)*(((Payments!$F$5:$F$504="Paid")+(Payments!$F$5:$F$504="Owed"))>0)*(((Payments!$G$5:$G$504="")+ISNUMBER(Payments!$G$5:$G$504))>0))*(Payments!$B$5:$B$504=Lists!$A$8)*(Payments!$F$5:$F$504="Owed"),Payments!$E$5:$E$504) -> 0
B10: =IF(Budget!A14="","",Budget!A14) -> Music & entertainment | C10: =N(Budget!E14) -> 1500 | D10: =SUMPRODUCT((ISNUMBER(Payments!$A$5:$A$504)*ISNUMBER(MATCH(Payments!$B$5:$B$504,Lists!$A$2:$A$21,0))*(((Payments!$C$5:$C$504="")+ISNUMBER(MATCH(Payments!$C$5:$C$504,Lists!$C$2:$C$41,0)))>0)*ISNUMBER(Payments!$E$5:$E$504)*(((Payments!$F$5:$F$504="Paid")+(Payments!$F$5:$F$504="Owed"))>0)*(((Payments!$G$5:$G$504="")+ISNUMBER(Payments!$G$5:$G$504))>0))*(Payments!$B$5:$B$504=Lists!$A$9),Payments!$E$5:$E$504) -> 0 | E10: =SUMPRODUCT((ISNUMBER(Payments!$A$5:$A$504)*ISNUMBER(MATCH(Payments!$B$5:$B$504,Lists!$A$2:$A$21,0))*(((Payments!$C$5:$C$504="")+ISNUMBER(MATCH(Payments!$C$5:$C$504,Lists!$C$2:$C$41,0)))>0)*ISNUMBER(Payments!$E$5:$E$504)*(((Payments!$F$5:$F$504="Paid")+(Payments!$F$5:$F$504="Owed"))>0)*(((Payments!$G$5:$G$504="")+ISNUMBER(Payments!$G$5:$G$504))>0))*(Payments!$B$5:$B$504=Lists!$A$9)*(Payments!$F$5:$F$504="Paid"),Payments!$E$5:$E$504) -> 0 | F10: =SUMPRODUCT((ISNUMBER(Payments!$A$5:$A$504)*ISNUMBER(MATCH(Payments!$B$5:$B$504,Lists!$A$2:$A$21,0))*(((Payments!$C$5:$C$504="")+ISNUMBER(MATCH(Payments!$C$5:$C$504,Lists!$C$2:$C$41,0)))>0)*ISNUMBER(Payments!$E$5:$E$504)*(((Payments!$F$5:$F$504="Paid")+(Payments!$F$5:$F$504="Owed"))>0)*(((Payments!$G$5:$G$504="")+ISNUMBER(Payments!$G$5:$G$504))>0))*(Payments!$B$5:$B$504=Lists!$A$9)*(Payments!$F$5:$F$504="Owed"),Payments!$E$5:$E$504) -> 0
