Workbook

Sheet Start Here
B2: Monthly Budget Planner
B3: Budget, spending log, 12-month overview, bill tracker and savings goals in one workbook. Works in Excel and Google Sheets.
B5: QUICK START (10 minutes)
B6: 1. 'Budget': 27 ready-made categories in 5 groups (Income, Bills, Living, Debt, Savings). Type what you plan per month for each.
B7: Rename, delete or add categories (3 spare rows). Every category needs a group.
B8: 2. 'Transactions': log money in and out: date, category, amount. Paychecks go under an Income category.
B9: Money moved to savings goes under a Savings category. Refund? Enter a negative amount in that category.
B10: 3. 'Dashboard': pick the year and month at the top. Every tile and chart switches to that month.
B11: 4. 'Bills': list your regular bills with the due day. Mark 'Yes' in the month column when paid; unpaid bills past their day turn orange.
B12: 5. 'Savings Goals': set a target and target date. Link a Savings category and money you log there counts toward the goal.
B13: 6. 'Monthly Overview': every category, every month of the year, with totals and averages. Nothing to type here.
B14: 7. Red cells mean a row needs fixing (text in an amount, a date that isn't a date, a category that isn't on your list).
... B30: Questions or a formula not behaving? Email nora@qnsai.com. Made by Nora Studio.

Sheet Dashboard
B1: Budget Dashboard
B3: Year: | C3: 2026 | D3: Month: | E3: January | G3: =IF(Calc!C4=0,"Year is not valid (type e.g. 2026). ","")&IF(Calc!C3=0,"Pick a month from the list. ","")&IF((Transactions!D2+Budget!H2+Bills!P2+'Savings Goals'!J2)>0,(Transactions!D2+Budget!H2+Bills!P2+'Savings Goals'!J2)&" row(s) need fixing - see red cells","Updates automatically from every tab") -> Updates automatically from every tab | V3: Chart data (do not edit)
V4: Category | W4: Budget | X4: Spent
B5: INCOME THIS MONTH | G5: SPENT THIS MONTH | L5: LEFT OVER THIS MONTH | V5: =Calc!B75 -> Rent / mortgage | W5: =Calc!E75 -> 1450 | X5: =Calc!F75 -> 1450
B6: =Calc!C6 -> 4600 | G6: =Calc!C10 -> 1562.4 | L6: =Calc!C12 -> 2737.6 | V6: =Calc!B76 -> Groceries | W6: =Calc!E76 -> 520 | X6: =Calc!F76 -> 112.4
V7: =Calc!B77 -> Car loan | W7: =Calc!E77 -> 320 | X7: =Calc!F77 -> 0
V8: =Calc!B78 -> Transportation & gas | W8: =Calc!E78 -> 200 | X8: =Calc!F78 -> 0
B9: SAVED THIS MONTH | G9: SAVINGS RATE | L9: BUDGET LEFT TO SPEND | V9: =Calc!B79 -> Dining out | W9: =Calc!E79 -> 180 | X9: =Calc!F79 -> 0
B10: =Calc!C11 -> 300 | G10: =IF(Calc!C6>0,Calc!C11/Calc!C6,0) -> 0.065217391 | L10: =Calc!C20 -> 2312.6 | V10: =Calc!B80 -> Utilities | W10: =Calc!E80 -> 160 | X10: =Calc!F80 -> 0
V11: =Calc!B81 -> Credit card | W11: =Calc!E81 -> 150 | X11: =Calc!F81 -> 0
V12: =Calc!B82 -> Insurance | W12: =Calc!E82 -> 140 | X12: =Calc!F82 -> 0
B13: INCOME THIS YEAR | G13: SPENT THIS YEAR | L13: LEFT OVER THIS YEAR | V13: =Calc!B83 -> Shopping | W13: =Calc!E83 -> 120 | X13: =Calc!F83 -> 0
B14: =Calc!C14 -> 4600 | G14: =Calc!C15 -> 1562.4 | L14: =Calc!C17 -> 2737.6 | V14: =Calc!B84 -> Phone & internet | W14: =Calc!E84 -> 110 | X14: =Calc!F84 -> 0
B17: BILLS STILL DUE THIS MONTH | G17: BIGGEST SPEND THIS MONTH | L17: SAVINGS GOALS PROGRESS | V17: Month | W17: Income | X17: Spent | Y17: Saved
B18: =Calc!C22 -> 65 | G18: =Calc!C86 -> Rent / mortgage | L18: =Calc!C27 -> 0.3 | V18: Jan | W18: ='Monthly Overview'!C38 -> 4600 | X18: ='Monthly Overview'!C42 -> 1562.4 | Y18: ='Monthly Overview'!C43 -> 300
V19: Feb | W19: ='Monthly Overview'!D38 -> 0 | X19: ='Monthly Overview'!D42 -> 0 | Y19: ='Monthly Overview'!D43 -> 0
V20: Mar | W20: ='Monthly Overview'!E38 -> 0 | X20: ='Monthly Overview'!E42 -> 0 | Y20: ='Monthly Overview'!E43 -> 0
B21: ="Transactions this month: "&Calc!C28&" | Bills paid this month: "&(Calc!C24-Calc!C23)&" of "&Calc!C24&" | Spending budget this month: "&TEXT(Calc!C19,"$#,##0") -> Transactions this month: 5 | Bills paid this month: 1 of 2 | Spending budget this month: $3,875 | V21: Apr | W21: ='Monthly Overview'!F38 -> 0 | X21: ='Monthly Overview'!F42 -> 0 | Y21: ='Monthly Overview'!F43 -> 0
B22: Spent = bills + living + debt. Left over = income - spent - saved. Savings rate = saved / income. | V22: May | W22: ='Monthly Overview'!G38 -> 0 | X22: ='Monthly Overview'!G42 -> 0 | Y22: ='Monthly Overview'!G43 -> 0
V23: Jun | W23: ='Monthly Overview'!H38 -> 0 | X23: ='Monthly Overview'!H42 -> 0 | Y23: ='Monthly Overview'!H43 -> 0
V24: Jul | W24: ='Monthly Overview'!I38 -> 0 | X24: ='Monthly Overview'!I42 -> 0 | Y24: ='Monthly Overview'!I43 -> 0
V25: Aug | W25: ='Monthly Overview'!J38 -> 0 | X25: ='Monthly Overview'!J42 -> 0 | Y25: ='Monthly Overview'!J43 -> 0
V26: Sep | W26: ='Monthly Overview'!K38 -> 0 | X26: ='Monthly Overview'!K42 -> 0 | Y26: ='Monthly Overview'!K43 -> 0
V27: Oct | W27: ='Monthly Overview'!L38 -> 0 | X27: ='Monthly Overview'!L42 -> 0 | Y27: ='Monthly Overview'!L43 -> 0
V28: Nov | W28: ='Monthly Overview'!M38 -> 0 | X28: ='Monthly Overview'!M42 -> 0 | Y28: ='Monthly Overview'!M43 -> 0
V29: Dec | W29: ='Monthly Overview'!N38 -> 0 | X29: ='Monthly Overview'!N42 -> 0 | Y29: ='Monthly Overview'!N43 -> 0
V32: Where it went | W32: Amount
V33: Bills | W33: =MAX(0,Calc!C7) -> 1450
V34: Living | W34: =MAX(0,Calc!C8) -> 112.4
V35: Debt | W35: =MAX(0,Calc!C9) -> 0
V36: Saved | W36: =MAX(0,Calc!C11) -> 300
V37: Left over | W37: =MAX(0,Calc!C12) -> 2737.6
V40: Goal | W40: Saved | X40: Left to save
V41: =Calc!B108 -> EXAMPLE: Emergency fund | W41: =Calc!E108 -> 1500 | X41: =Calc!F108 -> 3500
V42: =Calc!B109 | W42: =Calc!E109 -> 0 | X42: =Calc!F109 -> 0
V43: =Calc!B110 | W43: =Calc!E110 -> 0 | X43: =Calc!F110 -> 0
V44: =Calc!B111 | W44: =Calc!E111 -> 0 | X44: =Calc!F111 -> 0
V45: =Calc!B112 | W45: =Calc!E112 -> 0 | X45: =Calc!F112 -> 0
V46: =Calc!B113 | W46: =Calc!E113 -> 0 | X46: =Calc!F113 -> 0

Sheet Budget
A1: Budget
A2: What you plan to earn, spend and save each month. Actuals come from the Transactions tab. | G2: Rows to fix: | H2: =SUMPRODUCT((((Budget!$A$7:$A$36<>"")+(Budget!$B$7:$B$36<>"")+(Budget!$C$7:$C$36<>""))>0)*(((Budget!$A$7:$A$36<>"")*ISNUMBER(MATCH(Budget!$B$7:$B$36,Lists!$C$2:$C$6,0))*(((Budget!$C$7:$C$36="")+ISNUMBER(Budget!$C$7:$C$36))>0)*(Budget!$C$7:$C$36>=0))=0)) -> 0
A3: Red cell = something to fix. Orange = over budget (or income below plan).
A4: Planned income | B4: =SUMPRODUCT(((Budget!$A$7:$A$36<>"")*ISNUMBER(MATCH(Budget!$B$7:$B$36,Lists!$C$2:$C$6,0))*(((Budget!$C$7:$C$36="")+ISNUMBER(Budget!$C$7:$C$36))>0)*(Budget!$C$7:$C$36>=0))*(Budget!$B$7:$B$36="Income"),Budget!$C$7:$C$36) -> 5000 | C4: Planned out | D4: =SUMPRODUCT(((Budget!$A$7:$A$36<>"")*ISNUMBER(MATCH(Budget!$B$7:$B$36,Lists!$C$2:$C$6,0))*(((Budget!$C$7:$C$36="")+ISNUMBER(Budget!$C$7:$C$36))>0)*(Budget!$C$7:$C$36>=0))*(Budget!$B$7:$B$36<>"Income"),Budget!$C$7:$C$36) -> 4525 | E4: Left over | F4: =B4-D4 -> 475 | G4: (per month)
A6: Category | B6: Group | C6: Monthly budget | D6: This month | E6: Difference (+ = good) | F6: This year | G6: Yearly budget | H6: % of year used
A7: Paycheck | B7: Income | C7: 4600 | D7: =IF(A7="","",IF(Calc!$C$3=0,0,INDEX('Monthly Overview'!C6:N6,Calc!$C$3))) -> 4600 | E7: =IF(A7="","",IF(B7="Income",D7-N(C7),N(C7)-D7)) -> 0 | F7: =IF(A7="","",'Monthly Overview'!O6) -> 4600 | G7: =IF(A7="","",N(C7)*12) -> 55200 | H7: =IF(OR(A7="",N(G7)=0),"",F7/G7) -> 0.083333333
A8: Side income | B8: Income | C8: 400 | D8: =IF(A8="","",IF(Calc!$C$3=0,0,INDEX('Monthly Overview'!C7:N7,Calc!$C$3))) -> 0 | E8: =IF(A8="","",IF(B8="Income",D8-N(C8),N(C8)-D8)) -> -400 | F8: =IF(A8="","",'Monthly Overview'!O7) -> 0 | G8: =IF(A8="","",N(C8)*12) -> 4800 | H8: =IF(OR(A8="",N(G8)=0),"",F8/G8) -> 0
A9: Other income | B9: Income | C9: 0 | D9: =IF(A9="","",IF(Calc!$C$3=0,0,INDEX('Monthly Overview'!C8:N8,Calc!$C$3))) -> 0 | E9: =IF(A9="","",IF(B9="Income",D9-N(C9),N(C9)-D9)) -> 0 | F9: =IF(A9="","",'Monthly Overview'!O8) -> 0 | G9: =IF(A9="","",N(C9)*12) -> 0 | H9: =IF(OR(A9="",N(G9)=0),"",F9/G9)
A10: Rent / mortgage | B10: Bills | C10: 1450 | D10: =IF(A10="","",IF(Calc!$C$3=0,0,INDEX('Monthly Overview'!C9:N9,Calc!$C$3))) -> 1450 | E10: =IF(A10="","",IF(B10="Income",D10-N(C10),N(C10)-D10)) -> 0 | F10: =IF(A10="","",'Monthly Overview'!O9) -> 1450 | G10: =IF(A10="","",N(C10)*12) -> 17400 | H10: =IF(OR(A10="",N(G10)=0),"",F10/G10) -> 0.083333333
A11: Utilities | B11: Bills | C11: 160 | D11: =IF(A11="","",IF(Calc!$C$3=0,0,INDEX('Monthly Overview'!C10:N10,Calc!$C$3))) -> 0 | E11: =IF(A11="","",IF(B11="Income",D11-N(C11),N(C11)-D11)) -> 160 | F11: =IF(A11="","",'Monthly Overview'!O10) -> 0 | G11: =IF(A11="","",N(C11)*12) -> 1920 | H11: =IF(OR(A11="",N(G11)=0),"",F11/G11) -> 0
A12: Phone & internet | B12: Bills | C12: 110 | D12: =IF(A12="","",IF(Calc!$C$3=0,0,INDEX('Monthly Overview'!C11:N11,Calc!$C$3))) -> 0 | E12: =IF(A12="","",IF(B12="Income",D12-N(C12),N(C12)-D12)) -> 110 | F12: =IF(A12="","",'Monthly Overview'!O11) -> 0 | G12: =IF(A12="","",N(C12)*12) -> 1320 | H12: =IF(OR(A12="",N(G12)=0),"",F12/G12) -> 0
A13: Insurance | B13: Bills | C13: 140 | D13: =IF(A13="","",IF(Calc!$C$3=0,0,INDEX('Monthly Overview'!C12:N12,Calc!$C$3))) -> 0 | E13: =IF(A13="","",IF(B13="Income",D13-N(C13),N(C13)-D13)) -> 140 | F13: =IF(A13="","",'Monthly Overview'!O12) -> 0 | G13: =IF(A13="","",N(C13)*12) -> 1680 | H13: =IF(OR(A13="",N(G13)=0),"",F13/G13) -> 0
A14: Subscriptions | B14: Bills | C14: 45 | D14: =IF(A14="","",IF(Calc!$C$3=0,0,INDEX('Monthly Overview'!C13:N13,Calc!$C$3))) -> 0 | E14: =IF(A14="","",IF(B14="Income",D14-N(C14),N(C14)-D14)) -> 45 | F14: =IF(A14="","",'Monthly Overview'!O13) -> 0 | G14: =IF(A14="","",N(C14)*12) -> 540 | H14: =IF(OR(A14="",N(G14)=0),"",F14/G14) -> 0
A15: Groceries | B15: Living | C15: 520 | D15: =IF(A15="","",IF(Calc!$C$3=0,0,INDEX('Monthly Overview'!C14:N14,Calc!$C$3))) -> 112.4 | E15: =IF(A15="","",IF(B15="Income",D15-N(C15),N(C15)-D15)) -> 407.6 | F15: =IF(A15="","",'Monthly Overview'!O14) -> 112.4 | G15: =IF(A15="","",N(C15)*12) -> 6240 | H15: =IF(OR(A15="",N(G15)=0),"",F15/G15) -> 0.018012821
A16: Dining out | B16: Living | C16: 180 | D16: =IF(A16="","",IF(Calc!$C$3=0,0,INDEX('Monthly Overview'!C15:N15,Calc!$C$3))) -> 0 | E16: =IF(A16="","",IF(B16="Income",D16-N(C16),N(C16)-D16)) -> 180 | F16: =IF(A16="","",'Monthly Overview'!O15) -> 0 | G16: =IF(A16="","",N(C16)*12) -> 2160 | H16: =IF(OR(A16="",N(G16)=0),"",F16/G16) -> 0
A17: Transportation & gas | B17: Living | C17: 200 | D17: =IF(A17="","",IF(Calc!$C$3=0,0,INDEX('Monthly Overview'!C16:N16,Calc!$C$3))) -> 0 | E17: =IF(A17="","",IF(B17="Income",D17-N(C17),N(C17)-D17)) -> 200 | F17: =IF(A17="","",'Monthly Overview'!O16) -> 0 | G17: =IF(A17="","",N(C17)*12) -> 2400 | H17: =IF(OR(A17="",N(G17)=0),"",F17/G17) -> 0
A18: Health | B18: Living | C18: 60 | D18: =IF(A18="","",IF(Calc!$C$3=0,0,INDEX('Monthly Overview'!C17:N17,Calc!$C$3))) -> 0 | E18: =IF(A18="","",IF(B18="Income",D18-N(C18),N(C18)-D18)) -> 60 | F18: =IF(A18="","",'Monthly Overview'!O17) -> 0 | G18: =IF(A18="","",N(C18)*12) -> 720 | H18: =IF(OR(A18="",N(G18)=0),"",F18/G18) -> 0
... A33: Sinking funds | B33: Savings | C33: 100 | D33: =IF(A33="","",IF(Calc!$C$3=0,0,INDEX('Monthly Overview'!C32:N32,Calc!$C$3))) -> 0 | E33: =IF(A33="","",IF(B33="Income",D33-N(C33),N(C33)-D33)) -> 100 | F33: =IF(A33="","",'Monthly Overview'!O32) -> 0 | G33: =IF(A33="","",N(C33)*12) -> 1200 | H33: =IF(OR(A33="",N(G33)=0),"",F33/G33) -> 0
D34: =IF(A34="","",IF(Calc!$C$3=0,0,INDEX('Monthly Overview'!C33:N33,Calc!$C$3))) | E34: =IF(A34="","",IF(B34="Income",D34-N(C34),N(C34)-D34)) | F34: =IF(A34="","",'Monthly Overview'!O33) | G34: =IF(A34="","",N(C34)*12) | H34: =IF(OR(A34="",N(G34)=0),"",F34/G34)
D35: =IF(A35="","",IF(Calc!$C$3=0,0,INDEX('Monthly Overview'!C34:N34,Calc!$C$3))) | E35: =IF(A35="","",IF(B35="Income",D35-N(C35),N(C35)-D35)) | F35: =IF(A35="","",'Monthly Overview'!O34) | G35: =IF(A35="","",N(C35)*12) | H35: =IF(OR(A35="",N(G35)=0),"",F35/G35)
D36: =IF(A36="","",IF(Calc!$C$3=0,0,INDEX('Monthly Overview'!C35:N35,Calc!$C$3))) | E36: =IF(A36="","",IF(B36="Income",D36-N(C36),N(C36)-D36)) | F36: =IF(A36="","",'Monthly Overview'!O35) | G36: =IF(A36="","",N(C36)*12) | H36: =IF(OR(A36="",N(G36)=0),"",F36/G36)
A37: Spending + saving total | C37: =SUMPRODUCT(((Budget!$A$7:$A$36<>"")*ISNUMBER(MATCH(Budget!$B$7:$B$36,Lists!$C$2:$C$6,0))*(((Budget!$C$7:$C$36="")+ISNUMBER(Budget!$C$7:$C$36))>0)*(Budget!$C$7:$C$36>=0))*(Budget!$B$7:$B$36<>"Income"),Budget!$C$7:$C$36) -> 4525 | D37: =SUMPRODUCT((Budget!$B$7:$B$36<>"Income")*(Budget!$A$7:$A$36<>""),D7:D36) -> 1862.4 | F37: =SUMPRODUCT((Budget!$B$7:$B$36<>"Income")*(Budget!$A$7:$A$36<>""),F7:F36) -> 1862.4
A39: Groups: Income (money in), Bills (fixed), Living (day to day), Debt (payments), Savings (money you set aside).
A40: Renaming a category? Rename it here first; transactions under the old name turn red until you pick the new name.

Sheet Transactions
A1: Transactions
A2: Money in and out. Pick the category; the group (income, bill, savings...) comes from the Budget tab. | C2: Rows to fix: | D2: =SUMPRODUCT((((Transactions!$A$5:$A$1504<>"")+(Transactions!$B$5:$B$1504<>"")+(Transactions!$C$5:$C$1504<>"")+(Transactions!$D$5:$D$1504<>""))>0)*((ISNUMBER(Transactions!$A$5:$A$1504)*ISNUMBER(MATCH(Transactions!$B$5:$B$1504,Lists!$A$2:$A$31,0))*ISNUMBER(Transactions!$D$5:$D$1504))=0)) -> 0
A3: Red cell = something to fix (row stays out of the totals). Refund? Enter a negative amount.
A4: Date | B4: Category | C4: Description | D4: Amount | E4: Account / notes (optional)
A5: 46024 | B5: Paycheck | C5: EXAMPLE: paycheck | D5: 2300
A6: 46038 | B6: Paycheck | C6: EXAMPLE: paycheck | D6: 2300
A7: 46025 | B7: Rent / mortgage | C7: EXAMPLE: January rent | D7: 1450
A8: 46031 | B8: Groceries | C8: EXAMPLE: weekly shop | D8: 112.4
A9: 46039 | B9: Emergency fund | C9: EXAMPLE: transfer to savings | D9: 300

Sheet Monthly Overview
A1: Monthly Overview
A2: =IF(Calc!$C$4=0,"Type a valid year on the Dashboard.","Every category, every month of "&Calc!$C$4&". Nothing to type here.") -> Every category, every month of 2026. Nothing to type here.
A5: Category | B5: Group | C5: Jan | D5: Feb | E5: Mar | F5: Apr | G5: May | H5: Jun | I5: Jul | J5: Aug | K5: Sep | L5: Oct | M5: Nov | N5: Dec | O5: Year total | P5: Avg / month
A6: =IF(Budget!A7="","",Budget!A7) -> Paycheck | B6: =IF(LEFT(Lists!$A$2,1)="[","",Budget!B7) -> Income | C6: =SUMPRODUCT(ISNUMBER(Transactions!$A$5:$A$1504)*ISNUMBER(MATCH(Transactions!$B$5:$B$1504,Lists!$A$2:$A$31,0))*ISNUMBER(Transactions!$D$5:$D$1504)*(Transactions!$B$5:$B$1504=Lists!$A$2)*(Transactions!$A$5:$A$1504>=DATE(Calc!$C$4,1,1))*(Transactions!$A$5:$A$1504<DATE(Calc!$C$4,2,1)),Transactions!$D$5:$D$1504) -> 4600 | D6: =SUMPRODUCT(ISNUMBER(Transactions!$A$5:$A$1504)*ISNUMBER(MATCH(Transactions!$B$5:$B$1504,Lists!$A$2:$A$31,0))*ISNUMBER(Transactions!$D$5:$D$1504)*(Transactions!$B$5:$B$1504=Lists!$A$2)*(Transactions!$A$5:$A$1504>=DATE(Calc!$C$4,2,1))*(Transactions!$A$5:$A$1504<DATE(Calc!$C$4,3,1)),Transactions!$D$5:$D$1504) -> 0 | E6: =SUMPRODUCT(ISNUMBER(Transactions!$A$5:$A$1504)*ISNUMBER(MATCH(Transactions!$B$5:$B$1504,Lists!$A$2:$A$31,0))*ISNUMBER(Transactions!$D$5:$D$1504)*(Transactions!$B$5:$B$1504=Lists!$A$2)*(Transactions!$A$5:$A$1504>=DATE(Calc!$C$4,3,1))*(Transactions!$A$5:$A$1504<DATE(Calc!$C$4,4,1)),Transactions!$D$5:$D$1504) -> 0 | F6: =SUMPRODUCT(ISNUMBER(Transactions!$A$5:$A$1504)*ISNUMBER(MATCH(Transactions!$B$5:$B$1504,Lists!$A$2:$A$31,0))*ISNUMBER(Transactions!$D$5:$D$1504)*(Transactions!$B$5:$B$1504=Lists!$A$2)*(Transactions!$A$5:$A$1504>=DATE(Calc!$C$4,4,1))*(Transactions!$A$5:$A$1504<DATE(Calc!$C$4,5,1)),Transactions!$D$5:$D$1504) -> 0 | G6: =SUMPRODUCT(ISNUMBER(Transactions!$A$5:$A$1504)*ISNUMBER(MATCH(Transactions!$B$5:$B$1504,Lists!$A$2:$A$31,0))*ISNUMBER(Transactions!$D$5:$D$1504)*(Transactions!$B$5:$B$1504=Lists!$A$2)*(Transactions!$A$5:$A$1504>=DATE(Calc!$C$4,5,1))*(Transactions!$A$5:$A$1504<DATE(Calc!$C$4,6,1)),Transactions!$D$5:$D$1504) -> 0 | H6: =SUMPRODUCT(ISNUMBER(Transactions!$A$5:$A$1504)*ISNUMBER(MATCH(Transactions!$B$5:$B$1504,Lists!$A$2:$A$31,0))*ISNUMBER(Transactions!$D$5:$D$1504)*(Transactions!$B$5:$B$1504=Lists!$A$2)*(Transactions!$A$5:$A$1504>=DATE(Calc!$C$4,6,1))*(Transactions!$A$5:$A$1504<DATE(Calc!$C$4,7,1)),Transactions!$D$5:$D$1504) -> 0 | I6: =SUMPRODUCT(ISNUMBER(Transactions!$A$5:$A$1504)*ISNUMBER(MATCH(Transactions!$B$5:$B$1504,Lists!$A$2:$A$31,0))*ISNUMBER(Transactions!$D$5:$D$1504)*(Transactions!$B$5:$B$1504=Lists!$A$2)*(Transactions!$A$5:$A$1504>=DATE(Calc!$C$4,7,1))*(Transactions!$A$5:$A$1504<DATE(Calc!$C$4,8,1)),Transactions!$D$5:$D$1504) -> 0 | J6: =SUMPRODUCT(ISNUMBER(Transactions!$A$5:$A$1504)*ISNUMBER(MATCH(Transactions!$B$5:$B$1504,Lists!$A$2:$A$31,0))*ISNUMBER(Transactions!$D$5:$D$1504)*(Transactions!$B$5:$B$1504=Lists!$A$2)*(Transactions!$A$5:$A$1504>=DATE(Calc!$C$4,8,1))*(Transactions!$A$5:$A$1504<DATE(Calc!$C$4,9,1)),Transactions!$D$5:$D$1504) -> 0 | K6: =SUMPRODUCT(ISNUMBER(Transactions!$A$5:$A$1504)*ISNUMBER(MATCH(Transactions!$B$5:$B$1504,Lists!$A$2:$A$31,0))*ISNUMBER(Transactions!$D$5:$D$1504)*(Transactions!$B$5:$B$1504=Lists!$A$2)*(Transactions!$A$5:$A$1504>=DATE(Calc!$C$4,9,1))*(Transactions!$A$5:$A$1504<DATE(Calc!$C$4,10,1)),Transactions!$D$5:$D$1504) -> 0 | L6: =SUMPRODUCT(ISNUMBER(Transactions!$A$5:$A$1504)*ISNUMBER(MATCH(Transactions!$B$5:$B$1504,Lists!$A$2:$A$31,0))*ISNUMBER(Transactions!$D$5:$D$1504)*(Transactions!$B$5:$B$1504=Lists!$A$2)*(Transactions!$A$5:$A$1504>=DATE(Calc!$C$4,10,1))*(Transactions!$A$5:$A$1504<DATE(Calc!$C$4,11,1)),Transactions!$D$5:$D$1504) -> 0 | M6: =SUMPRODUCT(ISNUMBER(Transactions!$A$5:$A$1504)*ISNUMBER(MATCH(Transactions!$B$5:$B$1504,Lists!$A$2:$A$31,0))*ISNUMBER(Transactions!$D$5:$D$1504)*(Transactions!$B$5:$B$1504=Lists!$A$2)*(Transactions!$A$5:$A$1504>=DATE(Calc!$C$4,11,1))*(Transactions!$A$5:$A$1504<DATE(Calc!$C$4,12,1)),Transactions!$D$5:$D$1504) -> 0 | N6: =SUMPRODUCT(ISNUMBER(Transactions!$A$5:$A$1504)*ISNUMBER(MATCH(Transactions!$B$5:$B$1504,Lists!$A$2:$A$31,0))*ISNUMBER(Transactions!$D$5:$D$1504)*(Transactions!$B$5:$B$1504=Lists!$A$2)*(Transactions!$A$5:$A$1504>=DATE(Calc!$C$4,12,1))*(Transactions!$A$5:$A$1504<DATE(Calc!$C$4,13,1)),Transactions!$D$5:$D$1504) -> 0 | O6: =SUM(C6:N6) -> 4600 | P6: =IF(Calc!$C$5=0,0,O6/Calc!$C$5) -> 4600
A7: =IF(Budget!A8="","",Budget!A8) -> Side income | B7: =IF(LEFT(Lists!$A$3,1)="[","",Budget!B8) -> Income | C7: =SUMPRODUCT(ISNUMBER(Transactions!$A$5:$A$1504)*ISNUMBER(MATCH(Transactions!$B$5:$B$1504,Lists!$A$2:$A$31,0))*ISNUMBER(Transactions!$D$5:$D$1504)*(Transactions!$B$5:$B$1504=Lists!$A$3)*(Transactions!$A$5:$A$1504>=DATE(Calc!$C$4,1,1))*(Transactions!$A$5:$A$1504<DATE(Calc!$C$4,2,1)),Transactions!$D$5:$D$1504) -> 0 | D7: =SUMPRODUCT(ISNUMBER(Transactions!$A$5:$A$1504)*ISNUMBER(MATCH(Transactions!$B$5:$B$1504,Lists!$A$2:$A$31,0))*ISNUMBER(Transactions!$D$5:$D$1504)*(Transactions!$B$5:$B$1504=Lists!$A$3)*(Transactions!$A$5:$A$1504>=DATE(Calc!$C$4,2,1))*(Transactions!$A$5:$A$1504<DATE(Calc!$C$4,3,1)),Transactions!$D$5:$D$1504) -> 0 | E7: =SUMPRODUCT(ISNUMBER(Transactions!$A$5:$A$1504)*ISNUMBER(MATCH(Transactions!$B$5:$B$1504,Lists!$A$2:$A$31,0))*ISNUMBER(Transactions!$D$5:$D$1504)*(Transactions!$B$5:$B$1504=Lists!$A$3)*(Transactions!$A$5:$A$1504>=DATE(Calc!$C$4,3,1))*(Transactions!$A$5:$A$1504<DATE(Calc!$C$4,4,1)),Transactions!$D$5:$D$1504) -> 0 | F7: =SUMPRODUCT(ISNUMBER(Transactions!$A$5:$A$1504)*ISNUMBER(MATCH(Transactions!$B$5:$B$1504,Lists!$A$2:$A$31,0))*ISNUMBER(Transactions!$D$5:$D$1504)*(Transactions!$B$5:$B$1504=Lists!$A$3)*(Transactions!$A$5:$A$1504>=DATE(Calc!$C$4,4,1))*(Transactions!$A$5:$A$1504<DATE(Calc!$C$4,5,1)),Transactions!$D$5:$D$1504) -> 0 | G7: =SUMPRODUCT(ISNUMBER(Transactions!$A$5:$A$1504)*ISNUMBER(MATCH(Transactions!$B$5:$B$1504,Lists!$A$2:$A$31,0))*ISNUMBER(Transactions!$D$5:$D$1504)*(Transactions!$B$5:$B$1504=Lists!$A$3)*(Transactions!$A$5:$A$1504>=DATE(Calc!$C$4,5,1))*(Transactions!$A$5:$A$1504<DATE(Calc!$C$4,6,1)),Transactions!$D$5:$D$1504) -> 0 | H7: =SUMPRODUCT(ISNUMBER(Transactions!$A$5:$A$1504)*ISNUMBER(MATCH(Transactions!$B$5:$B$1504,Lists!$A$2:$A$31,0))*ISNUMBER(Transactions!$D$5:$D$1504)*(Transactions!$B$5:$B$1504=Lists!$A$3)*(Transactions!$A$5:$A$1504>=DATE(Calc!$C$4,6,1))*(Transactions!$A$5:$A$1504<DATE(Calc!$C$4,7,1)),Transactions!$D$5:$D$1504) -> 0 | I7: =SUMPRODUCT(ISNUMBER(Transactions!$A$5:$A$1504)*ISNUMBER(MATCH(Transactions!$B$5:$B$1504,Lists!$A$2:$A$31,0))*ISNUMBER(Transactions!$D$5:$D$1504)*(Transactions!$B$5:$B$1504=Lists!$A$3)*(Transactions!$A$5:$A$1504>=DATE(Calc!$C$4,7,1))*(Transactions!$A$5:$A$1504<DATE(Calc!$C$4,8,1)),Transactions!$D$5:$D$1504) -> 0 | J7: =SUMPRODUCT(ISNUMBER(Transactions!$A$5:$A$1504)*ISNUMBER(MATCH(Transactions!$B$5:$B$1504,Lists!$A$2:$A$31,0))*ISNUMBER(Transactions!$D$5:$D$1504)*(Transactions!$B$5:$B$1504=Lists!$A$3)*(Transactions!$A$5:$A$1504>=DATE(Calc!$C$4,8,1))*(Transactions!$A$5:$A$1504<DATE(Calc!$C$4,9,1)),Transactions!$D$5:$D$1504) -> 0 | K7: =SUMPRODUCT(ISNUMBER(Transactions!$A$5:$A$1504)*ISNUMBER(MATCH(Transactions!$B$5:$B$1504,Lists!$A$2:$A$31,0))*ISNUMBER(Transactions!$D$5:$D$1504)*(Transactions!$B$5:$B$1504=Lists!$A$3)*(Transactions!$A$5:$A$1504>=DATE(Calc!$C$4,9,1))*(Transactions!$A$5:$A$1504<DATE(Calc!$C$4,10,1)),Transactions!$D$5:$D$1504) -> 0 | L7: =SUMPRODUCT(ISNUMBER(Transactions!$A$5:$A$1504)*ISNUMBER(MATCH(Transactions!$B$5:$B$1504,Lists!$A$2:$A$31,0))*ISNUMBER(Transactions!$D$5:$D$1504)*(Transactions!$B$5:$B$1504=Lists!$A$3)*(Transactions!$A$5:$A$1504>=DATE(Calc!$C$4,10,1))*(Transactions!$A$5:$A$1504<DATE(Calc!$C$4,11,1)),Transactions!$D$5:$D$1504) -> 0 | M7: =SUMPRODUCT(ISNUMBER(Transactions!$A$5:$A$1504)*ISNUMBER(MATCH(Transactions!$B$5:$B$1504,Lists!$A$2:$A$31,0))*ISNUMBER(Transactions!$D$5:$D$1504)*(Transactions!$B$5:$B$1504=Lists!$A$3)*(Transactions!$A$5:$A$1504>=DATE(Calc!$C$4,11,1))*(Transactions!$A$5:$A$1504<DATE(Calc!$C$4,12,1)),Transactions!$D$5:$D$1504) -> 0 | N7: =SUMPRODUCT(ISNUMBER(Transactions!$A$5:$A$1504)*ISNUMBER(MATCH(Transactions!$B$5:$B$1504,Lists!$A$2:$A$31,0))*ISNUMBER(Transactions!$D$5:$D$1504)*(Transactions!$B$5:$B$1504=Lists!$A$3)*(Transactions!$A$5:$A$1504>=DATE(Calc!$C$4,12,1))*(Transactions!$A$5:$A$1504<DATE(Calc!$C$4,13,1)),Transactions!$D$5:$D$1504) -> 0 | O7: =SUM(C7:N7) -> 0 | P7: =IF(Calc!$C$5=0,0,O7/Calc!$C$5) -> 0
A8: =IF(Budget!A9="","",Budget!A9) -> Other income | B8: =IF(LEFT(Lists!$A$4,1)="[","",Budget!B9) -> Income | C8: =SUMPRODUCT(ISNUMBER(Transactions!$A$5:$A$1504)*ISNUMBER(MATCH(Transactions!$B$5:$B$1504,Lists!$A$2:$A$31,0))*ISNUMBER(Transactions!$D$5:$D$1504)*(Transactions!$B$5:$B$1504=Lists!$A$4)*(Transactions!$A$5:$A$1504>=DATE(Calc!$C$4,1,1))*(Transactions!$A$5:$A$1504<DATE(Calc!$C$4,2,1)),Transactions!$D$5:$D$1504) -> 0 | D8: =SUMPRODUCT(ISNUMBER(Transactions!$A$5:$A$1504)*ISNUMBER(MATCH(Transactions!$B$5:$B$1504,Lists!$A$2:$A$31,0))*ISNUMBER(Transactions!$D$5:$D$1504)*(Transactions!$B$5:$B$1504=Lists!$A$4)*(Transactions!$A$5:$A$1504>=DATE(Calc!$C$4,2,1))*(Transactions!$A$5:$A$1504<DATE(Calc!$C$4,3,1)),Transactions!$D$5:$D$1504) -> 0 | E8: =SUMPRODUCT(ISNUMBER(Transactions!$A$5:$A$1504)*ISNUMBER(MATCH(Transactions!$B$5:$B$1504,Lists!$A$2:$A$31,0))*ISNUMBER(Transactions!$D$5:$D$1504)*(Transactions!$B$5:$B$1504=Lists!$A$4)*(Transactions!$A$5:$A$1504>=DATE(Calc!$C$4,3,1))*(Transactions!$A$5:$A$1504<DATE(Calc!$C$4,4,1)),Transactions!$D$5:$D$1504) -> 0 | F8: =SUMPRODUCT(ISNUMBER(Transactions!$A$5:$A$1504)*ISNUMBER(MATCH(Transactions!$B$5:$B$1504,Lists!$A$2:$A$31,0))*ISNUMBER(Transactions!$D$5:$D$1504)*(Transactions!$B$5:$B$1504=Lists!$A$4)*(Transactions!$A$5:$A$1504>=DATE(Calc!$C$4,4,1))*(Transactions!$A$5:$A$1504<DATE(Calc!$C$4,5,1)),Transactions!$D$5:$D$1504) -> 0 | G8: =SUMPRODUCT(ISNUMBER(Transactions!$A$5:$A$1504)*ISNUMBER(MATCH(Transactions!$B$5:$B$1504,Lists!$A$2:$A$31,0))*ISNUMBER(Transactions!$D$5:$D$1504)*(Transactions!$B$5:$B$1504=Lists!$A$4)*(Transactions!$A$5:$A$1504>=DATE(Calc!$C$4,5,1))*(Transactions!$A$5:$A$1504<DATE(Calc!$C$4,6,1)),Transactions!$D$5:$D$1504) -> 0 | H8: =SUMPRODUCT(ISNUMBER(Transactions!$A$5:$A$1504)*ISNUMBER(MATCH(Transactions!$B$5:$B$1504,Lists!$A$2:$A$31,0))*ISNUMBER(Transactions!$D$5:$D$1504)*(Transactions!$B$5:$B$1504=Lists!$A$4)*(Transactions!$A$5:$A$1504>=DATE(Calc!$C$4,6,1))*(Transactions!$A$5:$A$1504<DATE(Calc!$C$4,7,1)),Transactions!$D$5:$D$1504) -> 0 | I8: =SUMPRODUCT(ISNUMBER(Transactions!$A$5:$A$1504)*ISNUMBER(MATCH(Transactions!$B$5:$B$1504,Lists!$A$2:$A$31,0))*ISNUMBER(Transactions!$D$5:$D$1504)*(Transactions!$B$5:$B$1504=Lists!$A$4)*(Transactions!$A$5:$A$1504>=DATE(Calc!$C$4,7,1))*(Transactions!$A$5:$A$1504<DATE(Calc!$C$4,8,1)),Transactions!$D$5:$D$1504) -> 0 | J8: =SUMPRODUCT(ISNUMBER(Transactions!$A$5:$A$1504)*ISNUMBER(MATCH(Transactions!$B$5:$B$1504,Lists!$A$2:$A$31,0))*ISNUMBER(Transactions!$D$5:$D$1504)*(Transactions!$B$5:$B$1504=Lists!$A$4)*(Transactions!$A$5:$A$1504>=DATE(Calc!$C$4,8,1))*(Transactions!$A$5:$A$1504<DATE(Calc!$C$4,9,1)),Transactions!$D$5:$D$1504) -> 0 | K8: =SUMPRODUCT(ISNUMBER(Transactions!$A$5:$A$1504)*ISNUMBER(MATCH(Transactions!$B$5:$B$1504,Lists!$A$2:$A$31,0))*ISNUMBER(Transactions!$D$5:$D$1504)*(Transactions!$B$5:$B$1504=Lists!$A$4)*(Transactions!$A$5:$A$1504>=DATE(Calc!$C$4,9,1))*(Transactions!$A$5:$A$1504<DATE(Calc!$C$4,10,1)),Transactions!$D$5:$D$1504) -> 0 | L8: =SUMPRODUCT(ISNUMBER(Transactions!$A$5:$A$1504)*ISNUMBER(MATCH(Transactions!$B$5:$B$1504,Lists!$A$2:$A$31,0))*ISNUMBER(Transactions!$D$5:$D$1504)*(Transactions!$B$5:$B$1504=Lists!$A$4)*(Transactions!$A$5:$A$1504>=DATE(Calc!$C$4,10,1))*(Transactions!$A$5:$A$1504<DATE(Calc!$C$4,11,1)),Transactions!$D$5:$D$1504) -> 0 | M8: =SUMPRODUCT(ISNUMBER(Transactions!$A$5:$A$1504)*ISNUMBER(MATCH(Transactions!$B$5:$B$1504,Lists!$A$2:$A$31,0))*ISNUMBER(Transactions!$D$5:$D$1504)*(Transactions!$B$5:$B$1504=Lists!$A$4)*(Transactions!$A$5:$A$1504>=DATE(Calc!$C$4,11,1))*(Transactions!$A$5:$A$1504<DATE(Calc!$C$4,12,1)),Transactions!$D$5:$D$1504) -> 0 | N8: =SUMPRODUCT(ISNUMBER(Transactions!$A$5:$A$1504)*ISNUMBER(MATCH(Transactions!$B$5:$B$1504,Lists!$A$2:$A$31,0))*ISNUMBER(Transactions!$D$5:$D$1504)*(Transactions!$B$5:$B$1504=Lists!$A$4)*(Transactions!$A$5:$A$1504>=DATE(Calc!$C$4,12,1))*(Transactions!$A$5:$A$1504<DATE(Calc!$C$4,13,1)),Transactions!$D$5:$D$1504) -> 0 | O8: =SUM(C8:N8) -> 0 | P8: =IF(Calc!$C$5=0,0,O8/Calc!$C$5) -> 0
A9: =IF(Budget!A10="","",Budget!A10) -> Rent / mortgage | B9: =IF(LEFT(Lists!$A$5,1)="[","",Budget!B10) -> Bills | C9: =SUMPRODUCT(ISNUMBER(Transactions!$A$5:$A$1504)*ISNUMBER(MATCH(Transactions!$B$5:$B$1504,Lists!$A$2:$A$31,0))*ISNUMBER(Transactions!$D$5:$D$1504)*(Transactions!$B$5:$B$1504=Lists!$A$5)*(Transactions!$A$5:$A$1504>=DATE(Calc!$C$4,1,1))*(Transactions!$A$5:$A$1504<DATE(Calc!$C$4,2,1)),Transactions!$D$5:$D$1504) -> 1450 | D9: =SUMPRODUCT(ISNUMBER(Transactions!$A$5:$A$1504)*ISNUMBER(MATCH(Transactions!$B$5:$B$1504,Lists!$A$2:$A$31,0))*ISNUMBER(Transactions!$D$5:$D$1504)*(Transactions!$B$5:$B$1504=Lists!$A$5)*(Transactions!$A$5:$A$1504>=DATE(Calc!$C$4,2,1))*(Transactions!$A$5:$A$1504<DATE(Calc!$C$4,3,1)),Transactions!$D$5:$D$1504) -> 0 | E9: =SUMPRODUCT(ISNUMBER(Transactions!$A$5:$A$1504)*ISNUMBER(MATCH(Transactions!$B$5:$B$1504,Lists!$A$2:$A$31,0))*ISNUMBER(Transactions!$D$5:$D$1504)*(Transactions!$B$5:$B$1504=Lists!$A$5)*(Transactions!$A$5:$A$1504>=DATE(Calc!$C$4,3,1))*(Transactions!$A$5:$A$1504<DATE(Calc!$C$4,4,1)),Transactions!$D$5:$D$1504) -> 0 | F9: =SUMPRODUCT(ISNUMBER(Transactions!$A$5:$A$1504)*ISNUMBER(MATCH(Transactions!$B$5:$B$1504,Lists!$A$2:$A$31,0))*ISNUMBER(Transactions!$D$5:$D$1504)*(Transactions!$B$5:$B$1504=Lists!$A$5)*(Transactions!$A$5:$A$1504>=DATE(Calc!$C$4,4,1))*(Transactions!$A$5:$A$1504<DATE(Calc!$C$4,5,1)),Transactions!$D$5:$D$1504) -> 0 | G9: =SUMPRODUCT(ISNUMBER(Transactions!$A$5:$A$1504)*ISNUMBER(MATCH(Transactions!$B$5:$B$1504,Lists!$A$2:$A$31,0))*ISNUMBER(Transactions!$D$5:$D$1504)*(Transactions!$B$5:$B$1504=Lists!$A$5)*(Transactions!$A$5:$A$1504>=DATE(Calc!$C$4,5,1))*(Transactions!$A$5:$A$1504<DATE(Calc!$C$4,6,1)),Transactions!$D$5:$D$1504) -> 0 | H9: =SUMPRODUCT(ISNUMBER(Transactions!$A$5:$A$1504)*ISNUMBER(MATCH(Transactions!$B$5:$B$1504,Lists!$A$2:$A$31,0))*ISNUMBER(Transactions!$D$5:$D$1504)*(Transactions!$B$5:$B$1504=Lists!$A$5)*(Transactions!$A$5:$A$1504>=DATE(Calc!$C$4,6,1))*(Transactions!$A$5:$A$1504<DATE(Calc!$C$4,7,1)),Transactions!$D$5:$D$1504) -> 0 | I9: =SUMPRODUCT(ISNUMBER(Transactions!$A$5:$A$1504)*ISNUMBER(MATCH(Transactions!$B$5:$B$1504,Lists!$A$2:$A$31,0))*ISNUMBER(Transactions!$D$5:$D$1504)*(Transactions!$B$5:$B$1504=Lists!$A$5)*(Transactions!$A$5:$A$1504>=DATE(Calc!$C$4,7,1))*(Transactions!$A$5:$A$1504<DATE(Calc!$C$4,8,1)),Transactions!$D$5:$D$1504) -> 0 | J9: =SUMPRODUCT(ISNUMBER(Transactions!$A$5:$A$1504)*ISNUMBER(MATCH(Transactions!$B$5:$B$1504,Lists!$A$2:$A$31,0))*ISNUMBER(Transactions!$D$5:$D$1504)*(Transactions!$B$5:$B$1504=Lists!$A$5)*(Transactions!$A$5:$A$1504>=DATE(Calc!$C$4,8,1))*(Transactions!$A$5:$A$1504<DATE(Calc!$C$4,9,1)),Transactions!$D$5:$D$1504) -> 0 | K9: =SUMPRODUCT(ISNUMBER(Transactions!$A$5:$A$1504)*ISNUMBER(MATCH(Transactions!$B$5:$B$1504,Lists!$A$2:$A$31,0))*ISNUMBER(Transactions!$D$5:$D$1504)*(Transactions!$B$5:$B$1504=Lists!$A$5)*(Transactions!$A$5:$A$1504>=DATE(Calc!$C$4,9,1))*(Transactions!$A$5:$A$1504<DATE(Calc!$C$4,10,1)),Transactions!$D$5:$D$1504) -> 0 | L9: =SUMPRODUCT(ISNUMBER(Transactions!$A$5:$A$1504)*ISNUMBER(MATCH(Transactions!$B$5:$B$1504,Lists!$A$2:$A$31,0))*ISNUMBER(Transactions!$D$5:$D$1504)*(Transactions!$B$5:$B$1504=Lists!$A$5)*(Transactions!$A$5:$A$1504>=DATE(Calc!$C$4,10,1))*(Transactions!$A$5:$A$1504<DATE(Calc!$C$4,11,1)),Transactions!$D$5:$D$1504) -> 0 | M9: =SUMPRODUCT(ISNUMBER(Transactions!$A$5:$A$1504)*ISNUMBER(MATCH(Transactions!$B$5:$B$1504,Lists!$A$2:$A$31,0))*ISNUMBER(Transactions!$D$5:$D$1504)*(Transactions!$B$5:$B$1504=Lists!$A$5)*(Transactions!$A$5:$A$1504>=DATE(Calc!$C$4,11,1))*(Transactions!$A$5:$A$1504<DATE(Calc!$C$4,12,1)),Transactions!$D$5:$D$1504) -> 0 | N9: =SUMPRODUCT(ISNUMBER(Transactions!$A$5:$A$1504)*ISNUMBER(MATCH(Transactions!$B$5:$B$1504,Lists!$A$2:$A$31,0))*ISNUMBER(Transactions!$D$5:$D$1504)*(Transactions!$B$5:$B$1504=Lists!$A$5)*(Transactions!$A$5:$A$1504>=DATE(Calc!$C$4,12,1))*(Transactions!$A$5:$A$1504<DATE(Calc!$C$4,13,1)),Transactions!$D$5:$D$1504) -> 0 | O9: =SUM(C9:N9) -> 1450 | P9: =IF(Calc!$C$5=0,0,O9/Calc!$C$5) -> 1450
A10: =IF(Budget!A11="","",Budget!A11) -> Utilities | B10: =IF(LEFT(Lists!$A$6,1)="[","",Budget!B11) -> Bills | C10: =SUMPRODUCT(ISNUMBER(Transactions!$A$5:$A$1504)*ISNUMBER(MATCH(Transactions!$B$5:$B$1504,Lists!$A$2:$A$31,0))*ISNUMBER(Transactions!$D$5:$D$1504)*(Transactions!$B$5:$B$1504=Lists!$A$6)*(Transactions!$A$5:$A$1504>=DATE(Calc!$C$4,1,1))*(Transactions!$A$5:$A$1504<DATE(Calc!$C$4,2,1)),Transactions!$D$5:$D$1504) -> 0 | D10: =SUMPRODUCT(ISNUMBER(Transactions!$A$5:$A$1504)*ISNUMBER(MATCH(Transactions!$B$5:$B$1504,Lists!$A$2:$A$31,0))*ISNUMBER(Transactions!$D$5:$D$1504)*(Transactions!$B$5:$B$1504=Lists!$A$6)*(Transactions!$A$5:$A$1504>=DATE(Calc!$C$4,2,1))*(Transactions!$A$5:$A$1504<DATE(Calc!$C$4,3,1)),Transactions!$D$5:$D$1504) -> 0 | E10: =SUMPRODUCT(ISNUMBER(Transactions!$A$5:$A$1504)*ISNUMBER(MATCH(Transactions!$B$5:$B$1504,Lists!$A$2:$A$31,0))*ISNUMBER(Transactions!$D$5:$D$1504)*(Transactions!$B$5:$B$1504=Lists!$A$6)*(Transactions!$A$5:$A$1504>=DATE(Calc!$C$4,3,1))*(Transactions!$A$5:$A$1504<DATE(Calc!$C$4,4,1)),Transactions!$D$5:$D$1504) -> 0 | F10: =SUMPRODUCT(ISNUMBER(Transactions!$A$5:$A$1504)*ISNUMBER(MATCH(Transactions!$B$5:$B$1504,Lists!$A$2:$A$31,0))*ISNUMBER(Transactions!$D$5:$D$1504)*(Transactions!$B$5:$B$1504=Lists!$A$6)*(Transactions!$A$5:$A$1504>=DATE(Calc!$C$4,4,1))*(Transactions!$A$5:$A$1504<DATE(Calc!$C$4,5,1)),Transactions!$D$5:$D$1504) -> 0 | G10: =SUMPRODUCT(ISNUMBER(Transactions!$A$5:$A$1504)*ISNUMBER(MATCH(Transactions!$B$5:$B$1504,Lists!$A$2:$A$31,0))*ISNUMBER(Transactions!$D$5:$D$1504)*(Transactions!$B$5:$B$1504=Lists!$A$6)*(Transactions!$A$5:$A$1504>=DATE(Calc!$C$4,5,1))*(Transactions!$A$5:$A$1504<DATE(Calc!$C$4,6,1)),Transactions!$D$5:$D$1504) -> 0 | H10: =SUMPRODUCT(ISNUMBER(Transactions!$A$5:$A$1504)*ISNUMBER(MATCH(Transactions!$B$5:$B$1504,Lists!$A$2:$A$31,0))*ISNUMBER(Transactions!$D$5:$D$1504)*(Transactions!$B$5:$B$1504=Lists!$A$6)*(Transactions!$A$5:$A$1504>=DATE(Calc!$C$4,6,1))*(Transactions!$A$5:$A$1504<DATE(Calc!$C$4,7,1)),Transactions!$D$5:$D$1504) -> 0 | I10: =SUMPRODUCT(ISNUMBER(Transactions!$A$5:$A$1504)*ISNUMBER(MATCH(Transactions!$B$5:$B$1504,Lists!$A$2:$A$31,0))*ISNUMBER(Transactions!$D$5:$D$1504)*(Transactions!$B$5:$B$1504=Lists!$A$6)*(Transactions!$A$5:$A$1504>=DATE(Calc!$C$4,7,1))*(Transactions!$A$5:$A$1504<DATE(Calc!$C$4,8,1)),Transactions!$D$5:$D$1504) -> 0 | J10: =SUMPRODUCT(ISNUMBER(Transactions!$A$5:$A$1504)*ISNUMBER(MATCH(Transactions!$B$5:$B$1504,Lists!$A$2:$A$31,0))*ISNUMBER(Transactions!$D$5:$D$1504)*(Transactions!$B$5:$B$1504=Lists!$A$6)*(Transactions!$A$5:$A$1504>=DATE(Calc!$C$4,8,1))*(Transactions!$A$5:$A$1504<DATE(Calc!$C$4,9,1)),Transactions!$D$5:$D$1504) -> 0 | K10: =SUMPRODUCT(ISNUMBER(Transactions!$A$5:$A$1504)*ISNUMBER(MATCH(Transactions!$B$5:$B$1504,Lists!$A$2:$A$31,0))*ISNUMBER(Transactions!$D$5:$D$1504)*(Transactions!$B$5:$B$1504=Lists!$A$6)*(Transactions!$A$5:$A$1504>=DATE(Calc!$C$4,9,1))*(Transactions!$A$5:$A$1504<DATE(Calc!$C$4,10,1)),Transactions!$D$5:$D$1504) -> 0 | L10: =SUMPRODUCT(ISNUMBER(Transactions!$A$5:$A$1504)*ISNUMBER(MATCH(Transactions!$B$5:$B$1504,Lists!$A$2:$A$31,0))*ISNUMBER(Transactions!$D$5:$D$1504)*(Transactions!$B$5:$B$1504=Lists!$A$6)*(Transactions!$A$5:$A$1504>=DATE(Calc!$C$4,10,1))*(Transactions!$A$5:$A$1504<DATE(Calc!$C$4,11,1)),Transactions!$D$5:$D$1504) -> 0 | M10: =SUMPRODUCT(ISNUMBER(Transactions!$A$5:$A$1504)*ISNUMBER(MATCH(Transactions!$B$5:$B$1504,Lists!$A$2:$A$31,0))*ISNUMBER(Transactions!$D$5:$D$1504)*(Transactions!$B$5:$B$1504=Lists!$A$6)*(Transactions!$A$5:$A$1504>=DATE(Calc!$C$4,11,1))*(Transactions!$A$5:$A$1504<DATE(Calc!$C$4,12,1)),Transactions!$D$5:$D$1504) -> 0 | N10: =SUMPRODUCT(ISNUMBER(Transactions!$A$5:$A$1504)*ISNUMBER(MATCH(Transactions!$B$5:$B$1504,Lists!$A$2:$A$31,0))*ISNUMBER(Transactions!$D$5:$D$1504)*(Transactions!$B$5:$B$1504=Lists!$A$6)*(Transactions!$A$5:$A$1504>=DATE(Calc!$C$4,12,1))*(Transactions!$A$5:$A$1504<DATE(Calc!$C$4,13,1)),Transactions!$D$5:$D$1504) -> 0 | O10: =SUM(C10:N10) -> 0 | P10: =IF(Calc!$C$5=0,0,O10/Calc!$C$5) -> 0
A11: =IF(Budget!A12="","",Budget!A12) -> Phone & internet | B11: =IF(LEFT(Lists!$A$7,1)="[","",Budget!B12) -> Bills | C11: =SUMPRODUCT(ISNUMBER(Transactions!$A$5:$A$1504)*ISNUMBER(MATCH(Transactions!$B$5:$B$1504,Lists!$A$2:$A$31,0))*ISNUMBER(Transactions!$D$5:$D$1504)*(Transactions!$B$5:$B$1504=Lists!$A$7)*(Transactions!$A$5:$A$1504>=DATE(Calc!$C$4,1,1))*(Transactions!$A$5:$A$1504<DATE(Calc!$C$4,2,1)),Transactions!$D$5:$D$1504) -> 0 | D11: =SUMPRODUCT(ISNUMBER(Transactions!$A$5:$A$1504)*ISNUMBER(MATCH(Transactions!$B$5:$B$1504,Lists!$A$2:$A$31,0))*ISNUMBER(Transactions!$D$5:$D$1504)*(Transactions!$B$5:$B$1504=Lists!$A$7)*(Transactions!$A$5:$A$1504>=DATE(Calc!$C$4,2,1))*(Transactions!$A$5:$A$1504<DATE(Calc!$C$4,3,1)),Transactions!$D$5:$D$1504) -> 0 | E11: =SUMPRODUCT(ISNUMBER(Transactions!$A$5:$A$1504)*ISNUMBER(MATCH(Transactions!$B$5:$B$1504,Lists!$A$2:$A$31,0))*ISNUMBER(Transactions!$D$5:$D$1504)*(Transactions!$B$5:$B$1504=Lists!$A$7)*(Transactions!$A$5:$A$1504>=DATE(Calc!$C$4,3,1))*(Transactions!$A$5:$A$1504<DATE(Calc!$C$4,4,1)),Transactions!$D$5:$D$1504) -> 0 | F11: =SUMPRODUCT(ISNUMBER(Transactions!$A$5:$A$1504)*ISNUMBER(MATCH(Transactions!$B$5:$B$1504,Lists!$A$2:$A$31,0))*ISNUMBER(Transactions!$D$5:$D$1504)*(Transactions!$B$5:$B$1504=Lists!$A$7)*(Transactions!$A$5:$A$1504>=DATE(Calc!$C$4,4,1))*(Transactions!$A$5:$A$1504<DATE(Calc!$C$4,5,1)),Transactions!$D$5:$D$1504) -> 0 | G11: =SUMPRODUCT(ISNUMBER(Transactions!$A$5:$A$1504)*ISNUMBER(MATCH(Transactions!$B$5:$B$1504,Lists!$A$2:$A$31,0))*ISNUMBER(Transactions!$D$5:$D$1504)*(Transactions!$B$5:$B$1504=Lists!$A$7)*(Transactions!$A$5:$A$1504>=DATE(Calc!$C$4,5,1))*(Transactions!$A$5:$A$1504<DATE(Calc!$C$4,6,1)),Transactions!$D$5:$D$1504) -> 0 | H11: =SUMPRODUCT(ISNUMBER(Transactions!$A$5:$A$1504)*ISNUMBER(MATCH(Transactions!$B$5:$B$1504,Lists!$A$2:$A$31,0))*ISNUMBER(Transactions!$D$5:$D$1504)*(Transactions!$B$5:$B$1504=Lists!$A$7)*(Transactions!$A$5:$A$1504>=DATE(Calc!$C$4,6,1))*(Transactions!$A$5:$A$1504<DATE(Calc!$C$4,7,1)),Transactions!$D$5:$D$1504) -> 0 | I11: =SUMPRODUCT(ISNUMBER(Transactions!$A$5:$A$1504)*ISNUMBER(MATCH(Transactions!$B$5:$B$1504,Lists!$A$2:$A$31,0))*ISNUMBER(Transactions!$D$5:$D$1504)*(Transactions!$B$5:$B$1504=Lists!$A$7)*(Transactions!$A$5:$A$1504>=DATE(Calc!$C$4,7,1))*(Transactions!$A$5:$A$1504<DATE(Calc!$C$4,8,1)),Transactions!$D$5:$D$1504) -> 0 | J11: =SUMPRODUCT(ISNUMBER(Transactions!$A$5:$A$1504)*ISNUMBER(MATCH(Transactions!$B$5:$B$1504,Lists!$A$2:$A$31,0))*ISNUMBER(Transactions!$D$5:$D$1504)*(Transactions!$B$5:$B$1504=Lists!$A$7)*(Transactions!$A$5:$A$1504>=DATE(Calc!$C$4,8,1))*(Transactions!$A$5:$A$1504<DATE(Calc!$C$4,9,1)),Transactions!$D$5:$D$1504) -> 0 | K11: =SUMPRODUCT(ISNUMBER(Transactions!$A$5:$A$1504)*ISNUMBER(MATCH(Transactions!$B$5:$B$1504,Lists!$A$2:$A$31,0))*ISNUMBER(Transactions!$D$5:$D$1504)*(Transactions!$B$5:$B$1504=Lists!$A$7)*(Transactions!$A$5:$A$1504>=DATE(Calc!$C$4,9,1))*(Transactions!$A$5:$A$1504<DATE(Calc!$C$4,10,1)),Transactions!$D$5:$D$1504) -> 0 | L11: =SUMPRODUCT(ISNUMBER(Transactions!$A$5:$A$1504)*ISNUMBER(MATCH(Transactions!$B$5:$B$1504,Lists!$A$2:$A$31,0))*ISNUMBER(Transactions!$D$5:$D$1504)*(Transactions!$B$5:$B$1504=Lists!$A$7)*(Transactions!$A$5:$A$1504>=DATE(Calc!$C$4,10,1))*(Transactions!$A$5:$A$1504<DATE(Calc!$C$4,11,1)),Transactions!$D$5:$D$1504) -> 0 | M11: =SUMPRODUCT(ISNUMBER(Transactions!$A$5:$A$1504)*ISNUMBER(MATCH(Transactions!$B$5:$B$1504,Lists!$A$2:$A$31,0))*ISNUMBER(Transactions!$D$5:$D$1504)*(Transactions!$B$5:$B$1504=Lists!$A$7)*(Transactions!$A$5:$A$1504>=DATE(Calc!$C$4,11,1))*(Transactions!$A$5:$A$1504<DATE(Calc!$C$4,12,1)),Transactions!$D$5:$D$1504) -> 0 | N11: =SUMPRODUCT(ISNUMBER(Transactions!$A$5:$A$1504)*ISNUMBER(MATCH(Transactions!$B$5:$B$1504,Lists!$A$2:$A$31,0))*ISNUMBER(Transactions!$D$5:$D$1504)*(Transactions!$B$5:$B$1504=Lists!$A$7)*(Transactions!$A$5:$A$1504>=DATE(Calc!$C$4,12,1))*(Transactions!$A$5:$A$1504<DATE(Calc!$C$4,13,1)),Transactions!$D$5:$D$1504) -> 0 | O11: =SUM(C11:N11) -> 0 | P11: =IF(Calc!$C$5=0,0,O11/Calc!$C$5) -> 0
A12: =IF(Budget!A13="","",Budget!A13) -> Insurance | B12: =IF(LEFT(Lists!$A$8,1)="[","",Budget!B13) -> Bills | C12: =SUMPRODUCT(ISNUMBER(Transactions!$A$5:$A$1504)*ISNUMBER(MATCH(Transactions!$B$5:$B$1504,Lists!$A$2:$A$31,0))*ISNUMBER(Transactions!$D$5:$D$1504)*(Transactions!$B$5:$B$1504=Lists!$A$8)*(Transactions!$A$5:$A$1504>=DATE(Calc!$C$4,1,1))*(Transactions!$A$5:$A$1504<DATE(Calc!$C$4,2,1)),Transactions!$D$5:$D$1504) -> 0 | D12: =SUMPRODUCT(ISNUMBER(Transactions!$A$5:$A$1504)*ISNUMBER(MATCH(Transactions!$B$5:$B$1504,Lists!$A$2:$A$31,0))*ISNUMBER(Transactions!$D$5:$D$1504)*(Transactions!$B$5:$B$1504=Lists!$A$8)*(Transactions!$A$5:$A$1504>=DATE(Calc!$C$4,2,1))*(Transactions!$A$5:$A$1504<DATE(Calc!$C$4,3,1)),Transactions!$D$5:$D$1504) -> 0 | E12: =SUMPRODUCT(ISNUMBER(Transactions!$A$5:$A$1504)*ISNUMBER(MATCH(Transactions!$B$5:$B$1504,Lists!$A$2:$A$31,0))*ISNUMBER(Transactions!$D$5:$D$1504)*(Transactions!$B$5:$B$1504=Lists!$A$8)*(Transactions!$A$5:$A$1504>=DATE(Calc!$C$4,3,1))*(Transactions!$A$5:$A$1504<DATE(Calc!$C$4,4,1)),Transactions!$D$5:$D$1504) -> 0 | F12: =SUMPRODUCT(ISNUMBER(Transactions!$A$5:$A$1504)*ISNUMBER(MATCH(Transactions!$B$5:$B$1504,Lists!$A$2:$A$31,0))*ISNUMBER(Transactions!$D$5:$D$1504)*(Transactions!$B$5:$B$1504=Lists!$A$8)*(Transactions!$A$5:$A$1504>=DATE(Calc!$C$4,4,1))*(Transactions!$A$5:$A$1504<DATE(Calc!$C$4,5,1)),Transactions!$D$5:$D$1504) -> 0 | G12: =SUMPRODUCT(ISNUMBER(Transactions!$A$5:$A$1504)*ISNUMBER(MATCH(Transactions!$B$5:$B$1504,Lists!$A$2:$A$31,0))*ISNUMBER(Transactions!$D$5:$D$1504)*(Transactions!$B$5:$B$1504=Lists!$A$8)*(Transactions!$A$5:$A$1504>=DATE(Calc!$C$4,5,1))*(Transactions!$A$5:$A$1504<DATE(Calc!$C$4,6,1)),Transactions!$D$5:$D$1504) -> 0 | H12: =SUMPRODUCT(ISNUMBER(Transactions!$A$5:$A$1504)*ISNUMBER(MATCH(Transactions!$B$5:$B$1504,Lists!$A$2:$A$31,0))*ISNUMBER(Transactions!$D$5:$D$1504)*(Transactions!$B$5:$B$1504=Lists!$A$8)*(Transactions!$A$5:$A$1504>=DATE(Calc!$C$4,6,1))*(Transactions!$A$5:$A$1504<DATE(Calc!$C$4,7,1)),Transactions!$D$5:$D$1504) -> 0 | I12: =SUMPRODUCT(ISNUMBER(Transactions!$A$5:$A$1504)*ISNUMBER(MATCH(Transactions!$B$5:$B$1504,Lists!$A$2:$A$31,0))*ISNUMBER(Transactions!$D$5:$D$1504)*(Transactions!$B$5:$B$1504=Lists!$A$8)*(Transactions!$A$5:$A$1504>=DATE(Calc!$C$4,7,1))*(Transactions!$A$5:$A$1504<DATE(Calc!$C$4,8,1)),Transactions!$D$5:$D$1504) -> 0 | J12: =SUMPRODUCT(ISNUMBER(Transactions!$A$5:$A$1504)*ISNUMBER(MATCH(Transactions!$B$5:$B$1504,Lists!$A$2:$A$31,0))*ISNUMBER(Transactions!$D$5:$D$1504)*(Transactions!$B$5:$B$1504=Lists!$A$8)*(Transactions!$A$5:$A$1504>=DATE(Calc!$C$4,8,1))*(Transactions!$A$5:$A$1504<DATE(Calc!$C$4,9,1)),Transactions!$D$5:$D$1504) -> 0 | K12: =SUMPRODUCT(ISNUMBER(Transactions!$A$5:$A$1504)*ISNUMBER(MATCH(Transactions!$B$5:$B$1504,Lists!$A$2:$A$31,0))*ISNUMBER(Transactions!$D$5:$D$1504)*(Transactions!$B$5:$B$1504=Lists!$A$8)*(Transactions!$A$5:$A$1504>=DATE(Calc!$C$4,9,1))*(Transactions!$A$5:$A$1504<DATE(Calc!$C$4,10,1)),Transactions!$D$5:$D$1504) -> 0 | L12: =SUMPRODUCT(ISNUMBER(Transactions!$A$5:$A$1504)*ISNUMBER(MATCH(Transactions!$B$5:$B$1504,Lists!$A$2:$A$31,0))*ISNUMBER(Transactions!$D$5:$D$1504)*(Transactions!$B$5:$B$1504=Lists!$A$8)*(Transactions!$A$5:$A$1504>=DATE(Calc!$C$4,10,1))*(Transactions!$A$5:$A$1504<DATE(Calc!$C$4,11,1)),Transactions!$D$5:$D$1504) -> 0 | M12: =SUMPRODUCT(ISNUMBER(Transactions!$A$5:$A$1504)*ISNUMBER(MATCH(Transactions!$B$5:$B$1504,Lists!$A$2:$A$31,0))*ISNUMBER(Transactions!$D$5:$D$1504)*(Transactions!$B$5:$B$1504=Lists!$A$8)*(Transactions!$A$5:$A$1504>=DATE(Calc!$C$4,11,1))*(Transactions!$A$5:$A$1504<DATE(Calc!$C$4,12,1)),Transactions!$D$5:$D$1504) -> 0 | N12: =SUMPRODUCT(ISNUMBER(Transactions!$A$5:$A$1504)*ISNUMBER(MATCH(Transactions!$B$5:$B$1504,Lists!$A$2:$A$31,0))*ISNUMBER(Transactions!$D$5:$D$1504)*(Transactions!$B$5:$B$1504=Lists!$A$8)*(Transactions!$A$5:$A$1504>=DATE(Calc!$C$4,12,1))*(Transactions!$A$5:$A$1504<DATE(Calc!$C$4,13,1)),Transactions!$D$5:$D$1504) -> 0 | O12: =SUM(C12:N12) -> 0 | P12: =IF(Calc!$C$5=0,0,O12/Calc!$C$5) -> 0
A13: =IF(Budget!A14="","",Budget!A14) -> Subscriptions | B13: =IF(LEFT(Lists!$A$9,1)="[","",Budget!B14) -> Bills | C13: =SUMPRODUCT(ISNUMBER(Transactions!$A$5:$A$1504)*ISNUMBER(MATCH(Transactions!$B$5:$B$1504,Lists!$A$2:$A$31,0))*ISNUMBER(Transactions!$D$5:$D$1504)*(Transactions!$B$5:$B$1504=Lists!$A$9)*(Transactions!$A$5:$A$1504>=DATE(Calc!$C$4,1,1))*(Transactions!$A$5:$A$1504<DATE(Calc!$C$4,2,1)),Transactions!$D$5:$D$1504) -> 0 | D13: =SUMPRODUCT(ISNUMBER(Transactions!$A$5:$A$1504)*ISNUMBER(MATCH(Transactions!$B$5:$B$1504,Lists!$A$2:$A$31,0))*ISNUMBER(Transactions!$D$5:$D$1504)*(Transactions!$B$5:$B$1504=Lists!$A$9)*(Transactions!$A$5:$A$1504>=DATE(Calc!$C$4,2,1))*(Transactions!$A$5:$A$1504<DATE(Calc!$C$4,3,1)),Transactions!$D$5:$D$1504) -> 0 | E13: =SUMPRODUCT(ISNUMBER(Transactions!$A$5:$A$1504)*ISNUMBER(MATCH(Transactions!$B$5:$B$1504,Lists!$A$2:$A$31,0))*ISNUMBER(Transactions!$D$5:$D$1504)*(Transactions!$B$5:$B$1504=Lists!$A$9)*(Transactions!$A$5:$A$1504>=DATE(Calc!$C$4,3,1))*(Transactions!$A$5:$A$1504<DATE(Calc!$C$4,4,1)),Transactions!$D$5:$D$1504) -> 0 | F13: =SUMPRODUCT(ISNUMBER(Transactions!$A$5:$A$1504)*ISNUMBER(MATCH(Transactions!$B$5:$B$1504,Lists!$A$2:$A$31,0))*ISNUMBER(Transactions!$D$5:$D$1504)*(Transactions!$B$5:$B$1504=Lists!$A$9)*(Transactions!$A$5:$A$1504>=DATE(Calc!$C$4,4,1))*(Transactions!$A$5:$A$1504<DATE(Calc!$C$4,5,1)),Transactions!$D$5:$D$1504) -> 0 | G13: =SUMPRODUCT(ISNUMBER(Transactions!$A$5:$A$1504)*ISNUMBER(MATCH(Transactions!$B$5:$B$1504,Lists!$A$2:$A$31,0))*ISNUMBER(Transactions!$D$5:$D$1504)*(Transactions!$B$5:$B$1504=Lists!$A$9)*(Transactions!$A$5:$A$1504>=DATE(Calc!$C$4,5,1))*(Transactions!$A$5:$A$1504<DATE(Calc!$C$4,6,1)),Transactions!$D$5:$D$1504) -> 0 | H13: =SUMPRODUCT(ISNUMBER(Transactions!$A$5:$A$1504)*ISNUMBER(MATCH(Transactions!$B$5:$B$1504,Lists!$A$2:$A$31,0))*ISNUMBER(Transactions!$D$5:$D$1504)*(Transactions!$B$5:$B$1504=Lists!$A$9)*(Transactions!$A$5:$A$1504>=DATE(Calc!$C$4,6,1))*(Transactions!$A$5:$A$1504<DATE(Calc!$C$4,7,1)),Transactions!$D$5:$D$1504) -> 0 | I13: =SUMPRODUCT(ISNUMBER(Transactions!$A$5:$A$1504)*ISNUMBER(MATCH(Transactions!$B$5:$B$1504,Lists!$A$2:$A$31,0))*ISNUMBER(Transactions!$D$5:$D$1504)*(Transactions!$B$5:$B$1504=Lists!$A$9)*(Transactions!$A$5:$A$1504>=DATE(Calc!$C$4,7,1))*(Transactions!$A$5:$A$1504<DATE(Calc!$C$4,8,1)),Transactions!$D$5:$D$1504) -> 0 | J13: =SUMPRODUCT(ISNUMBER(Transactions!$A$5:$A$1504)*ISNUMBER(MATCH(Transactions!$B$5:$B$1504,Lists!$A$2:$A$31,0))*ISNUMBER(Transactions!$D$5:$D$1504)*(Transactions!$B$5:$B$1504=Lists!$A$9)*(Transactions!$A$5:$A$1504>=DATE(Calc!$C$4,8,1))*(Transactions!$A$5:$A$1504<DATE(Calc!$C$4,9,1)),Transactions!$D$5:$D$1504) -> 0 | K13: =SUMPRODUCT(ISNUMBER(Transactions!$A$5:$A$1504)*ISNUMBER(MATCH(Transactions!$B$5:$B$1504,Lists!$A$2:$A$31,0))*ISNUMBER(Transactions!$D$5:$D$1504)*(Transactions!$B$5:$B$1504=Lists!$A$9)*(Transactions!$A$5:$A$1504>=DATE(Calc!$C$4,9,1))*(Transactions!$A$5:$A$1504<DATE(Calc!$C$4,10,1)),Transactions!$D$5:$D$1504) -> 0 | L13: =SUMPRODUCT(ISNUMBER(Transactions!$A$5:$A$1504)*ISNUMBER(MATCH(Transactions!$B$5:$B$1504,Lists!$A$2:$A$31,0))*ISNUMBER(Transactions!$D$5:$D$1504)*(Transactions!$B$5:$B$1504=Lists!$A$9)*(Transactions!$A$5:$A$1504>=DATE(Calc!$C$4,10,1))*(Transactions!$A$5:$A$1504<DATE(Calc!$C$4,11,1)),Transactions!$D$5:$D$1504) -> 0 | M13: =SUMPRODUCT(ISNUMBER(Transactions!$A$5:$A$1504)*ISNUMBER(MATCH(Transactions!$B$5:$B$1504,Lists!$A$2:$A$31,0))*ISNUMBER(Transactions!$D$5:$D$1504)*(Transactions!$B$5:$B$1504=Lists!$A$9)*(Transactions!$A$5:$A$1504>=DATE(Calc!$C$4,11,1))*(Transactions!$A$5:$A$1504<DATE(Calc!$C$4,12,1)),Transactions!$D$5:$D$1504) -> 0 | N13: =SUMPRODUCT(ISNUMBER(Transactions!$A$5:$A$1504)*ISNUMBER(MATCH(Transactions!$B$5:$B$1504,Lists!$A$2:$A$31,0))*ISNUMBER(Transactions!$D$5:$D$1504)*(Transactions!$B$5:$B$1504=Lists!$A$9)*(Transactions!$A$5:$A$1504>=DATE(Calc!$C$4,12,1))*(Transactions!$A$5:$A$1504<DATE(Calc!$C$4,13,1)),Transactions!$D$5:$D$1504) -> 0 | O13: =SUM(C13:N13) -> 0 | P13: =IF(Calc!$C$5=0,0,O13/Calc!$C$5) -> 0
A14: =IF(Budget!A15="","",Budget!A15) -> Groceries | B14: =IF(LEFT(Lists!$A$10,1)="[","",Budget!B15) -> Living | C14: =SUMPRODUCT(ISNUMBER(Transactions!$A$5:$A$1504)*ISNUMBER(MATCH(Transactions!$B$5:$B$1504,Lists!$A$2:$A$31,0))*ISNUMBER(Transactions!$D$5:$D$1504)*(Transactions!$B$5:$B$1504=Lists!$A$10)*(Transactions!$A$5:$A$1504>=DATE(Calc!$C$4,1,1))*(Transactions!$A$5:$A$1504<DATE(Calc!$C$4,2,1)),Transactions!$D$5:$D$1504) -> 112.4 | D14: =SUMPRODUCT(ISNUMBER(Transactions!$A$5:$A$1504)*ISNUMBER(MATCH(Transactions!$B$5:$B$1504,Lists!$A$2:$A$31,0))*ISNUMBER(Transactions!$D$5:$D$1504)*(Transactions!$B$5:$B$1504=Lists!$A$10)*(Transactions!$A$5:$A$1504>=DATE(Calc!$C$4,2,1))*(Transactions!$A$5:$A$1504<DATE(Calc!$C$4,3,1)),Transactions!$D$5:$D$1504) -> 0 | E14: =SUMPRODUCT(ISNUMBER(Transactions!$A$5:$A$1504)*ISNUMBER(MATCH(Transactions!$B$5:$B$1504,Lists!$A$2:$A$31,0))*ISNUMBER(Transactions!$D$5:$D$1504)*(Transactions!$B$5:$B$1504=Lists!$A$10)*(Transactions!$A$5:$A$1504>=DATE(Calc!$C$4,3,1))*(Transactions!$A$5:$A$1504<DATE(Calc!$C$4,4,1)),Transactions!$D$5:$D$1504) -> 0 | F14: =SUMPRODUCT(ISNUMBER(Transactions!$A$5:$A$1504)*ISNUMBER(MATCH(Transactions!$B$5:$B$1504,Lists!$A$2:$A$31,0))*ISNUMBER(Transactions!$D$5:$D$1504)*(Transactions!$B$5:$B$1504=Lists!$A$10)*(Transactions!$A$5:$A$1504>=DATE(Calc!$C$4,4,1))*(Transactions!$A$5:$A$1504<DATE(Calc!$C$4,5,1)),Transactions!$D$5:$D$1504) -> 0 | G14: =SUMPRODUCT(ISNUMBER(Transactions!$A$5:$A$1504)*ISNUMBER(MATCH(Transactions!$B$5:$B$1504,Lists!$A$2:$A$31,0))*ISNUMBER(Transactions!$D$5:$D$1504)*(Transactions!$B$5:$B$1504=Lists!$A$10)*(Transactions!$A$5:$A$1504>=DATE(Calc!$C$4,5,1))*(Transactions!$A$5:$A$1504<DATE(Calc!$C$4,6,1)),Transactions!$D$5:$D$1504) -> 0 | H14: =SUMPRODUCT(ISNUMBER(Transactions!$A$5:$A$1504)*ISNUMBER(MATCH(Transactions!$B$5:$B$1504,Lists!$A$2:$A$31,0))*ISNUMBER(Transactions!$D$5:$D$1504)*(Transactions!$B$5:$B$1504=Lists!$A$10)*(Transactions!$A$5:$A$1504>=DATE(Calc!$C$4,6,1))*(Transactions!$A$5:$A$1504<DATE(Calc!$C$4,7,1)),Transactions!$D$5:$D$1504) -> 0 | I14: =SUMPRODUCT(ISNUMBER(Transactions!$A$5:$A$1504)*ISNUMBER(MATCH(Transactions!$B$5:$B$1504,Lists!$A$2:$A$31,0))*ISNUMBER(Transactions!$D$5:$D$1504)*(Transactions!$B$5:$B$1504=Lists!$A$10)*(Transactions!$A$5:$A$1504>=DATE(Calc!$C$4,7,1))*(Transactions!$A$5:$A$1504<DATE(Calc!$C$4,8,1)),Transactions!$D$5:$D$1504) -> 0 | J14: =SUMPRODUCT(ISNUMBER(Transactions!$A$5:$A$1504)*ISNUMBER(MATCH(Transactions!$B$5:$B$1504,Lists!$A$2:$A$31,0))*ISNUMBER(Transactions!$D$5:$D$1504)*(Transactions!$B$5:$B$1504=Lists!$A$10)*(Transactions!$A$5:$A$1504>=DATE(Calc!$C$4,8,1))*(Transactions!$A$5:$A$1504<DATE(Calc!$C$4,9,1)),Transactions!$D$5:$D$1504) -> 0 | K14: =SUMPRODUCT(ISNUMBER(Transactions!$A$5:$A$1504)*ISNUMBER(MATCH(Transactions!$B$5:$B$1504,Lists!$A$2:$A$31,0))*ISNUMBER(Transactions!$D$5:$D$1504)*(Transactions!$B$5:$B$1504=Lists!$A$10)*(Transactions!$A$5:$A$1504>=DATE(Calc!$C$4,9,1))*(Transactions!$A$5:$A$1504<DATE(Calc!$C$4,10,1)),Transactions!$D$5:$D$1504) -> 0 | L14: =SUMPRODUCT(ISNUMBER(Transactions!$A$5:$A$1504)*ISNUMBER(MATCH(Transactions!$B$5:$B$1504,Lists!$A$2:$A$31,0))*ISNUMBER(Transactions!$D$5:$D$1504)*(Transactions!$B$5:$B$1504=Lists!$A$10)*(Transactions!$A$5:$A$1504>=DATE(Calc!$C$4,10,1))*(Transactions!$A$5:$A$1504<DATE(Calc!$C$4,11,1)),Transactions!$D$5:$D$1504) -> 0 | M14: =SUMPRODUCT(ISNUMBER(Transactions!$A$5:$A$1504)*ISNUMBER(MATCH(Transactions!$B$5:$B$1504,Lists!$A$2:$A$31,0))*ISNUMBER(Transactions!$D$5:$D$1504)*(Transactions!$B$5:$B$1504=Lists!$A$10)*(Transactions!$A$5:$A$1504>=DATE(Calc!$C$4,11,1))*(Transactions!$A$5:$A$1504<DATE(Calc!$C$4,12,1)),Transactions!$D$5:$D$1504) -> 0 | N14: =SUMPRODUCT(ISNUMBER(Transactions!$A$5:$A$1504)*ISNUMBER(MATCH(Transactions!$B$5:$B$1504,Lists!$A$2:$A$31,0))*ISNUMBER(Transactions!$D$5:$D$1504)*(Transactions!$B$5:$B$1504=Lists!$A$10)*(Transactions!$A$5:$A$1504>=DATE(Calc!$C$4,12,1))*(Transactions!$A$5:$A$1504<DATE(Calc!$C$4,13,1)),Transactions!$D$5:$D$1504) -> 0 | O14: =SUM(C14:N14) -> 112.4 | P14: =IF(Calc!$C$5=0,0,O14/Calc!$C$5) -> 112.4
A15: =IF(Budget!A16="","",Budget!A16) -> Dining out | B15: =IF(LEFT(Lists!$A$11,1)="[","",Budget!B16) -> Living | C15: =SUMPRODUCT(ISNUMBER(Transactions!$A$5:$A$1504)*ISNUMBER(MATCH(Transactions!$B$5:$B$1504,Lists!$A$2:$A$31,0))*ISNUMBER(Transactions!$D$5:$D$1504)*(Transactions!$B$5:$B$1504=Lists!$A$11)*(Transactions!$A$5:$A$1504>=DATE(Calc!$C$4,1,1))*(Transactions!$A$5:$A$1504<DATE(Calc!$C$4,2,1)),Transactions!$D$5:$D$1504) -> 0 | D15: =SUMPRODUCT(ISNUMBER(Transactions!$A$5:$A$1504)*ISNUMBER(MATCH(Transactions!$B$5:$B$1504,Lists!$A$2:$A$31,0))*ISNUMBER(Transactions!$D$5:$D$1504)*(Transactions!$B$5:$B$1504=Lists!$A$11)*(Transactions!$A$5:$A$1504>=DATE(Calc!$C$4,2,1))*(Transactions!$A$5:$A$1504<DATE(Calc!$C$4,3,1)),Transactions!$D$5:$D$1504) -> 0 | E15: =SUMPRODUCT(ISNUMBER(Transactions!$A$5:$A$1504)*ISNUMBER(MATCH(Transactions!$B$5:$B$1504,Lists!$A$2:$A$31,0))*ISNUMBER(Transactions!$D$5:$D$1504)*(Transactions!$B$5:$B$1504=Lists!$A$11)*(Transactions!$A$5:$A$1504>=DATE(Calc!$C$4,3,1))*(Transactions!$A$5:$A$1504<DATE(Calc!$C$4,4,1)),Transactions!$D$5:$D$1504) -> 0 | F15: =SUMPRODUCT(ISNUMBER(Transactions!$A$5:$A$1504)*ISNUMBER(MATCH(Transactions!$B$5:$B$1504,Lists!$A$2:$A$31,0))*ISNUMBER(Transactions!$D$5:$D$1504)*(Transactions!$B$5:$B$1504=Lists!$A$11)*(Transactions!$A$5:$A$1504>=DATE(Calc!$C$4,4,1))*(Transactions!$A$5:$A$1504<DATE(Calc!$C$4,5,1)),Transactions!$D$5:$D$1504) -> 0 | G15: =SUMPRODUCT(ISNUMBER(Transactions!$A$5:$A$1504)*ISNUMBER(MATCH(Transactions!$B$5:$B$1504,Lists!$A$2:$A$31,0))*ISNUMBER(Transactions!$D$5:$D$1504)*(Transactions!$B$5:$B$1504=Lists!$A$11)*(Transactions!$A$5:$A$1504>=DATE(Calc!$C$4,5,1))*(Transactions!$A$5:$A$1504<DATE(Calc!$C$4,6,1)),Transactions!$D$5:$D$1504) -> 0 | H15: =SUMPRODUCT(ISNUMBER(Transactions!$A$5:$A$1504)*ISNUMBER(MATCH(Transactions!$B$5:$B$1504,Lists!$A$2:$A$31,0))*ISNUMBER(Transactions!$D$5:$D$1504)*(Transactions!$B$5:$B$1504=Lists!$A$11)*(Transactions!$A$5:$A$1504>=DATE(Calc!$C$4,6,1))*(Transactions!$A$5:$A$1504<DATE(Calc!$C$4,7,1)),Transactions!$D$5:$D$1504) -> 0 | I15: =SUMPRODUCT(ISNUMBER(Transactions!$A$5:$A$1504)*ISNUMBER(MATCH(Transactions!$B$5:$B$1504,Lists!$A$2:$A$31,0))*ISNUMBER(Transactions!$D$5:$D$1504)*(Transactions!$B$5:$B$1504=Lists!$A$11)*(Transactions!$A$5:$A$1504>=DATE(Calc!$C$4,7,1))*(Transactions!$A$5:$A$1504<DATE(Calc!$C$4,8,1)),Transactions!$D$5:$D$1504) -> 0 | J15: =SUMPRODUCT(ISNUMBER(Transactions!$A$5:$A$1504)*ISNUMBER(MATCH(Transactions!$B$5:$B$1504,Lists!$A$2:$A$31,0))*ISNUMBER(Transactions!$D$5:$D$1504)*(Transactions!$B$5:$B$1504=Lists!$A$11)*(Transactions!$A$5:$A$1504>=DATE(Calc!$C$4,8,1))*(Transactions!$A$5:$A$1504<DATE(Calc!$C$4,9,1)),Transactions!$D$5:$D$1504) -> 0 | K15: =SUMPRODUCT(ISNUMBER(Transactions!$A$5:$A$1504)*ISNUMBER(MATCH(Transactions!$B$5:$B$1504,Lists!$A$2:$A$31,0))*ISNUMBER(Transactions!$D$5:$D$1504)*(Transactions!$B$5:$B$1504=Lists!$A$11)*(Transactions!$A$5:$A$1504>=DATE(Calc!$C$4,9,1))*(Transactions!$A$5:$A$1504<DATE(Calc!$C$4,10,1)),Transactions!$D$5:$D$1504) -> 0 | L15: =SUMPRODUCT(ISNUMBER(Transactions!$A$5:$A$1504)*ISNUMBER(MATCH(Transactions!$B$5:$B$1504,Lists!$A$2:$A$31,0))*ISNUMBER(Transactions!$D$5:$D$1504)*(Transactions!$B$5:$B$1504=Lists!$A$11)*(Transactions!$A$5:$A$1504>=DATE(Calc!$C$4,10,1))*(Transactions!$A$5:$A$1504<DATE(Calc!$C$4,11,1)),Transactions!$D$5:$D$1504) -> 0 | M15: =SUMPRODUCT(ISNUMBER(Transactions!$A$5:$A$1504)*ISNUMBER(MATCH(Transactions!$B$5:$B$1504,Lists!$A$2:$A$31,0))*ISNUMBER(Transactions!$D$5:$D$1504)*(Transactions!$B$5:$B$1504=Lists!$A$11)*(Transactions!$A$5:$A$1504>=DATE(Calc!$C$4,11,1))*(Transactions!$A$5:$A$1504<DATE(Calc!$C$4,12,1)),Transactions!$D$5:$D$1504) -> 0 | N15: =SUMPRODUCT(ISNUMBER(Transactions!$A$5:$A$1504)*ISNUMBER(MATCH(Transactions!$B$5:$B$1504,Lists!$A$2:$A$31,0))*ISNUMBER(Transactions!$D$5:$D$1504)*(Transactions!$B$5:$B$1504=Lists!$A$11)*(Transactions!$A$5:$A$1504>=DATE(Calc!$C$4,12,1))*(Transactions!$A$5:$A$1504<DATE(Calc!$C$4,13,1)),Transactions!$D$5:$D$1504) -> 0 | O15: =SUM(C15:N15) -> 0 | P15: =IF(Calc!$C$5=0,0,O15/Calc!$C$5) -> 0
A16: =IF(Budget!A17="","",Budget!A17) -> Transportation & gas | B16: =IF(LEFT(Lists!$A$12,1)="[","",Budget!B17) -> Living | C16: =SUMPRODUCT(ISNUMBER(Transactions!$A$5:$A$1504)*ISNUMBER(MATCH(Transactions!$B$5:$B$1504,Lists!$A$2:$A$31,0))*ISNUMBER(Transactions!$D$5:$D$1504)*(Transactions!$B$5:$B$1504=Lists!$A$12)*(Transactions!$A$5:$A$1504>=DATE(Calc!$C$4,1,1))*(Transactions!$A$5:$A$1504<DATE(Calc!$C$4,2,1)),Transactions!$D$5:$D$1504) -> 0 | D16: =SUMPRODUCT(ISNUMBER(Transactions!$A$5:$A$1504)*ISNUMBER(MATCH(Transactions!$B$5:$B$1504,Lists!$A$2:$A$31,0))*ISNUMBER(Transactions!$D$5:$D$1504)*(Transactions!$B$5:$B$1504=Lists!$A$12)*(Transactions!$A$5:$A$1504>=DATE(Calc!$C$4,2,1))*(Transactions!$A$5:$A$1504<DATE(Calc!$C$4,3,1)),Transactions!$D$5:$D$1504) -> 0 | E16: =SUMPRODUCT(ISNUMBER(Transactions!$A$5:$A$1504)*ISNUMBER(MATCH(Transactions!$B$5:$B$1504,Lists!$A$2:$A$31,0))*ISNUMBER(Transactions!$D$5:$D$1504)*(Transactions!$B$5:$B$1504=Lists!$A$12)*(Transactions!$A$5:$A$1504>=DATE(Calc!$C$4,3,1))*(Transactions!$A$5:$A$1504<DATE(Calc!$C$4,4,1)),Transactions!$D$5:$D$1504) -> 0 | F16: =SUMPRODUCT(ISNUMBER(Transactions!$A$5:$A$1504)*ISNUMBER(MATCH(Transactions!$B$5:$B$1504,Lists!$A$2:$A$31,0))*ISNUMBER(Transactions!$D$5:$D$1504)*(Transactions!$B$5:$B$1504=Lists!$A$12)*(Transactions!$A$5:$A$1504>=DATE(Calc!$C$4,4,1))*(Transactions!$A$5:$A$1504<DATE(Calc!$C$4,5,1)),Transactions!$D$5:$D$1504) -> 0 | G16: =SUMPRODUCT(ISNUMBER(Transactions!$A$5:$A$1504)*ISNUMBER(MATCH(Transactions!$B$5:$B$1504,Lists!$A$2:$A$31,0))*ISNUMBER(Transactions!$D$5:$D$1504)*(Transactions!$B$5:$B$1504=Lists!$A$12)*(Transactions!$A$5:$A$1504>=DATE(Calc!$C$4,5,1))*(Transactions!$A$5:$A$1504<DATE(Calc!$C$4,6,1)),Transactions!$D$5:$D$1504) -> 0 | H16: =SUMPRODUCT(ISNUMBER(Transactions!$A$5:$A$1504)*ISNUMBER(MATCH(Transactions!$B$5:$B$1504,Lists!$A$2:$A$31,0))*ISNUMBER(Transactions!$D$5:$D$1504)*(Transactions!$B$5:$B$1504=Lists!$A$12)*(Transactions!$A$5:$A$1504>=DATE(Calc!$C$4,6,1))*(Transactions!$A$5:$A$1504<DATE(Calc!$C$4,7,1)),Transactions!$D$5:$D$1504) -> 0 | I16: =SUMPRODUCT(ISNUMBER(Transactions!$A$5:$A$1504)*ISNUMBER(MATCH(Transactions!$B$5:$B$1504,Lists!$A$2:$A$31,0))*ISNUMBER(Transactions!$D$5:$D$1504)*(Transactions!$B$5:$B$1504=Lists!$A$12)*(Transactions!$A$5:$A$1504>=DATE(Calc!$C$4,7,1))*(Transactions!$A$5:$A$1504<DATE(Calc!$C$4,8,1)),Transactions!$D$5:$D$1504) -> 0 | J16: =SUMPRODUCT(ISNUMBER(Transactions!$A$5:$A$1504)*ISNUMBER(MATCH(Transactions!$B$5:$B$1504,Lists!$A$2:$A$31,0))*ISNUMBER(Transactions!$D$5:$D$1504)*(Transactions!$B$5:$B$1504=Lists!$A$12)*(Transactions!$A$5:$A$1504>=DATE(Calc!$C$4,8,1))*(Transactions!$A$5:$A$1504<DATE(Calc!$C$4,9,1)),Transactions!$D$5:$D$1504) -> 0 | K16: =SUMPRODUCT(ISNUMBER(Transactions!$A$5:$A$1504)*ISNUMBER(MATCH(Transactions!$B$5:$B$1504,Lists!$A$2:$A$31,0))*ISNUMBER(Transactions!$D$5:$D$1504)*(Transactions!$B$5:$B$1504=Lists!$A$12)*(Transactions!$A$5:$A$1504>=DATE(Calc!$C$4,9,1))*(Transactions!$A$5:$A$1504<DATE(Calc!$C$4,10,1)),Transactions!$D$5:$D$1504) -> 0 | L16: =SUMPRODUCT(ISNUMBER(Transactions!$A$5:$A$1504)*ISNUMBER(MATCH(Transactions!$B$5:$B$1504,Lists!$A$2:$A$31,0))*ISNUMBER(Transactions!$D$5:$D$1504)*(Transactions!$B$5:$B$1504=Lists!$A$12)*(Transactions!$A$5:$A$1504>=DATE(Calc!$C$4,10,1))*(Transactions!$A$5:$A$1504<DATE(Calc!$C$4,11,1)),Transactions!$D$5:$D$1504) -> 0 | M16: =SUMPRODUCT(ISNUMBER(Transactions!$A$5:$A$1504)*ISNUMBER(MATCH(Transactions!$B$5:$B$1504,Lists!$A$2:$A$31,0))*ISNUMBER(Transactions!$D$5:$D$1504)*(Transactions!$B$5:$B$1504=Lists!$A$12)*(Transactions!$A$5:$A$1504>=DATE(Calc!$C$4,11,1))*(Transactions!$A$5:$A$1504<DATE(Calc!$C$4,12,1)),Transactions!$D$5:$D$1504) -> 0 | N16: =SUMPRODUCT(ISNUMBER(Transactions!$A$5:$A$1504)*ISNUMBER(MATCH(Transactions!$B$5:$B$1504,Lists!$A$2:$A$31,0))*ISNUMBER(Transactions!$D$5:$D$1504)*(Transactions!$B$5:$B$1504=Lists!$A$12)*(Transactions!$A$5:$A$1504>=DATE(Calc!$C$4,12,1))*(Transactions!$A$5:$A$1504<DATE(Calc!$C$4,13,1)),Transactions!$D$5:$D$1504) -> 0 | O16: =SUM(C16:N16) -> 0 | P16: =IF(Calc!$C$5=0,0,O16/Calc!$C$5) -> 0
