Workbook

Sheet Start Here
B2: Reseller Inventory & Profit Tracker
B3: Every item you flip, from purchase to payout, across eBay, Poshmark, Mercari, Depop, Facebook, Etsy and Whatnot. Works in Excel and Google Sheets.
B5: QUICK START (10 minutes)
B6: 1. 'Inventory' tab: one row per item. When you buy it, enter the date, what you paid and any cleaning or repair costs.
B7: 2. When it sells, pick the platform and enter the sold date, sale price, shipping the buyer paid and the postage label you paid.
B8: Platform fees, profit, ROI and days held work themselves out. Delete the EXAMPLE rows first.
B9: 3. 'Expenses' tab: costs not tied to one item: shipping supplies, mileage, storage, crosslisting apps, store subscriptions.
B10: 4. 'Dashboard' shows the year at a glance (change the year in cell C3), plus what is still sitting in stock and for how long.
B11: 5. 'Buy or Pass' tells you the most you should pay for an item to make the profit you want, and which platform pays you most.
B12: 6. 'Platforms' holds each platform's fee rates and shows your results per platform. Fees change: check yours and edit the yellow cells.
B13: Know the exact fee from the sale page? Type it in 'Actual platform fees' on that row and it replaces the estimate.
B14: 7. Red cells mean a row needs fixing (sold date before purchase, price with no sold date, unknown platform, text in an amount).
... B34: Questions or a formula not behaving? Email nora@qnsai.com. Made by Nora Studio.

Sheet Dashboard
B1: Reseller Dashboard
B3: Year: | C3: 2026 | D3: ="Updates automatically from Inventory and Expenses"&IF(Inventory!T2+Expenses!G2>0," | "&(Inventory!T2+Expenses!G2)&" row(s) need fixing - see red cells","") -> Updates automatically from Inventory and Expenses | V3: Chart data (do not edit)
V4: Month | W4: Revenue | X4: Net profit | Y4: Inventory bought
B5: NET PROFIT | G5: REVENUE | L5: ITEMS SOLD | V5: Jan | W5: =Calc!G3 -> 50 | X5: =Calc!L3 -> 14.31 | Y5: =Calc!N3 -> 9
B6: =Calc!L15 -> 14.31 | G6: =Calc!G15 -> 50 | L6: =Calc!C15 -> 1 | V6: Feb | W6: =Calc!G4 -> 0 | X6: =Calc!L4 -> 0 | Y6: =Calc!N4 -> 0
V7: Mar | W7: =Calc!G5 -> 0 | X7: =Calc!L5 -> 0 | Y7: =Calc!N5 -> 0
V8: Apr | W8: =Calc!G6 -> 0 | X8: =Calc!L6 -> 0 | Y8: =Calc!N6 -> 0
B9: AVG PROFIT PER ITEM | G9: PLATFORM FEES | L9: AVG DAYS TO SELL | V9: May | W9: =Calc!G7 -> 0 | X9: =Calc!L7 -> 0 | Y9: =Calc!N7 -> 0
B10: =IF(Calc!C15>0,(Calc!G15-Calc!H15-Calc!I15-Calc!J15)/Calc!C15,0) -> 29.3 | G10: =Calc!H15 -> 7.2 | L10: =Calc!C42 -> 15 | V10: Jun | W10: =Calc!G8 -> 0 | X10: =Calc!L8 -> 0 | Y10: =Calc!N8 -> 0
V11: Jul | W11: =Calc!G9 -> 0 | X11: =Calc!L9 -> 0 | Y11: =Calc!N9 -> 0
V12: Aug | W12: =Calc!G10 -> 0 | X12: =Calc!L10 -> 0 | Y12: =Calc!N10 -> 0
B13: IN STOCK NOW (ITEMS) | G13: STOCK VALUE AT COST | L13: SELL-THROUGH | V13: Sep | W13: =Calc!G11 -> 0 | X13: =Calc!L11 -> 0 | Y13: =Calc!N11 -> 0
B14: =Calc!C38 -> 1 | G14: =Calc!D38 -> 3 | L14: =Calc!C43 -> 0.5 | V14: Oct | W14: =Calc!G12 -> 0 | X14: =Calc!L12 -> 0 | Y14: =Calc!N12 -> 0
V15: Nov | W15: =Calc!G13 -> 0 | X15: =Calc!L13 -> 0 | Y15: =Calc!N13 -> 0
B16: Avg profit per item is before shop expenses. In stock, stock value and age are as of today, whatever year is selected. | V16: Dec | W16: =Calc!G14 -> 0 | X16: =Calc!L14 -> 0 | Y16: =Calc!N14 -> 0
V19: Platform | W19: Profit | X19: Fees
V20: =IF(Calc!B20=0,"",Calc!B20) -> eBay | W20: =Calc!U20 -> 29.3 | X20: =Calc!R20 -> 7.2
V21: =IF(Calc!B21=0,"",Calc!B21) -> Poshmark | W21: =Calc!U21 -> 0 | X21: =Calc!R21 -> 0
V22: =IF(Calc!B22=0,"",Calc!B22) -> Mercari | W22: =Calc!U22 -> 0 | X22: =Calc!R22 -> 0
V23: =IF(Calc!B23=0,"",Calc!B23) -> Depop | W23: =Calc!U23 -> 0 | X23: =Calc!R23 -> 0
V24: =IF(Calc!B24=0,"",Calc!B24) -> Facebook Marketplace | W24: =Calc!U24 -> 0 | X24: =Calc!R24 -> 0
V25: =IF(Calc!B25=0,"",Calc!B25) -> Etsy | W25: =Calc!U25 -> 0 | X25: =Calc!R25 -> 0
V26: =IF(Calc!B26=0,"",Calc!B26) -> Whatnot | W26: =Calc!U26 -> 0 | X26: =Calc!R26 -> 0
V27: =IF(Calc!B27=0,"",Calc!B27) -> Local / cash | W27: =Calc!U27 -> 0 | X27: =Calc!R27 -> 0
V28: =IF(Calc!B28=0,"",Calc!B28) | W28: =Calc!U28 -> 0 | X28: =Calc!R28 -> 0
V29: =IF(Calc!B29=0,"",Calc!B29) | W29: =Calc!U29 -> 0 | X29: =Calc!R29 -> 0
V31: Age in stock | W31: Items | X31: Cost
V32: =Calc!B33 -> 0-30 days | W32: =Calc!C33 -> 0 | X32: =Calc!D33 -> 0
V33: =Calc!B34 -> 31-90 days | W33: =Calc!C34 -> 0 | X33: =Calc!D34 -> 0
V34: =Calc!B35 -> 91-180 days | W34: =Calc!C35 -> 0 | X34: =Calc!D35 -> 0
V35: =Calc!B36 -> Over 180 days | W35: =Calc!C36 -> 1 | X35: =Calc!D36 -> 3
V36: =Calc!B37 -> No purchase date | W36: =Calc!C37 -> 0 | X36: =Calc!D37 -> 0

Sheet Inventory
A1: Inventory
A2: One row per item. Fill the left side when you buy it, the right side when it sells. Amounts before platform fees. | R2: Rows to fix: | T2: =SUMPRODUCT((((Inventory!$B$5:$B$2004<>"")+(Inventory!$D$5:$D$2004<>"")+(Inventory!$F$5:$F$2004<>"")+(Inventory!$G$5:$G$2004<>"")+(Inventory!$H$5:$H$2004<>"")+(Inventory!$I$5:$I$2004<>"")+(Inventory!$J$5:$J$2004<>"")+(Inventory!$K$5:$K$2004<>"")+(Inventory!$L$5:$L$2004<>"")+(Inventory!$M$5:$M$2004<>"")+(Inventory!$N$5:$N$2004<>"")+(Inventory!$O$5:$O$2004<>""))>0)*(((ISNUMBER(Inventory!$J$5:$J$2004)*ISNUMBER(Inventory!$K$5:$K$2004)*ISNUMBER(MATCH(Inventory!$H$5:$H$2004,Lists!$A$2:$A$11,0))*(ISNUMBER(Inventory!$D$5:$D$2004)+(Inventory!$D$5:$D$2004=""))*(ISNUMBER(Inventory!$F$5:$F$2004)+(Inventory!$F$5:$F$2004=""))*(ISNUMBER(Inventory!$G$5:$G$2004)+(Inventory!$G$5:$G$2004=""))*(ISNUMBER(Inventory!$I$5:$I$2004)+(Inventory!$I$5:$I$2004=""))*(Inventory!$F$5:$F$2004>=0)*(Inventory!$G$5:$G$2004>=0)*(Inventory!$K$5:$K$2004>=0)*(Inventory!$L$5:$L$2004>=0)*(Inventory!$M$5:$M$2004>=0)*(Inventory!$N$5:$N$2004>=0)*(Inventory!$O$5:$O$2004>=0)*(ISNUMBER(Inventory!$L$5:$L$2004)+(Inventory!$L$5:$L$2004=""))*(ISNUMBER(Inventory!$M$5:$M$2004)+(Inventory!$M$5:$M$2004=""))*(ISNUMBER(Inventory!$N$5:$N$2004)+(Inventory!$N$5:$N$2004=""))*(ISNUMBER(Inventory!$O$5:$O$2004)+(Inventory!$O$5:$O$2004=""))*(((Inventory!$D$5:$D$2004="")+(Inventory!$J$5:$J$2004>=Inventory!$D$5:$D$2004))>0))+((Inventory!$J$5:$J$2004="")*(Inventory!$K$5:$K$2004="")*(Inventory!$L$5:$L$2004="")*(Inventory!$M$5:$M$2004="")*(Inventory!$N$5:$N$2004="")*(Inventory!$O$5:$O$2004="")*(ISNUMBER(Inventory!$D$5:$D$2004)+(Inventory!$D$5:$D$2004=""))*(ISNUMBER(Inventory!$F$5:$F$2004)+(Inventory!$F$5:$F$2004=""))*(ISNUMBER(Inventory!$G$5:$G$2004)+(Inventory!$G$5:$G$2004=""))*(ISNUMBER(Inventory!$I$5:$I$2004)+(Inventory!$I$5:$I$2004=""))*(Inventory!$F$5:$F$2004>=0)*(Inventory!$G$5:$G$2004>=0)*(Inventory!$K$5:$K$2004>=0)*(Inventory!$L$5:$L$2004>=0)*(Inventory!$M$5:$M$2004>=0)*(Inventory!$N$5:$N$2004>=0)*(Inventory!$O$5:$O$2004>=0)*(((Inventory!$H$5:$H$2004="")+ISNUMBER(MATCH(Inventory!$H$5:$H$2004,Lists!$A$2:$A$11,0)))>0)))=0)) -> 0
A3: Red cell = something to fix. That row stays out of the totals until fixed.
A4: Item ID / SKU | B4: Item | C4: Category | D4: Purchase date | E4: Bought from | F4: Item cost | G4: Extra costs (cleaning, repair) | H4: Platform | I4: Date listed | J4: Date sold | K4: Sale price | L4: Shipping buyer paid | M4: Postage you paid | N4: Actual platform fees (optional) | O4: Refunded to buyer | P4: Status | Q4: Platform fees | R4: Profit | S4: ROI | T4: Days held
A5: EX-001 | B5: EXAMPLE: Levi's 501 jeans | C5: Clothing | D5: 46026 | E5: Thrift store | F5: 6 | G5: 0 | H5: eBay | I5: 46027 | J5: 46041 | K5: 42 | L5: 8 | M5: 7.5 | P5: =IF(OR(B5<>"",F5<>"",H5<>"",J5<>"",K5<>""),IF(J5<>"","Sold",IF(I5<>"","Listed","In stock")),"") -> Sold | Q5: =IF(OR(J5="",H5=""),"",IFERROR(IF(ISNUMBER(N5),N5,IF(K5<N(INDEX(Platforms!$G$5:$G$14,MATCH(H5,Lists!$A$2:$A$11,0))),N(INDEX(Platforms!$H$5:$H$14,MATCH(H5,Lists!$A$2:$A$11,0))),MAX(N(INDEX(Platforms!$F$5:$F$14,MATCH(H5,Lists!$A$2:$A$11,0))),N(INDEX(Platforms!$C$5:$C$14,MATCH(H5,Lists!$A$2:$A$11,0)))*(K5+IF(INDEX(Platforms!$E$5:$E$14,MATCH(H5,Lists!$A$2:$A$11,0))="Yes",N(L5),0))+N(INDEX(Platforms!$D$5:$D$14,MATCH(H5,Lists!$A$2:$A$11,0)))))),"")) -> 7.2 | R5: =IF(J5="","",IFERROR(K5+N(L5)-N(O5)-Q5-N(M5)-N(F5)-N(G5),"")) -> 29.3 | S5: =IF(OR(R5="",N(F5)+N(G5)=0),"",R5/(N(F5)+N(G5))) -> 4.8833333 | T5: =IFERROR(IF(ISNUMBER(D5),IF(ISNUMBER(J5),J5,IF(J5="",TODAY(),""))-D5,""),"") -> 15
A6: EX-002 | B6: EXAMPLE: Le Creuset mug | C6: Home | D6: 46033 | E6: Garage sale | F6: 2 | G6: 1 | H6: Poshmark | I6: 46034 | P6: =IF(OR(B6<>"",F6<>"",H6<>"",J6<>"",K6<>""),IF(J6<>"","Sold",IF(I6<>"","Listed","In stock")),"") -> Listed | Q6: =IF(OR(J6="",H6=""),"",IFERROR(IF(ISNUMBER(N6),N6,IF(K6<N(INDEX(Platforms!$G$5:$G$14,MATCH(H6,Lists!$A$2:$A$11,0))),N(INDEX(Platforms!$H$5:$H$14,MATCH(H6,Lists!$A$2:$A$11,0))),MAX(N(INDEX(Platforms!$F$5:$F$14,MATCH(H6,Lists!$A$2:$A$11,0))),N(INDEX(Platforms!$C$5:$C$14,MATCH(H6,Lists!$A$2:$A$11,0)))*(K6+IF(INDEX(Platforms!$E$5:$E$14,MATCH(H6,Lists!$A$2:$A$11,0))="Yes",N(L6),0))+N(INDEX(Platforms!$D$5:$D$14,MATCH(H6,Lists!$A$2:$A$11,0)))))),"")) | R6: =IF(J6="","",IFERROR(K6+N(L6)-N(O6)-Q6-N(M6)-N(F6)-N(G6),"")) | S6: =IF(OR(R6="",N(F6)+N(G6)=0),"",R6/(N(F6)+N(G6))) | T6: =IFERROR(IF(ISNUMBER(D6),IF(ISNUMBER(J6),J6,IF(J6="",TODAY(),""))-D6,""),"") -> 285
P7: =IF(OR(B7<>"",F7<>"",H7<>"",J7<>"",K7<>""),IF(J7<>"","Sold",IF(I7<>"","Listed","In stock")),"") | Q7: =IF(OR(J7="",H7=""),"",IFERROR(IF(ISNUMBER(N7),N7,IF(K7<N(INDEX(Platforms!$G$5:$G$14,MATCH(H7,Lists!$A$2:$A$11,0))),N(INDEX(Platforms!$H$5:$H$14,MATCH(H7,Lists!$A$2:$A$11,0))),MAX(N(INDEX(Platforms!$F$5:$F$14,MATCH(H7,Lists!$A$2:$A$11,0))),N(INDEX(Platforms!$C$5:$C$14,MATCH(H7,Lists!$A$2:$A$11,0)))*(K7+IF(INDEX(Platforms!$E$5:$E$14,MATCH(H7,Lists!$A$2:$A$11,0))="Yes",N(L7),0))+N(INDEX(Platforms!$D$5:$D$14,MATCH(H7,Lists!$A$2:$A$11,0)))))),"")) | R7: =IF(J7="","",IFERROR(K7+N(L7)-N(O7)-Q7-N(M7)-N(F7)-N(G7),"")) | S7: =IF(OR(R7="",N(F7)+N(G7)=0),"",R7/(N(F7)+N(G7))) | T7: =IFERROR(IF(ISNUMBER(D7),IF(ISNUMBER(J7),J7,IF(J7="",TODAY(),""))-D7,""),"")
P8: =IF(OR(B8<>"",F8<>"",H8<>"",J8<>"",K8<>""),IF(J8<>"","Sold",IF(I8<>"","Listed","In stock")),"") | Q8: =IF(OR(J8="",H8=""),"",IFERROR(IF(ISNUMBER(N8),N8,IF(K8<N(INDEX(Platforms!$G$5:$G$14,MATCH(H8,Lists!$A$2:$A$11,0))),N(INDEX(Platforms!$H$5:$H$14,MATCH(H8,Lists!$A$2:$A$11,0))),MAX(N(INDEX(Platforms!$F$5:$F$14,MATCH(H8,Lists!$A$2:$A$11,0))),N(INDEX(Platforms!$C$5:$C$14,MATCH(H8,Lists!$A$2:$A$11,0)))*(K8+IF(INDEX(Platforms!$E$5:$E$14,MATCH(H8,Lists!$A$2:$A$11,0))="Yes",N(L8),0))+N(INDEX(Platforms!$D$5:$D$14,MATCH(H8,Lists!$A$2:$A$11,0)))))),"")) | R8: =IF(J8="","",IFERROR(K8+N(L8)-N(O8)-Q8-N(M8)-N(F8)-N(G8),"")) | S8: =IF(OR(R8="",N(F8)+N(G8)=0),"",R8/(N(F8)+N(G8))) | T8: =IFERROR(IF(ISNUMBER(D8),IF(ISNUMBER(J8),J8,IF(J8="",TODAY(),""))-D8,""),"")
P9: =IF(OR(B9<>"",F9<>"",H9<>"",J9<>"",K9<>""),IF(J9<>"","Sold",IF(I9<>"","Listed","In stock")),"") | Q9: =IF(OR(J9="",H9=""),"",IFERROR(IF(ISNUMBER(N9),N9,IF(K9<N(INDEX(Platforms!$G$5:$G$14,MATCH(H9,Lists!$A$2:$A$11,0))),N(INDEX(Platforms!$H$5:$H$14,MATCH(H9,Lists!$A$2:$A$11,0))),MAX(N(INDEX(Platforms!$F$5:$F$14,MATCH(H9,Lists!$A$2:$A$11,0))),N(INDEX(Platforms!$C$5:$C$14,MATCH(H9,Lists!$A$2:$A$11,0)))*(K9+IF(INDEX(Platforms!$E$5:$E$14,MATCH(H9,Lists!$A$2:$A$11,0))="Yes",N(L9),0))+N(INDEX(Platforms!$D$5:$D$14,MATCH(H9,Lists!$A$2:$A$11,0)))))),"")) | R9: =IF(J9="","",IFERROR(K9+N(L9)-N(O9)-Q9-N(M9)-N(F9)-N(G9),"")) | S9: =IF(OR(R9="",N(F9)+N(G9)=0),"",R9/(N(F9)+N(G9))) | T9: =IFERROR(IF(ISNUMBER(D9),IF(ISNUMBER(J9),J9,IF(J9="",TODAY(),""))-D9,""),"")
P10: =IF(OR(B10<>"",F10<>"",H10<>"",J10<>"",K10<>""),IF(J10<>"","Sold",IF(I10<>"","Listed","In stock")),"") | Q10: =IF(OR(J10="",H10=""),"",IFERROR(IF(ISNUMBER(N10),N10,IF(K10<N(INDEX(Platforms!$G$5:$G$14,MATCH(H10,Lists!$A$2:$A$11,0))),N(INDEX(Platforms!$H$5:$H$14,MATCH(H10,Lists!$A$2:$A$11,0))),MAX(N(INDEX(Platforms!$F$5:$F$14,MATCH(H10,Lists!$A$2:$A$11,0))),N(INDEX(Platforms!$C$5:$C$14,MATCH(H10,Lists!$A$2:$A$11,0)))*(K10+IF(INDEX(Platforms!$E$5:$E$14,MATCH(H10,Lists!$A$2:$A$11,0))="Yes",N(L10),0))+N(INDEX(Platforms!$D$5:$D$14,MATCH(H10,Lists!$A$2:$A$11,0)))))),"")) | R10: =IF(J10="","",IFERROR(K10+N(L10)-N(O10)-Q10-N(M10)-N(F10)-N(G10),"")) | S10: =IF(OR(R10="",N(F10)+N(G10)=0),"",R10/(N(F10)+N(G10))) | T10: =IFERROR(IF(ISNUMBER(D10),IF(ISNUMBER(J10),J10,IF(J10="",TODAY(),""))-D10,""),"")
P11: =IF(OR(B11<>"",F11<>"",H11<>"",J11<>"",K11<>""),IF(J11<>"","Sold",IF(I11<>"","Listed","In stock")),"") | Q11: =IF(OR(J11="",H11=""),"",IFERROR(IF(ISNUMBER(N11),N11,IF(K11<N(INDEX(Platforms!$G$5:$G$14,MATCH(H11,Lists!$A$2:$A$11,0))),N(INDEX(Platforms!$H$5:$H$14,MATCH(H11,Lists!$A$2:$A$11,0))),MAX(N(INDEX(Platforms!$F$5:$F$14,MATCH(H11,Lists!$A$2:$A$11,0))),N(INDEX(Platforms!$C$5:$C$14,MATCH(H11,Lists!$A$2:$A$11,0)))*(K11+IF(INDEX(Platforms!$E$5:$E$14,MATCH(H11,Lists!$A$2:$A$11,0))="Yes",N(L11),0))+N(INDEX(Platforms!$D$5:$D$14,MATCH(H11,Lists!$A$2:$A$11,0)))))),"")) | R11: =IF(J11="","",IFERROR(K11+N(L11)-N(O11)-Q11-N(M11)-N(F11)-N(G11),"")) | S11: =IF(OR(R11="",N(F11)+N(G11)=0),"",R11/(N(F11)+N(G11))) | T11: =IFERROR(IF(ISNUMBER(D11),IF(ISNUMBER(J11),J11,IF(J11="",TODAY(),""))-D11,""),"")
P12: =IF(OR(B12<>"",F12<>"",H12<>"",J12<>"",K12<>""),IF(J12<>"","Sold",IF(I12<>"","Listed","In stock")),"") | Q12: =IF(OR(J12="",H12=""),"",IFERROR(IF(ISNUMBER(N12),N12,IF(K12<N(INDEX(Platforms!$G$5:$G$14,MATCH(H12,Lists!$A$2:$A$11,0))),N(INDEX(Platforms!$H$5:$H$14,MATCH(H12,Lists!$A$2:$A$11,0))),MAX(N(INDEX(Platforms!$F$5:$F$14,MATCH(H12,Lists!$A$2:$A$11,0))),N(INDEX(Platforms!$C$5:$C$14,MATCH(H12,Lists!$A$2:$A$11,0)))*(K12+IF(INDEX(Platforms!$E$5:$E$14,MATCH(H12,Lists!$A$2:$A$11,0))="Yes",N(L12),0))+N(INDEX(Platforms!$D$5:$D$14,MATCH(H12,Lists!$A$2:$A$11,0)))))),"")) | R12: =IF(J12="","",IFERROR(K12+N(L12)-N(O12)-Q12-N(M12)-N(F12)-N(G12),"")) | S12: =IF(OR(R12="",N(F12)+N(G12)=0),"",R12/(N(F12)+N(G12))) | T12: =IFERROR(IF(ISNUMBER(D12),IF(ISNUMBER(J12),J12,IF(J12="",TODAY(),""))-D12,""),"")
P13: =IF(OR(B13<>"",F13<>"",H13<>"",J13<>"",K13<>""),IF(J13<>"","Sold",IF(I13<>"","Listed","In stock")),"") | Q13: =IF(OR(J13="",H13=""),"",IFERROR(IF(ISNUMBER(N13),N13,IF(K13<N(INDEX(Platforms!$G$5:$G$14,MATCH(H13,Lists!$A$2:$A$11,0))),N(INDEX(Platforms!$H$5:$H$14,MATCH(H13,Lists!$A$2:$A$11,0))),MAX(N(INDEX(Platforms!$F$5:$F$14,MATCH(H13,Lists!$A$2:$A$11,0))),N(INDEX(Platforms!$C$5:$C$14,MATCH(H13,Lists!$A$2:$A$11,0)))*(K13+IF(INDEX(Platforms!$E$5:$E$14,MATCH(H13,Lists!$A$2:$A$11,0))="Yes",N(L13),0))+N(INDEX(Platforms!$D$5:$D$14,MATCH(H13,Lists!$A$2:$A$11,0)))))),"")) | R13: =IF(J13="","",IFERROR(K13+N(L13)-N(O13)-Q13-N(M13)-N(F13)-N(G13),"")) | S13: =IF(OR(R13="",N(F13)+N(G13)=0),"",R13/(N(F13)+N(G13))) | T13: =IFERROR(IF(ISNUMBER(D13),IF(ISNUMBER(J13),J13,IF(J13="",TODAY(),""))-D13,""),"")
P14: =IF(OR(B14<>"",F14<>"",H14<>"",J14<>"",K14<>""),IF(J14<>"","Sold",IF(I14<>"","Listed","In stock")),"") | Q14: =IF(OR(J14="",H14=""),"",IFERROR(IF(ISNUMBER(N14),N14,IF(K14<N(INDEX(Platforms!$G$5:$G$14,MATCH(H14,Lists!$A$2:$A$11,0))),N(INDEX(Platforms!$H$5:$H$14,MATCH(H14,Lists!$A$2:$A$11,0))),MAX(N(INDEX(Platforms!$F$5:$F$14,MATCH(H14,Lists!$A$2:$A$11,0))),N(INDEX(Platforms!$C$5:$C$14,MATCH(H14,Lists!$A$2:$A$11,0)))*(K14+IF(INDEX(Platforms!$E$5:$E$14,MATCH(H14,Lists!$A$2:$A$11,0))="Yes",N(L14),0))+N(INDEX(Platforms!$D$5:$D$14,MATCH(H14,Lists!$A$2:$A$11,0)))))),"")) | R14: =IF(J14="","",IFERROR(K14+N(L14)-N(O14)-Q14-N(M14)-N(F14)-N(G14),"")) | S14: =IF(OR(R14="",N(F14)+N(G14)=0),"",R14/(N(F14)+N(G14))) | T14: =IFERROR(IF(ISNUMBER(D14),IF(ISNUMBER(J14),J14,IF(J14="",TODAY(),""))-D14,""),"")
P15: =IF(OR(B15<>"",F15<>"",H15<>"",J15<>"",K15<>""),IF(J15<>"","Sold",IF(I15<>"","Listed","In stock")),"") | Q15: =IF(OR(J15="",H15=""),"",IFERROR(IF(ISNUMBER(N15),N15,IF(K15<N(INDEX(Platforms!$G$5:$G$14,MATCH(H15,Lists!$A$2:$A$11,0))),N(INDEX(Platforms!$H$5:$H$14,MATCH(H15,Lists!$A$2:$A$11,0))),MAX(N(INDEX(Platforms!$F$5:$F$14,MATCH(H15,Lists!$A$2:$A$11,0))),N(INDEX(Platforms!$C$5:$C$14,MATCH(H15,Lists!$A$2:$A$11,0)))*(K15+IF(INDEX(Platforms!$E$5:$E$14,MATCH(H15,Lists!$A$2:$A$11,0))="Yes",N(L15),0))+N(INDEX(Platforms!$D$5:$D$14,MATCH(H15,Lists!$A$2:$A$11,0)))))),"")) | R15: =IF(J15="","",IFERROR(K15+N(L15)-N(O15)-Q15-N(M15)-N(F15)-N(G15),"")) | S15: =IF(OR(R15="",N(F15)+N(G15)=0),"",R15/(N(F15)+N(G15))) | T15: =IFERROR(IF(ISNUMBER(D15),IF(ISNUMBER(J15),J15,IF(J15="",TODAY(),""))-D15,""),"")
P16: =IF(OR(B16<>"",F16<>"",H16<>"",J16<>"",K16<>""),IF(J16<>"","Sold",IF(I16<>"","Listed","In stock")),"") | Q16: =IF(OR(J16="",H16=""),"",IFERROR(IF(ISNUMBER(N16),N16,IF(K16<N(INDEX(Platforms!$G$5:$G$14,MATCH(H16,Lists!$A$2:$A$11,0))),N(INDEX(Platforms!$H$5:$H$14,MATCH(H16,Lists!$A$2:$A$11,0))),MAX(N(INDEX(Platforms!$F$5:$F$14,MATCH(H16,Lists!$A$2:$A$11,0))),N(INDEX(Platforms!$C$5:$C$14,MATCH(H16,Lists!$A$2:$A$11,0)))*(K16+IF(INDEX(Platforms!$E$5:$E$14,MATCH(H16,Lists!$A$2:$A$11,0))="Yes",N(L16),0))+N(INDEX(Platforms!$D$5:$D$14,MATCH(H16,Lists!$A$2:$A$11,0)))))),"")) | R16: =IF(J16="","",IFERROR(K16+N(L16)-N(O16)-Q16-N(M16)-N(F16)-N(G16),"")) | S16: =IF(OR(R16="",N(F16)+N(G16)=0),"",R16/(N(F16)+N(G16))) | T16: =IFERROR(IF(ISNUMBER(D16),IF(ISNUMBER(J16),J16,IF(J16="",TODAY(),""))-D16,""),"")
P17: =IF(OR(B17<>"",F17<>"",H17<>"",J17<>"",K17<>""),IF(J17<>"","Sold",IF(I17<>"","Listed","In stock")),"") | Q17: =IF(OR(J17="",H17=""),"",IFERROR(IF(ISNUMBER(N17),N17,IF(K17<N(INDEX(Platforms!$G$5:$G$14,MATCH(H17,Lists!$A$2:$A$11,0))),N(INDEX(Platforms!$H$5:$H$14,MATCH(H17,Lists!$A$2:$A$11,0))),MAX(N(INDEX(Platforms!$F$5:$F$14,MATCH(H17,Lists!$A$2:$A$11,0))),N(INDEX(Platforms!$C$5:$C$14,MATCH(H17,Lists!$A$2:$A$11,0)))*(K17+IF(INDEX(Platforms!$E$5:$E$14,MATCH(H17,Lists!$A$2:$A$11,0))="Yes",N(L17),0))+N(INDEX(Platforms!$D$5:$D$14,MATCH(H17,Lists!$A$2:$A$11,0)))))),"")) | R17: =IF(J17="","",IFERROR(K17+N(L17)-N(O17)-Q17-N(M17)-N(F17)-N(G17),"")) | S17: =IF(OR(R17="",N(F17)+N(G17)=0),"",R17/(N(F17)+N(G17))) | T17: =IFERROR(IF(ISNUMBER(D17),IF(ISNUMBER(J17),J17,IF(J17="",TODAY(),""))-D17,""),"")
P18: =IF(OR(B18<>"",F18<>"",H18<>"",J18<>"",K18<>""),IF(J18<>"","Sold",IF(I18<>"","Listed","In stock")),"") | Q18: =IF(OR(J18="",H18=""),"",IFERROR(IF(ISNUMBER(N18),N18,IF(K18<N(INDEX(Platforms!$G$5:$G$14,MATCH(H18,Lists!$A$2:$A$11,0))),N(INDEX(Platforms!$H$5:$H$14,MATCH(H18,Lists!$A$2:$A$11,0))),MAX(N(INDEX(Platforms!$F$5:$F$14,MATCH(H18,Lists!$A$2:$A$11,0))),N(INDEX(Platforms!$C$5:$C$14,MATCH(H18,Lists!$A$2:$A$11,0)))*(K18+IF(INDEX(Platforms!$E$5:$E$14,MATCH(H18,Lists!$A$2:$A$11,0))="Yes",N(L18),0))+N(INDEX(Platforms!$D$5:$D$14,MATCH(H18,Lists!$A$2:$A$11,0)))))),"")) | R18: =IF(J18="","",IFERROR(K18+N(L18)-N(O18)-Q18-N(M18)-N(F18)-N(G18),"")) | S18: =IF(OR(R18="",N(F18)+N(G18)=0),"",R18/(N(F18)+N(G18))) | T18: =IFERROR(IF(ISNUMBER(D18),IF(ISNUMBER(J18),J18,IF(J18="",TODAY(),""))-D18,""),"")
... P2004: =IF(OR(B2004<>"",F2004<>"",H2004<>"",J2004<>"",K2004<>""),IF(J2004<>"","Sold",IF(I2004<>"","Listed","In stock")),"") | Q2004: =IF(OR(J2004="",H2004=""),"",IFERROR(IF(ISNUMBER(N2004),N2004,IF(K2004<N(INDEX(Platforms!$G$5:$G$14,MATCH(H2004,Lists!$A$2:$A$11,0))),N(INDEX(Platforms!$H$5:$H$14,MATCH(H2004,Lists!$A$2:$A$11,0))),MAX(N(INDEX(Platforms!$F$5:$F$14,MATCH(H2004,Lists!$A$2:$A$11,0))),N(INDEX(Platforms!$C$5:$C$14,MATCH(H2004,Lists!$A$2:$A$11,0)))*(K2004+IF(INDEX(Platforms!$E$5:$E$14,MATCH(H2004,Lists!$A$2:$A$11,0))="Yes",N(L2004),0))+N(INDEX(Platforms!$D$5:$D$14,MATCH(H2004,Lists!$A$2:$A$11,0)))))),"")) | R2004: =IF(J2004="","",IFERROR(K2004+N(L2004)-N(O2004)-Q2004-N(M2004)-N(F2004)-N(G2004),"")) | S2004: =IF(OR(R2004="",N(F2004)+N(G2004)=0),"",R2004/(N(F2004)+N(G2004))) | T2004: =IFERROR(IF(ISNUMBER(D2004),IF(ISNUMBER(J2004),J2004,IF(J2004="",TODAY(),""))-D2004,""),"")

Sheet Expenses
A1: Expenses
A2: Business costs not tied to one item. Item costs and postage belong on the Inventory tab. | F2: Rows to fix: | G2: =SUMPRODUCT(((Expenses!$A$5:$A$504<>"")+(Expenses!$B$5:$B$504<>"")+(Expenses!$D$5:$D$504<>"")>0)*((ISNUMBER(Expenses!$A$5:$A$504)*ISNUMBER(MATCH(Expenses!$B$5:$B$504,Lists!$D$2:$D$12,0))*ISNUMBER(Expenses!$D$5:$D$504))=0)) -> 0
A3: Red cell = something to fix. That row stays out of the totals until fixed.
A4: Date | B4: Category | C4: Description / payee | D4: Amount
A5: 46030 | B5: Shipping supplies | C5: EXAMPLE: Poly mailers (100) | D5: 14.99

Sheet Monthly P&L
A1: Monthly P&L
B3: Year: | C3: =Dashboard!C3 -> 2026 | D3: (change it on the Dashboard)
B5: Month | C5: Items sold | D5: Revenue | E5: Platform fees | F5: Postage | G5: Cost of items sold | H5: Expenses | I5: Net profit | J5: Margin | K5: Inventory bought
B6: Jan | C6: =Calc!C3 -> 1 | D6: =Calc!G3 -> 50 | E6: =Calc!H3 -> 7.2 | F6: =Calc!I3 -> 7.5 | G6: =Calc!J3 -> 6 | H6: =Calc!K3 -> 14.99 | I6: =Calc!L3 -> 14.31 | J6: =Calc!M3 -> 0.2862 | K6: =Calc!N3 -> 9
B7: Feb | C7: =Calc!C4 -> 0 | D7: =Calc!G4 -> 0 | E7: =Calc!H4 -> 0 | F7: =Calc!I4 -> 0 | G7: =Calc!J4 -> 0 | H7: =Calc!K4 -> 0 | I7: =Calc!L4 -> 0 | J7: =Calc!M4 -> 0 | K7: =Calc!N4 -> 0
B8: Mar | C8: =Calc!C5 -> 0 | D8: =Calc!G5 -> 0 | E8: =Calc!H5 -> 0 | F8: =Calc!I5 -> 0 | G8: =Calc!J5 -> 0 | H8: =Calc!K5 -> 0 | I8: =Calc!L5 -> 0 | J8: =Calc!M5 -> 0 | K8: =Calc!N5 -> 0
B9: Apr | C9: =Calc!C6 -> 0 | D9: =Calc!G6 -> 0 | E9: =Calc!H6 -> 0 | F9: =Calc!I6 -> 0 | G9: =Calc!J6 -> 0 | H9: =Calc!K6 -> 0 | I9: =Calc!L6 -> 0 | J9: =Calc!M6 -> 0 | K9: =Calc!N6 -> 0
B10: May | C10: =Calc!C7 -> 0 | D10: =Calc!G7 -> 0 | E10: =Calc!H7 -> 0 | F10: =Calc!I7 -> 0 | G10: =Calc!J7 -> 0 | H10: =Calc!K7 -> 0 | I10: =Calc!L7 -> 0 | J10: =Calc!M7 -> 0 | K10: =Calc!N7 -> 0
B11: Jun | C11: =Calc!C8 -> 0 | D11: =Calc!G8 -> 0 | E11: =Calc!H8 -> 0 | F11: =Calc!I8 -> 0 | G11: =Calc!J8 -> 0 | H11: =Calc!K8 -> 0 | I11: =Calc!L8 -> 0 | J11: =Calc!M8 -> 0 | K11: =Calc!N8 -> 0
B12: Jul | C12: =Calc!C9 -> 0 | D12: =Calc!G9 -> 0 | E12: =Calc!H9 -> 0 | F12: =Calc!I9 -> 0 | G12: =Calc!J9 -> 0 | H12: =Calc!K9 -> 0 | I12: =Calc!L9 -> 0 | J12: =Calc!M9 -> 0 | K12: =Calc!N9 -> 0
B13: Aug | C13: =Calc!C10 -> 0 | D13: =Calc!G10 -> 0 | E13: =Calc!H10 -> 0 | F13: =Calc!I10 -> 0 | G13: =Calc!J10 -> 0 | H13: =Calc!K10 -> 0 | I13: =Calc!L10 -> 0 | J13: =Calc!M10 -> 0 | K13: =Calc!N10 -> 0
B14: Sep | C14: =Calc!C11 -> 0 | D14: =Calc!G11 -> 0 | E14: =Calc!H11 -> 0 | F14: =Calc!I11 -> 0 | G14: =Calc!J11 -> 0 | H14: =Calc!K11 -> 0 | I14: =Calc!L11 -> 0 | J14: =Calc!M11 -> 0 | K14: =Calc!N11 -> 0
B15: Oct | C15: =Calc!C12 -> 0 | D15: =Calc!G12 -> 0 | E15: =Calc!H12 -> 0 | F15: =Calc!I12 -> 0 | G15: =Calc!J12 -> 0 | H15: =Calc!K12 -> 0 | I15: =Calc!L12 -> 0 | J15: =Calc!M12 -> 0 | K15: =Calc!N12 -> 0
B16: Nov | C16: =Calc!C13 -> 0 | D16: =Calc!G13 -> 0 | E16: =Calc!H13 -> 0 | F16: =Calc!I13 -> 0 | G16: =Calc!J13 -> 0 | H16: =Calc!K13 -> 0 | I16: =Calc!L13 -> 0 | J16: =Calc!M13 -> 0 | K16: =Calc!N13 -> 0
B17: Dec | C17: =Calc!C14 -> 0 | D17: =Calc!G14 -> 0 | E17: =Calc!H14 -> 0 | F17: =Calc!I14 -> 0 | G17: =Calc!J14 -> 0 | H17: =Calc!K14 -> 0 | I17: =Calc!L14 -> 0 | J17: =Calc!M14 -> 0 | K17: =Calc!N14 -> 0
B18: Total | C18: =Calc!C15 -> 1 | D18: =Calc!G15 -> 50 | E18: =Calc!H15 -> 7.2 | F18: =Calc!I15 -> 7.5 | G18: =Calc!J15 -> 6 | H18: =Calc!K15 -> 14.99 | I18: =Calc!L15 -> 14.31 | J18: =Calc!M15 -> 0.2862 | K18: =Calc!N15 -> 9
B20: Revenue = sale prices + shipping buyers paid - refunds. Item costs count in the month the item sells.
B21: Inventory bought = item + extra costs of everything purchased that month (sold or not): your cash going into stock.

Sheet Buy or Pass
A1: Buy or Pass
A2: Standing in the store? Enter what it sells for and see the most you should pay. Fill the yellow cells.
B4: Inputs | E4: Same item on every platform | F4: Fees | G4: You keep | H4: Most to pay
B5: Platform you'll sell on | C5: eBay | E5: =IF(Platforms!B5="","",Platforms!B5) -> eBay | F5: =IF(E5="","",IFERROR(IF(N($C$6)=0,0,IF(N($C$6)<N(INDEX(Platforms!$G$5:$G$14,1)),N(INDEX(Platforms!$H$5:$H$14,1)),MAX(N(INDEX(Platforms!$F$5:$F$14,1)),N(INDEX(Platforms!$C$5:$C$14,1))*(N($C$6)+IF(INDEX(Platforms!$E$5:$E$14,1)="Yes",N($C$7),0))+N(INDEX(Platforms!$D$5:$D$14,1))))),0)) -> 6.928 | G5: =IF(E5="","",N($C$6)+N($C$7)-F5-N($C$8)) -> 33.072 | H5: =IF(E5="","",MAX(0,G5-N($C$9)-N($C$10))) -> 16.072
B6: Expected sale price | C6: 40 | E6: =IF(Platforms!B6="","",Platforms!B6) -> Poshmark | F6: =IF(E6="","",IFERROR(IF(N($C$6)=0,0,IF(N($C$6)<N(INDEX(Platforms!$G$5:$G$14,2)),N(INDEX(Platforms!$H$5:$H$14,2)),MAX(N(INDEX(Platforms!$F$5:$F$14,2)),N(INDEX(Platforms!$C$5:$C$14,2))*(N($C$6)+IF(INDEX(Platforms!$E$5:$E$14,2)="Yes",N($C$7),0))+N(INDEX(Platforms!$D$5:$D$14,2))))),0)) -> 8 | G6: =IF(E6="","",N($C$6)+N($C$7)-F6-N($C$8)) -> 32 | H6: =IF(E6="","",MAX(0,G6-N($C$9)-N($C$10))) -> 15
B7: Shipping the buyer pays | C7: 8 | E7: =IF(Platforms!B7="","",Platforms!B7) -> Mercari | F7: =IF(E7="","",IFERROR(IF(N($C$6)=0,0,IF(N($C$6)<N(INDEX(Platforms!$G$5:$G$14,3)),N(INDEX(Platforms!$H$5:$H$14,3)),MAX(N(INDEX(Platforms!$F$5:$F$14,3)),N(INDEX(Platforms!$C$5:$C$14,3))*(N($C$6)+IF(INDEX(Platforms!$E$5:$E$14,3)="Yes",N($C$7),0))+N(INDEX(Platforms!$D$5:$D$14,3))))),0)) -> 4.8 | G7: =IF(E7="","",N($C$6)+N($C$7)-F7-N($C$8)) -> 35.2 | H7: =IF(E7="","",MAX(0,G7-N($C$9)-N($C$10))) -> 18.2
B8: Postage you'll pay | C8: 8 | E8: =IF(Platforms!B8="","",Platforms!B8) -> Depop | F8: =IF(E8="","",IFERROR(IF(N($C$6)=0,0,IF(N($C$6)<N(INDEX(Platforms!$G$5:$G$14,4)),N(INDEX(Platforms!$H$5:$H$14,4)),MAX(N(INDEX(Platforms!$F$5:$F$14,4)),N(INDEX(Platforms!$C$5:$C$14,4))*(N($C$6)+IF(INDEX(Platforms!$E$5:$E$14,4)="Yes",N($C$7),0))+N(INDEX(Platforms!$D$5:$D$14,4))))),0)) -> 2.034 | G8: =IF(E8="","",N($C$6)+N($C$7)-F8-N($C$8)) -> 37.966 | H8: =IF(E8="","",MAX(0,G8-N($C$9)-N($C$10))) -> 20.966
B9: Cleaning / repair costs | C9: 2 | E9: =IF(Platforms!B9="","",Platforms!B9) -> Facebook Marketplace | F9: =IF(E9="","",IFERROR(IF(N($C$6)=0,0,IF(N($C$6)<N(INDEX(Platforms!$G$5:$G$14,5)),N(INDEX(Platforms!$H$5:$H$14,5)),MAX(N(INDEX(Platforms!$F$5:$F$14,5)),N(INDEX(Platforms!$C$5:$C$14,5))*(N($C$6)+IF(INDEX(Platforms!$E$5:$E$14,5)="Yes",N($C$7),0))+N(INDEX(Platforms!$D$5:$D$14,5))))),0)) -> 4.8 | G9: =IF(E9="","",N($C$6)+N($C$7)-F9-N($C$8)) -> 35.2 | H9: =IF(E9="","",MAX(0,G9-N($C$9)-N($C$10))) -> 18.2
B10: Profit you want | C10: 15 | E10: =IF(Platforms!B10="","",Platforms!B10) -> Etsy | F10: =IF(E10="","",IFERROR(IF(N($C$6)=0,0,IF(N($C$6)<N(INDEX(Platforms!$G$5:$G$14,6)),N(INDEX(Platforms!$H$5:$H$14,6)),MAX(N(INDEX(Platforms!$F$5:$F$14,6)),N(INDEX(Platforms!$C$5:$C$14,6))*(N($C$6)+IF(INDEX(Platforms!$E$5:$E$14,6)="Yes",N($C$7),0))+N(INDEX(Platforms!$D$5:$D$14,6))))),0)) -> 5.01 | G10: =IF(E10="","",N($C$6)+N($C$7)-F10-N($C$8)) -> 34.99 | H10: =IF(E10="","",MAX(0,G10-N($C$9)-N($C$10))) -> 17.99
E11: =IF(Platforms!B11="","",Platforms!B11) -> Whatnot | F11: =IF(E11="","",IFERROR(IF(N($C$6)=0,0,IF(N($C$6)<N(INDEX(Platforms!$G$5:$G$14,7)),N(INDEX(Platforms!$H$5:$H$14,7)),MAX(N(INDEX(Platforms!$F$5:$F$14,7)),N(INDEX(Platforms!$C$5:$C$14,7))*(N($C$6)+IF(INDEX(Platforms!$E$5:$E$14,7)="Yes",N($C$7),0))+N(INDEX(Platforms!$D$5:$D$14,7))))),0)) -> 5.532 | G11: =IF(E11="","",N($C$6)+N($C$7)-F11-N($C$8)) -> 34.468 | H11: =IF(E11="","",MAX(0,G11-N($C$9)-N($C$10))) -> 17.468
B12: Result | E12: =IF(Platforms!B12="","",Platforms!B12) -> Local / cash | F12: =IF(E12="","",IFERROR(IF(N($C$6)=0,0,IF(N($C$6)<N(INDEX(Platforms!$G$5:$G$14,8)),N(INDEX(Platforms!$H$5:$H$14,8)),MAX(N(INDEX(Platforms!$F$5:$F$14,8)),N(INDEX(Platforms!$C$5:$C$14,8))*(N($C$6)+IF(INDEX(Platforms!$E$5:$E$14,8)="Yes",N($C$7),0))+N(INDEX(Platforms!$D$5:$D$14,8))))),0)) -> 0 | G12: =IF(E12="","",N($C$6)+N($C$7)-F12-N($C$8)) -> 40 | H12: =IF(E12="","",MAX(0,G12-N($C$9)-N($C$10))) -> 23
B13: Platform fees at that price | C13: =IFERROR(IF(N(C6)=0,0,IF(N(C6)<N(INDEX(Platforms!$G$5:$G$14,MATCH($C$5,Lists!$A$2:$A$11,0))),N(INDEX(Platforms!$H$5:$H$14,MATCH($C$5,Lists!$A$2:$A$11,0))),MAX(N(INDEX(Platforms!$F$5:$F$14,MATCH($C$5,Lists!$A$2:$A$11,0))),N(INDEX(Platforms!$C$5:$C$14,MATCH($C$5,Lists!$A$2:$A$11,0)))*(N(C6)+IF(INDEX(Platforms!$E$5:$E$14,MATCH($C$5,Lists!$A$2:$A$11,0))="Yes",N(C7),0))+N(INDEX(Platforms!$D$5:$D$14,MATCH($C$5,Lists!$A$2:$A$11,0)))))),0) -> 6.928 | E13: =IF(Platforms!B13="","",Platforms!B13) | F13: =IF(E13="","",IFERROR(IF(N($C$6)=0,0,IF(N($C$6)<N(INDEX(Platforms!$G$5:$G$14,9)),N(INDEX(Platforms!$H$5:$H$14,9)),MAX(N(INDEX(Platforms!$F$5:$F$14,9)),N(INDEX(Platforms!$C$5:$C$14,9))*(N($C$6)+IF(INDEX(Platforms!$E$5:$E$14,9)="Yes",N($C$7),0))+N(INDEX(Platforms!$D$5:$D$14,9))))),0)) | G13: =IF(E13="","",N($C$6)+N($C$7)-F13-N($C$8)) | H13: =IF(E13="","",MAX(0,G13-N($C$9)-N($C$10)))
B14: You keep after fees and postage | C14: =N(C6)+N(C7)-C13-N(C8) -> 33.072 | E14: =IF(Platforms!B14="","",Platforms!B14) | F14: =IF(E14="","",IFERROR(IF(N($C$6)=0,0,IF(N($C$6)<N(INDEX(Platforms!$G$5:$G$14,10)),N(INDEX(Platforms!$H$5:$H$14,10)),MAX(N(INDEX(Platforms!$F$5:$F$14,10)),N(INDEX(Platforms!$C$5:$C$14,10))*(N($C$6)+IF(INDEX(Platforms!$E$5:$E$14,10)="Yes",N($C$7),0))+N(INDEX(Platforms!$D$5:$D$14,10))))),0)) | G14: =IF(E14="","",N($C$6)+N($C$7)-F14-N($C$8)) | H14: =IF(E14="","",MAX(0,G14-N($C$9)-N($C$10)))
B15: MOST YOU SHOULD PAY | C15: =MAX(0,C14-N(C9)-N(C10)) -> 16.072
B16: Check an asking price | C16: 10 | E16: Uses the sale price, shipping and postage on the left for every platform.
B17: Your profit at that price | C17: =C14-N(C9)-N(C16) -> 21.072
B18: Return on cost (ROI) | C18: =IF(N(C9)+N(C16)>0,C17/(N(C9)+N(C16)),0) -> 1.756
B19: Verdict | C19: =IF(N(C6)=0,"Enter a sale price",IF(N(C16)<=C15,"BUY","PASS (or offer less)")) -> BUY
B21: Postage: on platforms where the buyer pays the label (e.g. Poshmark), enter 0 for both shipping and postage.

Sheet Platforms
A1: Platforms
A2: Fee rates per platform (yellow, edit to match yours) and how each platform did for the Dashboard year.
B4: Platform | C4: Fee % | D4: Fixed fee per order | E4: % also on shipping? | F4: Minimum fee | G4: Flat fee under (price) | H4: Flat fee | J4: Items sold | K4: Revenue | L4: Fees paid | M4: Profit | N4: Profit per item | O4: Default rate notes
B5: eBay | C5: 0.136 | D5: 0.4 | E5: Yes | F5: 0 | G5: 0 | H5: 0 | J5: =IF(B5="","",Calc!P20) -> 1 | K5: =IF(B5="","",Calc!Q20) -> 50 | L5: =IF(B5="","",Calc!R20) -> 7.2 | M5: =IF(B5="","",Calc!U20) -> 29.3 | N5: =IF(OR(B5="",N(J5)=0),"",M5/J5) -> 29.3 | O5: 13.6% of item + shipping (most categories) + $0.40 per order.
B6: Poshmark | C6: 0.2 | D6: 0 | E6: No | F6: 0 | G6: 15 | H6: 2.95 | J6: =IF(B6="","",Calc!P21) -> 0 | K6: =IF(B6="","",Calc!Q21) -> 0 | L6: =IF(B6="","",Calc!R21) -> 0 | M6: =IF(B6="","",Calc!U21) -> 0 | N6: =IF(OR(B6="",N(J6)=0),"",M6/J6) | O6: 20%; flat $2.95 on sales under $15. Buyer pays the label.
B7: Mercari | C7: 0.1 | D7: 0 | E7: Yes | F7: 0 | G7: 0 | H7: 0 | J7: =IF(B7="","",Calc!P22) -> 0 | K7: =IF(B7="","",Calc!Q22) -> 0 | L7: =IF(B7="","",Calc!R22) -> 0 | M7: =IF(B7="","",Calc!U22) -> 0 | N7: =IF(OR(B7="",N(J7)=0),"",M7/J7) | O7: 10% of item + shipping.
B8: Depop | C8: 0.033 | D8: 0.45 | E8: Yes | F8: 0 | G8: 0 | H8: 0 | J8: =IF(B8="","",Calc!P23) -> 0 | K8: =IF(B8="","",Calc!Q23) -> 0 | L8: =IF(B8="","",Calc!R23) -> 0 | M8: =IF(B8="","",Calc!U23) -> 0 | N8: =IF(OR(B8="",N(J8)=0),"",M8/J8) | O8: US: no selling fee; payment processing 3.3% + $0.45.
B9: Facebook Marketplace | C9: 0.1 | D9: 0 | E9: Yes | F9: 0.8 | G9: 0 | H9: 0 | J9: =IF(B9="","",Calc!P24) -> 0 | K9: =IF(B9="","",Calc!Q24) -> 0 | L9: =IF(B9="","",Calc!R24) -> 0 | M9: =IF(B9="","",Calc!U24) -> 0 | N9: =IF(OR(B9="",N(J9)=0),"",M9/J9) | O9: Shipped orders: 10%, minimum $0.80. Local cash sales: use 'Local / cash'.
B10: Etsy | C10: 0.095 | D10: 0.45 | E10: Yes | F10: 0 | G10: 0 | H10: 0 | J10: =IF(B10="","",Calc!P25) -> 0 | K10: =IF(B10="","",Calc!Q25) -> 0 | L10: =IF(B10="","",Calc!R25) -> 0 | M10: =IF(B10="","",Calc!U25) -> 0 | N10: =IF(OR(B10="",N(J10)=0),"",M10/J10) | O10: 6.5% transaction + 3% processing; $0.25 + $0.20 listing renewal.
B11: Whatnot | C11: 0.109 | D11: 0.3 | E11: Yes | F11: 0 | G11: 0 | H11: 0 | J11: =IF(B11="","",Calc!P26) -> 0 | K11: =IF(B11="","",Calc!Q26) -> 0 | L11: =IF(B11="","",Calc!R26) -> 0 | M11: =IF(B11="","",Calc!U26) -> 0 | N11: =IF(OR(B11="",N(J11)=0),"",M11/J11) | O11: 8% commission + 2.9% + $0.30 processing (most categories).
B12: Local / cash | C12: 0 | D12: 0 | E12: No | F12: 0 | G12: 0 | H12: 0 | J12: =IF(B12="","",Calc!P27) -> 0 | K12: =IF(B12="","",Calc!Q27) -> 0 | L12: =IF(B12="","",Calc!R27) -> 0 | M12: =IF(B12="","",Calc!U27) -> 0 | N12: =IF(OR(B12="",N(J12)=0),"",M12/J12) | O12: No fees.
J13: =IF(B13="","",Calc!P28) | K13: =IF(B13="","",Calc!Q28) | L13: =IF(B13="","",Calc!R28) | M13: =IF(B13="","",Calc!U28) | N13: =IF(OR(B13="",N(J13)=0),"",M13/J13) | O13: Add another platform here.
J14: =IF(B14="","",Calc!P29) | K14: =IF(B14="","",Calc!Q29) | L14: =IF(B14="","",Calc!R29) | M14: =IF(B14="","",Calc!U29) | N14: =IF(OR(B14="",N(J14)=0),"",M14/J14) | O14: Add another platform here.
B16: Default rates checked October 2026 (US). Platforms change fees often: confirm on each platform's fee page.

Sheet Lists
A1: Valid platforms (for totals) | B1: Platform dropdown | D1: Expense categories | F1: Yes/No
A2: =IF(Platforms!B5="","[empty slot 1]",Platforms!B5) -> eBay | B2: =IF(Platforms!B5="","",Platforms!B5) -> eBay | D2: Shipping supplies | F2: Yes
A3: =IF(Platforms!B6="","[empty slot 2]",Platforms!B6) -> Poshmark | B3: =IF(Platforms!B6="","",Platforms!B6) -> Poshmark | D3: Packaging | F3: No
A4: =IF(Platforms!B7="","[empty slot 3]",Platforms!B7) -> Mercari | B4: =IF(Platforms!B7="","",Platforms!B7) -> Mercari | D4: Cleaning and repair supplies
A5: =IF(Platforms!B8="","[empty slot 4]",Platforms!B8) -> Depop | B5: =IF(Platforms!B8="","",Platforms!B8) -> Depop | D5: Mileage / sourcing trips
A6: =IF(Platforms!B9="","[empty slot 5]",Platforms!B9) -> Facebook Marketplace | B6: =IF(Platforms!B9="","",Platforms!B9) -> Facebook Marketplace | D6: Storage
A7: =IF(Platforms!B10="","[empty slot 6]",Platforms!B10) -> Etsy | B7: =IF(Platforms!B10="","",Platforms!B10) -> Etsy | D7: Crosslisting / listing software
A8: =IF(Platforms!B11="","[empty slot 7]",Platforms!B11) -> Whatnot | B8: =IF(Platforms!B11="","",Platforms!B11) -> Whatnot | D8: Store subscriptions
A9: =IF(Platforms!B12="","[empty slot 8]",Platforms!B12) -> Local / cash | B9: =IF(Platforms!B12="","",Platforms!B12) -> Local / cash | D9: Promoted listings / ads
A10: =IF(Platforms!B13="","[empty slot 9]",Platforms!B13) -> [empty slot 9] | B10: =IF(Platforms!B13="","",Platforms!B13) | D10: Equipment
A11: =IF(Platforms!B14="","[empty slot 10]",Platforms!B14) -> [empty slot 10] | B11: =IF(Platforms!B14="","",Platforms!B14) | D11: Bank and payout fees
D12: Other

Sheet Calc
B2: Month | C2: Items sold | D2: Sale prices | E2: Shipping paid | F2: Refunds | G2: Revenue | H2: Platform fees | I2: Postage | J2: Cost of items sold | K2: Expenses | L2: Net profit | M2: Margin | N2: Inventory bought
B3: Jan | C3: =SUMPRODUCT((ISNUMBER(Inventory!$J$5:$J$2004)*ISNUMBER(Inventory!$K$5:$K$2004)*ISNUMBER(MATCH(Inventory!$H$5:$H$2004,Lists!$A$2:$A$11,0))*(ISNUMBER(Inventory!$D$5:$D$2004)+(Inventory!$D$5:$D$2004=""))*(ISNUMBER(Inventory!$F$5:$F$2004)+(Inventory!$F$5:$F$2004=""))*(ISNUMBER(Inventory!$G$5:$G$2004)+(Inventory!$G$5:$G$2004=""))*(ISNUMBER(Inventory!$I$5:$I$2004)+(Inventory!$I$5:$I$2004=""))*(Inventory!$F$5:$F$2004>=0)*(Inventory!$G$5:$G$2004>=0)*(Inventory!$K$5:$K$2004>=0)*(Inventory!$L$5:$L$2004>=0)*(Inventory!$M$5:$M$2004>=0)*(Inventory!$N$5:$N$2004>=0)*(Inventory!$O$5:$O$2004>=0)*(ISNUMBER(Inventory!$L$5:$L$2004)+(Inventory!$L$5:$L$2004=""))*(ISNUMBER(Inventory!$M$5:$M$2004)+(Inventory!$M$5:$M$2004=""))*(ISNUMBER(Inventory!$N$5:$N$2004)+(Inventory!$N$5:$N$2004=""))*(ISNUMBER(Inventory!$O$5:$O$2004)+(Inventory!$O$5:$O$2004=""))*(((Inventory!$D$5:$D$2004="")+(Inventory!$J$5:$J$2004>=Inventory!$D$5:$D$2004))>0))*(Inventory!$J$5:$J$2004>=DATE(Dashboard!$C$3,1,1))*(Inventory!$J$5:$J$2004<DATE(Dashboard!$C$3,2,1))) -> 1 | D3: =SUMPRODUCT((ISNUMBER(Inventory!$J$5:$J$2004)*ISNUMBER(Inventory!$K$5:$K$2004)*ISNUMBER(MATCH(Inventory!$H$5:$H$2004,Lists!$A$2:$A$11,0))*(ISNUMBER(Inventory!$D$5:$D$2004)+(Inventory!$D$5:$D$2004=""))*(ISNUMBER(Inventory!$F$5:$F$2004)+(Inventory!$F$5:$F$2004=""))*(ISNUMBER(Inventory!$G$5:$G$2004)+(Inventory!$G$5:$G$2004=""))*(ISNUMBER(Inventory!$I$5:$I$2004)+(Inventory!$I$5:$I$2004=""))*(Inventory!$F$5:$F$2004>=0)*(Inventory!$G$5:$G$2004>=0)*(Inventory!$K$5:$K$2004>=0)*(Inventory!$L$5:$L$2004>=0)*(Inventory!$M$5:$M$2004>=0)*(Inventory!$N$5:$N$2004>=0)*(Inventory!$O$5:$O$2004>=0)*(ISNUMBER(Inventory!$L$5:$L$2004)+(Inventory!$L$5:$L$2004=""))*(ISNUMBER(Inventory!$M$5:$M$2004)+(Inventory!$M$5:$M$2004=""))*(ISNUMBER(Inventory!$N$5:$N$2004)+(Inventory!$N$5:$N$2004=""))*(ISNUMBER(Inventory!$O$5:$O$2004)+(Inventory!$O$5:$O$2004=""))*(((Inventory!$D$5:$D$2004="")+(Inventory!$J$5:$J$2004>=Inventory!$D$5:$D$2004))>0))*(Inventory!$J$5:$J$2004>=DATE(Dashboard!$C$3,1,1))*(Inventory!$J$5:$J$2004<DATE(Dashboard!$C$3,2,1)),Inventory!$K$5:$K$2004) -> 42 | E3: =SUMPRODUCT((ISNUMBER(Inventory!$J$5:$J$2004)*ISNUMBER(Inventory!$K$5:$K$2004)*ISNUMBER(MATCH(Inventory!$H$5:$H$2004,Lists!$A$2:$A$11,0))*(ISNUMBER(Inventory!$D$5:$D$2004)+(Inventory!$D$5:$D$2004=""))*(ISNUMBER(Inventory!$F$5:$F$2004)+(Inventory!$F$5:$F$2004=""))*(ISNUMBER(Inventory!$G$5:$G$2004)+(Inventory!$G$5:$G$2004=""))*(ISNUMBER(Inventory!$I$5:$I$2004)+(Inventory!$I$5:$I$2004=""))*(Inventory!$F$5:$F$2004>=0)*(Inventory!$G$5:$G$2004>=0)*(Inventory!$K$5:$K$2004>=0)*(Inventory!$L$5:$L$2004>=0)*(Inventory!$M$5:$M$2004>=0)*(Inventory!$N$5:$N$2004>=0)*(Inventory!$O$5:$O$2004>=0)*(ISNUMBER(Inventory!$L$5:$L$2004)+(Inventory!$L$5:$L$2004=""))*(ISNUMBER(Inventory!$M$5:$M$2004)+(Inventory!$M$5:$M$2004=""))*(ISNUMBER(Inventory!$N$5:$N$2004)+(Inventory!$N$5:$N$2004=""))*(ISNUMBER(Inventory!$O$5:$O$2004)+(Inventory!$O$5:$O$2004=""))*(((Inventory!$D$5:$D$2004="")+(Inventory!$J$5:$J$2004>=Inventory!$D$5:$D$2004))>0))*(Inventory!$J$5:$J$2004>=DATE(Dashboard!$C$3,1,1))*(Inventory!$J$5:$J$2004<DATE(Dashboard!$C$3,2,1)),Inventory!$L$5:$L$2004) -> 8 | F3: =SUMPRODUCT((ISNUMBER(Inventory!$J$5:$J$2004)*ISNUMBER(Inventory!$K$5:$K$2004)*ISNUMBER(MATCH(Inventory!$H$5:$H$2004,Lists!$A$2:$A$11,0))*(ISNUMBER(Inventory!$D$5:$D$2004)+(Inventory!$D$5:$D$2004=""))*(ISNUMBER(Inventory!$F$5:$F$2004)+(Inventory!$F$5:$F$2004=""))*(ISNUMBER(Inventory!$G$5:$G$2004)+(Inventory!$G$5:$G$2004=""))*(ISNUMBER(Inventory!$I$5:$I$2004)+(Inventory!$I$5:$I$2004=""))*(Inventory!$F$5:$F$2004>=0)*(Inventory!$G$5:$G$2004>=0)*(Inventory!$K$5:$K$2004>=0)*(Inventory!$L$5:$L$2004>=0)*(Inventory!$M$5:$M$2004>=0)*(Inventory!$N$5:$N$2004>=0)*(Inventory!$O$5:$O$2004>=0)*(ISNUMBER(Inventory!$L$5:$L$2004)+(Inventory!$L$5:$L$2004=""))*(ISNUMBER(Inventory!$M$5:$M$2004)+(Inventory!$M$5:$M$2004=""))*(ISNUMBER(Inventory!$N$5:$N$2004)+(Inventory!$N$5:$N$2004=""))*(ISNUMBER(Inventory!$O$5:$O$2004)+(Inventory!$O$5:$O$2004=""))*(((Inventory!$D$5:$D$2004="")+(Inventory!$J$5:$J$2004>=Inventory!$D$5:$D$2004))>0))*(Inventory!$J$5:$J$2004>=DATE(Dashboard!$C$3,1,1))*(Inventory!$J$5:$J$2004<DATE(Dashboard!$C$3,2,1)),Inventory!$O$5:$O$2004) -> 0 | G3: =D3+E3-F3 -> 50 | H3: =SUM(C20:C29) -> 7.2 | I3: =SUMPRODUCT((ISNUMBER(Inventory!$J$5:$J$2004)*ISNUMBER(Inventory!$K$5:$K$2004)*ISNUMBER(MATCH(Inventory!$H$5:$H$2004,Lists!$A$2:$A$11,0))*(ISNUMBER(Inventory!$D$5:$D$2004)+(Inventory!$D$5:$D$2004=""))*(ISNUMBER(Inventory!$F$5:$F$2004)+(Inventory!$F$5:$F$2004=""))*(ISNUMBER(Inventory!$G$5:$G$2004)+(Inventory!$G$5:$G$2004=""))*(ISNUMBER(Inventory!$I$5:$I$2004)+(Inventory!$I$5:$I$2004=""))*(Inventory!$F$5:$F$2004>=0)*(Inventory!$G$5:$G$2004>=0)*(Inventory!$K$5:$K$2004>=0)*(Inventory!$L$5:$L$2004>=0)*(Inventory!$M$5:$M$2004>=0)*(Inventory!$N$5:$N$2004>=0)*(Inventory!$O$5:$O$2004>=0)*(ISNUMBER(Inventory!$L$5:$L$2004)+(Inventory!$L$5:$L$2004=""))*(ISNUMBER(Inventory!$M$5:$M$2004)+(Inventory!$M$5:$M$2004=""))*(ISNUMBER(Inventory!$N$5:$N$2004)+(Inventory!$N$5:$N$2004=""))*(ISNUMBER(Inventory!$O$5:$O$2004)+(Inventory!$O$5:$O$2004=""))*(((Inventory!$D$5:$D$2004="")+(Inventory!$J$5:$J$2004>=Inventory!$D$5:$D$2004))>0))*(Inventory!$J$5:$J$2004>=DATE(Dashboard!$C$3,1,1))*(Inventory!$J$5:$J$2004<DATE(Dashboard!$C$3,2,1)),Inventory!$M$5:$M$2004) -> 7.5 | J3: =SUMPRODUCT((ISNUMBER(Inventory!$J$5:$J$2004)*ISNUMBER(Inventory!$K$5:$K$2004)*ISNUMBER(MATCH(Inventory!$H$5:$H$2004,Lists!$A$2:$A$11,0))*(ISNUMBER(Inventory!$D$5:$D$2004)+(Inventory!$D$5:$D$2004=""))*(ISNUMBER(Inventory!$F$5:$F$2004)+(Inventory!$F$5:$F$2004=""))*(ISNUMBER(Inventory!$G$5:$G$2004)+(Inventory!$G$5:$G$2004=""))*(ISNUMBER(Inventory!$I$5:$I$2004)+(Inventory!$I$5:$I$2004=""))*(Inventory!$F$5:$F$2004>=0)*(Inventory!$G$5:$G$2004>=0)*(Inventory!$K$5:$K$2004>=0)*(Inventory!$L$5:$L$2004>=0)*(Inventory!$M$5:$M$2004>=0)*(Inventory!$N$5:$N$2004>=0)*(Inventory!$O$5:$O$2004>=0)*(ISNUMBER(Inventory!$L$5:$L$2004)+(Inventory!$L$5:$L$2004=""))*(ISNUMBER(Inventory!$M$5:$M$2004)+(Inventory!$M$5:$M$2004=""))*(ISNUMBER(Inventory!$N$5:$N$2004)+(Inventory!$N$5:$N$2004=""))*(ISNUMBER(Inventory!$O$5:$O$2004)+(Inventory!$O$5:$O$2004=""))*(((Inventory!$D$5:$D$2004="")+(Inventory!$J$5:$J$2004>=Inventory!$D$5:$D$2004))>0))*(Inventory!$J$5:$J$2004>=DATE(Dashboard!$C$3,1,1))*(Inventory!$J$5:$J$2004<DATE(Dashboard!$C$3,2,1)),Inventory!$F$5:$F$2004)+SUMPRODUCT((ISNUMBER(Inventory!$J$5:$J$2004)*ISNUMBER(Inventory!$K$5:$K$2004)*ISNUMBER(MATCH(Inventory!$H$5:$H$2004,Lists!$A$2:$A$11,0))*(ISNUMBER(Inventory!$D$5:$D$2004)+(Inventory!$D$5:$D$2004=""))*(ISNUMBER(Inventory!$F$5:$F$2004)+(Inventory!$F$5:$F$2004=""))*(ISNUMBER(Inventory!$G$5:$G$2004)+(Inventory!$G$5:$G$2004=""))*(ISNUMBER(Inventory!$I$5:$I$2004)+(Inventory!$I$5:$I$2004=""))*(Inventory!$F$5:$F$2004>=0)*(Inventory!$G$5:$G$2004>=0)*(Inventory!$K$5:$K$2004>=0)*(Inventory!$L$5:$L$2004>=0)*(Inventory!$M$5:$M$2004>=0)*(Inventory!$N$5:$N$2004>=0)*(Inventory!$O$5:$O$2004>=0)*(ISNUMBER(Inventory!$L$5:$L$2004)+(Inventory!$L$5:$L$2004=""))*(ISNUMBER(Inventory!$M$5:$M$2004)+(Inventory!$M$5:$M$2004=""))*(ISNUMBER(Inventory!$N$5:$N$2004)+(Inventory!$N$5:$N$2004=""))*(ISNUMBER(Inventory!$O$5:$O$2004)+(Inventory!$O$5:$O$2004=""))*(((Inventory!$D$5:$D$2004="")+(Inventory!$J$5:$J$2004>=Inventory!$D$5:$D$2004))>0))*(Inventory!$J$5:$J$2004>=DATE(Dashboard!$C$3,1,1))*(Inventory!$J$5:$J$2004<DATE(Dashboard!$C$3,2,1)),Inventory!$G$5:$G$2004) -> 6 | K3: =SUMPRODUCT((ISNUMBER(Expenses!$A$5:$A$504)*ISNUMBER(MATCH(Expenses!$B$5:$B$504,Lists!$D$2:$D$12,0))*ISNUMBER(Expenses!$D$5:$D$504))*(Expenses!$A$5:$A$504>=DATE(Dashboard!$C$3,1,1))*(Expenses!$A$5:$A$504<DATE(Dashboard!$C$3,2,1)),Expenses!$D$5:$D$504) -> 14.99 | L3: =G3-H3-I3-J3-K3 -> 14.31 | M3: =IF(G3>0,L3/G3,0) -> 0.2862 | N3: =SUMPRODUCT(((((Inventory!$B$5:$B$2004<>"")+(Inventory!$D$5:$D$2004<>"")+(Inventory!$F$5:$F$2004<>"")+(Inventory!$G$5:$G$2004<>"")+(Inventory!$H$5:$H$2004<>"")+(Inventory!$I$5:$I$2004<>"")+(Inventory!$J$5:$J$2004<>"")+(Inventory!$K$5:$K$2004<>"")+(Inventory!$L$5:$L$2004<>"")+(Inventory!$M$5:$M$2004<>"")+(Inventory!$N$5:$N$2004<>"")+(Inventory!$O$5:$O$2004<>""))>0))*((ISNUMBER(Inventory!$J$5:$J$2004)*ISNUMBER(Inventory!$K$5:$K$2004)*ISNUMBER(MATCH(Inventory!$H$5:$H$2004,Lists!$A$2:$A$11,0))*(ISNUMBER(Inventory!$D$5:$D$2004)+(Inventory!$D$5:$D$2004=""))*(ISNUMBER(Inventory!$F$5:$F$2004)+(Inventory!$F$5:$F$2004=""))*(ISNUMBER(Inventory!$G$5:$G$2004)+(Inventory!$G$5:$G$2004=""))*(ISNUMBER(Inventory!$I$5:$I$2004)+(Inventory!$I$5:$I$2004=""))*(Inventory!$F$5:$F$2004>=0)*(Inventory!$G$5:$G$2004>=0)*(Inventory!$K$5:$K$2004>=0)*(Inventory!$L$5:$L$2004>=0)*(Inventory!$M$5:$M$2004>=0)*(Inventory!$N$5:$N$2004>=0)*(Inventory!$O$5:$O$2004>=0)*(ISNUMBER(Inventory!$L$5:$L$2004)+(Inventory!$L$5:$L$2004=""))*(ISNUMBER(Inventory!$M$5:$M$2004)+(Inventory!$M$5:$M$2004=""))*(ISNUMBER(Inventory!$N$5:$N$2004)+(Inventory!$N$5:$N$2004=""))*(ISNUMBER(Inventory!$O$5:$O$2004)+(Inventory!$O$5:$O$2004=""))*(((Inventory!$D$5:$D$2004="")+(Inventory!$J$5:$J$2004>=Inventory!$D$5:$D$2004))>0))+((Inventory!$J$5:$J$2004="")*(Inventory!$K$5:$K$2004="")*(Inventory!$L$5:$L$2004="")*(Inventory!$M$5:$M$2004="")*(Inventory!$N$5:$N$2004="")*(Inventory!$O$5:$O$2004="")*(ISNUMBER(Inventory!$D$5:$D$2004)+(Inventory!$D$5:$D$2004=""))*(ISNUMBER(Inventory!$F$5:$F$2004)+(Inventory!$F$5:$F$2004=""))*(ISNUMBER(Inventory!$G$5:$G$2004)+(Inventory!$G$5:$G$2004=""))*(ISNUMBER(Inventory!$I$5:$I$2004)+(Inventory!$I$5:$I$2004=""))*(Inventory!$F$5:$F$2004>=0)*(Inventory!$G$5:$G$2004>=0)*(Inventory!$K$5:$K$2004>=0)*(Inventory!$L$5:$L$2004>=0)*(Inventory!$M$5:$M$2004>=0)*(Inventory!$N$5:$N$2004>=0)*(Inventory!$O$5:$O$2004>=0)*(((Inventory!$H$5:$H$2004="")+ISNUMBER(MATCH(Inventory!$H$5:$H$2004,Lists!$A$2:$A$11,0)))>0)))*(Inventory!$D$5:$D$2004>=DATE(Dashboard!$C$3,1,1))*(Inventory!$D$5:$D$2004<DATE(Dashboard!$C$3,2,1)),Inventory!$F$5:$F$2004)+SUMPRODUCT(((((Inventory!$B$5:$B$2004<>"")+(Inventory!$D$5:$D$2004<>"")+(Inventory!$F$5:$F$2004<>"")+(Inventory!$G$5:$G$2004<>"")+(Inventory!$H$5:$H$2004<>"")+(Inventory!$I$5:$I$2004<>"")+(Inventory!$J$5:$J$2004<>"")+(Inventory!$K$5:$K$2004<>"")+(Inventory!$L$5:$L$2004<>"")+(Inventory!$M$5:$M$2004<>"")+(Inventory!$N$5:$N$2004<>"")+(Inventory!$O$5:$O$2004<>""))>0))*((ISNUMBER(Inventory!$J$5:$J$2004)*ISNUMBER(Inventory!$K$5:$K$2004)*ISNUMBER(MATCH(Inventory!$H$5:$H$2004,Lists!$A$2:$A$11,0))*(ISNUMBER(Inventory!$D$5:$D$2004)+(Inventory!$D$5:$D$2004=""))*(ISNUMBER(Inventory!$F$5:$F$2004)+(Inventory!$F$5:$F$2004=""))*(ISNUMBER(Inventory!$G$5:$G$2004)+(Inventory!$G$5:$G$2004=""))*(ISNUMBER(Inventory!$I$5:$I$2004)+(Inventory!$I$5:$I$2004=""))*(Inventory!$F$5:$F$2004>=0)*(Inventory!$G$5:$G$2004>=0)*(Inventory!$K$5:$K$2004>=0)*(Inventory!$L$5:$L$2004>=0)*(Inventory!$M$5:$M$2004>=0)*(Inventory!$N$5:$N$2004>=0)*(Inventory!$O$5:$O$2004>=0)*(ISNUMBER(Inventory!$L$5:$L$2004)+(Inventory!$L$5:$L$2004=""))*(ISNUMBER(Inventory!$M$5:$M$2004)+(Inventory!$M$5:$M$2004=""))*(ISNUMBER(Inventory!$N$5:$N$2004)+(Inventory!$N$5:$N$2004=""))*(ISNUMBER(Inventory!$O$5:$O$2004)+(Inventory!$O$5:$O$2004=""))*(((Inventory!$D$5:$D$2004="")+(Inventory!$J$5:$J$2004>=Inventory!$D$5:$D$2004))>0))+((Inventory!$J$5:$J$2004="")*(Inventory!$K$5:$K$2004="")*(Inventory!$L$5:$L$2004="")*(Inventory!$M$5:$M$2004="")*(Inventory!$N$5:$N$2004="")*(Inventory!$O$5:$O$2004="")*(ISNUMBER(Inventory!$D$5:$D$2004)+(Inventory!$D$5:$D$2004=""))*(ISNUMBER(Inventory!$F$5:$F$2004)+(Inventory!$F$5:$F$2004=""))*(ISNUMBER(Inventory!$G$5:$G$2004)+(Inventory!$G$5:$G$2004=""))*(ISNUMBER(Inventory!$I$5:$I$2004)+(Inventory!$I$5:$I$2004=""))*(Inventory!$F$5:$F$2004>=0)*(Inventory!$G$5:$G$2004>=0)*(Inventory!$K$5:$K$2004>=0)*(Inventory!$L$5:$L$2004>=0)*(Inventory!$M$5:$M$2004>=0)*(Inventory!$N$5:$N$2004>=0)*(Inventory!$O$5:$O$2004>=0)*(((Inventory!$H$5:$H$2004="")+ISNUMBER(MATCH(Inventory!$H$5:$H$2004,Lists!$A$2:$A$11,0)))>0)))*(Inventory!$D$5:$D$2004>=DATE(Dashboard!$C$3,1,1))*(Inventory!$D$5:$D$2004<DATE(Dashboard!$C$3,2,1)),Inventory!$G$5:$G$2004) -> 9
B4: Feb | C4: =SUMPRODUCT((ISNUMBER(Inventory!$J$5:$J$2004)*ISNUMBER(Inventory!$K$5:$K$2004)*ISNUMBER(MATCH(Inventory!$H$5:$H$2004,Lists!$A$2:$A$11,0))*(ISNUMBER(Inventory!$D$5:$D$2004)+(Inventory!$D$5:$D$2004=""))*(ISNUMBER(Inventory!$F$5:$F$2004)+(Inventory!$F$5:$F$2004=""))*(ISNUMBER(Inventory!$G$5:$G$2004)+(Inventory!$G$5:$G$2004=""))*(ISNUMBER(Inventory!$I$5:$I$2004)+(Inventory!$I$5:$I$2004=""))*(Inventory!$F$5:$F$2004>=0)*(Inventory!$G$5:$G$2004>=0)*(Inventory!$K$5:$K$2004>=0)*(Inventory!$L$5:$L$2004>=0)*(Inventory!$M$5:$M$2004>=0)*(Inventory!$N$5:$N$2004>=0)*(Inventory!$O$5:$O$2004>=0)*(ISNUMBER(Inventory!$L$5:$L$2004)+(Inventory!$L$5:$L$2004=""))*(ISNUMBER(Inventory!$M$5:$M$2004)+(Inventory!$M$5:$M$2004=""))*(ISNUMBER(Inventory!$N$5:$N$2004)+(Inventory!$N$5:$N$2004=""))*(ISNUMBER(Inventory!$O$5:$O$2004)+(Inventory!$O$5:$O$2004=""))*(((Inventory!$D$5:$D$2004="")+(Inventory!$J$5:$J$2004>=Inventory!$D$5:$D$2004))>0))*(Inventory!$J$5:$J$2004>=DATE(Dashboard!$C$3,2,1))*(Inventory!$J$5:$J$2004<DATE(Dashboard!$C$3,3,1))) -> 0 | D4: =SUMPRODUCT((ISNUMBER(Inventory!$J$5:$J$2004)*ISNUMBER(Inventory!$K$5:$K$2004)*ISNUMBER(MATCH(Inventory!$H$5:$H$2004,Lists!$A$2:$A$11,0))*(ISNUMBER(Inventory!$D$5:$D$2004)+(Inventory!$D$5:$D$2004=""))*(ISNUMBER(Inventory!$F$5:$F$2004)+(Inventory!$F$5:$F$2004=""))*(ISNUMBER(Inventory!$G$5:$G$2004)+(Inventory!$G$5:$G$2004=""))*(ISNUMBER(Inventory!$I$5:$I$2004)+(Inventory!$I$5:$I$2004=""))*(Inventory!$F$5:$F$2004>=0)*(Inventory!$G$5:$G$2004>=0)*(Inventory!$K$5:$K$2004>=0)*(Inventory!$L$5:$L$2004>=0)*(Inventory!$M$5:$M$2004>=0)*(Inventory!$N$5:$N$2004>=0)*(Inventory!$O$5:$O$2004>=0)*(ISNUMBER(Inventory!$L$5:$L$2004)+(Inventory!$L$5:$L$2004=""))*(ISNUMBER(Inventory!$M$5:$M$2004)+(Inventory!$M$5:$M$2004=""))*(ISNUMBER(Inventory!$N$5:$N$2004)+(Inventory!$N$5:$N$2004=""))*(ISNUMBER(Inventory!$O$5:$O$2004)+(Inventory!$O$5:$O$2004=""))*(((Inventory!$D$5:$D$2004="")+(Inventory!$J$5:$J$2004>=Inventory!$D$5:$D$2004))>0))*(Inventory!$J$5:$J$2004>=DATE(Dashboard!$C$3,2,1))*(Inventory!$J$5:$J$2004<DATE(Dashboard!$C$3,3,1)),Inventory!$K$5:$K$2004) -> 0 | E4: =SUMPRODUCT((ISNUMBER(Inventory!$J$5:$J$2004)*ISNUMBER(Inventory!$K$5:$K$2004)*ISNUMBER(MATCH(Inventory!$H$5:$H$2004,Lists!$A$2:$A$11,0))*(ISNUMBER(Inventory!$D$5:$D$2004)+(Inventory!$D$5:$D$2004=""))*(ISNUMBER(Inventory!$F$5:$F$2004)+(Inventory!$F$5:$F$2004=""))*(ISNUMBER(Inventory!$G$5:$G$2004)+(Inventory!$G$5:$G$2004=""))*(ISNUMBER(Inventory!$I$5:$I$2004)+(Inventory!$I$5:$I$2004=""))*(Inventory!$F$5:$F$2004>=0)*(Inventory!$G$5:$G$2004>=0)*(Inventory!$K$5:$K$2004>=0)*(Inventory!$L$5:$L$2004>=0)*(Inventory!$M$5:$M$2004>=0)*(Inventory!$N$5:$N$2004>=0)*(Inventory!$O$5:$O$2004>=0)*(ISNUMBER(Inventory!$L$5:$L$2004)+(Inventory!$L$5:$L$2004=""))*(ISNUMBER(Inventory!$M$5:$M$2004)+(Inventory!$M$5:$M$2004=""))*(ISNUMBER(Inventory!$N$5:$N$2004)+(Inventory!$N$5:$N$2004=""))*(ISNUMBER(Inventory!$O$5:$O$2004)+(Inventory!$O$5:$O$2004=""))*(((Inventory!$D$5:$D$2004="")+(Inventory!$J$5:$J$2004>=Inventory!$D$5:$D$2004))>0))*(Inventory!$J$5:$J$2004>=DATE(Dashboard!$C$3,2,1))*(Inventory!$J$5:$J$2004<DATE(Dashboard!$C$3,3,1)),Inventory!$L$5:$L$2004) -> 0 | F4: =SUMPRODUCT((ISNUMBER(Inventory!$J$5:$J$2004)*ISNUMBER(Inventory!$K$5:$K$2004)*ISNUMBER(MATCH(Inventory!$H$5:$H$2004,Lists!$A$2:$A$11,0))*(ISNUMBER(Inventory!$D$5:$D$2004)+(Inventory!$D$5:$D$2004=""))*(ISNUMBER(Inventory!$F$5:$F$2004)+(Inventory!$F$5:$F$2004=""))*(ISNUMBER(Inventory!$G$5:$G$2004)+(Inventory!$G$5:$G$2004=""))*(ISNUMBER(Inventory!$I$5:$I$2004)+(Inventory!$I$5:$I$2004=""))*(Inventory!$F$5:$F$2004>=0)*(Inventory!$G$5:$G$2004>=0)*(Inventory!$K$5:$K$2004>=0)*(Inventory!$L$5:$L$2004>=0)*(Inventory!$M$5:$M$2004>=0)*(Inventory!$N$5:$N$2004>=0)*(Inventory!$O$5:$O$2004>=0)*(ISNUMBER(Inventory!$L$5:$L$2004)+(Inventory!$L$5:$L$2004=""))*(ISNUMBER(Inventory!$M$5:$M$2004)+(Inventory!$M$5:$M$2004=""))*(ISNUMBER(Inventory!$N$5:$N$2004)+(Inventory!$N$5:$N$2004=""))*(ISNUMBER(Inventory!$O$5:$O$2004)+(Inventory!$O$5:$O$2004=""))*(((Inventory!$D$5:$D$2004="")+(Inventory!$J$5:$J$2004>=Inventory!$D$5:$D$2004))>0))*(Inventory!$J$5:$J$2004>=DATE(Dashboard!$C$3,2,1))*(Inventory!$J$5:$J$2004<DATE(Dashboard!$C$3,3,1)),Inventory!$O$5:$O$2004) -> 0 | G4: =D4+E4-F4 -> 0 | H4: =SUM(D20:D29) -> 0 | I4: =SUMPRODUCT((ISNUMBER(Inventory!$J$5:$J$2004)*ISNUMBER(Inventory!$K$5:$K$2004)*ISNUMBER(MATCH(Inventory!$H$5:$H$2004,Lists!$A$2:$A$11,0))*(ISNUMBER(Inventory!$D$5:$D$2004)+(Inventory!$D$5:$D$2004=""))*(ISNUMBER(Inventory!$F$5:$F$2004)+(Inventory!$F$5:$F$2004=""))*(ISNUMBER(Inventory!$G$5:$G$2004)+(Inventory!$G$5:$G$2004=""))*(ISNUMBER(Inventory!$I$5:$I$2004)+(Inventory!$I$5:$I$2004=""))*(Inventory!$F$5:$F$2004>=0)*(Inventory!$G$5:$G$2004>=0)*(Inventory!$K$5:$K$2004>=0)*(Inventory!$L$5:$L$2004>=0)*(Inventory!$M$5:$M$2004>=0)*(Inventory!$N$5:$N$2004>=0)*(Inventory!$O$5:$O$2004>=0)*(ISNUMBER(Inventory!$L$5:$L$2004)+(Inventory!$L$5:$L$2004=""))*(ISNUMBER(Inventory!$M$5:$M$2004)+(Inventory!$M$5:$M$2004=""))*(ISNUMBER(Inventory!$N$5:$N$2004)+(Inventory!$N$5:$N$2004=""))*(ISNUMBER(Inventory!$O$5:$O$2004)+(Inventory!$O$5:$O$2004=""))*(((Inventory!$D$5:$D$2004="")+(Inventory!$J$5:$J$2004>=Inventory!$D$5:$D$2004))>0))*(Inventory!$J$5:$J$2004>=DATE(Dashboard!$C$3,2,1))*(Inventory!$J$5:$J$2004<DATE(Dashboard!$C$3,3,1)),Inventory!$M$5:$M$2004) -> 0 | J4: =SUMPRODUCT((ISNUMBER(Inventory!$J$5:$J$2004)*ISNUMBER(Inventory!$K$5:$K$2004)*ISNUMBER(MATCH(Inventory!$H$5:$H$2004,Lists!$A$2:$A$11,0))*(ISNUMBER(Inventory!$D$5:$D$2004)+(Inventory!$D$5:$D$2004=""))*(ISNUMBER(Inventory!$F$5:$F$2004)+(Inventory!$F$5:$F$2004=""))*(ISNUMBER(Inventory!$G$5:$G$2004)+(Inventory!$G$5:$G$2004=""))*(ISNUMBER(Inventory!$I$5:$I$2004)+(Inventory!$I$5:$I$2004=""))*(Inventory!$F$5:$F$2004>=0)*(Inventory!$G$5:$G$2004>=0)*(Inventory!$K$5:$K$2004>=0)*(Inventory!$L$5:$L$2004>=0)*(Inventory!$M$5:$M$2004>=0)*(Inventory!$N$5:$N$2004>=0)*(Inventory!$O$5:$O$2004>=0)*(ISNUMBER(Inventory!$L$5:$L$2004)+(Inventory!$L$5:$L$2004=""))*(ISNUMBER(Inventory!$M$5:$M$2004)+(Inventory!$M$5:$M$2004=""))*(ISNUMBER(Inventory!$N$5:$N$2004)+(Inventory!$N$5:$N$2004=""))*(ISNUMBER(Inventory!$O$5:$O$2004)+(Inventory!$O$5:$O$2004=""))*(((Inventory!$D$5:$D$2004="")+(Inventory!$J$5:$J$2004>=Inventory!$D$5:$D$2004))>0))*(Inventory!$J$5:$J$2004>=DATE(Dashboard!$C$3,2,1))*(Inventory!$J$5:$J$2004<DATE(Dashboard!$C$3,3,1)),Inventory!$F$5:$F$2004)+SUMPRODUCT((ISNUMBER(Inventory!$J$5:$J$2004)*ISNUMBER(Inventory!$K$5:$K$2004)*ISNUMBER(MATCH(Inventory!$H$5:$H$2004,Lists!$A$2:$A$11,0))*(ISNUMBER(Inventory!$D$5:$D$2004)+(Inventory!$D$5:$D$2004=""))*(ISNUMBER(Inventory!$F$5:$F$2004)+(Inventory!$F$5:$F$2004=""))*(ISNUMBER(Inventory!$G$5:$G$2004)+(Inventory!$G$5:$G$2004=""))*(ISNUMBER(Inventory!$I$5:$I$2004)+(Inventory!$I$5:$I$2004=""))*(Inventory!$F$5:$F$2004>=0)*(Inventory!$G$5:$G$2004>=0)*(Inventory!$K$5:$K$2004>=0)*(Inventory!$L$5:$L$2004>=0)*(Inventory!$M$5:$M$2004>=0)*(Inventory!$N$5:$N$2004>=0)*(Inventory!$O$5:$O$2004>=0)*(ISNUMBER(Inventory!$L$5:$L$2004)+(Inventory!$L$5:$L$2004=""))*(ISNUMBER(Inventory!$M$5:$M$2004)+(Inventory!$M$5:$M$2004=""))*(ISNUMBER(Inventory!$N$5:$N$2004)+(Inventory!$N$5:$N$2004=""))*(ISNUMBER(Inventory!$O$5:$O$2004)+(Inventory!$O$5:$O$2004=""))*(((Inventory!$D$5:$D$2004="")+(Inventory!$J$5:$J$2004>=Inventory!$D$5:$D$2004))>0))*(Inventory!$J$5:$J$2004>=DATE(Dashboard!$C$3,2,1))*(Inventory!$J$5:$J$2004<DATE(Dashboard!$C$3,3,1)),Inventory!$G$5:$G$2004) -> 0 | K4: =SUMPRODUCT((ISNUMBER(Expenses!$A$5:$A$504)*ISNUMBER(MATCH(Expenses!$B$5:$B$504,Lists!$D$2:$D$12,0))*ISNUMBER(Expenses!$D$5:$D$504))*(Expenses!$A$5:$A$504>=DATE(Dashboard!$C$3,2,1))*(Expenses!$A$5:$A$504<DATE(Dashboard!$C$3,3,1)),Expenses!$D$5:$D$504) -> 0 | L4: =G4-H4-I4-J4-K4 -> 0 | M4: =IF(G4>0,L4/G4,0) -> 0 | N4: =SUMPRODUCT(((((Inventory!$B$5:$B$2004<>"")+(Inventory!$D$5:$D$2004<>"")+(Inventory!$F$5:$F$2004<>"")+(Inventory!$G$5:$G$2004<>"")+(Inventory!$H$5:$H$2004<>"")+(Inventory!$I$5:$I$2004<>"")+(Inventory!$J$5:$J$2004<>"")+(Inventory!$K$5:$K$2004<>"")+(Inventory!$L$5:$L$2004<>"")+(Inventory!$M$5:$M$2004<>"")+(Inventory!$N$5:$N$2004<>"")+(Inventory!$O$5:$O$2004<>""))>0))*((ISNUMBER(Inventory!$J$5:$J$2004)*ISNUMBER(Inventory!$K$5:$K$2004)*ISNUMBER(MATCH(Inventory!$H$5:$H$2004,Lists!$A$2:$A$11,0))*(ISNUMBER(Inventory!$D$5:$D$2004)+(Inventory!$D$5:$D$2004=""))*(ISNUMBER(Inventory!$F$5:$F$2004)+(Inventory!$F$5:$F$2004=""))*(ISNUMBER(Inventory!$G$5:$G$2004)+(Inventory!$G$5:$G$2004=""))*(ISNUMBER(Inventory!$I$5:$I$2004)+(Inventory!$I$5:$I$2004=""))*(Inventory!$F$5:$F$2004>=0)*(Inventory!$G$5:$G$2004>=0)*(Inventory!$K$5:$K$2004>=0)*(Inventory!$L$5:$L$2004>=0)*(Inventory!$M$5:$M$2004>=0)*(Inventory!$N$5:$N$2004>=0)*(Inventory!$O$5:$O$2004>=0)*(ISNUMBER(Inventory!$L$5:$L$2004)+(Inventory!$L$5:$L$2004=""))*(ISNUMBER(Inventory!$M$5:$M$2004)+(Inventory!$M$5:$M$2004=""))*(ISNUMBER(Inventory!$N$5:$N$2004)+(Inventory!$N$5:$N$2004=""))*(ISNUMBER(Inventory!$O$5:$O$2004)+(Inventory!$O$5:$O$2004=""))*(((Inventory!$D$5:$D$2004="")+(Inventory!$J$5:$J$2004>=Inventory!$D$5:$D$2004))>0))+((Inventory!$J$5:$J$2004="")*(Inventory!$K$5:$K$2004="")*(Inventory!$L$5:$L$2004="")*(Inventory!$M$5:$M$2004="")*(Inventory!$N$5:$N$2004="")*(Inventory!$O$5:$O$2004="")*(ISNUMBER(Inventory!$D$5:$D$2004)+(Inventory!$D$5:$D$2004=""))*(ISNUMBER(Inventory!$F$5:$F$2004)+(Inventory!$F$5:$F$2004=""))*(ISNUMBER(Inventory!$G$5:$G$2004)+(Inventory!$G$5:$G$2004=""))*(ISNUMBER(Inventory!$I$5:$I$2004)+(Inventory!$I$5:$I$2004=""))*(Inventory!$F$5:$F$2004>=0)*(Inventory!$G$5:$G$2004>=0)*(Inventory!$K$5:$K$2004>=0)*(Inventory!$L$5:$L$2004>=0)*(Inventory!$M$5:$M$2004>=0)*(Inventory!$N$5:$N$2004>=0)*(Inventory!$O$5:$O$2004>=0)*(((Inventory!$H$5:$H$2004="")+ISNUMBER(MATCH(Inventory!$H$5:$H$2004,Lists!$A$2:$A$11,0)))>0)))*(Inventory!$D$5:$D$2004>=DATE(Dashboard!$C$3,2,1))*(Inventory!$D$5:$D$2004<DATE(Dashboard!$C$3,3,1)),Inventory!$F$5:$F$2004)+SUMPRODUCT(((((Inventory!$B$5:$B$2004<>"")+(Inventory!$D$5:$D$2004<>"")+(Inventory!$F$5:$F$2004<>"")+(Inventory!$G$5:$G$2004<>"")+(Inventory!$H$5:$H$2004<>"")+(Inventory!$I$5:$I$2004<>"")+(Inventory!$J$5:$J$2004<>"")+(Inventory!$K$5:$K$2004<>"")+(Inventory!$L$5:$L$2004<>"")+(Inventory!$M$5:$M$2004<>"")+(Inventory!$N$5:$N$2004<>"")+(Inventory!$O$5:$O$2004<>""))>0))*((ISNUMBER(Inventory!$J$5:$J$2004)*ISNUMBER(Inventory!$K$5:$K$2004)*ISNUMBER(MATCH(Inventory!$H$5:$H$2004,Lists!$A$2:$A$11,0))*(ISNUMBER(Inventory!$D$5:$D$2004)+(Inventory!$D$5:$D$2004=""))*(ISNUMBER(Inventory!$F$5:$F$2004)+(Inventory!$F$5:$F$2004=""))*(ISNUMBER(Inventory!$G$5:$G$2004)+(Inventory!$G$5:$G$2004=""))*(ISNUMBER(Inventory!$I$5:$I$2004)+(Inventory!$I$5:$I$2004=""))*(Inventory!$F$5:$F$2004>=0)*(Inventory!$G$5:$G$2004>=0)*(Inventory!$K$5:$K$2004>=0)*(Inventory!$L$5:$L$2004>=0)*(Inventory!$M$5:$M$2004>=0)*(Inventory!$N$5:$N$2004>=0)*(Inventory!$O$5:$O$2004>=0)*(ISNUMBER(Inventory!$L$5:$L$2004)+(Inventory!$L$5:$L$2004=""))*(ISNUMBER(Inventory!$M$5:$M$2004)+(Inventory!$M$5:$M$2004=""))*(ISNUMBER(Inventory!$N$5:$N$2004)+(Inventory!$N$5:$N$2004=""))*(ISNUMBER(Inventory!$O$5:$O$2004)+(Inventory!$O$5:$O$2004=""))*(((Inventory!$D$5:$D$2004="")+(Inventory!$J$5:$J$2004>=Inventory!$D$5:$D$2004))>0))+((Inventory!$J$5:$J$2004="")*(Inventory!$K$5:$K$2004="")*(Inventory!$L$5:$L$2004="")*(Inventory!$M$5:$M$2004="")*(Inventory!$N$5:$N$2004="")*(Inventory!$O$5:$O$2004="")*(ISNUMBER(Inventory!$D$5:$D$2004)+(Inventory!$D$5:$D$2004=""))*(ISNUMBER(Inventory!$F$5:$F$2004)+(Inventory!$F$5:$F$2004=""))*(ISNUMBER(Inventory!$G$5:$G$2004)+(Inventory!$G$5:$G$2004=""))*(ISNUMBER(Inventory!$I$5:$I$2004)+(Inventory!$I$5:$I$2004=""))*(Inventory!$F$5:$F$2004>=0)*(Inventory!$G$5:$G$2004>=0)*(Inventory!$K$5:$K$2004>=0)*(Inventory!$L$5:$L$2004>=0)*(Inventory!$M$5:$M$2004>=0)*(Inventory!$N$5:$N$2004>=0)*(Inventory!$O$5:$O$2004>=0)*(((Inventory!$H$5:$H$2004="")+ISNUMBER(MATCH(Inventory!$H$5:$H$2004,Lists!$A$2:$A$11,0)))>0)))*(Inventory!$D$5:$D$2004>=DATE(Dashboard!$C$3,2,1))*(Inventory!$D$5:$D$2004<DATE(Dashboard!$C$3,3,1)),Inventory!$G$5:$G$2004) -> 0
